Workbook
Name a: #REF!
Name ai: #REF!
Name aq: #REF!
Name AV: #REF!
Name baa: #REF!
Name Coord: #REF!
Name CS: #REF!
Name CZ: #REF!
Name DG: #REF!
Name earlier: #REF!
Name EG: #REF!
Name EI: #REF!
Name HLinst: #REF!
Name HP: #REF!
Name I: #REF!
Name JA: #REF!
Name Mean_A: #REF!
Name mean_X: #REF!
Name mean_X.: #REF!
Name mean_Y: #REF!
Name mean_Y.: #REF!
Name mu: #REF!
Name mu_A: #REF!
Name mu_B: #REF!
Name P1_A: #REF!
Name P2_A: #REF!
Name P3_A: #REF!
Name P4_A: #REF!
Name P5_A: #REF!
Name Rot: #REF!
Name SD_A: #REF!
Name SD_X: #REF!
Name SD_Y: #REF!
Name sigma: #REF!
Name sigma_AB: #REF!
Name sigma2_A: #REF!
Name sigma2_B: #REF!
Name Tab.43: #REF!
Name Tab.44: #REF!
Name Target_P: #REF!
Name Total_Mass: #REF!
Name Variance_A: #REF!
Name X: #REF!
Name x_A: #REF!
Name x_B: #REF!
Name Xo: #REF!
Name Yo.1: #REF!
Name Yo.2: #REF!
Name yt: #REF!

Sheet 11
B1: a2_sfr_pakdata | Z1: b2_sfr_conn | AS1: c2_sfr_div | AX1: e2_ghb_spd.csv | CH1: 1
AS2: d2_sfr_spd.csv | AX2: f2_wel_spd | DE2: 1
R3: =MAX(R6:R41) -> 4 | S3: =MAX(S6:S41) -> 9 | T3: =MAX(T6:T41) -> 15 | U3: =MAX(U6:U41) -> 19 | V3: =MAX(V6:V41) -> 23 | W3: =MAX(W6:W41) -> 27 | X3: =MAX(X6:X41) -> 31 | Y3: =MAX(Y6:Y41) -> 36 | AX3: g2_obs_list | AZ3: K11_stream | BD3: K11_basin | BI3: idomain | BT3: dif | CE3: ET | CI3: =365.25 * 86400 -> 31557600 | CJ3: 1 | CK3: 2 | CL3: 3 | CM3: 4 | CN3: 1 | CO3: 2 | CP3: 3 | CQ3: 4 | CR3: sfr-p01.sfr.obs.csv
B4: SRT | C4: z | D4: y | E4: x | J4: - | K4: K_str | M4: order | O4: / | R4: 1 | S4: =R4+1 -> 2 | T4: =S4+1 -> 3 | U4: =T4+1 -> 4 | V4: =U4+1 -> 5 | W4: =V4+1 -> 6 | X4: =W4+1 -> 7 | Y4: =X4+1 -> 8 | AT4: ... | AU4: ... | AV4: ... | AZ4: 1 | BA4: 1 | BB4: 0 | BC4: 0 | BD4: 0 | BE4: 0 | BF4: 0 | BG4: 0 | BH4: 0 | BI4: 0 | BK4: =AZ20-BK20 -> -5 | BL4: =BA20-BL20 -> -5 | BM4: =BB20-BM20 -> 0 | BN4: =BC20-BN20 -> 0 | BO4: =BD20-BO20 -> 0 | BP4: =BE20-BP20 -> 0 | BQ4: =BF20-BQ20 -> 0 | BR4: =BG20-BR20 -> 0 | ... BT4: =BI20-BT20 -> 0 | BV4: 2.5e-10 | BW4: 1e-09 | BX4: 0 | BY4: 0 | BZ4: 0 | CA4: 0 | CB4: 0 | CC4: 0 | CD4: 0 | CE4: 0 | CH4: =MAX(CH5:CH105) -> 100 | CI4: time | CJ4: R01_STAGE | CK4: R02_STAGE | CL4: R03_STAGE | CM4: R04_STAGE | CN4: R01_FLOW | CO4: R02_FLOW | CP4: R03_FLOW | CQ4: R04_FLOW | CR4: =MIN(CN5:CN105) -> -16.431847
D5: i | E5: j | F5: Q | G5: Width | I5: H | J5: - | L5: Roughness | M5: 0 | O5: 0 | P5: 1 | Q5: 1 | R5: ="" | AA5: 0 | AB5: 1 | AC5: 2 | AD5: 3 | AE5: 1 | AT5: 0 | AU5: 1 | AV5: 2 | AW5: 3 | AZ5: 2 | BA5: 1 | BB5: 1 | BC5: 0 | BD5: 0 | BE5: 2 | BF5: 2 | BG5: 2 | BH5: 0 | BI5: 0 | BK5: =AZ21-BK21 -> -5 | BL5: =BA21-BL21 -> -10 | BM5: =BB21-BM21 -> -5 | BN5: =BC21-BN21 -> 0 | BO5: =BD21-BO21 -> 0 | BP5: =BE21-BP21 -> 0 | BQ5: =BF21-BQ21 -> 0 | BR5: =BG21-BR21 -> 0 | ... BT5: =BI21-BT21 -> 0 | BV5: 1e-09 | BW5: 2.5e-10 | BX5: 1e-09 | BY5: 0 | BZ5: 0 | CA5: 4e-09 | CB5: 4e-09 | CC5: 4e-09 | CD5: 0 | CE5: 0 | CH5: =CI5/$CI$3 -> 0 | CI5: 0 | CJ5: 1078.4168 | CK5: 1061.581 | CL5: 1026.2829 | CM5: 993.31165 | CN5: -16.431847 | CO5: -3.5856045 | CP5: -3.7018762 | CQ5: -153.67702 | CR5: =CN5-$CR$4 -> 0
A6: 1 | B6: 0 | C6: 0 | D6: 0 | E6: 0 | F6: 4500 | G6: 12 | H6: 0.00086767896 | I6: 1093.048 | J6: 3 | K6: 3e-05 | L6: 0.03 | M6: 1 | N6: 1 | O6: 0 | P6: =IF(OR(M6-M5<0,N6=0),MAX(P$5:P5)+1,0) -> 0 | Q6: =IF(P7="",Q5,IF(P6=0,Q5,P6)) -> 1 | R6: =IF($Q6=R$4,$A6,$R$5) -> 1 | S6: =IF($Q6=S$4,$A6,$R$5) | T6: =IF($Q6=T$4,$A6,$R$5) | U6: =IF($Q6=U$4,$A6,$R$5) | V6: =IF($Q6=V$4,$A6,$R$5) | W6: =IF($Q6=W$4,$A6,$R$5) | X6: =IF($Q6=X$4,$A6,$R$5) | Y6: =IF($Q6=Y$4,$A6,$R$5) | Z6: 0 | AA6: 0 | AB6: -1 | AE6: =_xlfn.CONCAT(E6+1,",",D6+1) -> 1,1 | AG6: =AG56 -> 1 | AH6: =AH56 -> 2 | AI6: =AI56 -> 3 | AJ6: =AJ56 -> 4 | AK6: =AK56 -> 5 | AL6: =AL56 -> 6 | AM6: =AM56 -> 7 | AN6: =AN56 -> 8 | ... AP6: =AP56 -> 10 | AS6: 0 | AT6: 3 | AU6: 0 | AV6: 9 | AW6: UPTO | AZ6: 0 | BA6: 2 | BB6: 1 | BC6: 1 | BD6: 2 | BE6: 2 | BF6: 2 | BG6: 2 | BH6: 0 | BI6: 0 | BK6: =AZ22-BK22 -> 0 | BL6: =BA22-BL22 -> 0 | BM6: =BB22-BM22 -> -10 | BN6: =BC22-BN22 -> -8 | BO6: =BD22-BO22 -> -7 | BP6: =BE22-BP22 -> -9 | BQ6: =BF22-BQ22 -> -12 | BR6: =BG22-BR22 -> 0 | ... BT6: =BI22-BT22 -> 0 | BV6: 0 | BW6: 1e-09 | BX6: 2.5e-10 | BY6: 1e-09 | BZ6: 1e-09 | CA6: 2.5e-10 | CB6: 2.5e-10 | CC6: 2.5e-10 | CD6: 0 | CE6: 0 | CH6: =CI6/$CI$3 -> 0.042958702 | CI6: 1355673.5 | CJ6: 1078.4168 | CK6: 1061.581 | CL6: 1026.2568 | CM6: 993.30937 | CN6: -16.431833 | CO6: -3.5771224 | CP6: -3.3101859 | CQ6: -153.27215 | CR6: =CN6-$CR$4 -> 1.37e-05
A7: =A6+1 -> 2 | B7: 1 | C7: 0 | D7: 1 | E7: 1 | F7: 7000 | G7: 12 | H7: 0.00086767896 | I7: 1088.059 | J7: 3 | K7: 3e-05 | L7: 0.03 | M7: 2 | N7: 1 | O7: 0 | P7: =IF(OR(M7-M6<0,N7=0),MAX(P$5:P6)+1,0) -> 0 | Q7: =IF(P8="",Q6,IF(P7=0,Q6,P7)) -> 1 | R7: =IF(Q7=R$4,A7,$R$5) -> 2 | S7: =IF($Q7=S$4,$A7,$R$5) | T7: =IF($Q7=T$4,$A7,$R$5) | U7: =IF($Q7=U$4,$A7,$R$5) | V7: =IF($Q7=V$4,$A7,$R$5) | W7: =IF($Q7=W$4,$A7,$R$5) | X7: =IF($Q7=X$4,$A7,$R$5) | Y7: =IF($Q7=Y$4,$A7,$R$5) | Z7: 1 | AA7: 1 | AB7: 0 | AC7: -2 | AE7: =_xlfn.CONCAT(E7+1,",",D7+1) -> 2,2 | AF7: 1 | AG7: =IF(ISNUMBER(MATCH(AG58,$AX$29:$AX$38,0)),$AX$28,IF(ISNUMBER(MATCH(AG58,$AX$26:$AX$27,0)),$AX$25,IF(ISNUMBER(MATCH(AG58,$AE$6:$AE$41,0)),$AE$5,$O$5))) -> 1 | AH7: =IF(ISNUMBER(MATCH(AH58,$AX$29:$AX$38,0)),$AX$28,IF(ISNUMBER(MATCH(AH58,$AX$26:$AX$27,0)),$AX$25,IF(ISNUMBER(MATCH(AH58,$AE$6:$AE$41,0)),$AE$5,$O$5))) -> 0 | AI7: =IF(ISNUMBER(MATCH(AI58,$AX$29:$AX$38,0)),$AX$28,IF(ISNUMBER(MATCH(AI58,$AX$26:$AX$27,0)),$AX$25,IF(ISNUMBER(MATCH(AI58,$AE$6:$AE$41,0)),$AE$5,$O$5))) -> 0 | AJ7: =IF(ISNUMBER(MATCH(AJ58,$AX$29:$AX$38,0)),$AX$28,IF(ISNUMBER(MATCH(AJ58,$AX$26:$AX$27,0)),$AX$25,IF(ISNUMBER(MATCH(AJ58,$AE$6:$AE$41,0)),$AE$5,$O$5))) -> 0 | AK7: =IF(ISNUMBER(MATCH(AK58,$AX$29:$AX$38,0)),$AX$28,IF(ISNUMBER(MATCH(AK58,$AX$26:$AX$27,0)),$AX$25,IF(ISNUMBER(MATCH(AK58,$AE$6:$AE$41,0)),$AE$5,$O$5))) -> 0 | AL7: =IF(ISNUMBER(MATCH(AL58,$AX$29:$AX$38,0)),$AX$28,IF(ISNUMBER(MATCH(AL58,$AX$26:$AX$27,0)),$AX$25,IF(ISNUMBER(MATCH(AL58,$AE$6:$AE$41,0)),$AE$5,$O$5))) -> 0 | AM7: =IF(ISNUMBER(MATCH(AM58,$AX$29:$AX$38,0)),$AX$28,IF(ISNUMBER(MATCH(AM58,$AX$26:$AX$27,0)),$AX$25,IF(ISNUMBER(MATCH(AM58,$AE$6:$AE$41,0)),$AE$5,$O$5))) -> 0 | AN7: =IF(ISNUMBER(MATCH(AN58,$AX$29:$AX$38,0)),$AX$28,IF(ISNUMBER(MATCH(AN58,$AX$26:$AX$27,0)),$AX$25,IF(ISNUMBER(MATCH(AN58,$AE$6:$AE$41,0)),$AE$5,$O$5))) -> 0 | ... AP7: =IF(ISNUMBER(MATCH(AP58,$AX$29:$AX$38,0)),$AX$28,IF(ISNUMBER(MATCH(AP58,$AX$26:$AX$27,0)),$AX$25,IF(ISNUMBER(MATCH(AP58,$AE$6:$AE$41,0)),$AE$5,$O$5))) -> 0 | AV7: Q ... | AZ7: 2 | BA7: 2 | BB7: 2 | BC7: 1 | BD7: 1 | BE7: 1 | BF7: 2 | BG7: 2 | BH7: 2 | BI7: 0 | BK7: =AZ23-BK23 -> 5 | BL7: =BA23-BL23 -> 0 | BM7: =BB23-BM23 -> 0 | BN7: =BC23-BN23 -> 2 | BO7: =BD23-BO23 -> -2 | BP7: =BE23-BP23 -> 5 | BQ7: =BF23-BQ23 -> 0 | BR7: =BG23-BR23 -> -15 | ... BT7: =BI23-BT23 -> 0 | BV7: 4e-09 | BW7: 2.5e-10 | BX7: 2.5e-10 | BY7: 2.5e-10 | BZ7: 2.5e-10 | CA7: 2.5e-10 | CB7: 2.5e-10 | CC7: 2.5e-10 | CD7: 1e-09 | CE7: 0 | CH7: =CI7/$CI$3 -> 0.090213275 | CI7: 2846914.4 | CJ7: 1078.4168 | CK7: 1061.581 | CL7: 1026.2035 | CM7: 993.30472 | CN7: -16.43174 | CO7: -3.5465207 | CP7: -2.5688975 | CQ7: -152.44663 | CR7: =CN7-$CR$4 -> 0.00010681
A8: =A7+1 -> 3 | B8: 2 | C8: 0 | D8: 2 | E8: 2 | F8: 6000 | G8: 12 | H8: 0.00086767896 | I8: 1082.419 | J8: 3 | K8: 3e-05 | L8: 0.03 | M8: 2 | N8: 1 | O8: 0 | P8: =IF(OR(M8-M7<0,N8=0),MAX(P$5:P7)+1,0) -> 0 | Q8: =IF(P9="",Q7,IF(P8=0,Q7,P8)) -> 1 | R8: =IF(Q8=R$4,A8,$R$5) -> 3 | S8: =IF($Q8=S$4,$A8,$R$5) | T8: =IF($Q8=T$4,$A8,$R$5) | U8: =IF($Q8=U$4,$A8,$R$5) | V8: =IF($Q8=V$4,$A8,$R$5) | W8: =IF($Q8=W$4,$A8,$R$5) | X8: =IF($Q8=X$4,$A8,$R$5) | Y8: =IF($Q8=Y$4,$A8,$R$5) | Z8: 2 | AA8: 2 | AB8: 1 | AC8: -3 | AE8: =_xlfn.CONCAT(E8+1,",",D8+1) -> 3,3 | AF8: =AF7+1 -> 2 | AG8: =IF(ISNUMBER(MATCH(AG59,$AX$29:$AX$38,0)),$AX$28,IF(ISNUMBER(MATCH(AG59,$AX$26:$AX$27,0)),$AX$25,IF(ISNUMBER(MATCH(AG59,$AE$6:$AE$41,0)),$AE$5,$O$5))) -> 0 | AH8: =IF(ISNUMBER(MATCH(AH59,$AX$29:$AX$38,0)),$AX$28,IF(ISNUMBER(MATCH(AH59,$AX$26:$AX$27,0)),$AX$25,IF(ISNUMBER(MATCH(AH59,$AE$6:$AE$41,0)),$AE$5,$O$5))) -> 1 | AI8: =IF(ISNUMBER(MATCH(AI59,$AX$29:$AX$38,0)),$AX$28,IF(ISNUMBER(MATCH(AI59,$AX$26:$AX$27,0)),$AX$25,IF(ISNUMBER(MATCH(AI59,$AE$6:$AE$41,0)),$AE$5,$O$5))) -> 0 | AJ8: =IF(ISNUMBER(MATCH(AJ59,$AX$29:$AX$38,0)),$AX$28,IF(ISNUMBER(MATCH(AJ59,$AX$26:$AX$27,0)),$AX$25,IF(ISNUMBER(MATCH(AJ59,$AE$6:$AE$41,0)),$AE$5,$O$5))) -> 0 | AK8: =IF(ISNUMBER(MATCH(AK59,$AX$29:$AX$38,0)),$AX$28,IF(ISNUMBER(MATCH(AK59,$AX$26:$AX$27,0)),$AX$25,IF(ISNUMBER(MATCH(AK59,$AE$6:$AE$41,0)),$AE$5,$O$5))) -> 0 | AL8: =IF(ISNUMBER(MATCH(AL59,$AX$29:$AX$38,0)),$AX$28,IF(ISNUMBER(MATCH(AL59,$AX$26:$AX$27,0)),$AX$25,IF(ISNUMBER(MATCH(AL59,$AE$6:$AE$41,0)),$AE$5,$O$5))) -> 0 | AM8: =IF(ISNUMBER(MATCH(AM59,$AX$29:$AX$38,0)),$AX$28,IF(ISNUMBER(MATCH(AM59,$AX$26:$AX$27,0)),$AX$25,IF(ISNUMBER(MATCH(AM59,$AE$6:$AE$41,0)),$AE$5,$O$5))) -> 0 | AN8: =IF(ISNUMBER(MATCH(AN59,$AX$29:$AX$38,0)),$AX$28,IF(ISNUMBER(MATCH(AN59,$AX$26:$AX$27,0)),$AX$25,IF(ISNUMBER(MATCH(AN59,$AE$6:$AE$41,0)),$AE$5,$O$5))) -> 0 | ... AP8: =IF(ISNUMBER(MATCH(AP59,$AX$29:$AX$38,0)),$AX$28,IF(ISNUMBER(MATCH(AP59,$AX$26:$AX$27,0)),$AX$25,IF(ISNUMBER(MATCH(AP59,$AE$6:$AE$41,0)),$AE$5,$O$5))) -> 0 | AT8: 0 | AU8: 1 | AV8: 2 | AW8: 3 | AZ8: 2 | BA8: 2 | BB8: 2 | BC8: 1 | BD8: 1 | BE8: 1 | BF8: 1 | BG8: 1 | BH8: 1 | BI8: 1 | BK8: =AZ24-BK24 -> 5 | BL8: =BA24-BL24 -> 10 | BM8: =BB24-BM24 -> 5 | BN8: =BC24-BN24 -> 3 | BO8: =BD24-BO24 -> 4 | BP8: =BE24-BP24 -> 1 | BQ8: =BF24-BQ24 -> 3 | BR8: =BG24-BR24 -> -12 | ... BT8: =BI24-BT24 -> -5 | BV8: 4e-09 | BW8: 2.5e-10 | BX8: 2.5e-10 | BY8: 2.5e-10 | BZ8: 2.5e-10 | CA8: 2.5e-10 | CB8: 2.5e-10 | CC8: 2.5e-10 | CD8: 2.5e-10 | CE8: 2.5e-10 | CH8: =CI8/$CI$3 -> 0.1421933 | CI8: 4487279.4 | CJ8: 1078.4168 | CK8: 1061.581 | CL8: 1026.1312 | CM8: 993.29866 | CN8: -16.431384 | CO8: -3.4785563 | CP8: -1.7018017 | CQ8: -151.37401 | CR8: =CN8-$CR$4 -> 0.00046252
A9: =A8+1 -> 4 | B9: 3 | C9: 0 | D9: 2 | E9: 3 | F9: 5550 | G9: 12 | H9: 0.00086767896 | I9: 1077.408 | J9: 3 | K9: 3e-05 | L9: 0.03 | M9: 3 | N9: 1 | O9: 1 | P9: =IF(OR(M9-M8<0,N9=0),MAX(P$5:P8)+1,0) -> 0 | Q9: =IF(P10="",Q8,IF(P9=0,Q8,P9)) -> 1 | R9: =IF(Q9=R$4,A9,$R$5) -> 4 | S9: =IF($Q9=S$4,$A9,$R$5) | T9: =IF($Q9=T$4,$A9,$R$5) | U9: =IF($Q9=U$4,$A9,$R$5) | V9: =IF($Q9=V$4,$A9,$R$5) | W9: =IF($Q9=W$4,$A9,$R$5) | X9: =IF($Q9=X$4,$A9,$R$5) | Y9: =IF($Q9=Y$4,$A9,$R$5) | Z9: 3 | AA9: 3 | AB9: 2 | AC9: -4 | AD9: -9 | AE9: =_xlfn.CONCAT(E9+1,",",D9+1) -> 4,3 | AF9: =AF8+1 -> 3 | AG9: =IF(ISNUMBER(MATCH(AG60,$AX$29:$AX$38,0)),$AX$28,IF(ISNUMBER(MATCH(AG60,$AX$26:$AX$27,0)),$AX$25,IF(ISNUMBER(MATCH(AG60,$AE$6:$AE$41,0)),$AE$5,$O$5))) -> 0 | AH9: =IF(ISNUMBER(MATCH(AH60,$AX$29:$AX$38,0)),$AX$28,IF(ISNUMBER(MATCH(AH60,$AX$26:$AX$27,0)),$AX$25,IF(ISNUMBER(MATCH(AH60,$AE$6:$AE$41,0)),$AE$5,$O$5))) -> 0 | AI9: =IF(ISNUMBER(MATCH(AI60,$AX$29:$AX$38,0)),$AX$28,IF(ISNUMBER(MATCH(AI60,$AX$26:$AX$27,0)),$AX$25,IF(ISNUMBER(MATCH(AI60,$AE$6:$AE$41,0)),$AE$5,$O$5))) -> 1 | AJ9: =IF(ISNUMBER(MATCH(AJ60,$AX$29:$AX$38,0)),$AX$28,IF(ISNUMBER(MATCH(AJ60,$AX$26:$AX$27,0)),$AX$25,IF(ISNUMBER(MATCH(AJ60,$AE$6:$AE$41,0)),$AE$5,$O$5))) -> 1 | AK9: =IF(ISNUMBER(MATCH(AK60,$AX$29:$AX$38,0)),$AX$28,IF(ISNUMBER(MATCH(AK60,$AX$26:$AX$27,0)),$AX$25,IF(ISNUMBER(MATCH(AK60,$AE$6:$AE$41,0)),$AE$5,$O$5))) -> 1 | AL9: =IF(ISNUMBER(MATCH(AL60,$AX$29:$AX$38,0)),$AX$28,IF(ISNUMBER(MATCH(AL60,$AX$26:$AX$27,0)),$AX$25,IF(ISNUMBER(MATCH(AL60,$AE$6:$AE$41,0)),$AE$5,$O$5))) -> 1 | AM9: =IF(ISNUMBER(MATCH(AM60,$AX$29:$AX$38,0)),$AX$28,IF(ISNUMBER(MATCH(AM60,$AX$26:$AX$27,0)),$AX$25,IF(ISNUMBER(MATCH(AM60,$AE$6:$AE$41,0)),$AE$5,$O$5))) -> 1 | AN9: =IF(ISNUMBER(MATCH(AN60,$AX$29:$AX$38,0)),$AX$28,IF(ISNUMBER(MATCH(AN60,$AX$26:$AX$27,0)),$AX$25,IF(ISNUMBER(MATCH(AN60,$AE$6:$AE$41,0)),$AE$5,$O$5))) -> 0 | ... AP9: =IF(ISNUMBER(MATCH(AP60,$AX$29:$AX$38,0)),$AX$28,IF(ISNUMBER(MATCH(AP60,$AX$26:$AX$27,0)),$AX$25,IF(ISNUMBER(MATCH(AP60,$AE$6:$AE$41,0)),$AE$5,$O$5))) -> 0 | AS9: 0 | AT9: 0 | AU9: inflow | AV9: 25 | AZ9: 2 | BA9: 2 | BB9: 2 | BC9: 1 | BD9: 1 | BE9: 1 | BF9: 1 | BG9: 1 | BH9: 2 | BI9: 2 | BK9: =AZ25-BK25 -> 5 | BL9: =BA25-BL25 -> 15 | BM9: =BB25-BM25 -> 5 | BN9: =BC25-BN25 -> 5 | BO9: =BD25-BO25 -> 2 | BP9: =BE25-BP25 -> 0 | BQ9: =BF25-BQ25 -> 0 | BR9: =BG25-BR25 -> -12 | ... BT9: =BI25-BT25 -> -5 | BV9: 1e-09 | BW9: 2.5e-10 | BX9: 2.5e-10 | BY9: 2.5e-10 | BZ9: 2.5e-10 | CA9: 2.5e-10 | CB9: 2.5e-10 | CC9: 2.5e-10 | CD9: 2.5e-10 | CE9: 1e-09 | CH9: =CI9/$CI$3 -> 0.19937134 | CI9: 6291680.9 | CJ9: 1078.4168 | CK9: 1061.581 | CL9: 1026.0303 | CM9: 993.29151 | CN9: -16.430382 | CO9: -3.3592292 | CP9: -0.78456948 | CQ9: -150.10997 | CR9: =CN9-$CR$4 -> 0.0014648
A10: =A9+1 -> 5 | B10: 4 | C10: 0 | D10: 3 | E10: 4 | F10: 6500 | G10: 12 | H10: 0.00094339624 | I10: 1071.934 | J10: 3 | K10: 3e-05 | L10: 0.03 | M10: 2 | N10: 1 | O10: 0 | P10: =IF(OR(M10-M9<0,N10=0),MAX(P$5:P9)+1,0) -> 2 | Q10: =IF(P11="",Q9,IF(P10=0,Q9,P10)) -> 2 | R10: =IF(Q10=R$4,A10,$R$5) | S10: =IF($Q10=S$4,$A10,$R$5) -> 5 | T10: =IF($Q10=T$4,$A10,$R$5) | U10: =IF($Q10=U$4,$A10,$R$5) | V10: =IF($Q10=V$4,$A10,$R$5) | W10: =IF($Q10=W$4,$A10,$R$5) | X10: =IF($Q10=X$4,$A10,$R$5) | Y10: =IF($Q10=Y$4,$A10,$R$5) | Z10: 4 | AA10: 4 | AB10: 3 | AC10: -5 | AE10: =_xlfn.CONCAT(E10+1,",",D10+1) -> 5,4 | AF10: =AF9+1 -> 4 | AG10: =IF(ISNUMBER(MATCH(AG61,$AX$29:$AX$38,0)),$AX$28,IF(ISNUMBER(MATCH(AG61,$AX$26:$AX$27,0)),$AX$25,IF(ISNUMBER(MATCH(AG61,$AE$6:$AE$41,0)),$AE$5,$O$5))) -> 0 | AH10: =IF(ISNUMBER(MATCH(AH61,$AX$29:$AX$38,0)),$AX$28,IF(ISNUMBER(MATCH(AH61,$AX$26:$AX$27,0)),$AX$25,IF(ISNUMBER(MATCH(AH61,$AE$6:$AE$41,0)),$AE$5,$O$5))) -> 0 | AI10: =IF(ISNUMBER(MATCH(AI61,$AX$29:$AX$38,0)),$AX$28,IF(ISNUMBER(MATCH(AI61,$AX$26:$AX$27,0)),$AX$25,IF(ISNUMBER(MATCH(AI61,$AE$6:$AE$41,0)),$AE$5,$O$5))) -> 0 | AJ10: =IF(ISNUMBER(MATCH(AJ61,$AX$29:$AX$38,0)),$AX$28,IF(ISNUMBER(MATCH(AJ61,$AX$26:$AX$27,0)),$AX$25,IF(ISNUMBER(MATCH(AJ61,$AE$6:$AE$41,0)),$AE$5,$O$5))) -> 0 | AK10: =IF(ISNUMBER(MATCH(AK61,$AX$29:$AX$38,0)),$AX$28,IF(ISNUMBER(MATCH(AK61,$AX$26:$AX$27,0)),$AX$25,IF(ISNUMBER(MATCH(AK61,$AE$6:$AE$41,0)),$AE$5,$O$5))) -> 1 | AL10: =IF(ISNUMBER(MATCH(AL61,$AX$29:$AX$38,0)),$AX$28,IF(ISNUMBER(MATCH(AL61,$AX$26:$AX$27,0)),$AX$25,IF(ISNUMBER(MATCH(AL61,$AE$6:$AE$41,0)),$AE$5,$O$5))) -> 0 | AM10: =IF(ISNUMBER(MATCH(AM61,$AX$29:$AX$38,0)),$AX$28,IF(ISNUMBER(MATCH(AM61,$AX$26:$AX$27,0)),$AX$25,IF(ISNUMBER(MATCH(AM61,$AE$6:$AE$41,0)),$AE$5,$O$5))) -> 0 | AN10: =IF(ISNUMBER(MATCH(AN61,$AX$29:$AX$38,0)),$AX$28,IF(ISNUMBER(MATCH(AN61,$AX$26:$AX$27,0)),$AX$25,IF(ISNUMBER(MATCH(AN61,$AE$6:$AE$41,0)),$AE$5,$O$5))) -> 1 | ... AP10: =IF(ISNUMBER(MATCH(AP61,$AX$29:$AX$38,0)),$AX$28,IF(ISNUMBER(MATCH(AP61,$AX$26:$AX$27,0)),$AX$25,IF(ISNUMBER(MATCH(AP61,$AE$6:$AE$41,0)),$AE$5,$O$5))) -> 0 | AS10: 1 | AT10: 15 | AU10: inflow | AV10: 10 | AZ10: 2 | BA10: 2 | BB10: 2 | BC10: 1 | BD10: 1 | BE10: 1 | BF10: 1 | BG10: 1 | BH10: 2 | BI10: 0 | BK10: =AZ26-BK26 -> 5 | BL10: =BA26-BL26 -> 10 | BM10: =BB26-BM26 -> 5 | BN10: =BC26-BN26 -> 7 | BO10: =BD26-BO26 -> 5 | BP10: =BE26-BP26 -> 0 | BQ10: =BF26-BQ26 -> 0 | BR10: =BG26-BR26 -> -1 | ... BT10: =BI26-BT26 -> 0 | BV10: 1e-09 | BW10: 2.5e-10 | BX10: 2.5e-10 | BY10: 2.5e-10 | BZ10: 2.5e-10 | CA10: 2.5e-10 | CB10: 2.5e-10 | CC10: 2.5e-10 | CD10: 1e-09 | CE10: 0 | CH10: =CI10/$CI$3 -> 0.26226717 | CI10: 8276522.6 | CJ10: 1078.4167 | CK10: 1061.581 | CL10: 1025.987 | CM10: 993.28666 | CN10: -16.428066 | CO10: -3.1775397 | CP10: -0.50988165 | CQ10: -149.25293 | CR10: =CN10-$CR$4 -> 0.0037812
A11: =A10+1 -> 6 | B11: 5 | C11: 0 | D11: 4 | E11: 5 | F11: 5000 | G11: 12 | H11: 0.00094339624 | I11: 1066.509 | J11: 3 | K11: 3e-05 | L11: 0.03 | M11: 2 | N11: 1 | O11: 0 | P11: =IF(OR(M11-M10<0,N11=0),MAX(P$5:P10)+1,0) -> 0 | Q11: =IF(P12="",Q10,IF(P11=0,Q10,P11)) -> 2 | R11: =IF(Q11=R$4,A11,$R$5) | S11: =IF($Q11=S$4,$A11,$R$5) -> 6 | T11: =IF($Q11=T$4,$A11,$R$5) | U11: =IF($Q11=U$4,$A11,$R$5) | V11: =IF($Q11=V$4,$A11,$R$5) | W11: =IF($Q11=W$4,$A11,$R$5) | X11: =IF($Q11=X$4,$A11,$R$5) | Y11: =IF($Q11=Y$4,$A11,$R$5) | Z11: 5 | AA11: 5 | AB11: 4 | AC11: -6 | AE11: =_xlfn.CONCAT(E11+1,",",D11+1) -> 6,5 | AF11: =AF10+1 -> 5 | AG11: =IF(ISNUMBER(MATCH(AG62,$AX$29:$AX$38,0)),$AX$28,IF(ISNUMBER(MATCH(AG62,$AX$26:$AX$27,0)),$AX$25,IF(ISNUMBER(MATCH(AG62,$AE$6:$AE$41,0)),$AE$5,$O$5))) -> 0 | AH11: =IF(ISNUMBER(MATCH(AH62,$AX$29:$AX$38,0)),$AX$28,IF(ISNUMBER(MATCH(AH62,$AX$26:$AX$27,0)),$AX$25,IF(ISNUMBER(MATCH(AH62,$AE$6:$AE$41,0)),$AE$5,$O$5))) -> 0 | AI11: =IF(ISNUMBER(MATCH(AI62,$AX$29:$AX$38,0)),$AX$28,IF(ISNUMBER(MATCH(AI62,$AX$26:$AX$27,0)),$AX$25,IF(ISNUMBER(MATCH(AI62,$AE$6:$AE$41,0)),$AE$5,$O$5))) -> 0 | AJ11: =IF(ISNUMBER(MATCH(AJ62,$AX$29:$AX$38,0)),$AX$28,IF(ISNUMBER(MATCH(AJ62,$AX$26:$AX$27,0)),$AX$25,IF(ISNUMBER(MATCH(AJ62,$AE$6:$AE$41,0)),$AE$5,$O$5))) -> 0 | AK11: =IF(ISNUMBER(MATCH(AK62,$AX$29:$AX$38,0)),$AX$28,IF(ISNUMBER(MATCH(AK62,$AX$26:$AX$27,0)),$AX$25,IF(ISNUMBER(MATCH(AK62,$AE$6:$AE$41,0)),$AE$5,$O$5))) -> 0 | AL11: =IF(ISNUMBER(MATCH(AL62,$AX$29:$AX$38,0)),$AX$28,IF(ISNUMBER(MATCH(AL62,$AX$26:$AX$27,0)),$AX$25,IF(ISNUMBER(MATCH(AL62,$AE$6:$AE$41,0)),$AE$5,$O$5))) -> 1 | AM11: =IF(ISNUMBER(MATCH(AM62,$AX$29:$AX$38,0)),$AX$28,IF(ISNUMBER(MATCH(AM62,$AX$26:$AX$27,0)),$AX$25,IF(ISNUMBER(MATCH(AM62,$AE$6:$AE$41,0)),$AE$5,$O$5))) -> 0 | AN11: =IF(ISNUMBER(MATCH(AN62,$AX$29:$AX$38,0)),$AX$28,IF(ISNUMBER(MATCH(AN62,$AX$26:$AX$27,0)),$AX$25,IF(ISNUMBER(MATCH(AN62,$AE$6:$AE$41,0)),$AE$5,$O$5))) -> 1 | ... AP11: =IF(ISNUMBER(MATCH(AP62,$AX$29:$AX$38,0)),$AX$28,IF(ISNUMBER(MATCH(AP62,$AX$26:$AX$27,0)),$AX$25,IF(ISNUMBER(MATCH(AP62,$AE$6:$AE$41,0)),$AE$5,$O$5))) -> 1 | AS11: 2 | AT11: 27 | AU11: inflow | AV11: 150 | AZ11: 0 | BA11: 2 | BB11: 2 | BC11: 1 | BD11: 1 | BE11: 1 | BF11: 1 | BG11: 2 | BH11: 2 | BI11: 0 | BK11: =AZ27-BK27 -> 0 | BL11: =BA27-BL27 -> 5 | BM11: =BB27-BM27 -> 5 | BN11: =BC27-BN27 -> 9 | BO11: =BD27-BO27 -> 4 | BP11: =BE27-BP27 -> 2 | BQ11: =BF27-BQ27 -> 0 | BR11: =BG27-BR27 -> -3 | ... BT11: =BI27-BT27 -> 0 | BV11: 0 | BW11: 1e-09 | BX11: 2.5e-10 | BY11: 2.5e-10 | BZ11: 2.5e-10 | CA11: 2.5e-10 | CB11: 2.5e-10 | CC11: 2.5e-10 | CD11: 1e-09 | CE11: 0 | CH11: =CI11/$CI$3 -> 0.33145259 | CI11: 10459848 | CJ11: 1078.4166 | CK11: 1061.581 | CL11: 1025.9865 | CM11: 993.28252 | CN11: -16.423425 | CO11: -2.9261195 | CP11: -0.50447548 | CQ11: -148.52267 | CR11: =CN11-$CR$4 -> 0.0084216
A12: =A11+1 -> 7 | B12: 6 | C12: 0 | D12: 5 | E12: 5 | F12: 5000 | G12: 12 | H12: 0.00094339624 | I12: 1061.792 | J12: 3 | K12: 3e-05 | L12: 0.03 | M12: 2 | N12: 1 | O12: 0 | P12: =IF(OR(M12-M11<0,N12=0),MAX(P$5:P11)+1,0) -> 0 | Q12: =IF(P13="",Q11,IF(P12=0,Q11,P12)) -> 2 | R12: =IF(Q12=R$4,A12,$R$5) | S12: =IF($Q12=S$4,$A12,$R$5) -> 7 | T12: =IF($Q12=T$4,$A12,$R$5) | U12: =IF($Q12=U$4,$A12,$R$5) | V12: =IF($Q12=V$4,$A12,$R$5) | W12: =IF($Q12=W$4,$A12,$R$5) | X12: =IF($Q12=X$4,$A12,$R$5) | Y12: =IF($Q12=Y$4,$A12,$R$5) | Z12: 6 | AA12: 6 | AB12: 5 | AC12: -7 | AE12: =_xlfn.CONCAT(E12+1,",",D12+1) -> 6,6 | AF12: =AF11+1 -> 6 | AG12: =IF(ISNUMBER(MATCH(AG63,$AX$29:$AX$38,0)),$AX$28,IF(ISNUMBER(MATCH(AG63,$AX$26:$AX$27,0)),$AX$25,IF(ISNUMBER(MATCH(AG63,$AE$6:$AE$41,0)),$AE$5,$O$5))) -> 0 | AH12: =IF(ISNUMBER(MATCH(AH63,$AX$29:$AX$38,0)),$AX$28,IF(ISNUMBER(MATCH(AH63,$AX$26:$AX$27,0)),$AX$25,IF(ISNUMBER(MATCH(AH63,$AE$6:$AE$41,0)),$AE$5,$O$5))) -> 0 | AI12: =IF(ISNUMBER(MATCH(AI63,$AX$29:$AX$38,0)),$AX$28,IF(ISNUMBER(MATCH(AI63,$AX$26:$AX$27,0)),$AX$25,IF(ISNUMBER(MATCH(AI63,$AE$6:$AE$41,0)),$AE$5,$O$5))) -> 0 | AJ12: =IF(ISNUMBER(MATCH(AJ63,$AX$29:$AX$38,0)),$AX$28,IF(ISNUMBER(MATCH(AJ63,$AX$26:$AX$27,0)),$AX$25,IF(ISNUMBER(MATCH(AJ63,$AE$6:$AE$41,0)),$AE$5,$O$5))) -> W | AK12: =IF(ISNUMBER(MATCH(AK63,$AX$29:$AX$38,0)),$AX$28,IF(ISNUMBER(MATCH(AK63,$AX$26:$AX$27,0)),$AX$25,IF(ISNUMBER(MATCH(AK63,$AE$6:$AE$41,0)),$AE$5,$O$5))) -> W | AL12: =IF(ISNUMBER(MATCH(AL63,$AX$29:$AX$38,0)),$AX$28,IF(ISNUMBER(MATCH(AL63,$AX$26:$AX$27,0)),$AX$25,IF(ISNUMBER(MATCH(AL63,$AE$6:$AE$41,0)),$AE$5,$O$5))) -> 1 | AM12: =IF(ISNUMBER(MATCH(AM63,$AX$29:$AX$38,0)),$AX$28,IF(ISNUMBER(MATCH(AM63,$AX$26:$AX$27,0)),$AX$25,IF(ISNUMBER(MATCH(AM63,$AE$6:$AE$41,0)),$AE$5,$O$5))) -> 0 | AN12: =IF(ISNUMBER(MATCH(AN63,$AX$29:$AX$38,0)),$AX$28,IF(ISNUMBER(MATCH(AN63,$AX$26:$AX$27,0)),$AX$25,IF(ISNUMBER(MATCH(AN63,$AE$6:$AE$41,0)),$AE$5,$O$5))) -> 1 | ... AP12: =IF(ISNUMBER(MATCH(AP63,$AX$29:$AX$38,0)),$AX$28,IF(ISNUMBER(MATCH(AP63,$AX$26:$AX$27,0)),$AX$25,IF(ISNUMBER(MATCH(AP63,$AE$6:$AE$41,0)),$AE$5,$O$5))) -> 0 | AS12: 3 | AT12: 3 | AU12: diversion | AV12: 10 | AW12: - | AZ12: 0 | BA12: 2 | BB12: 2 | BC12: 1 | BD12: 1 | BE12: 1 | BF12: 1 | BG12: 2 | BH12: 2 | BI12: 0 | BK12: =AZ28-BK28 -> 0 | BL12: =BA28-BL28 -> 10 | BM12: =BB28-BM28 -> 10 | BN12: =BC28-BN28 -> 9 | BO12: =BD28-BO28 -> 5 | BP12: =BE28-BP28 -> 0 | BQ12: =BF28-BQ28 -> 0 | BR12: =BG28-BR28 -> 0 | ... BT12: =BI28-BT28 -> 0 | BV12: 0 | BW12: 1e-09 | BX12: 2.5e-10 | BY12: 2.5e-10 | BZ12: 2.5e-10 | CA12: 2.5e-10 | CB12: 2.5e-10 | CC12: 2.5e-10 | CD12: 1e-09 | CE12: 0 | CH12: =CI12/$CI$3 -> 0.40755655 | CI12: 12861507 | CJ12: 1078.4163 | CK12: 1061.581 | CL12: 1025.9859 | CM12: 993.2777 | CN12: -16.41509 | CO12: -2.6008478 | CP12: -0.49843629 | CQ12: -147.67574 | CR12: =CN12-$CR$4 -> 0.01675671
A13: =A12+1 -> 8 | B13: 7 | C13: 0 | D13: 6 | E13: 5 | F13: 5000 | G13: 12 | H13: 0.00094339624 | I13: 1057.075 | J13: 3 | K13: 3e-05 | L13: 0.03 | M13: 2 | N13: 1 | O13: 0 | P13: =IF(OR(M13-M12<0,N13=0),MAX(P$5:P12)+1,0) -> 0 | Q13: =IF(P14="",Q12,IF(P13=0,Q12,P13)) -> 2 | R13: =IF(Q13=R$4,A13,$R$5) | S13: =IF($Q13=S$4,$A13,$R$5) -> 8 | T13: =IF($Q13=T$4,$A13,$R$5) | U13: =IF($Q13=U$4,$A13,$R$5) | V13: =IF($Q13=V$4,$A13,$R$5) | W13: =IF($Q13=W$4,$A13,$R$5) | X13: =IF($Q13=X$4,$A13,$R$5) | Y13: =IF($Q13=Y$4,$A13,$R$5) | Z13: 7 | AA13: 7 | AB13: 6 | AC13: -8 | AE13: =_xlfn.CONCAT(E13+1,",",D13+1) -> 6,7 | AF13: =AF12+1 -> 7 | AG13: =IF(ISNUMBER(MATCH(AG64,$AX$29:$AX$38,0)),$AX$28,IF(ISNUMBER(MATCH(AG64,$AX$26:$AX$27,0)),$AX$25,IF(ISNUMBER(MATCH(AG64,$AE$6:$AE$41,0)),$AE$5,$O$5))) -> 0 | AH13: =IF(ISNUMBER(MATCH(AH64,$AX$29:$AX$38,0)),$AX$28,IF(ISNUMBER(MATCH(AH64,$AX$26:$AX$27,0)),$AX$25,IF(ISNUMBER(MATCH(AH64,$AE$6:$AE$41,0)),$AE$5,$O$5))) -> 0 | AI13: =IF(ISNUMBER(MATCH(AI64,$AX$29:$AX$38,0)),$AX$28,IF(ISNUMBER(MATCH(AI64,$AX$26:$AX$27,0)),$AX$25,IF(ISNUMBER(MATCH(AI64,$AE$6:$AE$41,0)),$AE$5,$O$5))) -> 0 | AJ13: =IF(ISNUMBER(MATCH(AJ64,$AX$29:$AX$38,0)),$AX$28,IF(ISNUMBER(MATCH(AJ64,$AX$26:$AX$27,0)),$AX$25,IF(ISNUMBER(MATCH(AJ64,$AE$6:$AE$41,0)),$AE$5,$O$5))) -> W | AK13: =IF(ISNUMBER(MATCH(AK64,$AX$29:$AX$38,0)),$AX$28,IF(ISNUMBER(MATCH(AK64,$AX$26:$AX$27,0)),$AX$25,IF(ISNUMBER(MATCH(AK64,$AE$6:$AE$41,0)),$AE$5,$O$5))) -> W | AL13: =IF(ISNUMBER(MATCH(AL64,$AX$29:$AX$38,0)),$AX$28,IF(ISNUMBER(MATCH(AL64,$AX$26:$AX$27,0)),$AX$25,IF(ISNUMBER(MATCH(AL64,$AE$6:$AE$41,0)),$AE$5,$O$5))) -> 1 | AM13: =IF(ISNUMBER(MATCH(AM64,$AX$29:$AX$38,0)),$AX$28,IF(ISNUMBER(MATCH(AM64,$AX$26:$AX$27,0)),$AX$25,IF(ISNUMBER(MATCH(AM64,$AE$6:$AE$41,0)),$AE$5,$O$5))) -> 1 | AN13: =IF(ISNUMBER(MATCH(AN64,$AX$29:$AX$38,0)),$AX$28,IF(ISNUMBER(MATCH(AN64,$AX$26:$AX$27,0)),$AX$25,IF(ISNUMBER(MATCH(AN64,$AE$6:$AE$41,0)),$AE$5,$O$5))) -> 0 | ... AP13: =IF(ISNUMBER(MATCH(AP64,$AX$29:$AX$38,0)),$AX$28,IF(ISNUMBER(MATCH(AP64,$AX$26:$AX$27,0)),$AX$25,IF(ISNUMBER(MATCH(AP64,$AE$6:$AE$41,0)),$AE$5,$O$5))) -> 0 | AS13: 4 | AT13: 9 | AU13: status | AV13: simple | AZ13: 0 | BA13: 2 | BB13: 2 | BC13: 1 | BD13: 1 | BE13: 1 | BF13: 1 | BG13: 2 | BH13: 2 | BI13: 2 | BK13: =AZ29-BK29 -> 0 | BL13: =BA29-BL29 -> 10 | BM13: =BB29-BM29 -> 14 | BN13: =BC29-BN29 -> 9 | BO13: =BD29-BO29 -> 0 | BP13: =BE29-BP29 -> 0 | BQ13: =BF29-BQ29 -> 0 | BR13: =BG29-BR29 -> 0 | ... BT13: =BI29-BT29 -> 0 | BV13: 0 | BW13: 1e-09 | BX13: 2.5e-10 | BY13: 2.5e-10 | BZ13: 2.5e-10 | CA13: 2.5e-10 | CB13: 2.5e-10 | CC13: 2.5e-10 | CD13: 2.5e-10 | CE13: 4e-09 | CH13: =CI13/$CI$3 -> 0.49127091 | CI13: 15503331 | CJ13: 1078.4158 | CK13: 1061.581 | CL13: 1025.9853 | CM13: 993.27224 | CN13: -16.401311 | CO13: -2.2128129 | CP13: -0.49182705 | CQ13: -146.71751 | CR13: =CN13-$CR$4 -> 0.0305358
A14: =A13+1 -> 9 | B14: 8 | C14: 0 | D14: 7 | E14: 5 | F14: 5000 | G14: 12 | H14: 0.00094339624 | I14: 1052.359 | J14: 3 | K14: 3e-05 | L14: 0.03 | M14: 2 | N14: 1 | O14: 0 | P14: =IF(OR(M14-M13<0,N14=0),MAX(P$5:P13)+1,0) -> 0 | Q14: =IF(P15="",Q13,IF(P14=0,Q13,P14)) -> 2 | R14: =IF(Q14=R$4,A14,$R$5) | S14: =IF($Q14=S$4,$A14,$R$5) -> 9 | T14: =IF($Q14=T$4,$A14,$R$5) | U14: =IF($Q14=U$4,$A14,$R$5) | V14: =IF($Q14=V$4,$A14,$R$5) | W14: =IF($Q14=W$4,$A14,$R$5) | X14: =IF($Q14=X$4,$A14,$R$5) | Y14: =IF($Q14=Y$4,$A14,$R$5) | Z14: 8 | AA14: 8 | AB14: 7 | AC14: -22 | AE14: =_xlfn.CONCAT(E14+1,",",D14+1) -> 6,8 | AF14: =AF13+1 -> 8 | AG14: =IF(ISNUMBER(MATCH(AG65,$AX$29:$AX$38,0)),$AX$28,IF(ISNUMBER(MATCH(AG65,$AX$26:$AX$27,0)),$AX$25,IF(ISNUMBER(MATCH(AG65,$AE$6:$AE$41,0)),$AE$5,$O$5))) -> 0 | AH14: =IF(ISNUMBER(MATCH(AH65,$AX$29:$AX$38,0)),$AX$28,IF(ISNUMBER(MATCH(AH65,$AX$26:$AX$27,0)),$AX$25,IF(ISNUMBER(MATCH(AH65,$AE$6:$AE$41,0)),$AE$5,$O$5))) -> 0 | AI14: =IF(ISNUMBER(MATCH(AI65,$AX$29:$AX$38,0)),$AX$28,IF(ISNUMBER(MATCH(AI65,$AX$26:$AX$27,0)),$AX$25,IF(ISNUMBER(MATCH(AI65,$AE$6:$AE$41,0)),$AE$5,$O$5))) -> 0 | AJ14: =IF(ISNUMBER(MATCH(AJ65,$AX$29:$AX$38,0)),$AX$28,IF(ISNUMBER(MATCH(AJ65,$AX$26:$AX$27,0)),$AX$25,IF(ISNUMBER(MATCH(AJ65,$AE$6:$AE$41,0)),$AE$5,$O$5))) -> W | AK14: =IF(ISNUMBER(MATCH(AK65,$AX$29:$AX$38,0)),$AX$28,IF(ISNUMBER(MATCH(AK65,$AX$26:$AX$27,0)),$AX$25,IF(ISNUMBER(MATCH(AK65,$AE$6:$AE$41,0)),$AE$5,$O$5))) -> W | AL14: =IF(ISNUMBER(MATCH(AL65,$AX$29:$AX$38,0)),$AX$28,IF(ISNUMBER(MATCH(AL65,$AX$26:$AX$27,0)),$AX$25,IF(ISNUMBER(MATCH(AL65,$AE$6:$AE$41,0)),$AE$5,$O$5))) -> 1 | AM14: =IF(ISNUMBER(MATCH(AM65,$AX$29:$AX$38,0)),$AX$28,IF(ISNUMBER(MATCH(AM65,$AX$26:$AX$27,0)),$AX$25,IF(ISNUMBER(MATCH(AM65,$AE$6:$AE$41,0)),$AE$5,$O$5))) -> 1 | AN14: =IF(ISNUMBER(MATCH(AN65,$AX$29:$AX$38,0)),$AX$28,IF(ISNUMBER(MATCH(AN65,$AX$26:$AX$27,0)),$AX$25,IF(ISNUMBER(MATCH(AN65,$AE$6:$AE$41,0)),$AE$5,$O$5))) -> 0 | ... AP14: =IF(ISNUMBER(MATCH(AP65,$AX$29:$AX$38,0)),$AX$28,IF(ISNUMBER(MATCH(AP65,$AX$26:$AX$27,0)),$AX$25,IF(ISNUMBER(MATCH(AP65,$AE$6:$AE$41,0)),$AE$5,$O$5))) -> 0 | AS14: 5 | AT14: 10 | AU14: status | AV14: simple | AZ14: 0 | BA14: 2 | BB14: 2 | BC14: 1 | BD14: 1 | BE14: 1 | BF14: 1 | BG14: 2 | BH14: 2 | BI14: 0 | BK14: =AZ30-BK30 -> 0 | BL14: =BA30-BL30 -> 10 | BM14: =BB30-BM30 -> 11 | BN14: =BC30-BN30 -> 5 | BO14: =BD30-BO30 -> 0 | BP14: =BE30-BP30 -> 0 | BQ14: =BF30-BQ30 -> 0 | BR14: =BG30-BR30 -> 0 | ... BT14: =BI30-BT30 -> 0 | BV14: 0 | BW14: 1e-09 | BX14: 2.5e-10 | BY14: 2.5e-10 | BZ14: 2.5e-10 | CA14: 2.5e-10 | CB14: 2.5e-10 | CC14: 2.5e-10 | CD14: 1e-09 | CE14: 0 | CH14: =CI14/$CI$3 -> 0.58335671 | CI14: 18409338 | CJ14: 1078.4151 | CK14: 1061.581 | CL14: 1025.9846 | CM14: 993.2661 | CN14: -16.380027 | CO14: -1.7979557 | CP14: -0.48459116 | CQ14: -145.6439 | CR14: =CN14-$CR$4 -> 0.05181991
A15: =A14+1 -> 10 | B15: 9 | C15: 0 | D15: 2 | E15: 4 | F15: 5000 | G15: 10 | H15: 0.00054545456 | I15: 1073.636 | J15: 2 | K15: 3e-05 | L15: 0.03 | M15: 2 | N15: 0 | O15: 0 | P15: =IF(OR(M15-M14<0,N15=0),MAX(P$5:P14)+1,0) -> 3 | Q15: =IF(P16="",Q14,IF(P15=0,Q14,P15)) -> 3 | R15: =IF(Q15=R$4,A15,$R$5) | S15: =IF($Q15=S$4,$A15,$R$5) | T15: =IF($Q15=T$4,$A15,$R$5) -> 10 | U15: =IF($Q15=U$4,$A15,$R$5) | V15: =IF($Q15=V$4,$A15,$R$5) | W15: =IF($Q15=W$4,$A15,$R$5) | X15: =IF($Q15=X$4,$A15,$R$5) | Y15: =IF($Q15=Y$4,$A15,$R$5) | Z15: 9 | AA15: 9 | AB15: 3 | AC15: -10 | AE15: =_xlfn.CONCAT(E15+1,",",D15+1) -> 5,3 | AF15: =AF14+1 -> 9 | AG15: =IF(ISNUMBER(MATCH(AG66,$AX$29:$AX$38,0)),$AX$28,IF(ISNUMBER(MATCH(AG66,$AX$26:$AX$27,0)),$AX$25,IF(ISNUMBER(MATCH(AG66,$AE$6:$AE$41,0)),$AE$5,$O$5))) -> 0 | AH15: =IF(ISNUMBER(MATCH(AH66,$AX$29:$AX$38,0)),$AX$28,IF(ISNUMBER(MATCH(AH66,$AX$26:$AX$27,0)),$AX$25,IF(ISNUMBER(MATCH(AH66,$AE$6:$AE$41,0)),$AE$5,$O$5))) -> 0 | AI15: =IF(ISNUMBER(MATCH(AI66,$AX$29:$AX$38,0)),$AX$28,IF(ISNUMBER(MATCH(AI66,$AX$26:$AX$27,0)),$AX$25,IF(ISNUMBER(MATCH(AI66,$AE$6:$AE$41,0)),$AE$5,$O$5))) -> 0 | AJ15: =IF(ISNUMBER(MATCH(AJ66,$AX$29:$AX$38,0)),$AX$28,IF(ISNUMBER(MATCH(AJ66,$AX$26:$AX$27,0)),$AX$25,IF(ISNUMBER(MATCH(AJ66,$AE$6:$AE$41,0)),$AE$5,$O$5))) -> W | AK15: =IF(ISNUMBER(MATCH(AK66,$AX$29:$AX$38,0)),$AX$28,IF(ISNUMBER(MATCH(AK66,$AX$26:$AX$27,0)),$AX$25,IF(ISNUMBER(MATCH(AK66,$AE$6:$AE$41,0)),$AE$5,$O$5))) -> W | AL15: =IF(ISNUMBER(MATCH(AL66,$AX$29:$AX$38,0)),$AX$28,IF(ISNUMBER(MATCH(AL66,$AX$26:$AX$27,0)),$AX$25,IF(ISNUMBER(MATCH(AL66,$AE$6:$AE$41,0)),$AE$5,$O$5))) -> 1 | AM15: =IF(ISNUMBER(MATCH(AM66,$AX$29:$AX$38,0)),$AX$28,IF(ISNUMBER(MATCH(AM66,$AX$26:$AX$27,0)),$AX$25,IF(ISNUMBER(MATCH(AM66,$AE$6:$AE$41,0)),$AE$5,$O$5))) -> 0 | AN15: =IF(ISNUMBER(MATCH(AN66,$AX$29:$AX$38,0)),$AX$28,IF(ISNUMBER(MATCH(AN66,$AX$26:$AX$27,0)),$AX$25,IF(ISNUMBER(MATCH(AN66,$AE$6:$AE$41,0)),$AE$5,$O$5))) -> 0 | ... AP15: =IF(ISNUMBER(MATCH(AP66,$AX$29:$AX$38,0)),$AX$28,IF(ISNUMBER(MATCH(AP66,$AX$26:$AX$27,0)),$AX$25,IF(ISNUMBER(MATCH(AP66,$AE$6:$AE$41,0)),$AE$5,$O$5))) -> 0 | AS15: 6 | AT15: 11 | AU15: status | AV15: simple | AZ15: 2 | BA15: 2 | BB15: 1 | BC15: 1 | BD15: 1 | BE15: 1 | BF15: 1 | BG15: 2 | BH15: 2 | BI15: 0 | BK15: =AZ31-BK31 -> 0 | BL15: =BA31-BL31 -> 0 | BM15: =BB31-BM31 -> 0 | BN15: =BC31-BN31 -> 0 | BO15: =BD31-BO31 -> 0 | BP15: =BE31-BP31 -> 0 | BQ15: =BF31-BQ31 -> 0 | BR15: =BG31-BR31 -> 0 | ... BT15: =BI31-BT31 -> 0 | BV15: 1e-09 | BW15: 2.5e-10 | BX15: 2.5e-10 | BY15: 2.5e-10 | BZ15: 2.5e-10 | CA15: 2.5e-10 | CB15: 2.5e-10 | CC15: 2.5e-10 | CD15: 1e-09 | CE15: 0 | CH15: =CI15/$CI$3 -> 0.68465108 | CI15: 21605945 | CJ15: 1078.414 | CK15: 1061.581 | CL15: 1025.9839 | CM15: 993.25933 | CN15: -16.348992 | CO15: -1.3056966 | CP15: -0.47672752 | CQ15: -144.46386 | CR15: =CN15-$CR$4 -> 0.08285492
A16: =A15+1 -> 11 | B16: 10 | C16: 0 | D16: 2 | E16: 5 | F16: 5000 | G16: 10 | H16: 0.00054545456 | I16: 1070.909 | J16: 2 | K16: 3e-05 | L16: 0.03 | M16: 2 | N16: 1 | O16: 0 | P16: =IF(OR(M16-M15<0,N16=0),MAX(P$5:P15)+1,0) -> 0 | Q16: =IF(P17="",Q15,IF(P16=0,Q15,P16)) -> 3 | R16: =IF(Q16=R$4,A16,$R$5) | S16: =IF($Q16=S$4,$A16,$R$5) | T16: =IF($Q16=T$4,$A16,$R$5) -> 11 | U16: =IF($Q16=U$4,$A16,$R$5) | V16: =IF($Q16=V$4,$A16,$R$5) | W16: =IF($Q16=W$4,$A16,$R$5) | X16: =IF($Q16=X$4,$A16,$R$5) | Y16: =IF($Q16=Y$4,$A16,$R$5) | Z16: 10 | AA16: 10 | AB16: 9 | AC16: -11 | AE16: =_xlfn.CONCAT(E16+1,",",D16+1) -> 6,3 | AF16: =AF15+1 -> 10 | AG16: =IF(ISNUMBER(MATCH(AG67,$AX$29:$AX$38,0)),$AX$28,IF(ISNUMBER(MATCH(AG67,$AX$26:$AX$27,0)),$AX$25,IF(ISNUMBER(MATCH(AG67,$AE$6:$AE$41,0)),$AE$5,$O$5))) -> 0 | AH16: =IF(ISNUMBER(MATCH(AH67,$AX$29:$AX$38,0)),$AX$28,IF(ISNUMBER(MATCH(AH67,$AX$26:$AX$27,0)),$AX$25,IF(ISNUMBER(MATCH(AH67,$AE$6:$AE$41,0)),$AE$5,$O$5))) -> 0 | AI16: =IF(ISNUMBER(MATCH(AI67,$AX$29:$AX$38,0)),$AX$28,IF(ISNUMBER(MATCH(AI67,$AX$26:$AX$27,0)),$AX$25,IF(ISNUMBER(MATCH(AI67,$AE$6:$AE$41,0)),$AE$5,$O$5))) -> 0 | AJ16: =IF(ISNUMBER(MATCH(AJ67,$AX$29:$AX$38,0)),$AX$28,IF(ISNUMBER(MATCH(AJ67,$AX$26:$AX$27,0)),$AX$25,IF(ISNUMBER(MATCH(AJ67,$AE$6:$AE$41,0)),$AE$5,$O$5))) -> W | AK16: =IF(ISNUMBER(MATCH(AK67,$AX$29:$AX$38,0)),$AX$28,IF(ISNUMBER(MATCH(AK67,$AX$26:$AX$27,0)),$AX$25,IF(ISNUMBER(MATCH(AK67,$AE$6:$AE$41,0)),$AE$5,$O$5))) -> W | AL16: =IF(ISNUMBER(MATCH(AL67,$AX$29:$AX$38,0)),$AX$28,IF(ISNUMBER(MATCH(AL67,$AX$26:$AX$27,0)),$AX$25,IF(ISNUMBER(MATCH(AL67,$AE$6:$AE$41,0)),$AE$5,$O$5))) -> 0 | AM16: =IF(ISNUMBER(MATCH(AM67,$AX$29:$AX$38,0)),$AX$28,IF(ISNUMBER(MATCH(AM67,$AX$26:$AX$27,0)),$AX$25,IF(ISNUMBER(MATCH(AM67,$AE$6:$AE$41,0)),$AE$5,$O$5))) -> 1 | AN16: =IF(ISNUMBER(MATCH(AN67,$AX$29:$AX$38,0)),$AX$28,IF(ISNUMBER(MATCH(AN67,$AX$26:$AX$27,0)),$AX$25,IF(ISNUMBER(MATCH(AN67,$AE$6:$AE$41,0)),$AE$5,$O$5))) -> 0 | ... AP16: =IF(ISNUMBER(MATCH(AP67,$AX$29:$AX$38,0)),$AX$28,IF(ISNUMBER(MATCH(AP67,$AX$26:$AX$27,0)),$AX$25,IF(ISNUMBER(MATCH(AP67,$AE$6:$AE$41,0)),$AE$5,$O$5))) -> 0 | AS16: 7 | AT16: 12 | AU16: status | AV16: simple | AZ16: 1 | BA16: 1 | BB16: 1 | BC16: 1 | BD16: 1 | BE16: 1 | BF16: 1 | BG16: 1 | BH16: 1 | BI16: 0 | BK16: =AZ32-BK32 -> 0 | BL16: =BA32-BL32 -> 0 | BM16: =BB32-BM32 -> 0 | BN16: =BC32-BN32 -> 0 | BO16: =BD32-BO32 -> 0 | BP16: =BE32-BP32 -> 0 | BQ16: =BF32-BQ32 -> 0 | BR16: =BG32-BR32 -> 0 | ... BT16: =BI32-BT32 -> 0 | BV16: 2.5e-10 | BW16: 2.5e-10 | BX16: 2.5e-10 | BY16: 2.5e-10 | BZ16: 2.5e-10 | CA16: 2.5e-10 | CB16: 2.5e-10 | CC16: 2.5e-10 | CD16: 1e-09 | CE16: 0 | CH16: =CI16/$CI$3 -> 0.79607489 | CI16: 25122213 | CJ16: 1078.4125 | CK16: 1061.581 | CL16: 1025.9831 | CM16: 993.25202 | CN16: -16.305869 | CO16: -0.87097068 | CP16: -0.46830936 | CQ16: -143.19233 | CR16: =CN16-$CR$4 -> 0.12597829
A17: =A16+1 -> 12 | B17: 11 | C17: 0 | D17: 2 | E17: 6 | F17: 4500 | G17: 10 | H17: 0.00054545456 | I17: 1068.318 | J17: 2 | K17: 3e-05 | L17: 0.03 | M17: 2 | N17: 1 | O17: 0 | P17: =IF(OR(M17-M16<0,N17=0),MAX(P$5:P16)+1,0) -> 0 | Q17: =IF(P18="",Q16,IF(P17=0,Q16,P17)) -> 3 | R17: =IF(Q17=R$4,A17,$R$5) | S17: =IF($Q17=S$4,$A17,$R$5) | T17: =IF($Q17=T$4,$A17,$R$5) -> 12 | U17: =IF($Q17=U$4,$A17,$R$5) | V17: =IF($Q17=V$4,$A17,$R$5) | W17: =IF($Q17=W$4,$A17,$R$5) | X17: =IF($Q17=X$4,$A17,$R$5) | Y17: =IF($Q17=Y$4,$A17,$R$5) | Z17: 11 | AA17: 11 | AB17: 10 | AC17: -12 | AE17: =_xlfn.CONCAT(E17+1,",",D17+1) -> 7,3 | AF17: =AF16+1 -> 11 | AG17: =IF(ISNUMBER(MATCH(AG68,$AX$29:$AX$38,0)),$AX$28,IF(ISNUMBER(MATCH(AG68,$AX$26:$AX$27,0)),$AX$25,IF(ISNUMBER(MATCH(AG68,$AE$6:$AE$41,0)),$AE$5,$O$5))) -> 0 | AH17: =IF(ISNUMBER(MATCH(AH68,$AX$29:$AX$38,0)),$AX$28,IF(ISNUMBER(MATCH(AH68,$AX$26:$AX$27,0)),$AX$25,IF(ISNUMBER(MATCH(AH68,$AE$6:$AE$41,0)),$AE$5,$O$5))) -> 0 | AI17: =IF(ISNUMBER(MATCH(AI68,$AX$29:$AX$38,0)),$AX$28,IF(ISNUMBER(MATCH(AI68,$AX$26:$AX$27,0)),$AX$25,IF(ISNUMBER(MATCH(AI68,$AE$6:$AE$41,0)),$AE$5,$O$5))) -> 0 | AJ17: =IF(ISNUMBER(MATCH(AJ68,$AX$29:$AX$38,0)),$AX$28,IF(ISNUMBER(MATCH(AJ68,$AX$26:$AX$27,0)),$AX$25,IF(ISNUMBER(MATCH(AJ68,$AE$6:$AE$41,0)),$AE$5,$O$5))) -> 0 | AK17: =IF(ISNUMBER(MATCH(AK68,$AX$29:$AX$38,0)),$AX$28,IF(ISNUMBER(MATCH(AK68,$AX$26:$AX$27,0)),$AX$25,IF(ISNUMBER(MATCH(AK68,$AE$6:$AE$41,0)),$AE$5,$O$5))) -> 0 | AL17: =IF(ISNUMBER(MATCH(AL68,$AX$29:$AX$38,0)),$AX$28,IF(ISNUMBER(MATCH(AL68,$AX$26:$AX$27,0)),$AX$25,IF(ISNUMBER(MATCH(AL68,$AE$6:$AE$41,0)),$AE$5,$O$5))) -> 0 | AM17: =IF(ISNUMBER(MATCH(AM68,$AX$29:$AX$38,0)),$AX$28,IF(ISNUMBER(MATCH(AM68,$AX$26:$AX$27,0)),$AX$25,IF(ISNUMBER(MATCH(AM68,$AE$6:$AE$41,0)),$AE$5,$O$5))) -> 1 | AN17: =IF(ISNUMBER(MATCH(AN68,$AX$29:$AX$38,0)),$AX$28,IF(ISNUMBER(MATCH(AN68,$AX$26:$AX$27,0)),$AX$25,IF(ISNUMBER(MATCH(AN68,$AE$6:$AE$41,0)),$AE$5,$O$5))) -> 0 | ... AP17: =IF(ISNUMBER(MATCH(AP68,$AX$29:$AX$38,0)),$AX$28,IF(ISNUMBER(MATCH(AP68,$AX$26:$AX$27,0)),$AX$25,IF(ISNUMBER(MATCH(AP68,$AE$6:$AE$41,0)),$AE$5,$O$5))) -> 0 | AS17: 8 | AT17: 13 | AU17: status | AV17: simple | AZ17: 0 | BA17: 2 | BB17: 2 | BC17: 2 | BD17: 2 | BE17: 2 | BF17: 2 | BG17: 2 | BH17: 1 | BI17: 0 | BK17: =AZ33-BK33 -> 0 | BL17: =BA33-BL33 -> 0 | BM17: =BB33-BM33 -> 0 | BN17: =BC33-BN33 -> 0 | BO17: =BD33-BO33 -> 0 | BP17: =BE33-BP33 -> 0 | BQ17: =BF33-BQ33 -> 0 | BR17: =BG33-BR33 -> 0 | ... BT17: =BI33-BT33 -> 0 | BV17: 0 | BW17: 2.5e-10 | BX17: 2.5e-10 | BY17: 2.5e-10 | BZ17: 2.5e-10 | CA17: 2.5e-10 | CB17: 1e-09 | CC17: 1e-09 | CD17: 2.5e-10 | CE17: 0 | CF17: =MAX(BV4:CE18) -> 4e-09 | CH17: =CI17/$CI$3 -> 0.91864108 | CI17: 28990108 | CJ17: 1078.4105 | CK17: 1061.581 | CL17: 1025.9822 | CM17: 993.24423 | CN17: -16.248319 | CO17: -0.3944121 | CP17: -0.4594154 | CQ17: -141.8435 | CR17: =CN17-$CR$4 -> 0.18352773
A18: =A17+1 -> 13 | B18: 12 | C18: 0 | D18: 3 | E18: 7 | F18: 6000 | G18: 10 | H18: 0.00054545456 | I18: 1065.455 | J18: 2 | K18: 3e-05 | L18: 0.03 | M18: 2 | N18: 1 | O18: 0 | P18: =IF(OR(M18-M17<0,N18=0),MAX(P$5:P17)+1,0) -> 0 | Q18: =IF(P19="",Q17,IF(P18=0,Q17,P18)) -> 3 | R18: =IF(Q18=R$4,A18,$R$5) | S18: =IF($Q18=S$4,$A18,$R$5) | T18: =IF($Q18=T$4,$A18,$R$5) -> 13 | U18: =IF($Q18=U$4,$A18,$R$5) | V18: =IF($Q18=V$4,$A18,$R$5) | W18: =IF($Q18=W$4,$A18,$R$5) | X18: =IF($Q18=X$4,$A18,$R$5) | Y18: =IF($Q18=Y$4,$A18,$R$5) | Z18: 12 | AA18: 12 | AB18: 11 | AC18: -13 | AE18: =_xlfn.CONCAT(E18+1,",",D18+1) -> 8,4 | AF18: =AF17+1 -> 12 | AG18: =IF(ISNUMBER(MATCH(AG69,$AX$29:$AX$38,0)),$AX$28,IF(ISNUMBER(MATCH(AG69,$AX$26:$AX$27,0)),$AX$25,IF(ISNUMBER(MATCH(AG69,$AE$6:$AE$41,0)),$AE$5,$O$5))) -> 0 | AH18: =IF(ISNUMBER(MATCH(AH69,$AX$29:$AX$38,0)),$AX$28,IF(ISNUMBER(MATCH(AH69,$AX$26:$AX$27,0)),$AX$25,IF(ISNUMBER(MATCH(AH69,$AE$6:$AE$41,0)),$AE$5,$O$5))) -> 0 | AI18: =IF(ISNUMBER(MATCH(AI69,$AX$29:$AX$38,0)),$AX$28,IF(ISNUMBER(MATCH(AI69,$AX$26:$AX$27,0)),$AX$25,IF(ISNUMBER(MATCH(AI69,$AE$6:$AE$41,0)),$AE$5,$O$5))) -> 0 | AJ18: =IF(ISNUMBER(MATCH(AJ69,$AX$29:$AX$38,0)),$AX$28,IF(ISNUMBER(MATCH(AJ69,$AX$26:$AX$27,0)),$AX$25,IF(ISNUMBER(MATCH(AJ69,$AE$6:$AE$41,0)),$AE$5,$O$5))) -> 0 | AK18: =IF(ISNUMBER(MATCH(AK69,$AX$29:$AX$38,0)),$AX$28,IF(ISNUMBER(MATCH(AK69,$AX$26:$AX$27,0)),$AX$25,IF(ISNUMBER(MATCH(AK69,$AE$6:$AE$41,0)),$AE$5,$O$5))) -> 0 | AL18: =IF(ISNUMBER(MATCH(AL69,$AX$29:$AX$38,0)),$AX$28,IF(ISNUMBER(MATCH(AL69,$AX$26:$AX$27,0)),$AX$25,IF(ISNUMBER(MATCH(AL69,$AE$6:$AE$41,0)),$AE$5,$O$5))) -> 0 | AM18: =IF(ISNUMBER(MATCH(AM69,$AX$29:$AX$38,0)),$AX$28,IF(ISNUMBER(MATCH(AM69,$AX$26:$AX$27,0)),$AX$25,IF(ISNUMBER(MATCH(AM69,$AE$6:$AE$41,0)),$AE$5,$O$5))) -> 1 | AN18: =IF(ISNUMBER(MATCH(AN69,$AX$29:$AX$38,0)),$AX$28,IF(ISNUMBER(MATCH(AN69,$AX$26:$AX$27,0)),$AX$25,IF(ISNUMBER(MATCH(AN69,$AE$6:$AE$41,0)),$AE$5,$O$5))) -> 0 | ... AP18: =IF(ISNUMBER(MATCH(AP69,$AX$29:$AX$38,0)),$AX$28,IF(ISNUMBER(MATCH(AP69,$AX$26:$AX$27,0)),$AX$25,IF(ISNUMBER(MATCH(AP69,$AE$6:$AE$41,0)),$AE$5,$O$5))) -> 0 | AS18: 9 | AT18: 14 | AU18: status | AV18: simple | AZ18: 0 | BA18: 0 | BB18: 2 | BC18: 2 | BD18: 2 | BE18: 2 | BF18: 0 | BG18: 0 | BH18: 0 | BI18: 0 | BK18: =AZ34-BK34 -> 0 | BL18: =BA34-BL34 -> 0 | BM18: =BB34-BM34 -> 0 | BN18: =BC34-BN34 -> 0 | BO18: =BD34-BO34 -> 0 | BP18: =BE34-BP34 -> 0 | BQ18: =BF34-BQ34 -> 0 | BR18: =BG34-BR34 -> 0 | ... BT18: =BI34-BT34 -> 0 | BV18: 0 | BW18: 0 | BX18: 1e-09 | BY18: 1e-09 | BZ18: 1e-09 | CA18: 1e-09 | CB18: 0 | CC18: 0 | CD18: 0 | CE18: 0 | CF18: =MIN(BV4:CE18) -> 0 | CH18: =CI18/$CI$3 -> 1.0534639 | CI18: 33244792 | CJ18: 1078.4079 | CK18: 1060.545 | CL18: 1025.9813 | CM18: 993.23604 | CN18: -16.174118 | CO18: 0 | CP18: -0.45008878 | CQ18: -140.42966 | CR18: =CN18-$CR$4 -> 0.25772865
A19: =A18+1 -> 14 | B19: 13 | C19: 0 | D19: 4 | E19: 7 | F19: 5000 | G19: 10 | H19: 0.00054545456 | I19: 1062.455 | J19: 2 | K19: 3e-05 | L19: 0.03 | M19: 2 | N19: 1 | O19: 0 | P19: =IF(OR(M19-M18<0,N19=0),MAX(P$5:P18)+1,0) -> 0 | Q19: =IF(P20="",Q18,IF(P19=0,Q18,P19)) -> 3 | R19: =IF(Q19=R$4,A19,$R$5) | S19: =IF($Q19=S$4,$A19,$R$5) | T19: =IF($Q19=T$4,$A19,$R$5) -> 14 | U19: =IF($Q19=U$4,$A19,$R$5) | V19: =IF($Q19=V$4,$A19,$R$5) | W19: =IF($Q19=W$4,$A19,$R$5) | X19: =IF($Q19=X$4,$A19,$R$5) | Y19: =IF($Q19=Y$4,$A19,$R$5) | Z19: 13 | AA19: 13 | AB19: 12 | AC19: -14 | AE19: =_xlfn.CONCAT(E19+1,",",D19+1) -> 8,5 | AF19: =AF18+1 -> 13 | AG19: =IF(ISNUMBER(MATCH(AG70,$AX$29:$AX$38,0)),$AX$28,IF(ISNUMBER(MATCH(AG70,$AX$26:$AX$27,0)),$AX$25,IF(ISNUMBER(MATCH(AG70,$AE$6:$AE$41,0)),$AE$5,$O$5))) -> -1 | AH19: =IF(ISNUMBER(MATCH(AH70,$AX$29:$AX$38,0)),$AX$28,IF(ISNUMBER(MATCH(AH70,$AX$26:$AX$27,0)),$AX$25,IF(ISNUMBER(MATCH(AH70,$AE$6:$AE$41,0)),$AE$5,$O$5))) -> 1 | AI19: =IF(ISNUMBER(MATCH(AI70,$AX$29:$AX$38,0)),$AX$28,IF(ISNUMBER(MATCH(AI70,$AX$26:$AX$27,0)),$AX$25,IF(ISNUMBER(MATCH(AI70,$AE$6:$AE$41,0)),$AE$5,$O$5))) -> 1 | AJ19: =IF(ISNUMBER(MATCH(AJ70,$AX$29:$AX$38,0)),$AX$28,IF(ISNUMBER(MATCH(AJ70,$AX$26:$AX$27,0)),$AX$25,IF(ISNUMBER(MATCH(AJ70,$AE$6:$AE$41,0)),$AE$5,$O$5))) -> 1 | AK19: =IF(ISNUMBER(MATCH(AK70,$AX$29:$AX$38,0)),$AX$28,IF(ISNUMBER(MATCH(AK70,$AX$26:$AX$27,0)),$AX$25,IF(ISNUMBER(MATCH(AK70,$AE$6:$AE$41,0)),$AE$5,$O$5))) -> 1 | AL19: =IF(ISNUMBER(MATCH(AL70,$AX$29:$AX$38,0)),$AX$28,IF(ISNUMBER(MATCH(AL70,$AX$26:$AX$27,0)),$AX$25,IF(ISNUMBER(MATCH(AL70,$AE$6:$AE$41,0)),$AE$5,$O$5))) -> 1 | AM19: =IF(ISNUMBER(MATCH(AM70,$AX$29:$AX$38,0)),$AX$28,IF(ISNUMBER(MATCH(AM70,$AX$26:$AX$27,0)),$AX$25,IF(ISNUMBER(MATCH(AM70,$AE$6:$AE$41,0)),$AE$5,$O$5))) -> 1 | AN19: =IF(ISNUMBER(MATCH(AN70,$AX$29:$AX$38,0)),$AX$28,IF(ISNUMBER(MATCH(AN70,$AX$26:$AX$27,0)),$AX$25,IF(ISNUMBER(MATCH(AN70,$AE$6:$AE$41,0)),$AE$5,$O$5))) -> 1 | ... AP19: =IF(ISNUMBER(MATCH(AP70,$AX$29:$AX$38,0)),$AX$28,IF(ISNUMBER(MATCH(AP70,$AX$26:$AX$27,0)),$AX$25,IF(ISNUMBER(MATCH(AP70,$AE$6:$AE$41,0)),$AE$5,$O$5))) -> 0 | AS19: 10 | AT19: 9 | AU19: stage | AV19: 1075.545 | AZ19: =_xlfn.MINIFS(AZ20:BI34,AZ20:BI34,"<>0") -> 997 | BI19: Top | BK19: =_xlfn.MINIFS(BK20:BT34,BK20:BT34,"<>0") -> 997 | BT19: Surf | BV19: =_xlfn.MINIFS(BV20:CE34,BV20:CE34,"<>0") -> 530 | CE19: Bot | CH19: =CI19/$CI$3 -> 1.201769 | CI19: 37924945 | CJ19: 1078.4047 | CK19: 1060.545 | CL19: 1025.9804 | CM19: 993.22752 | CN19: -16.081238 | CO19: 0 | CP19: -0.44038516 | CQ19: -138.96363 | CR19: =CN19-$CR$4 -> 0.35060946
A20: =A19+1 -> 15 | B20: 14 | C20: 0 | D20: 5 | E20: 7 | F20: 2000 | G20: 10 | H20: 0.00054545456 | I20: 1060.545 | J20: 2 | K20: 3e-05 | L20: 0.03 | M20: 2 | N20: 1 | O20: 0 | P20: =IF(OR(M20-M19<0,N20=0),MAX(P$5:P19)+1,0) -> 0 | Q20: =IF(P21="",Q19,IF(P20=0,Q19,P20)) -> 3 | R20: =IF(Q20=R$4,A20,$R$5) | S20: =IF($Q20=S$4,$A20,$R$5) | T20: =IF($Q20=T$4,$A20,$R$5) -> 15 | U20: =IF($Q20=U$4,$A20,$R$5) | V20: =IF($Q20=V$4,$A20,$R$5) | W20: =IF($Q20=W$4,$A20,$R$5) | X20: =IF($Q20=X$4,$A20,$R$5) | Y20: =IF($Q20=Y$4,$A20,$R$5) | Z20: 14 | AA20: 14 | AB20: 13 | AC20: -18 | AE20: =_xlfn.CONCAT(E20+1,",",D20+1) -> 8,6 | AF20: =AF19+1 -> 14 | AG20: =IF(ISNUMBER(MATCH(AG71,$AX$29:$AX$38,0)),$AX$28,IF(ISNUMBER(MATCH(AG71,$AX$26:$AX$27,0)),$AX$25,IF(ISNUMBER(MATCH(AG71,$AE$6:$AE$41,0)),$AE$5,$O$5))) -> 0 | AH20: =IF(ISNUMBER(MATCH(AH71,$AX$29:$AX$38,0)),$AX$28,IF(ISNUMBER(MATCH(AH71,$AX$26:$AX$27,0)),$AX$25,IF(ISNUMBER(MATCH(AH71,$AE$6:$AE$41,0)),$AE$5,$O$5))) -> 0 | AI20: =IF(ISNUMBER(MATCH(AI71,$AX$29:$AX$38,0)),$AX$28,IF(ISNUMBER(MATCH(AI71,$AX$26:$AX$27,0)),$AX$25,IF(ISNUMBER(MATCH(AI71,$AE$6:$AE$41,0)),$AE$5,$O$5))) -> 0 | AJ20: =IF(ISNUMBER(MATCH(AJ71,$AX$29:$AX$38,0)),$AX$28,IF(ISNUMBER(MATCH(AJ71,$AX$26:$AX$27,0)),$AX$25,IF(ISNUMBER(MATCH(AJ71,$AE$6:$AE$41,0)),$AE$5,$O$5))) -> 0 | AK20: =IF(ISNUMBER(MATCH(AK71,$AX$29:$AX$38,0)),$AX$28,IF(ISNUMBER(MATCH(AK71,$AX$26:$AX$27,0)),$AX$25,IF(ISNUMBER(MATCH(AK71,$AE$6:$AE$41,0)),$AE$5,$O$5))) -> 0 | AL20: =IF(ISNUMBER(MATCH(AL71,$AX$29:$AX$38,0)),$AX$28,IF(ISNUMBER(MATCH(AL71,$AX$26:$AX$27,0)),$AX$25,IF(ISNUMBER(MATCH(AL71,$AE$6:$AE$41,0)),$AE$5,$O$5))) -> 0 | AM20: =IF(ISNUMBER(MATCH(AM71,$AX$29:$AX$38,0)),$AX$28,IF(ISNUMBER(MATCH(AM71,$AX$26:$AX$27,0)),$AX$25,IF(ISNUMBER(MATCH(AM71,$AE$6:$AE$41,0)),$AE$5,$O$5))) -> 0 | AN20: =IF(ISNUMBER(MATCH(AN71,$AX$29:$AX$38,0)),$AX$28,IF(ISNUMBER(MATCH(AN71,$AX$26:$AX$27,0)),$AX$25,IF(ISNUMBER(MATCH(AN71,$AE$6:$AE$41,0)),$AE$5,$O$5))) -> 0 | ... AP20: =IF(ISNUMBER(MATCH(AP71,$AX$29:$AX$38,0)),$AX$28,IF(ISNUMBER(MATCH(AP71,$AX$26:$AX$27,0)),$AX$25,IF(ISNUMBER(MATCH(AP71,$AE$6:$AE$41,0)),$AE$5,$O$5))) -> 0 | AS20: 11 | AT20: 10 | AU20: stage | AV20: 1072.636 | AZ20: 1105 | BA20: 1105 | BB20: 0 | BC20: 0 | BD20: 0 | BE20: 0 | BF20: 0 | BG20: 0 | BH20: 0 | BI20: 0 | BK20: 1110 | BL20: 1110 | BM20: 0 | BN20: 0 | BO20: 0 | BP20: 0 | BQ20: 0 | BR20: 0 | BS20: 0 | BT20: 0 | BV20: 1000 | BW20: 1000 | BX20: 0 | BY20: 0 | BZ20: 0 | CA20: 0 | CB20: 0 | CC20: 0 | CD20: 0 | CE20: 0 | CH20: =CI20/$CI$3 -> 1.3649046 | CI20: 43073113 | CJ20: 1078.4008 | CK20: 1060.545 | CL20: 1025.9794 | CM20: 993.21866 | CN20: -15.967824 | CO20: 0 | CP20: -0.43019646 | CQ20: -137.44502 | CR20: =CN20-$CR$4 -> 0.46402255
A21: =A20+1 -> 16 | B21: 15 | C21: 0 | D21: 4 | E21: 9 | F21: 2500 | G21: 10 | H21: 0.0018181818 | I21: 1077.727 | J21: 3 | K21: 3e-05 | L21: 0.03 | M21: 1 | N21: 1 | O21: 0 | P21: =IF(OR(M21-M20<0,N21=0),MAX(P$5:P20)+1,0) -> 4 | Q21: =IF(P22="",Q20,IF(P21=0,Q20,P21)) -> 4 | R21: =IF(Q21=R$4,A21,$R$5) | S21: =IF($Q21=S$4,$A21,$R$5) | T21: =IF($Q21=T$4,$A21,$R$5) | U21: =IF($Q21=U$4,$A21,$R$5) -> 16 | V21: =IF($Q21=V$4,$A21,$R$5) | W21: =IF($Q21=W$4,$A21,$R$5) | X21: =IF($Q21=X$4,$A21,$R$5) | Y21: =IF($Q21=Y$4,$A21,$R$5) | Z21: 15 | AA21: 15 | AB21: -16 | AE21: =_xlfn.CONCAT(E21+1,",",D21+1) -> 10,5 | AF21: =AF20+1 -> 15 | AG21: =IF(ISNUMBER(MATCH(AG72,$AX$29:$AX$38,0)),$AX$28,IF(ISNUMBER(MATCH(AG72,$AX$26:$AX$27,0)),$AX$25,IF(ISNUMBER(MATCH(AG72,$AE$6:$AE$41,0)),$AE$5,$O$5))) -> 0 | AH21: =IF(ISNUMBER(MATCH(AH72,$AX$29:$AX$38,0)),$AX$28,IF(ISNUMBER(MATCH(AH72,$AX$26:$AX$27,0)),$AX$25,IF(ISNUMBER(MATCH(AH72,$AE$6:$AE$41,0)),$AE$5,$O$5))) -> 0 | AI21: =IF(ISNUMBER(MATCH(AI72,$AX$29:$AX$38,0)),$AX$28,IF(ISNUMBER(MATCH(AI72,$AX$26:$AX$27,0)),$AX$25,IF(ISNUMBER(MATCH(AI72,$AE$6:$AE$41,0)),$AE$5,$O$5))) -> 0 | AJ21: =IF(ISNUMBER(MATCH(AJ72,$AX$29:$AX$38,0)),$AX$28,IF(ISNUMBER(MATCH(AJ72,$AX$26:$AX$27,0)),$AX$25,IF(ISNUMBER(MATCH(AJ72,$AE$6:$AE$41,0)),$AE$5,$O$5))) -> 0 | AK21: =IF(ISNUMBER(MATCH(AK72,$AX$29:$AX$38,0)),$AX$28,IF(ISNUMBER(MATCH(AK72,$AX$26:$AX$27,0)),$AX$25,IF(ISNUMBER(MATCH(AK72,$AE$6:$AE$41,0)),$AE$5,$O$5))) -> 0 | AL21: =IF(ISNUMBER(MATCH(AL72,$AX$29:$AX$38,0)),$AX$28,IF(ISNUMBER(MATCH(AL72,$AX$26:$AX$27,0)),$AX$25,IF(ISNUMBER(MATCH(AL72,$AE$6:$AE$41,0)),$AE$5,$O$5))) -> 0 | AM21: =IF(ISNUMBER(MATCH(AM72,$AX$29:$AX$38,0)),$AX$28,IF(ISNUMBER(MATCH(AM72,$AX$26:$AX$27,0)),$AX$25,IF(ISNUMBER(MATCH(AM72,$AE$6:$AE$41,0)),$AE$5,$O$5))) -> 0 | AN21: =IF(ISNUMBER(MATCH(AN72,$AX$29:$AX$38,0)),$AX$28,IF(ISNUMBER(MATCH(AN72,$AX$26:$AX$27,0)),$AX$25,IF(ISNUMBER(MATCH(AN72,$AE$6:$AE$41,0)),$AE$5,$O$5))) -> 0 | ... AP21: =IF(ISNUMBER(MATCH(AP72,$AX$29:$AX$38,0)),$AX$28,IF(ISNUMBER(MATCH(AP72,$AX$26:$AX$27,0)),$AX$25,IF(ISNUMBER(MATCH(AP72,$AE$6:$AE$41,0)),$AE$5,$O$5))) -> 0 | AS21: 12 | AT21: 11 | AU21: stage | AV21: 1069.873 | AZ21: 1105 | BA21: 1095 | BB21: 1105 | BC21: 0 | BD21: 0 | BE21: 1100 | BF21: 1100 | BG21: 1110 | BH21: 0 | BI21: 0 | BK21: 1110 | BL21: 1105 | BM21: 1110 | BN21: 0 | BO21: 0 | BP21: 1100 | BQ21: 1100 | BR21: 1110 | BS21: 0 | BT21: 0 | BV21: 1000 | BW21: 900 | BX21: 900 | BY21: 0 | BZ21: 0 | CA21: 950 | CB21: 950 | CC21: 950 | CD21: 0 | CE21: 0 | CH21: =CI21/$CI$3 -> 1.5443537 | CI21: 48736098 | CJ21: 1078.396 | CK21: 1060.545 | CL21: 1025.9783 | CM21: 993.20938 | CN21: -15.832239 | CO21: 0 | CP21: -0.41948819 | CQ21: -135.86067 | CR21: =CN21-$CR$4 -> 0.59960773
A22: =A21+1 -> 17 | B22: 16 | C22: 0 | D22: 4 | E22: 8 | F22: 5000 | G22: 10 | H22: 0.0018181818 | I22: 1070.909 | J22: 3 | K22: 3e-05 | L22: 0.03 | M22: 2 | N22: 1 | O22: 0 | P22: =IF(OR(M22-M21<0,N22=0),MAX(P$5:P21)+1,0) -> 0 | Q22: =IF(P23="",Q21,IF(P22=0,Q21,P22)) -> 4 | R22: =IF(Q22=R$4,A22,$R$5) | S22: =IF($Q22=S$4,$A22,$R$5) | T22: =IF($Q22=T$4,$A22,$R$5) | U22: =IF($Q22=U$4,$A22,$R$5) -> 17 | V22: =IF($Q22=V$4,$A22,$R$5) | W22: =IF($Q22=W$4,$A22,$R$5) | X22: =IF($Q22=X$4,$A22,$R$5) | Y22: =IF($Q22=Y$4,$A22,$R$5) | Z22: 16 | AA22: 16 | AB22: 15 | AC22: -17 | AE22: =_xlfn.CONCAT(E22+1,",",D22+1) -> 9,5 | AS22: 13 | AT22: 12 | AU22: stage | AV22: 1066.819 | AZ22: 0 | BA22: 1100 | BB22: 1085 | BC22: 1080 | BD22: 1078 | BE22: 1076 | BF22: 1073 | BG22: 1090 | BH22: 0 | BI22: 0 | BK22: 0 | BL22: 1100 | BM22: 1095 | BN22: 1088 | BO22: 1085 | BP22: 1085 | BQ22: 1085 | BR22: 1090 | BS22: 0 | BT22: 0 | BV22: 0 | BW22: 850 | BX22: 670 | BY22: 680 | BZ22: 680 | CA22: 770 | CB22: 770 | CC22: 890 | CD22: 0 | CE22: 0 | CH22: =CI22/$CI$3 -> 1.7417478 | CI22: 54965381 | CJ22: 1078.3905 | CK22: 1060.545 | CL22: 1025.9772 | CM22: 993.19976 | CN22: -15.673089 | CO22: 0 | CP22: -0.4083856 | CQ22: -134.2258 | CR22: =CN22-$CR$4 -> 0.7587581
A23: =A22+1 -> 18 | B23: 17 | C23: 0 | D23: 5 | E23: 7 | F23: 3500 | G23: 10 | H23: 0.0018181818 | I23: 1063.182 | J23: 3 | K23: 3e-05 | L23: 0.03 | M23: 2 | N23: 1 | O23: 0 | P23: =IF(OR(M23-M22<0,N23=0),MAX(P$5:P22)+1,0) -> 0 | Q23: =IF(P24="",Q22,IF(P23=0,Q22,P23)) -> 4 | R23: =IF(Q23=R$4,A23,$R$5) | S23: =IF($Q23=S$4,$A23,$R$5) | T23: =IF($Q23=T$4,$A23,$R$5) | U23: =IF($Q23=U$4,$A23,$R$5) -> 18 | V23: =IF($Q23=V$4,$A23,$R$5) | W23: =IF($Q23=W$4,$A23,$R$5) | X23: =IF($Q23=X$4,$A23,$R$5) | Y23: =IF($Q23=Y$4,$A23,$R$5) | Z23: 17 | AA23: 17 | AB23: 16 | AC23: -18 | AE23: =_xlfn.CONCAT(E23+1,",",D23+1) -> 8,6 | AS23: 14 | AT23: 13 | AU23: stage | AV23: 1063.619 | AZ23: 1110 | BA23: 1100 | BB23: 1090 | BC23: 1085 | BD23: 1076 | BE23: 1080 | BF23: 1080 | BG23: 1070 | BH23: 1100 | BI23: 0 | BK23: 1105 | BL23: 1100 | BM23: 1090 | BN23: 1083 | BO23: 1078 | BP23: 1075 | BQ23: 1080 | BR23: 1085 | BS23: 1100 | BT23: 0 | BV23: 925 | BW23: 850 | BX23: 650 | BY23: 650 | BZ23: 650 | CA23: 680 | CB23: 740 | CC23: 850 | CD23: 950 | CE23: 0 | CH23: =CI23/$CI$3 -> 1.9588813 | CI23: 61817593 | CJ23: 1078.384 | CK23: 1060.545 | CL23: 1025.9761 | CM23: 993.18991 | CN23: -15.489201 | CO23: 0 | CP23: -0.39702994 | CQ23: -132.56021 | CR23: =CN23-$CR$4 -> 0.94264574
A24: =A23+1 -> 19 | B24: 18 | C24: 0 | D24: 5 | E24: 7 | F24: 4000 | G24: 15 | H24: 0.001 | I24: 1058 | J24: 3 | K24: 3e-05 | L24: 0.03 | M24: 3 | N24: 1 | O24: 0 | P24: =IF(OR(M24-M23<0,N24=0),MAX(P$5:P23)+1,0) -> 0 | Q24: =IF(P25="",Q23,IF(P24=0,Q23,P24)) -> 4 | R24: =IF(Q24=R$4,A24,$R$5) | S24: =IF($Q24=S$4,$A24,$R$5) | T24: =IF($Q24=T$4,$A24,$R$5) | U24: =IF($Q24=U$4,$A24,$R$5) -> 19 | V24: =IF($Q24=V$4,$A24,$R$5) | W24: =IF($Q24=W$4,$A24,$R$5) | X24: =IF($Q24=X$4,$A24,$R$5) | Y24: =IF($Q24=Y$4,$A24,$R$5) | Z24: 18 | AA24: 18 | AB24: 14 | AC24: 17 | AD24: -19 | AE24: =_xlfn.CONCAT(E24+1,",",D24+1) -> 8,6 | AP24: manu | AS24: 15 | AT24: 14 | AU24: stage | AV24: 1061.581 | AZ24: 1110 | BA24: 1100 | BB24: 1085 | BC24: 1080 | BD24: 1078 | BE24: 1074 | BF24: 1077 | BG24: 1066 | BH24: 1075 | BI24: 1080 | BK24: 1105 | BL24: 1090 | BM24: 1080 | BN24: 1077 | BO24: 1074 | BP24: 1073 | BQ24: 1074 | BR24: 1078 | BS24: 1080 | BT24: 1085 | BV24: 925 | BW24: 800 | BX24: 650 | BY24: 600 | BZ24: 600 | CA24: 600 | CB24: 650 | CC24: 720 | CD24: 850 | CE24: 950 | CH24: =CI24/$CI$3 -> 2.1977281 | CI24: 69355025 | CJ24: 1078.3766 | CK24: 1060.545 | CL24: 1025.9749 | CM24: 993.17991 | CN24: -15.279631 | CO24: 0 | CP24: -0.38552422 | CQ24: -130.87627 | CR24: =CN24-$CR$4 -> 1.1522161
A25: =A24+1 -> 20 | B25: 19 | C25: 0 | D25: 6 | E25: 6 | F25: 5000 | G25: 15 | H25: 0.001 | I25: 1053.5 | J25: 3 | K25: 3e-05 | L25: 0.03 | M25: 2 | N25: 1 | O25: 0 | P25: =IF(OR(M25-M24<0,N25=0),MAX(P$5:P24)+1,0) -> 5 | Q25: =IF(P26="",Q24,IF(P25=0,Q24,P25)) -> 5 | R25: =IF(Q25=R$4,A25,$R$5) | S25: =IF($Q25=S$4,$A25,$R$5) | T25: =IF($Q25=T$4,$A25,$R$5) | U25: =IF($Q25=U$4,$A25,$R$5) | V25: =IF($Q25=V$4,$A25,$R$5) -> 20 | W25: =IF($Q25=W$4,$A25,$R$5) | X25: =IF($Q25=X$4,$A25,$R$5) | Y25: =IF($Q25=Y$4,$A25,$R$5) | Z25: 19 | AA25: 19 | AB25: 18 | AC25: -20 | AE25: =_xlfn.CONCAT(E25+1,",",D25+1) -> 7,7 | AG25: 1 | AH25: =AG25+1 -> 2 | AI25: =AH25+1 -> 3 | AJ25: =AI25+1 -> 4 | AK25: =AJ25+1 -> 5 | AL25: =AK25+1 -> 6 | AM25: =AL25+1 -> 7 | AN25: =AM25+1 -> 8 | AO25: =AN25+1 -> 9 | AP25: =AO25+1 -> 10 | AS25: =AX1 -> e2_ghb_spd.csv | AU25: xy | AV25: H | AW25: Cont | AX25: -1 | AZ25: 1105 | BA25: 1095 | BB25: 1080 | BC25: 1077 | BD25: 1073 | BE25: 1069 | BF25: 1070 | BG25: 1063 | BH25: 1085 | BI25: 1095 | BK25: 1100 | BL25: 1080 | BM25: 1075 | BN25: 1072 | BO25: 1071 | BP25: 1069 | BQ25: 1070 | BR25: 1075 | BS25: 1080 | BT25: 1100 | BV25: 925 | BW25: 800 | BX25: 650 | BY25: 600 | BZ25: 550 | CA25: 600 | CB25: 650 | CC25: 720 | CD25: 850 | CE25: 970 | CH25: =CI25/$CI$3 -> 2.4604597 | CI25: 77646202 | CJ25: 1078.3685 | CK25: 1060.545 | CL25: 1025.9737 | CM25: 993.16977 | CN25: -15.051648 | CO25: 0 | CP25: -0.37393075 | CQ25: -129.1784 | CR25: =CN25-$CR$4 -> 1.3801987
A26: =A25+1 -> 21 | B26: 20 | C26: 0 | D26: 7 | E26: 6 | F26: 3500 | G26: 15 | H26: 0.001 | I26: 1049.25 | J26: 3 | K26: 3e-05 | L26: 0.03 | M26: 2 | N26: 1 | O26: 0 | P26: =IF(OR(M26-M25<0,N26=0),MAX(P$5:P25)+1,0) -> 0 | Q26: =IF(P27="",Q25,IF(P26=0,Q25,P26)) -> 5 | R26: =IF(Q26=R$4,A26,$R$5) | S26: =IF($Q26=S$4,$A26,$R$5) | T26: =IF($Q26=T$4,$A26,$R$5) | U26: =IF($Q26=U$4,$A26,$R$5) | V26: =IF($Q26=V$4,$A26,$R$5) -> 21 | W26: =IF($Q26=W$4,$A26,$R$5) | X26: =IF($Q26=X$4,$A26,$R$5) | Y26: =IF($Q26=Y$4,$A26,$R$5) | Z26: 20 | AA26: 20 | AB26: 19 | AC26: -21 | AE26: =_xlfn.CONCAT(E26+1,",",D26+1) -> 7,8 | AF26: 1 | AG26: =AG7 -> 1 | AH26: =AH7 -> 0 | AI26: =AI7 -> 0 | AJ26: =AJ7 -> 0 | AK26: =AK7 -> 0 | AL26: =AL7 -> 0 | AM26: =AM7 -> 0 | AN26: =AN7 -> 0 | ... AP26: =AP7 -> 0 | AS26: 0 | AT26: 12 | AU26: 0 | AV26: 988 | AW26: 0.038 | AX26: =_xlfn.CONCAT(AU26+1,",",AT26+1) -> 1,13 | AZ26: 1105 | BA26: 1090 | BB26: 1075 | BC26: 1072 | BD26: 1070 | BE26: 1065 | BF26: 1065 | BG26: 1069 | BH26: 1090 | BI26: 0 | BK26: 1100 | BL26: 1080 | BM26: 1070 | BN26: 1065 | BO26: 1065 | BP26: 1065 | BQ26: 1065 | BR26: 1070 | BS26: 1090 | BT26: 0 | BV26: 925 | BW26: 800 | BX26: 650 | BY26: 600 | BZ26: 550 | CA26: 600 | CB26: 650 | CC26: 720 | CD26: 950 | CE26: 0 | CH26: =CI26/$CI$3 -> 2.7494643 | CI26: 86766495 | CJ26: 1078.3674 | CK26: 1060.545 | CL26: 1025.9725 | CM26: 993.15938 | CN26: -15.021569 | CO26: 0 | CP26: -0.36209155 | CQ26: -127.44652 | CR26: =CN26-$CR$4 -> 1.410278
A27: =A26+1 -> 22 | B27: 21 | C27: 0 | D27: 7 | E27: 5 | F27: 2500 | G27: 15 | H27: 0.001 | I27: 1046.25 | J27: 3 | K27: 3e-05 | L27: 0.03 | M27: 2 | N27: 1 | O27: 0 | P27: =IF(OR(M27-M26<0,N27=0),MAX(P$5:P26)+1,0) -> 0 | Q27: =IF(P28="",Q26,IF(P27=0,Q26,P27)) -> 5 | R27: =IF(Q27=R$4,A27,$R$5) | S27: =IF($Q27=S$4,$A27,$R$5) | T27: =IF($Q27=T$4,$A27,$R$5) | U27: =IF($Q27=U$4,$A27,$R$5) | V27: =IF($Q27=V$4,$A27,$R$5) -> 22 | W27: =IF($Q27=W$4,$A27,$R$5) | X27: =IF($Q27=X$4,$A27,$R$5) | Y27: =IF($Q27=Y$4,$A27,$R$5) | Z27: 21 | AA27: 21 | AB27: 20 | AC27: -22 | AE27: =_xlfn.CONCAT(E27+1,",",D27+1) -> 6,8 | AF27: =AF26+1 -> 2 | AG27: =AG8 -> 0 | AH27: =AH8 -> 1 | AI27: =AI8 -> 0 | AJ27: =AJ8 -> 0 | AK27: =AK8 -> 0 | AL27: =AL8 -> 0 | AM27: =AM8 -> 0 | AN27: =AN8 -> 0 | ... AP27: =AP8 -> 0 | AS27: 0 | AT27: 13 | AU27: 8 | AV27: 1045 | AW27: 0.038 | AX27: =_xlfn.CONCAT(AU27+1,",",AT27+1) -> 9,14 | AZ27: 0 | BA27: 1080 | BB27: 1070 | BC27: 1068 | BD27: 1063 | BE27: 1060 | BF27: 1063 | BG27: 1067 | BH27: 1090 | BI27: 0 | BK27: 0 | BL27: 1075 | BM27: 1065 | BN27: 1059 | BO27: 1059 | BP27: 1058 | BQ27: 1063 | BR27: 1070 | BS27: 1090 | BT27: 0 | BV27: 0 | BW27: 850 | BX27: 700 | BY27: 650 | BZ27: 570 | CA27: 600 | CB27: 700 | CC27: 850 | CD27: 950 | CE27: 0 | CH27: =CI27/$CI$3 -> 3.0673695 | CI27: 96798818 | CJ27: 1078.3659 | CK27: 1060.545 | CL27: 1025.9712 | CM27: 993.14881 | CN27: -14.978788 | CO27: 0 | CP27: -0.35005202 | CQ27: -125.69301 | CR27: =CN27-$CR$4 -> 1.4530589
A28: =A27+1 -> 23 | B28: 22 | C28: 0 | D28: 8 | E28: 5 | F28: 5000 | G28: 12 | H28: 0.00090909092 | I28: 1042.727 | J28: 3 | K28: 3e-05 | L28: 0.03 | M28: 3 | N28: 1 | O28: 0 | P28: =IF(OR(M28-M27<0,N28=0),MAX(P$5:P27)+1,0) -> 0 | Q28: =IF(P29="",Q27,IF(P28=0,Q27,P28)) -> 5 | R28: =IF(Q28=R$4,A28,$R$5) | S28: =IF($Q28=S$4,$A28,$R$5) | T28: =IF($Q28=T$4,$A28,$R$5) | U28: =IF($Q28=U$4,$A28,$R$5) | V28: =IF($Q28=V$4,$A28,$R$5) -> 23 | W28: =IF($Q28=W$4,$A28,$R$5) | X28: =IF($Q28=X$4,$A28,$R$5) | Y28: =IF($Q28=Y$4,$A28,$R$5) | Z28: 22 | AA28: 22 | AB28: 8 | AC28: 21 | AD28: -23 | AE28: =_xlfn.CONCAT(E28+1,",",D28+1) -> 6,9 | AF28: =AF27+1 -> 3 | AG28: =AG9 -> 0 | AH28: =AH9 -> 0 | AI28: =AI9 -> 1 | AJ28: =AJ9 -> 1 | AK28: 3 | AL28: 3 | AM28: 3 | AN28: =AN9 -> 0 | AO28: =AO9 -> 0 | AP28: =AP9 -> 0 | AS28: =AX2 -> f2_wel_spd | AU28: xy | AX28: W | AZ28: 0 | BA28: 1075 | BB28: 1065 | BC28: 1062 | BD28: 1058 | BE28: 1052 | BF28: 1055 | BG28: 1065 | BH28: 1090 | BI28: 0 | BK28: 0 | BL28: 1065 | BM28: 1055 | BN28: 1053 | BO28: 1053 | BP28: 1052 | BQ28: 1055 | BR28: 1065 | BS28: 1090 | BT28: 0 | BV28: 0 | BW28: 850 | BX28: 700 | BY28: 650 | BZ28: 540 | CA28: 580 | CB28: 700 | CC28: 850 | CD28: 950 | CE28: 0 | CH28: =CI28/$CI$3 -> 3.4170651 | CI28: 1.0783437e+08 | CJ28: 1078.3638 | CK28: 1060.545 | CL28: 1025.9699 | CM28: 993.13809 | CN28: -14.920057 | CO28: 0 | CP28: -0.33789061 | CQ28: -123.92632 | CR28: =CN28-$CR$4 -> 1.5117897
A29: =A28+1 -> 24 | B29: 23 | C29: 0 | D29: 9 | E29: 6 | F29: 5000 | G29: 12 | H29: 0.00090909092 | I29: 1038.182 | J29: 3 | K29: 3e-05 | L29: 0.03 | M29: 2 | N29: 1 | O29: 0 | P29: =IF(OR(M29-M28<0,N29=0),MAX(P$5:P28)+1,0) -> 6 | Q29: =IF(P30="",Q28,IF(P29=0,Q28,P29)) -> 6 | R29: =IF(Q29=R$4,A29,$R$5) | S29: =IF($Q29=S$4,$A29,$R$5) | T29: =IF($Q29=T$4,$A29,$R$5) | U29: =IF($Q29=U$4,$A29,$R$5) | V29: =IF($Q29=V$4,$A29,$R$5) | W29: =IF($Q29=W$4,$A29,$R$5) -> 24 | X29: =IF($Q29=X$4,$A29,$R$5) | Y29: =IF($Q29=Y$4,$A29,$R$5) | Z29: 23 | AA29: 23 | AB29: 22 | AC29: -24 | AE29: =_xlfn.CONCAT(E29+1,",",D29+1) -> 7,10 | AF29: =AF28+1 -> 4 | AG29: =AG10 -> 0 | AH29: =AH10 -> 0 | AI29: =AI10 -> 0 | AJ29: =AJ10 -> 0 | AK29: 2 | AL29: =AL10 -> 0 | AM29: =AM10 -> 0 | AN29: 3 | AO29: =AO10 -> 0 | AP29: =AP10 -> 0 | AS29: 0 | AT29: 5 | AU29: 3 | AV29: -10 | AX29: =_xlfn.CONCAT(AU29+1,",",AT29+1) -> 4,6 | AZ29: 0 | BA29: 1070 | BB29: 1060 | BC29: 1055 | BD29: 1046 | BE29: 1046 | BF29: 1044 | BG29: 1060 | BH29: 1088 | BI29: 1100 | BK29: 0 | BL29: 1060 | BM29: 1046 | BN29: 1046 | BO29: 1046 | BP29: 1046 | BQ29: 1044 | BR29: 1060 | BS29: 1088 | BT29: 1100 | BV29: 0 | BW29: 850 | BX29: 700 | BY29: 630 | BZ29: 530 | CA29: 580 | CB29: 650 | CC29: 800 | CD29: 900 | CE29: 950 | CH29: =CI29/$CI$3 -> 3.8017303 | CI29: 1.1997348e+08 | CJ29: 1078.3611 | CK29: 1060.545 | CL29: 1025.9686 | CM29: 993.12727 | CN29: -14.843518 | CO29: 0 | CP29: -0.32564766 | CQ29: -122.15214 | CR29: =CN29-$CR$4 -> 1.5883292
A30: =A29+1 -> 25 | B30: 24 | C30: 0 | D30: 10 | E30: 6 | F30: 5000 | G30: 12 | H30: 0.00090909092 | I30: 1033.636 | J30: 3 | K30: 3e-05 | L30: 0.03 | M30: 2 | N30: 1 | O30: 0 | P30: =IF(OR(M30-M29<0,N30=0),MAX(P$5:P29)+1,0) -> 0 | Q30: =IF(P31="",Q29,IF(P30=0,Q29,P30)) -> 6 | R30: =IF(Q30=R$4,A30,$R$5) | S30: =IF($Q30=S$4,$A30,$R$5) | T30: =IF($Q30=T$4,$A30,$R$5) | U30: =IF($Q30=U$4,$A30,$R$5) | V30: =IF($Q30=V$4,$A30,$R$5) | W30: =IF($Q30=W$4,$A30,$R$5) -> 25 | X30: =IF($Q30=X$4,$A30,$R$5) | Y30: =IF($Q30=Y$4,$A30,$R$5) | Z30: 24 | AA30: 24 | AB30: 23 | AC30: -25 | AE30: =_xlfn.CONCAT(E30+1,",",D30+1) -> 7,11 | AF30: =AF29+1 -> 5 | AG30: =AG11 -> 0 | AH30: =AH11 -> 0 | AI30: =AI11 -> 0 | AJ30: =AJ11 -> 0 | AK30: =AK11 -> 0 | AL30: 2 | AM30: =AM11 -> 0 | AN30: 3 | AO30: 4 | AP30: 4 | AS30: 0 | AT30: 5 | AU30: 4 | AV30: -10 | AX30: =_xlfn.CONCAT(AU30+1,",",AT30+1) -> 5,6 | AZ30: 0 | BA30: 1055 | BB30: 1050 | BC30: 1045 | BD30: 1041 | BE30: 1042 | BF30: 1040 | BG30: 1050 | BH30: 1075 | BI30: 0 | BK30: 0 | BL30: 1045 | BM30: 1039 | BN30: 1040 | BO30: 1041 | BP30: 1042 | BQ30: 1040 | BR30: 1050 | BS30: 1075 | BT30: 0 | BV30: 0 | BW30: 850 | BX30: 700 | BY30: 620 | BZ30: 580 | CA30: 620 | CB30: 700 | CC30: 800 | CD30: 900 | CE30: 0 | CH30: =CI30/$CI$3 -> 4.224862 | CI30: 1.3332651e+08 | CJ30: 1078.3577 | CK30: 1060.545 | CL30: 1025.9672 | CM30: 993.11636 | CN30: -14.748468 | CO30: 0 | CP30: -0.31333644 | CQ30: -120.37262 | CR30: =CN30-$CR$4 -> 1.6833787
