Workbook
Name a: #REF!
Name ai: #REF!
Name aq: #REF!
Name AV: #REF!
Name baa: #REF!
Name Coord: #REF!
Name CS: #REF!
Name CZ: #REF!
Name DG: #REF!
Name earlier: #REF!
Name EG: #REF!
Name EI: #REF!
Name HLinst: #REF!
Name HP: #REF!
Name I: #REF!
Name JA: #REF!
Name Mean_A: #REF!
Name mean_X: #REF!
Name mean_X.: #REF!
Name mean_Y: #REF!
Name mean_Y.: #REF!
Name mu: #REF!
Name mu_A: #REF!
Name mu_B: #REF!
Name P1_A: #REF!
Name P2_A: #REF!
Name P3_A: #REF!
Name P4_A: #REF!
Name P5_A: #REF!
Name Rot: #REF!
Name SD_A: #REF!
Name SD_X: #REF!
Name SD_Y: #REF!
Name sigma: #REF!
Name sigma_AB: #REF!
Name sigma2_A: #REF!
Name sigma2_B: #REF!
Name Tab.43: #REF!
Name Tab.44: #REF!
Name Target_P: #REF!
Name Total_Mass: #REF!
Name Variance_A: #REF!
Name X: #REF!
Name x_A: #REF!
Name x_B: #REF!
Name Xo: #REF!
Name Yo.1: #REF!
Name Yo.2: #REF!
Name yt: #REF!

Sheet ALL
A1: =COLUMN() -> 1 | M1: =COLUMN()-COLUMN(A1) -> 12 | Q1: =COLUMN()-COLUMN(P1) -> 1 | AO1: =COLUMN()-$Q1 -> 40 | BA1: =COLUMN()-COLUMN(AZ1) -> 1 | BF1: =COLUMN()-COLUMN(BA1) -> 5
N2: REF1 | O2: REF2 | AY2: ↓
C3: =MAX(C5:C1000) -> 22 | D3: =COUNTA(N5:N1000)-C3 -> 14 | N3: =COUNTA(N5:N181) -> 36 | O3: =COUNTA(O5:O181) -> 32 | P3: =SUM(K5:K52) -> 46 | AH3: =MAX(AH5:AH1000) -> 21 | AI3: =MAX(AI5:AI1000) -> 15 | AJ3: =MAX(AJ5:AJ1000) -> 36 | AK3: =MAX(AK5:AK1000) -> 22 | AL3: =MAX(AL5:AL1000) -> 24 | AM3: =MAX(AM5:AM1000) -> 24 | AN3: =MAX(AN5:AN1000) -> 0 | AP3: =COUNTA(AP5:AP322) -> 21 | AQ3: =COUNTA(AQ5:AQ322) -> 16 | AR3: =COUNTA(AR5:AR322) -> 36 | AS3: =COUNTA(AS5:AS322) -> 22 | AT3: =COUNTA(AT5:AT322) -> 24 | AU3: =COUNTA(AU5:AU322) -> 24 | AY3: MANU | AZ3: ← PREP
B4: =COUNTA(N5:N1000) -> 36 | E4: =COUNTA(O5:O1000) -> 32 | N4: -- | O4: -- | P4: RES | R4: 1 | S4: =R4+1 -> 2 | T4: =S4+1 -> 3 | U4: =T4+1 -> 4 | V4: =U4+1 -> 5 | W4: =V4+1 -> 6 | X4: =W4+1 -> 7 | Z4: 1 | AA4: =Z4+1 -> 2 | AB4: =AA4+1 -> 3 | AC4: =AB4+1 -> 4 | AD4: =AC4+1 -> 5 | AE4: =AD4+1 -> 6 | AF4: =AE4+1 -> 7 | AH4: A1 | AI4: A2 | AJ4: A3 | AK4: A4 | AL4: A5 | AM4: A6 | AN4: A7 | AP4: 11 | AQ4: 12 | AR4: 13 | AS4: 14 | AT4: 15 | AU4: 51 | AV4: - | AW4: FIX | AY4: - | AZ4: - | BC4: =COUNT(BC5:BC54) -> 37 | BD4: =ROW() -> 4 | BE4: =P4 -> RES | BG4: =IF(AP4=0,"",AP4) -> 11 | BH4: =IF(AQ4=0,"",AQ4) -> 12 | BI4: =IF(AR4=0,"",AR4) -> 13 | BJ4: =IF(AS4=0,"",AS4) -> 14 | BK4: =IF(AT4=0,"",AT4) -> 15 | BL4: =IF(AU4=0,"",AU4) -> 51 | BM4: =IF(ISNUMBER(MATCH($BE4,AF$5:AF$501,0)),INDEX(AF$5:AF$501,MATCH($BE4,AF$5:AF$501,0),1),"")
B5: =IF(ISNUMBER(MATCH(O5,$N$5:$N$1000,0)),MATCH(O5,$N$5:$N$1000,0),"") -> 1 | C5: =IF(ISNUMBER(B5),MAX(C$4:C4)+1,"") -> 1 | D5: =IF(IF(ISNUMBER(B5),"",MAX(D$4:D4)+1)<=D$3,IF(ISNUMBER(B5),"",MAX(D$4:D4)+1),"") | E5: =IF(M5<=D$3,MATCH(M5,D$5:D$1000,0),"") -> 2 | F5: =IF(ISNUMBER(E5),INDEX($N$5:$N$1000,E5,1),"") -> .dis | G5: =IF(ISNUMBER(C5),N5,IF(ISTEXT(N5),INDEX($F$5:$F$1000,MATCH(M5,$E$5:$E$1000,0),1),"")) -> .cbc | H5: =IF(O5="","",IF(ISNUMBER(MATCH(O5,$G$5:$G$1000,0)),"",IF(D5=1,C$3,0)+MAX(H$4:H4)+1)) | I5: =IF(O5="","",IF(ISNUMBER(MATCH(O5,$G$5:$G$1000,0)),"",IF(D5=1,B$4,0)+MAX(I$4:I4)+1)) | J5: =IF(ISNUMBER(MATCH(M5,$I$5:$I$1000,0)),INDEX($O$5:$O$1000,MATCH(M5,$I$5:$I$1000,0),1),"") | K5: =IF(P5="",0,1) -> 1 | M5: =IF(ROW()-ROW(M$4)<=1000,ROW()-ROW(M$4),"") -> 1 | N5: .cbc | O5: .cbc | P5: =IF(M5<=$B$4,IF(ISTEXT(G5),G5,""),IF(ISTEXT(J5),J5,"")) -> .cbc | R5: =IF(ROW()-ROW(R$4)<=AH$3,ROW()-ROW(R$4),"") -> 1 | S5: =IF(ROW()-ROW(S$4)<=AI$3,ROW()-ROW(S$4),"") -> 1 | T5: =IF(ROW()-ROW(T$4)<=AJ$3,ROW()-ROW(T$4),"") -> 1 | U5: =IF(ROW()-ROW(U$4)<=AK$3,ROW()-ROW(U$4),"") -> 1 | V5: =IF(ROW()-ROW(V$4)<=AL$3,ROW()-ROW(V$4),"") -> 1 | W5: =IF(ROW()-ROW(W$4)<=AM$3,ROW()-ROW(W$4),"") -> 1 | X5: =IF(ROW()-ROW(X$4)<=AN$3,ROW()-ROW(X$4),"") | Z5: =IF(ISNUMBER(R5),INDEX($BE$5:$BE$2999,MATCH(R5,AH$5:AH$2999,0),1),"") -> .ic | AA5: =IF(ISNUMBER(S5),INDEX($BE$5:$BE$2999,MATCH(S5,AI$5:AI$2999,0),1),"") -> .ic | AB5: =IF(ISNUMBER(T5),INDEX($BE$5:$BE$2999,MATCH(T5,AJ$5:AJ$2999,0),1),"") -> .ic | AC5: =IF(ISNUMBER(U5),INDEX($BE$5:$BE$2999,MATCH(U5,AK$5:AK$2999,0),1),"") -> .chd | AD5: =IF(ISNUMBER(V5),INDEX($BE$5:$BE$2999,MATCH(V5,AL$5:AL$2999,0),1),"") -> .chd | AE5: =IF(ISNUMBER(W5),INDEX($BE$5:$BE$2999,MATCH(W5,AM$5:AM$2999,0),1),"") -> .chd | AF5: =IF(ISNUMBER(X5),INDEX($BE$5:$BE$2999,MATCH(X5,AN$5:AN$2999,0),1),"") | AH5: =IF($BE5="","",IF(ISNUMBER(MATCH($BE5,AP$5:AP$29999,0)),MAX(AH$4:AH4)+1,0)) -> 0 | AI5: =IF($BE5="","",IF(ISNUMBER(MATCH($BE5,AQ$5:AQ$29999,0)),MAX(AI$4:AI4)+1,0)) -> 0 | AJ5: =IF($BE5="","",IF(ISNUMBER(MATCH($BE5,AR$5:AR$29999,0)),MAX(AJ$4:AJ4)+1,0)) -> 0 | AK5: =IF($BE5="","",IF(ISNUMBER(MATCH($BE5,AS$5:AS$29999,0)),MAX(AK$4:AK4)+1,0)) -> 1 | AL5: =IF($BE5="","",IF(ISNUMBER(MATCH($BE5,AT$5:AT$29999,0)),MAX(AL$4:AL4)+1,0)) -> 1 | AM5: =IF($BE5="","",IF(ISNUMBER(MATCH($BE5,AU$5:AU$29999,0)),MAX(AM$4:AM4)+1,0)) -> 1 | AN5: =IF($BE5="","",IF(ISNUMBER(MATCH($BE5,AV$5:AV$29999,0)),MAX(AN$4:AN4)+1,0)) -> 0 | AP5: .cbc | AQ5: .dis | AR5: .cbc | AS5: .cbc | AT5: .cbc | AU5: .bud | AW5: .cbc | AY5: .chd | AZ5: .chd | BB5: =IF(ISTEXT(AW5),IF(ISNUMBER(MATCH(AW5,$AY$5:$AY$100,0)),0,MAX(BB$4:BB4)+1),"") -> 0 | BC5: =IF(ISTEXT(AY5),MATCH(AY5,$AW$5:$AW$127,0),"") -> 2 | BD5: =IF(ISNUMBER(BC5),AY5,INDEX($AW$5:$AW$140,ROW()-SUM($BC$4:$BD$4),1)) -> .chd | BE5: =IF(ISTEXT(AW5),IF(ISNUMBER(BC5),AY5,INDEX($AW$5:$AW$140,MATCH(BD5,$BB$5:$BB$185,0),1)),"") -> .chd | BG5: =IF(ISNUMBER(MATCH($BE5,Z$5:Z$501,0)),INDEX(Z$5:Z$501,MATCH($BE5,Z$5:Z$501,0),1),"") | BH5: =IF(ISNUMBER(MATCH($BE5,AA$5:AA$501,0)),INDEX(AA$5:AA$501,MATCH($BE5,AA$5:AA$501,0),1),"") | BI5: =IF(ISNUMBER(MATCH($BE5,AB$5:AB$501,0)),INDEX(AB$5:AB$501,MATCH($BE5,AB$5:AB$501,0),1),"") | BJ5: =IF(ISNUMBER(MATCH($BE5,AC$5:AC$501,0)),INDEX(AC$5:AC$501,MATCH($BE5,AC$5:AC$501,0),1),"") -> .chd | BK5: =IF(ISNUMBER(MATCH($BE5,AD$5:AD$501,0)),INDEX(AD$5:AD$501,MATCH($BE5,AD$5:AD$501,0),1),"") -> .chd | BL5: =IF(ISNUMBER(MATCH($BE5,AE$5:AE$501,0)),INDEX(AE$5:AE$501,MATCH($BE5,AE$5:AE$501,0),1),"") -> .chd | BM5: =IF(ISNUMBER(MATCH($BE5,AF$5:AF$501,0)),INDEX(AF$5:AF$501,MATCH($BE5,AF$5:AF$501,0),1),"")
B6: =IF(ISNUMBER(MATCH(O6,$N$5:$N$1000,0)),MATCH(O6,$N$5:$N$1000,0),"") | C6: =IF(ISNUMBER(B6),MAX(C$4:C5)+1,"") | D6: =IF(IF(ISNUMBER(B6),"",MAX(D$4:D5)+1)<=D$3,IF(ISNUMBER(B6),"",MAX(D$4:D5)+1),"") -> 1 | E6: =IF(M6<=D$3,MATCH(M6,D$5:D$1000,0),"") -> 5 | F6: =IF(ISNUMBER(E6),INDEX($N$5:$N$1000,E6,1),"") -> .hds | G6: =IF(ISNUMBER(C6),N6,IF(ISTEXT(N6),INDEX($F$5:$F$1000,MATCH(M6,$E$5:$E$1000,0),1),"")) -> .dis | H6: =IF(O6="","",IF(ISNUMBER(MATCH(O6,$G$5:$G$1000,0)),"",IF(D6=1,C$3,0)+MAX(H$4:H5)+1)) -> 23 | I6: =IF(O6="","",IF(ISNUMBER(MATCH(O6,$G$5:$G$1000,0)),"",IF(D6=1,B$4,0)+MAX(I$4:I5)+1)) -> 37 | J6: =IF(ISNUMBER(MATCH(M6,$I$5:$I$1000,0)),INDEX($O$5:$O$1000,MATCH(M6,$I$5:$I$1000,0),1),"") | K6: =IF(P6="",0,1) -> 1 | M6: =IF(ROW()-ROW(M$4)<=1000,ROW()-ROW(M$4),"") -> 2 | N6: .dis | O6: .chd | P6: =IF(M6<=$B$4,IF(ISTEXT(G6),G6,""),IF(ISTEXT(J6),J6,"")) -> .dis | R6: =IF(ROW()-ROW(R$4)<=AH$3,ROW()-ROW(R$4),"") -> 2 | S6: =IF(ROW()-ROW(S$4)<=AI$3,ROW()-ROW(S$4),"") -> 2 | T6: =IF(ROW()-ROW(T$4)<=AJ$3,ROW()-ROW(T$4),"") -> 2 | U6: =IF(ROW()-ROW(U$4)<=AK$3,ROW()-ROW(U$4),"") -> 2 | V6: =IF(ROW()-ROW(V$4)<=AL$3,ROW()-ROW(V$4),"") -> 2 | W6: =IF(ROW()-ROW(W$4)<=AM$3,ROW()-ROW(W$4),"") -> 2 | X6: =IF(ROW()-ROW(X$4)<=AN$3,ROW()-ROW(X$4),"") | Z6: =IF(ISNUMBER(R6),INDEX($BE$5:$BE$2999,MATCH(R6,AH$5:AH$2999,0),1),"") -> .oc | AA6: =IF(ISNUMBER(S6),INDEX($BE$5:$BE$2999,MATCH(S6,AI$5:AI$2999,0),1),"") -> .oc | AB6: =IF(ISNUMBER(T6),INDEX($BE$5:$BE$2999,MATCH(T6,AJ$5:AJ$2999,0),1),"") -> .oc | AC6: =IF(ISNUMBER(U6),INDEX($BE$5:$BE$2999,MATCH(U6,AK$5:AK$2999,0),1),"") -> .ic | AD6: =IF(ISNUMBER(V6),INDEX($BE$5:$BE$2999,MATCH(V6,AL$5:AL$2999,0),1),"") -> .ic | AE6: =IF(ISNUMBER(W6),INDEX($BE$5:$BE$2999,MATCH(W6,AM$5:AM$2999,0),1),"") -> .ic | AF6: =IF(ISNUMBER(X6),INDEX($BE$5:$BE$2999,MATCH(X6,AN$5:AN$2999,0),1),"") | AH6: =IF($BE6="","",IF(ISNUMBER(MATCH($BE6,AP$5:AP$29999,0)),MAX(AH$4:AH5)+1,0)) -> 1 | AI6: =IF($BE6="","",IF(ISNUMBER(MATCH($BE6,AQ$5:AQ$29999,0)),MAX(AI$4:AI5)+1,0)) -> 1 | AJ6: =IF($BE6="","",IF(ISNUMBER(MATCH($BE6,AR$5:AR$29999,0)),MAX(AJ$4:AJ5)+1,0)) -> 1 | AK6: =IF($BE6="","",IF(ISNUMBER(MATCH($BE6,AS$5:AS$29999,0)),MAX(AK$4:AK5)+1,0)) -> 2 | AL6: =IF($BE6="","",IF(ISNUMBER(MATCH($BE6,AT$5:AT$29999,0)),MAX(AL$4:AL5)+1,0)) -> 2 | AM6: =IF($BE6="","",IF(ISNUMBER(MATCH($BE6,AU$5:AU$29999,0)),MAX(AM$4:AM5)+1,0)) -> 2 | AN6: =IF($BE6="","",IF(ISNUMBER(MATCH($BE6,AV$5:AV$29999,0)),MAX(AN$4:AN5)+1,0)) -> 0 | AP6: .dis | AQ6: .dis.grb | AR6: .dis | AS6: .chd | AT6: .chd | AU6: .chd | AW6: .chd | AY6: .ic | AZ6: .ic | BB6: =IF(ISTEXT(AW6),IF(ISNUMBER(MATCH(AW6,$AY$5:$AY$100,0)),0,MAX(BB$4:BB5)+1),"") -> 0 | BC6: =IF(ISTEXT(AY6),MATCH(AY6,$AW$5:$AW$127,0),"") -> 9 | BD6: =IF(ISNUMBER(BC6),AY6,ROW()-SUM($BC$4:$BD$4)) -> .ic | BE6: =IF(ISTEXT(AW6),IF(ISNUMBER(BC6),AY6,INDEX($AW$5:$AW$140,MATCH(BD6,$BB$5:$BB$185,0),1)),"") -> .ic | BG6: =IF(ISNUMBER(MATCH($BE6,Z$5:Z$501,0)),INDEX(Z$5:Z$501,MATCH($BE6,Z$5:Z$501,0),1),"") -> .ic | BH6: =IF(ISNUMBER(MATCH($BE6,AA$5:AA$501,0)),INDEX(AA$5:AA$501,MATCH($BE6,AA$5:AA$501,0),1),"") -> .ic | BI6: =IF(ISNUMBER(MATCH($BE6,AB$5:AB$501,0)),INDEX(AB$5:AB$501,MATCH($BE6,AB$5:AB$501,0),1),"") -> .ic | BJ6: =IF(ISNUMBER(MATCH($BE6,AC$5:AC$501,0)),INDEX(AC$5:AC$501,MATCH($BE6,AC$5:AC$501,0),1),"") -> .ic | BK6: =IF(ISNUMBER(MATCH($BE6,AD$5:AD$501,0)),INDEX(AD$5:AD$501,MATCH($BE6,AD$5:AD$501,0),1),"") -> .ic | BL6: =IF(ISNUMBER(MATCH($BE6,AE$5:AE$501,0)),INDEX(AE$5:AE$501,MATCH($BE6,AE$5:AE$501,0),1),"") -> .ic | BM6: =IF(ISNUMBER(MATCH($BE6,AF$5:AF$501,0)),INDEX(AF$5:AF$501,MATCH($BE6,AF$5:AF$501,0),1),"")
B7: =IF(ISNUMBER(MATCH(O7,$N$5:$N$1000,0)),MATCH(O7,$N$5:$N$1000,0),"") -> 2 | C7: =IF(ISNUMBER(B7),MAX(C$4:C6)+1,"") -> 2 | D7: =IF(IF(ISNUMBER(B7),"",MAX(D$4:D6)+1)<=D$3,IF(ISNUMBER(B7),"",MAX(D$4:D6)+1),"") | E7: =IF(M7<=D$3,MATCH(M7,D$5:D$1000,0),"") -> 6 | F7: =IF(ISNUMBER(E7),INDEX($N$5:$N$1000,E7,1),"") -> .ic | G7: =IF(ISNUMBER(C7),N7,IF(ISTEXT(N7),INDEX($F$5:$F$1000,MATCH(M7,$E$5:$E$1000,0),1),"")) -> .dis.grb | H7: =IF(O7="","",IF(ISNUMBER(MATCH(O7,$G$5:$G$1000,0)),"",IF(D7=1,C$3,0)+MAX(H$4:H6)+1)) | I7: =IF(O7="","",IF(ISNUMBER(MATCH(O7,$G$5:$G$1000,0)),"",IF(D7=1,B$4,0)+MAX(I$4:I6)+1)) | J7: =IF(ISNUMBER(MATCH(M7,$I$5:$I$1000,0)),INDEX($O$5:$O$1000,MATCH(M7,$I$5:$I$1000,0),1),"") | K7: =IF(P7="",0,1) -> 1 | M7: =IF(ROW()-ROW(M$4)<=1000,ROW()-ROW(M$4),"") -> 3 | N7: .dis.grb | O7: .dis | P7: =IF(M7<=$B$4,IF(ISTEXT(G7),G7,""),IF(ISTEXT(J7),J7,"")) -> .dis.grb | R7: =IF(ROW()-ROW(R$4)<=AH$3,ROW()-ROW(R$4),"") -> 3 | S7: =IF(ROW()-ROW(S$4)<=AI$3,ROW()-ROW(S$4),"") -> 3 | T7: =IF(ROW()-ROW(T$4)<=AJ$3,ROW()-ROW(T$4),"") -> 3 | U7: =IF(ROW()-ROW(U$4)<=AK$3,ROW()-ROW(U$4),"") -> 3 | V7: =IF(ROW()-ROW(V$4)<=AL$3,ROW()-ROW(V$4),"") -> 3 | W7: =IF(ROW()-ROW(W$4)<=AM$3,ROW()-ROW(W$4),"") -> 3 | X7: =IF(ROW()-ROW(X$4)<=AN$3,ROW()-ROW(X$4),"") | Z7: =IF(ISNUMBER(R7),INDEX($BE$5:$BE$2999,MATCH(R7,AH$5:AH$2999,0),1),"") -> .ims | AA7: =IF(ISNUMBER(S7),INDEX($BE$5:$BE$2999,MATCH(S7,AI$5:AI$2999,0),1),"") -> .ims | AB7: =IF(ISNUMBER(T7),INDEX($BE$5:$BE$2999,MATCH(T7,AJ$5:AJ$2999,0),1),"") -> .ims | AC7: =IF(ISNUMBER(U7),INDEX($BE$5:$BE$2999,MATCH(U7,AK$5:AK$2999,0),1),"") -> .oc | AD7: =IF(ISNUMBER(V7),INDEX($BE$5:$BE$2999,MATCH(V7,AL$5:AL$2999,0),1),"") -> .oc | AE7: =IF(ISNUMBER(W7),INDEX($BE$5:$BE$2999,MATCH(W7,AM$5:AM$2999,0),1),"") -> .oc | AF7: =IF(ISNUMBER(X7),INDEX($BE$5:$BE$2999,MATCH(X7,AN$5:AN$2999,0),1),"") | AH7: =IF($BE7="","",IF(ISNUMBER(MATCH($BE7,AP$5:AP$29999,0)),MAX(AH$4:AH6)+1,0)) -> 2 | AI7: =IF($BE7="","",IF(ISNUMBER(MATCH($BE7,AQ$5:AQ$29999,0)),MAX(AI$4:AI6)+1,0)) -> 2 | AJ7: =IF($BE7="","",IF(ISNUMBER(MATCH($BE7,AR$5:AR$29999,0)),MAX(AJ$4:AJ6)+1,0)) -> 2 | AK7: =IF($BE7="","",IF(ISNUMBER(MATCH($BE7,AS$5:AS$29999,0)),MAX(AK$4:AK6)+1,0)) -> 3 | AL7: =IF($BE7="","",IF(ISNUMBER(MATCH($BE7,AT$5:AT$29999,0)),MAX(AL$4:AL6)+1,0)) -> 3 | AM7: =IF($BE7="","",IF(ISNUMBER(MATCH($BE7,AU$5:AU$29999,0)),MAX(AM$4:AM6)+1,0)) -> 3 | AN7: =IF($BE7="","",IF(ISNUMBER(MATCH($BE7,AV$5:AV$29999,0)),MAX(AN$4:AN6)+1,0)) -> 0 | AP7: .dis.grb | AQ7: .ic | AR7: .dis.grb | AS7: .dis | AT7: .dis | AU7: .dis | AW7: .dis | AY7: .oc | AZ7: .oc | BB7: =IF(ISTEXT(AW7),IF(ISNUMBER(MATCH(AW7,$AY$5:$AY$100,0)),0,MAX(BB$4:BB6)+1),"") -> 0 | BC7: =IF(ISTEXT(AY7),MATCH(AY7,$AW$5:$AW$127,0),"") -> 18 | BD7: =IF(ISNUMBER(BC7),AY7,ROW()-SUM($BC$4:$BD$4)) -> .oc | BE7: =IF(ISTEXT(AW7),IF(ISNUMBER(BC7),AY7,INDEX($AW$5:$AW$140,MATCH(BD7,$BB$5:$BB$185,0),1)),"") -> .oc | BG7: =IF(ISNUMBER(MATCH($BE7,Z$5:Z$501,0)),INDEX(Z$5:Z$501,MATCH($BE7,Z$5:Z$501,0),1),"") -> .oc | BH7: =IF(ISNUMBER(MATCH($BE7,AA$5:AA$501,0)),INDEX(AA$5:AA$501,MATCH($BE7,AA$5:AA$501,0),1),"") -> .oc | BI7: =IF(ISNUMBER(MATCH($BE7,AB$5:AB$501,0)),INDEX(AB$5:AB$501,MATCH($BE7,AB$5:AB$501,0),1),"") -> .oc | BJ7: =IF(ISNUMBER(MATCH($BE7,AC$5:AC$501,0)),INDEX(AC$5:AC$501,MATCH($BE7,AC$5:AC$501,0),1),"") -> .oc | BK7: =IF(ISNUMBER(MATCH($BE7,AD$5:AD$501,0)),INDEX(AD$5:AD$501,MATCH($BE7,AD$5:AD$501,0),1),"") -> .oc | BL7: =IF(ISNUMBER(MATCH($BE7,AE$5:AE$501,0)),INDEX(AE$5:AE$501,MATCH($BE7,AE$5:AE$501,0),1),"") -> .oc | BM7: =IF(ISNUMBER(MATCH($BE7,AF$5:AF$501,0)),INDEX(AF$5:AF$501,MATCH($BE7,AF$5:AF$501,0),1),"")
B8: =IF(ISNUMBER(MATCH(O8,$N$5:$N$1000,0)),MATCH(O8,$N$5:$N$1000,0),"") -> 3 | C8: =IF(ISNUMBER(B8),MAX(C$4:C7)+1,"") -> 3 | D8: =IF(IF(ISNUMBER(B8),"",MAX(D$4:D7)+1)<=D$3,IF(ISNUMBER(B8),"",MAX(D$4:D7)+1),"") | E8: =IF(M8<=D$3,MATCH(M8,D$5:D$1000,0),"") -> 7 | F8: =IF(ISNUMBER(E8),INDEX($N$5:$N$1000,E8,1),"") -> .ims | G8: =IF(ISNUMBER(C8),N8,IF(ISTEXT(N8),INDEX($F$5:$F$1000,MATCH(M8,$E$5:$E$1000,0),1),"")) -> .ghb | H8: =IF(O8="","",IF(ISNUMBER(MATCH(O8,$G$5:$G$1000,0)),"",IF(D8=1,C$3,0)+MAX(H$4:H7)+1)) | I8: =IF(O8="","",IF(ISNUMBER(MATCH(O8,$G$5:$G$1000,0)),"",IF(D8=1,B$4,0)+MAX(I$4:I7)+1)) | J8: =IF(ISNUMBER(MATCH(M8,$I$5:$I$1000,0)),INDEX($O$5:$O$1000,MATCH(M8,$I$5:$I$1000,0),1),"") | K8: =IF(P8="",0,1) -> 1 | M8: =IF(ROW()-ROW(M$4)<=1000,ROW()-ROW(M$4),"") -> 4 | N8: .ghb | O8: .dis.grb | P8: =IF(M8<=$B$4,IF(ISTEXT(G8),G8,""),IF(ISTEXT(J8),J8,"")) -> .ghb | R8: =IF(ROW()-ROW(R$4)<=AH$3,ROW()-ROW(R$4),"") -> 4 | S8: =IF(ROW()-ROW(S$4)<=AI$3,ROW()-ROW(S$4),"") -> 4 | T8: =IF(ROW()-ROW(T$4)<=AJ$3,ROW()-ROW(T$4),"") -> 4 | U8: =IF(ROW()-ROW(U$4)<=AK$3,ROW()-ROW(U$4),"") -> 4 | V8: =IF(ROW()-ROW(V$4)<=AL$3,ROW()-ROW(V$4),"") -> 4 | W8: =IF(ROW()-ROW(W$4)<=AM$3,ROW()-ROW(W$4),"") -> 4 | X8: =IF(ROW()-ROW(X$4)<=AN$3,ROW()-ROW(X$4),"") | Z8: =IF(ISNUMBER(R8),INDEX($BE$5:$BE$2999,MATCH(R8,AH$5:AH$2999,0),1),"") -> .npf | AA8: =IF(ISNUMBER(S8),INDEX($BE$5:$BE$2999,MATCH(S8,AI$5:AI$2999,0),1),"") -> .npf | AB8: =IF(ISNUMBER(T8),INDEX($BE$5:$BE$2999,MATCH(T8,AJ$5:AJ$2999,0),1),"") -> .npf | AC8: =IF(ISNUMBER(U8),INDEX($BE$5:$BE$2999,MATCH(U8,AK$5:AK$2999,0),1),"") -> .ims | AD8: =IF(ISNUMBER(V8),INDEX($BE$5:$BE$2999,MATCH(V8,AL$5:AL$2999,0),1),"") -> .ims | AE8: =IF(ISNUMBER(W8),INDEX($BE$5:$BE$2999,MATCH(W8,AM$5:AM$2999,0),1),"") -> .ims | AF8: =IF(ISNUMBER(X8),INDEX($BE$5:$BE$2999,MATCH(X8,AN$5:AN$2999,0),1),"") | AH8: =IF($BE8="","",IF(ISNUMBER(MATCH($BE8,AP$5:AP$29999,0)),MAX(AH$4:AH7)+1,0)) -> 3 | AI8: =IF($BE8="","",IF(ISNUMBER(MATCH($BE8,AQ$5:AQ$29999,0)),MAX(AI$4:AI7)+1,0)) -> 3 | AJ8: =IF($BE8="","",IF(ISNUMBER(MATCH($BE8,AR$5:AR$29999,0)),MAX(AJ$4:AJ7)+1,0)) -> 3 | AK8: =IF($BE8="","",IF(ISNUMBER(MATCH($BE8,AS$5:AS$29999,0)),MAX(AK$4:AK7)+1,0)) -> 4 | AL8: =IF($BE8="","",IF(ISNUMBER(MATCH($BE8,AT$5:AT$29999,0)),MAX(AL$4:AL7)+1,0)) -> 4 | AM8: =IF($BE8="","",IF(ISNUMBER(MATCH($BE8,AU$5:AU$29999,0)),MAX(AM$4:AM7)+1,0)) -> 4 | AN8: =IF($BE8="","",IF(ISNUMBER(MATCH($BE8,AV$5:AV$29999,0)),MAX(AN$4:AN7)+1,0)) -> 0 | AP8: .evta | AQ8: .ims | AR8: .ghb | AS8: .dis.grb | AT8: .dis.grb | AU8: .dis.grb | AW8: .dis.grb | AY8: .ims | AZ8: .ims | BB8: =IF(ISTEXT(AW8),IF(ISNUMBER(MATCH(AW8,$AY$5:$AY$100,0)),0,MAX(BB$4:BB7)+1),"") -> 0 | BC8: =IF(ISTEXT(AY8),MATCH(AY8,$AW$5:$AW$127,0),"") -> 10 | BD8: =IF(ISNUMBER(BC8),AY8,ROW()-SUM($BC$4:$BD$4)) -> .ims | BE8: =IF(ISTEXT(AW8),IF(ISNUMBER(BC8),AY8,INDEX($AW$5:$AW$140,MATCH(BD8,$BB$5:$BB$185,0),1)),"") -> .ims | BG8: =IF(ISNUMBER(MATCH($BE8,Z$5:Z$501,0)),INDEX(Z$5:Z$501,MATCH($BE8,Z$5:Z$501,0),1),"") -> .ims | BH8: =IF(ISNUMBER(MATCH($BE8,AA$5:AA$501,0)),INDEX(AA$5:AA$501,MATCH($BE8,AA$5:AA$501,0),1),"") -> .ims | BI8: =IF(ISNUMBER(MATCH($BE8,AB$5:AB$501,0)),INDEX(AB$5:AB$501,MATCH($BE8,AB$5:AB$501,0),1),"") -> .ims | BJ8: =IF(ISNUMBER(MATCH($BE8,AC$5:AC$501,0)),INDEX(AC$5:AC$501,MATCH($BE8,AC$5:AC$501,0),1),"") -> .ims | BK8: =IF(ISNUMBER(MATCH($BE8,AD$5:AD$501,0)),INDEX(AD$5:AD$501,MATCH($BE8,AD$5:AD$501,0),1),"") -> .ims | BL8: =IF(ISNUMBER(MATCH($BE8,AE$5:AE$501,0)),INDEX(AE$5:AE$501,MATCH($BE8,AE$5:AE$501,0),1),"") -> .ims | BM8: =IF(ISNUMBER(MATCH($BE8,AF$5:AF$501,0)),INDEX(AF$5:AF$501,MATCH($BE8,AF$5:AF$501,0),1),"")
B9: =IF(ISNUMBER(MATCH(O9,$N$5:$N$1000,0)),MATCH(O9,$N$5:$N$1000,0),"") | C9: =IF(ISNUMBER(B9),MAX(C$4:C8)+1,"") | D9: =IF(IF(ISNUMBER(B9),"",MAX(D$4:D8)+1)<=D$3,IF(ISNUMBER(B9),"",MAX(D$4:D8)+1),"") -> 2 | E9: =IF(M9<=D$3,MATCH(M9,D$5:D$1000,0),"") -> 13 | F9: =IF(ISNUMBER(E9),INDEX($N$5:$N$1000,E9,1),"") -> .mvr.bud | G9: =IF(ISNUMBER(C9),N9,IF(ISTEXT(N9),INDEX($F$5:$F$1000,MATCH(M9,$E$5:$E$1000,0),1),"")) -> .hds | H9: =IF(O9="","",IF(ISNUMBER(MATCH(O9,$G$5:$G$1000,0)),"",IF(D9=1,C$3,0)+MAX(H$4:H8)+1)) -> 24 | I9: =IF(O9="","",IF(ISNUMBER(MATCH(O9,$G$5:$G$1000,0)),"",IF(D9=1,B$4,0)+MAX(I$4:I8)+1)) -> 38 | J9: =IF(ISNUMBER(MATCH(M9,$I$5:$I$1000,0)),INDEX($O$5:$O$1000,MATCH(M9,$I$5:$I$1000,0),1),"") | K9: =IF(P9="",0,1) -> 1 | M9: =IF(ROW()-ROW(M$4)<=1000,ROW()-ROW(M$4),"") -> 5 | N9: .hds | O9: .evta | P9: =IF(M9<=$B$4,IF(ISTEXT(G9),G9,""),IF(ISTEXT(J9),J9,"")) -> .hds | R9: =IF(ROW()-ROW(R$4)<=AH$3,ROW()-ROW(R$4),"") -> 5 | S9: =IF(ROW()-ROW(S$4)<=AI$3,ROW()-ROW(S$4),"") -> 5 | T9: =IF(ROW()-ROW(T$4)<=AJ$3,ROW()-ROW(T$4),"") -> 5 | U9: =IF(ROW()-ROW(U$4)<=AK$3,ROW()-ROW(U$4),"") -> 5 | V9: =IF(ROW()-ROW(V$4)<=AL$3,ROW()-ROW(V$4),"") -> 5 | W9: =IF(ROW()-ROW(W$4)<=AM$3,ROW()-ROW(W$4),"") -> 5 | X9: =IF(ROW()-ROW(X$4)<=AN$3,ROW()-ROW(X$4),"") | Z9: =IF(ISNUMBER(R9),INDEX($BE$5:$BE$2999,MATCH(R9,AH$5:AH$2999,0),1),"") -> .lst | AA9: =IF(ISNUMBER(S9),INDEX($BE$5:$BE$2999,MATCH(S9,AI$5:AI$2999,0),1),"") -> .lst | AB9: =IF(ISNUMBER(T9),INDEX($BE$5:$BE$2999,MATCH(T9,AJ$5:AJ$2999,0),1),"") -> .lst | AC9: =IF(ISNUMBER(U9),INDEX($BE$5:$BE$2999,MATCH(U9,AK$5:AK$2999,0),1),"") -> .npf | AD9: =IF(ISNUMBER(V9),INDEX($BE$5:$BE$2999,MATCH(V9,AL$5:AL$2999,0),1),"") -> .npf | AE9: =IF(ISNUMBER(W9),INDEX($BE$5:$BE$2999,MATCH(W9,AM$5:AM$2999,0),1),"") -> .npf | AF9: =IF(ISNUMBER(X9),INDEX($BE$5:$BE$2999,MATCH(X9,AN$5:AN$2999,0),1),"") | AH9: =IF($BE9="","",IF(ISNUMBER(MATCH($BE9,AP$5:AP$29999,0)),MAX(AH$4:AH8)+1,0)) -> 4 | AI9: =IF($BE9="","",IF(ISNUMBER(MATCH($BE9,AQ$5:AQ$29999,0)),MAX(AI$4:AI8)+1,0)) -> 4 | AJ9: =IF($BE9="","",IF(ISNUMBER(MATCH($BE9,AR$5:AR$29999,0)),MAX(AJ$4:AJ8)+1,0)) -> 4 | AK9: =IF($BE9="","",IF(ISNUMBER(MATCH($BE9,AS$5:AS$29999,0)),MAX(AK$4:AK8)+1,0)) -> 5 | AL9: =IF($BE9="","",IF(ISNUMBER(MATCH($BE9,AT$5:AT$29999,0)),MAX(AL$4:AL8)+1,0)) -> 5 | AM9: =IF($BE9="","",IF(ISNUMBER(MATCH($BE9,AU$5:AU$29999,0)),MAX(AM$4:AM8)+1,0)) -> 5 | AN9: =IF($BE9="","",IF(ISNUMBER(MATCH($BE9,AV$5:AV$29999,0)),MAX(AN$4:AN8)+1,0)) -> 0 | AP9: .ghb | AQ9: .lst | AR9: .hds | AS9: .evta | AT9: .evta | AU9: .hds | AW9: .evta | AY9: .npf | AZ9: .npf | BB9: =IF(ISTEXT(AW9),IF(ISNUMBER(MATCH(AW9,$AY$5:$AY$100,0)),0,MAX(BB$4:BB8)+1),"") -> 0 | BC9: =IF(ISTEXT(AY9),MATCH(AY9,$AW$5:$AW$127,0),"") -> 17 | BD9: =IF(ISNUMBER(BC9),AY9,ROW()-SUM($BC$4:$BD$4)) -> .npf | BE9: =IF(ISTEXT(AW9),IF(ISNUMBER(BC9),AY9,INDEX($AW$5:$AW$140,MATCH(BD9,$BB$5:$BB$185,0),1)),"") -> .npf | BG9: =IF(ISNUMBER(MATCH($BE9,Z$5:Z$501,0)),INDEX(Z$5:Z$501,MATCH($BE9,Z$5:Z$501,0),1),"") -> .npf | BH9: =IF(ISNUMBER(MATCH($BE9,AA$5:AA$501,0)),INDEX(AA$5:AA$501,MATCH($BE9,AA$5:AA$501,0),1),"") -> .npf | BI9: =IF(ISNUMBER(MATCH($BE9,AB$5:AB$501,0)),INDEX(AB$5:AB$501,MATCH($BE9,AB$5:AB$501,0),1),"") -> .npf | BJ9: =IF(ISNUMBER(MATCH($BE9,AC$5:AC$501,0)),INDEX(AC$5:AC$501,MATCH($BE9,AC$5:AC$501,0),1),"") -> .npf | BK9: =IF(ISNUMBER(MATCH($BE9,AD$5:AD$501,0)),INDEX(AD$5:AD$501,MATCH($BE9,AD$5:AD$501,0),1),"") -> .npf | BL9: =IF(ISNUMBER(MATCH($BE9,AE$5:AE$501,0)),INDEX(AE$5:AE$501,MATCH($BE9,AE$5:AE$501,0),1),"") -> .npf | BM9: =IF(ISNUMBER(MATCH($BE9,AF$5:AF$501,0)),INDEX(AF$5:AF$501,MATCH($BE9,AF$5:AF$501,0),1),"")
B10: =IF(ISNUMBER(MATCH(O10,$N$5:$N$1000,0)),MATCH(O10,$N$5:$N$1000,0),"") | C10: =IF(ISNUMBER(B10),MAX(C$4:C9)+1,"") | D10: =IF(IF(ISNUMBER(B10),"",MAX(D$4:D9)+1)<=D$3,IF(ISNUMBER(B10),"",MAX(D$4:D9)+1),"") -> 3 | E10: =IF(M10<=D$3,MATCH(M10,D$5:D$1000,0),"") -> 19 | F10: =IF(ISNUMBER(E10),INDEX($N$5:$N$1000,E10,1),"") -> .sfr.obs | G10: =IF(ISNUMBER(C10),N10,IF(ISTEXT(N10),INDEX($F$5:$F$1000,MATCH(M10,$E$5:$E$1000,0),1),"")) -> .ic | H10: =IF(O10="","",IF(ISNUMBER(MATCH(O10,$G$5:$G$1000,0)),"",IF(D10=1,C$3,0)+MAX(H$4:H9)+1)) -> 25 | I10: =IF(O10="","",IF(ISNUMBER(MATCH(O10,$G$5:$G$1000,0)),"",IF(D10=1,B$4,0)+MAX(I$4:I9)+1)) -> 39 | J10: =IF(ISNUMBER(MATCH(M10,$I$5:$I$1000,0)),INDEX($O$5:$O$1000,MATCH(M10,$I$5:$I$1000,0),1),"") | K10: =IF(P10="",0,1) -> 1 | M10: =IF(ROW()-ROW(M$4)<=1000,ROW()-ROW(M$4),"") -> 6 | N10: .ic | O10: .gwf.obs | P10: =IF(M10<=$B$4,IF(ISTEXT(G10),G10,""),IF(ISTEXT(J10),J10,"")) -> .ic | R10: =IF(ROW()-ROW(R$4)<=AH$3,ROW()-ROW(R$4),"") -> 6 | S10: =IF(ROW()-ROW(S$4)<=AI$3,ROW()-ROW(S$4),"") -> 6 | T10: =IF(ROW()-ROW(T$4)<=AJ$3,ROW()-ROW(T$4),"") -> 6 | U10: =IF(ROW()-ROW(U$4)<=AK$3,ROW()-ROW(U$4),"") -> 6 | V10: =IF(ROW()-ROW(V$4)<=AL$3,ROW()-ROW(V$4),"") -> 6 | W10: =IF(ROW()-ROW(W$4)<=AM$3,ROW()-ROW(W$4),"") -> 6 | X10: =IF(ROW()-ROW(X$4)<=AN$3,ROW()-ROW(X$4),"") | Z10: =IF(ISNUMBER(R10),INDEX($BE$5:$BE$2999,MATCH(R10,AH$5:AH$2999,0),1),"") -> .dis | AA10: =IF(ISNUMBER(S10),INDEX($BE$5:$BE$2999,MATCH(S10,AI$5:AI$2999,0),1),"") -> .dis | AB10: =IF(ISNUMBER(T10),INDEX($BE$5:$BE$2999,MATCH(T10,AJ$5:AJ$2999,0),1),"") -> .dis | AC10: =IF(ISNUMBER(U10),INDEX($BE$5:$BE$2999,MATCH(U10,AK$5:AK$2999,0),1),"") -> .lst | AD10: =IF(ISNUMBER(V10),INDEX($BE$5:$BE$2999,MATCH(V10,AL$5:AL$2999,0),1),"") -> .lst | AE10: =IF(ISNUMBER(W10),INDEX($BE$5:$BE$2999,MATCH(W10,AM$5:AM$2999,0),1),"") -> .lst | AF10: =IF(ISNUMBER(X10),INDEX($BE$5:$BE$2999,MATCH(X10,AN$5:AN$2999,0),1),"") | AH10: =IF($BE10="","",IF(ISNUMBER(MATCH($BE10,AP$5:AP$29999,0)),MAX(AH$4:AH9)+1,0)) -> 5 | AI10: =IF($BE10="","",IF(ISNUMBER(MATCH($BE10,AQ$5:AQ$29999,0)),MAX(AI$4:AI9)+1,0)) -> 5 | AJ10: =IF($BE10="","",IF(ISNUMBER(MATCH($BE10,AR$5:AR$29999,0)),MAX(AJ$4:AJ9)+1,0)) -> 5 | AK10: =IF($BE10="","",IF(ISNUMBER(MATCH($BE10,AS$5:AS$29999,0)),MAX(AK$4:AK9)+1,0)) -> 6 | AL10: =IF($BE10="","",IF(ISNUMBER(MATCH($BE10,AT$5:AT$29999,0)),MAX(AL$4:AL9)+1,0)) -> 6 | AM10: =IF($BE10="","",IF(ISNUMBER(MATCH($BE10,AU$5:AU$29999,0)),MAX(AM$4:AM9)+1,0)) -> 6 | AN10: =IF($BE10="","",IF(ISNUMBER(MATCH($BE10,AV$5:AV$29999,0)),MAX(AN$4:AN9)+1,0)) -> 0 | AP10: .hds | AQ10: .nam | AR10: .ic | AS10: .gwf.obs | AT10: .gwf.obs | AU10: .ic | AW10: .gwf.obs | AY10: .lst | AZ10: .lst | BB10: =IF(ISTEXT(AW10),IF(ISNUMBER(MATCH(AW10,$AY$5:$AY$100,0)),0,MAX(BB$4:BB9)+1),"") -> 0 | BC10: =IF(ISTEXT(AY10),MATCH(AY10,$AW$5:$AW$127,0),"") -> 14 | BD10: =IF(ISNUMBER(BC10),AY10,ROW()-SUM($BC$4:$BD$4)) -> .lst | BE10: =IF(ISTEXT(AW10),IF(ISNUMBER(BC10),AY10,INDEX($AW$5:$AW$140,MATCH(BD10,$BB$5:$BB$185,0),1)),"") -> .lst | BG10: =IF(ISNUMBER(MATCH($BE10,Z$5:Z$501,0)),INDEX(Z$5:Z$501,MATCH($BE10,Z$5:Z$501,0),1),"") -> .lst | BH10: =IF(ISNUMBER(MATCH($BE10,AA$5:AA$501,0)),INDEX(AA$5:AA$501,MATCH($BE10,AA$5:AA$501,0),1),"") -> .lst | BI10: =IF(ISNUMBER(MATCH($BE10,AB$5:AB$501,0)),INDEX(AB$5:AB$501,MATCH($BE10,AB$5:AB$501,0),1),"") -> .lst | BJ10: =IF(ISNUMBER(MATCH($BE10,AC$5:AC$501,0)),INDEX(AC$5:AC$501,MATCH($BE10,AC$5:AC$501,0),1),"") -> .lst | BK10: =IF(ISNUMBER(MATCH($BE10,AD$5:AD$501,0)),INDEX(AD$5:AD$501,MATCH($BE10,AD$5:AD$501,0),1),"") -> .lst | BL10: =IF(ISNUMBER(MATCH($BE10,AE$5:AE$501,0)),INDEX(AE$5:AE$501,MATCH($BE10,AE$5:AE$501,0),1),"") -> .lst | BM10: =IF(ISNUMBER(MATCH($BE10,AF$5:AF$501,0)),INDEX(AF$5:AF$501,MATCH($BE10,AF$5:AF$501,0),1),"")
B11: =IF(ISNUMBER(MATCH(O11,$N$5:$N$1000,0)),MATCH(O11,$N$5:$N$1000,0),"") | C11: =IF(ISNUMBER(B11),MAX(C$4:C10)+1,"") | D11: =IF(IF(ISNUMBER(B11),"",MAX(D$4:D10)+1)<=D$3,IF(ISNUMBER(B11),"",MAX(D$4:D10)+1),"") -> 4 | E11: =IF(M11<=D$3,MATCH(M11,D$5:D$1000,0),"") -> 25 | F11: =IF(ISNUMBER(E11),INDEX($N$5:$N$1000,E11,1),"") -> .wel | G11: =IF(ISNUMBER(C11),N11,IF(ISTEXT(N11),INDEX($F$5:$F$1000,MATCH(M11,$E$5:$E$1000,0),1),"")) -> .ims | H11: =IF(O11="","",IF(ISNUMBER(MATCH(O11,$G$5:$G$1000,0)),"",IF(D11=1,C$3,0)+MAX(H$4:H10)+1)) -> 26 | I11: =IF(O11="","",IF(ISNUMBER(MATCH(O11,$G$5:$G$1000,0)),"",IF(D11=1,B$4,0)+MAX(I$4:I10)+1)) -> 40 | J11: =IF(ISNUMBER(MATCH(M11,$I$5:$I$1000,0)),INDEX($O$5:$O$1000,MATCH(M11,$I$5:$I$1000,0),1),"") | K11: =IF(P11="",0,1) -> 1 | M11: =IF(ROW()-ROW(M$4)<=1000,ROW()-ROW(M$4),"") -> 7 | N11: .ims | O11: .gwf.obs.csv | P11: =IF(M11<=$B$4,IF(ISTEXT(G11),G11,""),IF(ISTEXT(J11),J11,"")) -> .ims | R11: =IF(ROW()-ROW(R$4)<=AH$3,ROW()-ROW(R$4),"") -> 7 | S11: =IF(ROW()-ROW(S$4)<=AI$3,ROW()-ROW(S$4),"") -> 7 | T11: =IF(ROW()-ROW(T$4)<=AJ$3,ROW()-ROW(T$4),"") -> 7 | U11: =IF(ROW()-ROW(U$4)<=AK$3,ROW()-ROW(U$4),"") -> 7 | V11: =IF(ROW()-ROW(V$4)<=AL$3,ROW()-ROW(V$4),"") -> 7 | W11: =IF(ROW()-ROW(W$4)<=AM$3,ROW()-ROW(W$4),"") -> 7 | X11: =IF(ROW()-ROW(X$4)<=AN$3,ROW()-ROW(X$4),"") | Z11: =IF(ISNUMBER(R11),INDEX($BE$5:$BE$2999,MATCH(R11,AH$5:AH$2999,0),1),"") -> .sfr | AA11: =IF(ISNUMBER(S11),INDEX($BE$5:$BE$2999,MATCH(S11,AI$5:AI$2999,0),1),"") -> .sfr | AB11: =IF(ISNUMBER(T11),INDEX($BE$5:$BE$2999,MATCH(T11,AJ$5:AJ$2999,0),1),"") -> .sfr | AC11: =IF(ISNUMBER(U11),INDEX($BE$5:$BE$2999,MATCH(U11,AK$5:AK$2999,0),1),"") -> .dis | AD11: =IF(ISNUMBER(V11),INDEX($BE$5:$BE$2999,MATCH(V11,AL$5:AL$2999,0),1),"") -> .dis | AE11: =IF(ISNUMBER(W11),INDEX($BE$5:$BE$2999,MATCH(W11,AM$5:AM$2999,0),1),"") -> .dis | AF11: =IF(ISNUMBER(X11),INDEX($BE$5:$BE$2999,MATCH(X11,AN$5:AN$2999,0),1),"") | AH11: =IF($BE11="","",IF(ISNUMBER(MATCH($BE11,AP$5:AP$29999,0)),MAX(AH$4:AH10)+1,0)) -> 6 | AI11: =IF($BE11="","",IF(ISNUMBER(MATCH($BE11,AQ$5:AQ$29999,0)),MAX(AI$4:AI10)+1,0)) -> 6 | AJ11: =IF($BE11="","",IF(ISNUMBER(MATCH($BE11,AR$5:AR$29999,0)),MAX(AJ$4:AJ10)+1,0)) -> 6 | AK11: =IF($BE11="","",IF(ISNUMBER(MATCH($BE11,AS$5:AS$29999,0)),MAX(AK$4:AK10)+1,0)) -> 7 | AL11: =IF($BE11="","",IF(ISNUMBER(MATCH($BE11,AT$5:AT$29999,0)),MAX(AL$4:AL10)+1,0)) -> 7 | AM11: =IF($BE11="","",IF(ISNUMBER(MATCH($BE11,AU$5:AU$29999,0)),MAX(AM$4:AM10)+1,0)) -> 7 | AN11: =IF($BE11="","",IF(ISNUMBER(MATCH($BE11,AV$5:AV$29999,0)),MAX(AN$4:AN10)+1,0)) -> 0 | AP11: .ic | AQ11: .npf | AR11: .ims | AS11: .gwf.obs.csv | AT11: .gwf.obs.csv | AU11: .ims | AW11: .gwf.obs.csv | AY11: .dis | AZ11: .dis | BB11: =IF(ISTEXT(AW11),IF(ISNUMBER(MATCH(AW11,$AY$5:$AY$100,0)),0,MAX(BB$4:BB10)+1),"") -> 0 | BC11: =IF(ISTEXT(AY11),MATCH(AY11,$AW$5:$AW$127,0),"") -> 3 | BD11: =IF(ISNUMBER(BC11),AY11,ROW()-SUM($BC$4:$BD$4)) -> .dis | BE11: =IF(ISTEXT(AW11),IF(ISNUMBER(BC11),AY11,INDEX($AW$5:$AW$140,MATCH(BD11,$BB$5:$BB$185,0),1)),"") -> .dis | BG11: =IF(ISNUMBER(MATCH($BE11,Z$5:Z$501,0)),INDEX(Z$5:Z$501,MATCH($BE11,Z$5:Z$501,0),1),"") -> .dis | BH11: =IF(ISNUMBER(MATCH($BE11,AA$5:AA$501,0)),INDEX(AA$5:AA$501,MATCH($BE11,AA$5:AA$501,0),1),"") -> .dis | BI11: =IF(ISNUMBER(MATCH($BE11,AB$5:AB$501,0)),INDEX(AB$5:AB$501,MATCH($BE11,AB$5:AB$501,0),1),"") -> .dis | BJ11: =IF(ISNUMBER(MATCH($BE11,AC$5:AC$501,0)),INDEX(AC$5:AC$501,MATCH($BE11,AC$5:AC$501,0),1),"") -> .dis | BK11: =IF(ISNUMBER(MATCH($BE11,AD$5:AD$501,0)),INDEX(AD$5:AD$501,MATCH($BE11,AD$5:AD$501,0),1),"") -> .dis | BL11: =IF(ISNUMBER(MATCH($BE11,AE$5:AE$501,0)),INDEX(AE$5:AE$501,MATCH($BE11,AE$5:AE$501,0),1),"") -> .dis | BM11: =IF(ISNUMBER(MATCH($BE11,AF$5:AF$501,0)),INDEX(AF$5:AF$501,MATCH($BE11,AF$5:AF$501,0),1),"")
B12: =IF(ISNUMBER(MATCH(O12,$N$5:$N$1000,0)),MATCH(O12,$N$5:$N$1000,0),"") -> 5 | C12: =IF(ISNUMBER(B12),MAX(C$4:C11)+1,"") -> 4 | D12: =IF(IF(ISNUMBER(B12),"",MAX(D$4:D11)+1)<=D$3,IF(ISNUMBER(B12),"",MAX(D$4:D11)+1),"") | E12: =IF(M12<=D$3,MATCH(M12,D$5:D$1000,0),"") -> 26 | F12: =IF(ISNUMBER(E12),INDEX($N$5:$N$1000,E12,1),"") -> mfsim.lst | G12: =IF(ISNUMBER(C12),N12,IF(ISTEXT(N12),INDEX($F$5:$F$1000,MATCH(M12,$E$5:$E$1000,0),1),"")) -> .lak | H12: =IF(O12="","",IF(ISNUMBER(MATCH(O12,$G$5:$G$1000,0)),"",IF(D12=1,C$3,0)+MAX(H$4:H11)+1)) | I12: =IF(O12="","",IF(ISNUMBER(MATCH(O12,$G$5:$G$1000,0)),"",IF(D12=1,B$4,0)+MAX(I$4:I11)+1)) | J12: =IF(ISNUMBER(MATCH(M12,$I$5:$I$1000,0)),INDEX($O$5:$O$1000,MATCH(M12,$I$5:$I$1000,0),1),"") | K12: =IF(P12="",0,1) -> 1 | M12: =IF(ROW()-ROW(M$4)<=1000,ROW()-ROW(M$4),"") -> 8 | N12: .lak | O12: .hds | P12: =IF(M12<=$B$4,IF(ISTEXT(G12),G12,""),IF(ISTEXT(J12),J12,"")) -> .lak | R12: =IF(ROW()-ROW(R$4)<=AH$3,ROW()-ROW(R$4),"") -> 8 | S12: =IF(ROW()-ROW(S$4)<=AI$3,ROW()-ROW(S$4),"") -> 8 | T12: =IF(ROW()-ROW(T$4)<=AJ$3,ROW()-ROW(T$4),"") -> 8 | U12: =IF(ROW()-ROW(U$4)<=AK$3,ROW()-ROW(U$4),"") -> 8 | V12: =IF(ROW()-ROW(V$4)<=AL$3,ROW()-ROW(V$4),"") -> 8 | W12: =IF(ROW()-ROW(W$4)<=AM$3,ROW()-ROW(W$4),"") -> 8 | X12: =IF(ROW()-ROW(X$4)<=AN$3,ROW()-ROW(X$4),"") | Z12: =IF(ISNUMBER(R12),INDEX($BE$5:$BE$2999,MATCH(R12,AH$5:AH$2999,0),1),"") -> .sfr.obs | AA12: =IF(ISNUMBER(S12),INDEX($BE$5:$BE$2999,MATCH(S12,AI$5:AI$2999,0),1),"") -> .sfr.obs | AB12: =IF(ISNUMBER(T12),INDEX($BE$5:$BE$2999,MATCH(T12,AJ$5:AJ$2999,0),1),"") -> .sfr.obs | AC12: =IF(ISNUMBER(U12),INDEX($BE$5:$BE$2999,MATCH(U12,AK$5:AK$2999,0),1),"") -> .lak | AD12: =IF(ISNUMBER(V12),INDEX($BE$5:$BE$2999,MATCH(V12,AL$5:AL$2999,0),1),"") -> .sfr | AE12: =IF(ISNUMBER(W12),INDEX($BE$5:$BE$2999,MATCH(W12,AM$5:AM$2999,0),1),"") -> .sfr | AF12: =IF(ISNUMBER(X12),INDEX($BE$5:$BE$2999,MATCH(X12,AN$5:AN$2999,0),1),"") | AH12: =IF($BE12="","",IF(ISNUMBER(MATCH($BE12,AP$5:AP$29999,0)),MAX(AH$4:AH11)+1,0)) -> 7 | AI12: =IF($BE12="","",IF(ISNUMBER(MATCH($BE12,AQ$5:AQ$29999,0)),MAX(AI$4:AI11)+1,0)) -> 7 | AJ12: =IF($BE12="","",IF(ISNUMBER(MATCH($BE12,AR$5:AR$29999,0)),MAX(AJ$4:AJ11)+1,0)) -> 7 | AK12: =IF($BE12="","",IF(ISNUMBER(MATCH($BE12,AS$5:AS$29999,0)),MAX(AK$4:AK11)+1,0)) -> 0 | AL12: =IF($BE12="","",IF(ISNUMBER(MATCH($BE12,AT$5:AT$29999,0)),MAX(AL$4:AL11)+1,0)) -> 8 | AM12: =IF($BE12="","",IF(ISNUMBER(MATCH($BE12,AU$5:AU$29999,0)),MAX(AM$4:AM11)+1,0)) -> 8 | AN12: =IF($BE12="","",IF(ISNUMBER(MATCH($BE12,AV$5:AV$29999,0)),MAX(AN$4:AN11)+1,0)) -> 0 | AP12: .ims | AQ12: .oc | AR12: .lak | AS12: .hds | AT12: .hds | AU12: .lak | AW12: .hds | AY12: .sfr | AZ12: .sfr | BB12: =IF(ISTEXT(AW12),IF(ISNUMBER(MATCH(AW12,$AY$5:$AY$100,0)),0,MAX(BB$4:BB11)+1),"") -> 0 | BC12: =IF(ISTEXT(AY12),MATCH(AY12,$AW$5:$AW$127,0),"") -> 20 | BD12: =IF(ISNUMBER(BC12),AY12,ROW()-SUM($BC$4:$BD$4)) -> .sfr | BE12: =IF(ISTEXT(AW12),IF(ISNUMBER(BC12),AY12,INDEX($AW$5:$AW$140,MATCH(BD12,$BB$5:$BB$185,0),1)),"") -> .sfr | BG12: =IF(ISNUMBER(MATCH($BE12,Z$5:Z$501,0)),INDEX(Z$5:Z$501,MATCH($BE12,Z$5:Z$501,0),1),"") -> .sfr | BH12: =IF(ISNUMBER(MATCH($BE12,AA$5:AA$501,0)),INDEX(AA$5:AA$501,MATCH($BE12,AA$5:AA$501,0),1),"") -> .sfr | BI12: =IF(ISNUMBER(MATCH($BE12,AB$5:AB$501,0)),INDEX(AB$5:AB$501,MATCH($BE12,AB$5:AB$501,0),1),"") -> .sfr | BJ12: =IF(ISNUMBER(MATCH($BE12,AC$5:AC$501,0)),INDEX(AC$5:AC$501,MATCH($BE12,AC$5:AC$501,0),1),"") | BK12: =IF(ISNUMBER(MATCH($BE12,AD$5:AD$501,0)),INDEX(AD$5:AD$501,MATCH($BE12,AD$5:AD$501,0),1),"") -> .sfr | BL12: =IF(ISNUMBER(MATCH($BE12,AE$5:AE$501,0)),INDEX(AE$5:AE$501,MATCH($BE12,AE$5:AE$501,0),1),"") -> .sfr | BM12: =IF(ISNUMBER(MATCH($BE12,AF$5:AF$501,0)),INDEX(AF$5:AF$501,MATCH($BE12,AF$5:AF$501,0),1),"")
B13: =IF(ISNUMBER(MATCH(O13,$N$5:$N$1000,0)),MATCH(O13,$N$5:$N$1000,0),"") -> 6 | C13: =IF(ISNUMBER(B13),MAX(C$4:C12)+1,"") -> 5 | D13: =IF(IF(ISNUMBER(B13),"",MAX(D$4:D12)+1)<=D$3,IF(ISNUMBER(B13),"",MAX(D$4:D12)+1),"") | E13: =IF(M13<=D$3,MATCH(M13,D$5:D$1000,0),"") -> 29 | F13: =IF(ISNUMBER(E13),INDEX($N$5:$N$1000,E13,1),"") -> obs_uzf.csv | G13: =IF(ISNUMBER(C13),N13,IF(ISTEXT(N13),INDEX($F$5:$F$1000,MATCH(M13,$E$5:$E$1000,0),1),"")) -> .lak.bud | H13: =IF(O13="","",IF(ISNUMBER(MATCH(O13,$G$5:$G$1000,0)),"",IF(D13=1,C$3,0)+MAX(H$4:H12)+1)) | I13: =IF(O13="","",IF(ISNUMBER(MATCH(O13,$G$5:$G$1000,0)),"",IF(D13=1,B$4,0)+MAX(I$4:I12)+1)) | J13: =IF(ISNUMBER(MATCH(M13,$I$5:$I$1000,0)),INDEX($O$5:$O$1000,MATCH(M13,$I$5:$I$1000,0),1),"") | K13: =IF(P13="",0,1) -> 1 | M13: =IF(ROW()-ROW(M$4)<=1000,ROW()-ROW(M$4),"") -> 9 | N13: .lak.bud | O13: .ic | P13: =IF(M13<=$B$4,IF(ISTEXT(G13),G13,""),IF(ISTEXT(J13),J13,"")) -> .lak.bud | R13: =IF(ROW()-ROW(R$4)<=AH$3,ROW()-ROW(R$4),"") -> 9 | S13: =IF(ROW()-ROW(S$4)<=AI$3,ROW()-ROW(S$4),"") -> 9 | T13: =IF(ROW()-ROW(T$4)<=AJ$3,ROW()-ROW(T$4),"") -> 9 | U13: =IF(ROW()-ROW(U$4)<=AK$3,ROW()-ROW(U$4),"") -> 9 | V13: =IF(ROW()-ROW(V$4)<=AL$3,ROW()-ROW(V$4),"") -> 9 | W13: =IF(ROW()-ROW(W$4)<=AM$3,ROW()-ROW(W$4),"") -> 9 | X13: =IF(ROW()-ROW(X$4)<=AN$3,ROW()-ROW(X$4),"") | Z13: =IF(ISNUMBER(R13),INDEX($BE$5:$BE$2999,MATCH(R13,AH$5:AH$2999,0),1),"") -> .sfr.obs.csv | AA13: =IF(ISNUMBER(S13),INDEX($BE$5:$BE$2999,MATCH(S13,AI$5:AI$2999,0),1),"") -> .sfr.obs.csv | AB13: =IF(ISNUMBER(T13),INDEX($BE$5:$BE$2999,MATCH(T13,AJ$5:AJ$2999,0),1),"") -> .sfr.bud | AC13: =IF(ISNUMBER(U13),INDEX($BE$5:$BE$2999,MATCH(U13,AK$5:AK$2999,0),1),"") -> .lak.obs | AD13: =IF(ISNUMBER(V13),INDEX($BE$5:$BE$2999,MATCH(V13,AL$5:AL$2999,0),1),"") -> .lak | AE13: =IF(ISNUMBER(W13),INDEX($BE$5:$BE$2999,MATCH(W13,AM$5:AM$2999,0),1),"") -> .sfr.obs | AF13: =IF(ISNUMBER(X13),INDEX($BE$5:$BE$2999,MATCH(X13,AN$5:AN$2999,0),1),"") | AH13: =IF($BE13="","",IF(ISNUMBER(MATCH($BE13,AP$5:AP$29999,0)),MAX(AH$4:AH12)+1,0)) -> 8 | AI13: =IF($BE13="","",IF(ISNUMBER(MATCH($BE13,AQ$5:AQ$29999,0)),MAX(AI$4:AI12)+1,0)) -> 8 | AJ13: =IF($BE13="","",IF(ISNUMBER(MATCH($BE13,AR$5:AR$29999,0)),MAX(AJ$4:AJ12)+1,0)) -> 8 | AK13: =IF($BE13="","",IF(ISNUMBER(MATCH($BE13,AS$5:AS$29999,0)),MAX(AK$4:AK12)+1,0)) -> 0 | AL13: =IF($BE13="","",IF(ISNUMBER(MATCH($BE13,AT$5:AT$29999,0)),MAX(AL$4:AL12)+1,0)) -> 0 | AM13: =IF($BE13="","",IF(ISNUMBER(MATCH($BE13,AU$5:AU$29999,0)),MAX(AM$4:AM12)+1,0)) -> 9 | AN13: =IF($BE13="","",IF(ISNUMBER(MATCH($BE13,AV$5:AV$29999,0)),MAX(AN$4:AN12)+1,0)) -> 0 | AP13: .lst | AQ13: .sfr | AR13: .lak.bud | AS13: .ic | AT13: .ic | AU13: .lak.bin | AW13: .ic | AY13: .sfr.obs | AZ13: .sfr.obs | BB13: =IF(ISTEXT(AW13),IF(ISNUMBER(MATCH(AW13,$AY$5:$AY$100,0)),0,MAX(BB$4:BB12)+1),"") -> 0 | BC13: =IF(ISTEXT(AY13),MATCH(AY13,$AW$5:$AW$127,0),"") -> 31 | BD13: =IF(ISNUMBER(BC13),AY13,ROW()-SUM($BC$4:$BD$4)) -> .sfr.obs | BE13: =IF(ISTEXT(AW13),IF(ISNUMBER(BC13),AY13,INDEX($AW$5:$AW$140,MATCH(BD13,$BB$5:$BB$185,0),1)),"") -> .sfr.obs | BG13: =IF(ISNUMBER(MATCH($BE13,Z$5:Z$501,0)),INDEX(Z$5:Z$501,MATCH($BE13,Z$5:Z$501,0),1),"") -> .sfr.obs | BH13: =IF(ISNUMBER(MATCH($BE13,AA$5:AA$501,0)),INDEX(AA$5:AA$501,MATCH($BE13,AA$5:AA$501,0),1),"") -> .sfr.obs | BI13: =IF(ISNUMBER(MATCH($BE13,AB$5:AB$501,0)),INDEX(AB$5:AB$501,MATCH($BE13,AB$5:AB$501,0),1),"") -> .sfr.obs | BJ13: =IF(ISNUMBER(MATCH($BE13,AC$5:AC$501,0)),INDEX(AC$5:AC$501,MATCH($BE13,AC$5:AC$501,0),1),"") | BK13: =IF(ISNUMBER(MATCH($BE13,AD$5:AD$501,0)),INDEX(AD$5:AD$501,MATCH($BE13,AD$5:AD$501,0),1),"") | BL13: =IF(ISNUMBER(MATCH($BE13,AE$5:AE$501,0)),INDEX(AE$5:AE$501,MATCH($BE13,AE$5:AE$501,0),1),"") -> .sfr.obs | BM13: =IF(ISNUMBER(MATCH($BE13,AF$5:AF$501,0)),INDEX(AF$5:AF$501,MATCH($BE13,AF$5:AF$501,0),1),"")
B14: =IF(ISNUMBER(MATCH(O14,$N$5:$N$1000,0)),MATCH(O14,$N$5:$N$1000,0),"") -> 7 | C14: =IF(ISNUMBER(B14),MAX(C$4:C13)+1,"") -> 6 | D14: =IF(IF(ISNUMBER(B14),"",MAX(D$4:D13)+1)<=D$3,IF(ISNUMBER(B14),"",MAX(D$4:D13)+1),"") | E14: =IF(M14<=D$3,MATCH(M14,D$5:D$1000,0),"") -> 32 | F14: =IF(ISNUMBER(E14),INDEX($N$5:$N$1000,E14,1),"") -> sfr.reach01.csv | G14: =IF(ISNUMBER(C14),N14,IF(ISTEXT(N14),INDEX($F$5:$F$1000,MATCH(M14,$E$5:$E$1000,0),1),"")) -> .lak.obs | H14: =IF(O14="","",IF(ISNUMBER(MATCH(O14,$G$5:$G$1000,0)),"",IF(D14=1,C$3,0)+MAX(H$4:H13)+1)) | I14: =IF(O14="","",IF(ISNUMBER(MATCH(O14,$G$5:$G$1000,0)),"",IF(D14=1,B$4,0)+MAX(I$4:I13)+1)) | J14: =IF(ISNUMBER(MATCH(M14,$I$5:$I$1000,0)),INDEX($O$5:$O$1000,MATCH(M14,$I$5:$I$1000,0),1),"") | K14: =IF(P14="",0,1) -> 1 | M14: =IF(ROW()-ROW(M$4)<=1000,ROW()-ROW(M$4),"") -> 10 | N14: .lak.obs | O14: .ims | P14: =IF(M14<=$B$4,IF(ISTEXT(G14),G14,""),IF(ISTEXT(J14),J14,"")) -> .lak.obs | R14: =IF(ROW()-ROW(R$4)<=AH$3,ROW()-ROW(R$4),"") -> 10 | S14: =IF(ROW()-ROW(S$4)<=AI$3,ROW()-ROW(S$4),"") -> 10 | T14: =IF(ROW()-ROW(T$4)<=AJ$3,ROW()-ROW(T$4),"") -> 10 | U14: =IF(ROW()-ROW(U$4)<=AK$3,ROW()-ROW(U$4),"") -> 10 | V14: =IF(ROW()-ROW(V$4)<=AL$3,ROW()-ROW(V$4),"") -> 10 | W14: =IF(ROW()-ROW(W$4)<=AM$3,ROW()-ROW(W$4),"") -> 10 | X14: =IF(ROW()-ROW(X$4)<=AN$3,ROW()-ROW(X$4),"") | Z14: =IF(ISNUMBER(R14),INDEX($BE$5:$BE$2999,MATCH(R14,AH$5:AH$2999,0),1),"") -> .nam | AA14: =IF(ISNUMBER(S14),INDEX($BE$5:$BE$2999,MATCH(S14,AI$5:AI$2999,0),1),"") -> .nam | AB14: =IF(ISNUMBER(T14),INDEX($BE$5:$BE$2999,MATCH(T14,AJ$5:AJ$2999,0),1),"") -> .lak | AC14: =IF(ISNUMBER(U14),INDEX($BE$5:$BE$2999,MATCH(U14,AK$5:AK$2999,0),1),"") -> .lak.obs.csv | AD14: =IF(ISNUMBER(V14),INDEX($BE$5:$BE$2999,MATCH(V14,AL$5:AL$2999,0),1),"") -> .lak.obs | AE14: =IF(ISNUMBER(W14),INDEX($BE$5:$BE$2999,MATCH(W14,AM$5:AM$2999,0),1),"") -> .sfr.obs.csv | AF14: =IF(ISNUMBER(X14),INDEX($BE$5:$BE$2999,MATCH(X14,AN$5:AN$2999,0),1),"") | AH14: =IF($BE14="","",IF(ISNUMBER(MATCH($BE14,AP$5:AP$29999,0)),MAX(AH$4:AH13)+1,0)) -> 9 | AI14: =IF($BE14="","",IF(ISNUMBER(MATCH($BE14,AQ$5:AQ$29999,0)),MAX(AI$4:AI13)+1,0)) -> 9 | AJ14: =IF($BE14="","",IF(ISNUMBER(MATCH($BE14,AR$5:AR$29999,0)),MAX(AJ$4:AJ13)+1,0)) -> 0 | AK14: =IF($BE14="","",IF(ISNUMBER(MATCH($BE14,AS$5:AS$29999,0)),MAX(AK$4:AK13)+1,0)) -> 0 | AL14: =IF($BE14="","",IF(ISNUMBER(MATCH($BE14,AT$5:AT$29999,0)),MAX(AL$4:AL13)+1,0)) -> 0 | AM14: =IF($BE14="","",IF(ISNUMBER(MATCH($BE14,AU$5:AU$29999,0)),MAX(AM$4:AM13)+1,0)) -> 10 | AN14: =IF($BE14="","",IF(ISNUMBER(MATCH($BE14,AV$5:AV$29999,0)),MAX(AN$4:AN13)+1,0)) -> 0 | AP14: .nam | AQ14: .sfr.obs | AR14: .lak.obs | AS14: .ims | AT14: .ims | AU14: .lak.bud | AW14: .ims | AY14: .sfr.obs.csv | AZ14: .sfr.obs.csv | BB14: =IF(ISTEXT(AW14),IF(ISNUMBER(MATCH(AW14,$AY$5:$AY$100,0)),0,MAX(BB$4:BB13)+1),"") -> 0 | BC14: =IF(ISTEXT(AY14),MATCH(AY14,$AW$5:$AW$127,0),"") -> 32 | BD14: =IF(ISNUMBER(BC14),AY14,ROW()-SUM($BC$4:$BD$4)) -> .sfr.obs.csv | BE14: =IF(ISTEXT(AW14),IF(ISNUMBER(BC14),AY14,INDEX($AW$5:$AW$140,MATCH(BD14,$BB$5:$BB$185,0),1)),"") -> .sfr.obs.csv | BG14: =IF(ISNUMBER(MATCH($BE14,Z$5:Z$501,0)),INDEX(Z$5:Z$501,MATCH($BE14,Z$5:Z$501,0),1),"") -> .sfr.obs.csv | BH14: =IF(ISNUMBER(MATCH($BE14,AA$5:AA$501,0)),INDEX(AA$5:AA$501,MATCH($BE14,AA$5:AA$501,0),1),"") -> .sfr.obs.csv | BI14: =IF(ISNUMBER(MATCH($BE14,AB$5:AB$501,0)),INDEX(AB$5:AB$501,MATCH($BE14,AB$5:AB$501,0),1),"") | BJ14: =IF(ISNUMBER(MATCH($BE14,AC$5:AC$501,0)),INDEX(AC$5:AC$501,MATCH($BE14,AC$5:AC$501,0),1),"") | BK14: =IF(ISNUMBER(MATCH($BE14,AD$5:AD$501,0)),INDEX(AD$5:AD$501,MATCH($BE14,AD$5:AD$501,0),1),"") | BL14: =IF(ISNUMBER(MATCH($BE14,AE$5:AE$501,0)),INDEX(AE$5:AE$501,MATCH($BE14,AE$5:AE$501,0),1),"") -> .sfr.obs.csv | BM14: =IF(ISNUMBER(MATCH($BE14,AF$5:AF$501,0)),INDEX(AF$5:AF$501,MATCH($BE14,AF$5:AF$501,0),1),"")
B15: =IF(ISNUMBER(MATCH(O15,$N$5:$N$1000,0)),MATCH(O15,$N$5:$N$1000,0),"") -> 8 | C15: =IF(ISNUMBER(B15),MAX(C$4:C14)+1,"") -> 7 | D15: =IF(IF(ISNUMBER(B15),"",MAX(D$4:D14)+1)<=D$3,IF(ISNUMBER(B15),"",MAX(D$4:D14)+1),"") | E15: =IF(M15<=D$3,MATCH(M15,D$5:D$1000,0),"") -> 33 | F15: =IF(ISNUMBER(E15),INDEX($N$5:$N$1000,E15,1),"") -> sfr.reach24.csv | G15: =IF(ISNUMBER(C15),N15,IF(ISTEXT(N15),INDEX($F$5:$F$1000,MATCH(M15,$E$5:$E$1000,0),1),"")) -> .lst | H15: =IF(O15="","",IF(ISNUMBER(MATCH(O15,$G$5:$G$1000,0)),"",IF(D15=1,C$3,0)+MAX(H$4:H14)+1)) | I15: =IF(O15="","",IF(ISNUMBER(MATCH(O15,$G$5:$G$1000,0)),"",IF(D15=1,B$4,0)+MAX(I$4:I14)+1)) | J15: =IF(ISNUMBER(MATCH(M15,$I$5:$I$1000,0)),INDEX($O$5:$O$1000,MATCH(M15,$I$5:$I$1000,0),1),"") | K15: =IF(P15="",0,1) -> 1 | M15: =IF(ROW()-ROW(M$4)<=1000,ROW()-ROW(M$4),"") -> 11 | N15: .lst | O15: .lak | P15: =IF(M15<=$B$4,IF(ISTEXT(G15),G15,""),IF(ISTEXT(J15),J15,"")) -> .lst | R15: =IF(ROW()-ROW(R$4)<=AH$3,ROW()-ROW(R$4),"") -> 11 | S15: =IF(ROW()-ROW(S$4)<=AI$3,ROW()-ROW(S$4),"") -> 11 | T15: =IF(ROW()-ROW(T$4)<=AJ$3,ROW()-ROW(T$4),"") -> 11 | U15: =IF(ROW()-ROW(U$4)<=AK$3,ROW()-ROW(U$4),"") -> 11 | V15: =IF(ROW()-ROW(V$4)<=AL$3,ROW()-ROW(V$4),"") -> 11 | W15: =IF(ROW()-ROW(W$4)<=AM$3,ROW()-ROW(W$4),"") -> 11 | X15: =IF(ROW()-ROW(X$4)<=AN$3,ROW()-ROW(X$4),"") | Z15: =IF(ISNUMBER(R15),INDEX($BE$5:$BE$2999,MATCH(R15,AH$5:AH$2999,0),1),"") -> .tdis | AA15: =IF(ISNUMBER(S15),INDEX($BE$5:$BE$2999,MATCH(S15,AI$5:AI$2999,0),1),"") -> .tdis | AB15: =IF(ISNUMBER(T15),INDEX($BE$5:$BE$2999,MATCH(T15,AJ$5:AJ$2999,0),1),"") -> .lak.obs | AC15: =IF(ISNUMBER(U15),INDEX($BE$5:$BE$2999,MATCH(U15,AK$5:AK$2999,0),1),"") -> .nam | AD15: =IF(ISNUMBER(V15),INDEX($BE$5:$BE$2999,MATCH(V15,AL$5:AL$2999,0),1),"") -> .lak.obs.csv | AE15: =IF(ISNUMBER(W15),INDEX($BE$5:$BE$2999,MATCH(W15,AM$5:AM$2999,0),1),"") -> .sfr.bud | AF15: =IF(ISNUMBER(X15),INDEX($BE$5:$BE$2999,MATCH(X15,AN$5:AN$2999,0),1),"") | AH15: =IF($BE15="","",IF(ISNUMBER(MATCH($BE15,AP$5:AP$29999,0)),MAX(AH$4:AH14)+1,0)) -> 0 | AI15: =IF($BE15="","",IF(ISNUMBER(MATCH($BE15,AQ$5:AQ$29999,0)),MAX(AI$4:AI14)+1,0)) -> 0 | AJ15: =IF($BE15="","",IF(ISNUMBER(MATCH($BE15,AR$5:AR$29999,0)),MAX(AJ$4:AJ14)+1,0)) -> 9 | AK15: =IF($BE15="","",IF(ISNUMBER(MATCH($BE15,AS$5:AS$29999,0)),MAX(AK$4:AK14)+1,0)) -> 0 | AL15: =IF($BE15="","",IF(ISNUMBER(MATCH($BE15,AT$5:AT$29999,0)),MAX(AL$4:AL14)+1,0)) -> 0 | AM15: =IF($BE15="","",IF(ISNUMBER(MATCH($BE15,AU$5:AU$29999,0)),MAX(AM$4:AM14)+1,0)) -> 11 | AN15: =IF($BE15="","",IF(ISNUMBER(MATCH($BE15,AV$5:AV$29999,0)),MAX(AN$4:AN14)+1,0)) -> 0 | AP15: .npf | AQ15: .sfr.obs.csv | AR15: .lst | AS15: .lak | AT15: .lak | AU15: .lst | AW15: .lak | AY15: .sfr.bud | AZ15: .sfr.bud | BB15: =IF(ISTEXT(AW15),IF(ISNUMBER(MATCH(AW15,$AY$5:$AY$100,0)),0,MAX(BB$4:BB14)+1),"") -> 0 | BC15: =IF(ISTEXT(AY15),MATCH(AY15,$AW$5:$AW$127,0),"") -> 30 | BD15: =IF(ISNUMBER(BC15),AY15,ROW()-SUM($BC$4:$BD$4)) -> .sfr.bud | BE15: =IF(ISTEXT(AW15),IF(ISNUMBER(BC15),AY15,INDEX($AW$5:$AW$140,MATCH(BD15,$BB$5:$BB$185,0),1)),"") -> .sfr.bud | BG15: =IF(ISNUMBER(MATCH($BE15,Z$5:Z$501,0)),INDEX(Z$5:Z$501,MATCH($BE15,Z$5:Z$501,0),1),"") | BH15: =IF(ISNUMBER(MATCH($BE15,AA$5:AA$501,0)),INDEX(AA$5:AA$501,MATCH($BE15,AA$5:AA$501,0),1),"") | BI15: =IF(ISNUMBER(MATCH($BE15,AB$5:AB$501,0)),INDEX(AB$5:AB$501,MATCH($BE15,AB$5:AB$501,0),1),"") -> .sfr.bud | BJ15: =IF(ISNUMBER(MATCH($BE15,AC$5:AC$501,0)),INDEX(AC$5:AC$501,MATCH($BE15,AC$5:AC$501,0),1),"") | BK15: =IF(ISNUMBER(MATCH($BE15,AD$5:AD$501,0)),INDEX(AD$5:AD$501,MATCH($BE15,AD$5:AD$501,0),1),"") | BL15: =IF(ISNUMBER(MATCH($BE15,AE$5:AE$501,0)),INDEX(AE$5:AE$501,MATCH($BE15,AE$5:AE$501,0),1),"") -> .sfr.bud | BM15: =IF(ISNUMBER(MATCH($BE15,AF$5:AF$501,0)),INDEX(AF$5:AF$501,MATCH($BE15,AF$5:AF$501,0),1),"")
B16: =IF(ISNUMBER(MATCH(O16,$N$5:$N$1000,0)),MATCH(O16,$N$5:$N$1000,0),"") -> 10 | C16: =IF(ISNUMBER(B16),MAX(C$4:C15)+1,"") -> 8 | D16: =IF(IF(ISNUMBER(B16),"",MAX(D$4:D15)+1)<=D$3,IF(ISNUMBER(B16),"",MAX(D$4:D15)+1),"") | E16: =IF(M16<=D$3,MATCH(M16,D$5:D$1000,0),"") -> 34 | F16: =IF(ISNUMBER(E16),INDEX($N$5:$N$1000,E16,1),"") -> sfr.reach29.csv | G16: =IF(ISNUMBER(C16),N16,IF(ISTEXT(N16),INDEX($F$5:$F$1000,MATCH(M16,$E$5:$E$1000,0),1),"")) -> .mvr | H16: =IF(O16="","",IF(ISNUMBER(MATCH(O16,$G$5:$G$1000,0)),"",IF(D16=1,C$3,0)+MAX(H$4:H15)+1)) | I16: =IF(O16="","",IF(ISNUMBER(MATCH(O16,$G$5:$G$1000,0)),"",IF(D16=1,B$4,0)+MAX(I$4:I15)+1)) | J16: =IF(ISNUMBER(MATCH(M16,$I$5:$I$1000,0)),INDEX($O$5:$O$1000,MATCH(M16,$I$5:$I$1000,0),1),"") | K16: =IF(P16="",0,1) -> 1 | M16: =IF(ROW()-ROW(M$4)<=1000,ROW()-ROW(M$4),"") -> 12 | N16: .mvr | O16: .lak.obs | P16: =IF(M16<=$B$4,IF(ISTEXT(G16),G16,""),IF(ISTEXT(J16),J16,"")) -> .mvr | R16: =IF(ROW()-ROW(R$4)<=AH$3,ROW()-ROW(R$4),"") -> 12 | S16: =IF(ROW()-ROW(S$4)<=AI$3,ROW()-ROW(S$4),"") -> 12 | T16: =IF(ROW()-ROW(T$4)<=AJ$3,ROW()-ROW(T$4),"") -> 12 | U16: =IF(ROW()-ROW(U$4)<=AK$3,ROW()-ROW(U$4),"") -> 12 | V16: =IF(ROW()-ROW(V$4)<=AL$3,ROW()-ROW(V$4),"") -> 12 | W16: =IF(ROW()-ROW(W$4)<=AM$3,ROW()-ROW(W$4),"") -> 12 | X16: =IF(ROW()-ROW(X$4)<=AN$3,ROW()-ROW(X$4),"") | Z16: =IF(ISNUMBER(R16),INDEX($BE$5:$BE$2999,MATCH(R16,AH$5:AH$2999,0),1),"") -> mfsim.lst | AA16: =IF(ISNUMBER(S16),INDEX($BE$5:$BE$2999,MATCH(S16,AI$5:AI$2999,0),1),"") -> mfsim.lst | AB16: =IF(ISNUMBER(T16),INDEX($BE$5:$BE$2999,MATCH(T16,AJ$5:AJ$2999,0),1),"") -> .lak.bud | AC16: =IF(ISNUMBER(U16),INDEX($BE$5:$BE$2999,MATCH(U16,AK$5:AK$2999,0),1),"") -> .tdis | AD16: =IF(ISNUMBER(V16),INDEX($BE$5:$BE$2999,MATCH(V16,AL$5:AL$2999,0),1),"") -> .mvr | AE16: =IF(ISNUMBER(W16),INDEX($BE$5:$BE$2999,MATCH(W16,AM$5:AM$2999,0),1),"") -> .sfr.bin | AF16: =IF(ISNUMBER(X16),INDEX($BE$5:$BE$2999,MATCH(X16,AN$5:AN$2999,0),1),"") | AH16: =IF($BE16="","",IF(ISNUMBER(MATCH($BE16,AP$5:AP$29999,0)),MAX(AH$4:AH15)+1,0)) -> 0 | AI16: =IF($BE16="","",IF(ISNUMBER(MATCH($BE16,AQ$5:AQ$29999,0)),MAX(AI$4:AI15)+1,0)) -> 0 | AJ16: =IF($BE16="","",IF(ISNUMBER(MATCH($BE16,AR$5:AR$29999,0)),MAX(AJ$4:AJ15)+1,0)) -> 0 | AK16: =IF($BE16="","",IF(ISNUMBER(MATCH($BE16,AS$5:AS$29999,0)),MAX(AK$4:AK15)+1,0)) -> 0 | AL16: =IF($BE16="","",IF(ISNUMBER(MATCH($BE16,AT$5:AT$29999,0)),MAX(AL$4:AL15)+1,0)) -> 0 | AM16: =IF($BE16="","",IF(ISNUMBER(MATCH($BE16,AU$5:AU$29999,0)),MAX(AM$4:AM15)+1,0)) -> 12 | AN16: =IF($BE16="","",IF(ISNUMBER(MATCH($BE16,AV$5:AV$29999,0)),MAX(AN$4:AN15)+1,0)) -> 0 | AP16: .oc | AQ16: .sfr.ts | AR16: .mvr | AS16: .lak.obs | AT16: .lak.obs | AU16: .mvr | AW16: .lak.obs | AY16: .sfr.bin | AZ16: .sfr.bin | BB16: =IF(ISTEXT(AW16),IF(ISNUMBER(MATCH(AW16,$AY$5:$AY$100,0)),0,MAX(BB$4:BB15)+1),"") -> 0 | BC16: =IF(ISTEXT(AY16),MATCH(AY16,$AW$5:$AW$127,0),"") -> 29 | BD16: =IF(ISNUMBER(BC16),AY16,ROW()-SUM($BC$4:$BD$4)) -> .sfr.bin | BE16: =IF(ISTEXT(AW16),IF(ISNUMBER(BC16),AY16,INDEX($AW$5:$AW$140,MATCH(BD16,$BB$5:$BB$185,0),1)),"") -> .sfr.bin | BG16: =IF(ISNUMBER(MATCH($BE16,Z$5:Z$501,0)),INDEX(Z$5:Z$501,MATCH($BE16,Z$5:Z$501,0),1),"") | BH16: =IF(ISNUMBER(MATCH($BE16,AA$5:AA$501,0)),INDEX(AA$5:AA$501,MATCH($BE16,AA$5:AA$501,0),1),"") | BI16: =IF(ISNUMBER(MATCH($BE16,AB$5:AB$501,0)),INDEX(AB$5:AB$501,MATCH($BE16,AB$5:AB$501,0),1),"") | BJ16: =IF(ISNUMBER(MATCH($BE16,AC$5:AC$501,0)),INDEX(AC$5:AC$501,MATCH($BE16,AC$5:AC$501,0),1),"") | BK16: =IF(ISNUMBER(MATCH($BE16,AD$5:AD$501,0)),INDEX(AD$5:AD$501,MATCH($BE16,AD$5:AD$501,0),1),"") | BL16: =IF(ISNUMBER(MATCH($BE16,AE$5:AE$501,0)),INDEX(AE$5:AE$501,MATCH($BE16,AE$5:AE$501,0),1),"") -> .sfr.bin | BM16: =IF(ISNUMBER(MATCH($BE16,AF$5:AF$501,0)),INDEX(AF$5:AF$501,MATCH($BE16,AF$5:AF$501,0),1),"")
B17: =IF(ISNUMBER(MATCH(O17,$N$5:$N$1000,0)),MATCH(O17,$N$5:$N$1000,0),"") | C17: =IF(ISNUMBER(B17),MAX(C$4:C16)+1,"") | D17: =IF(IF(ISNUMBER(B17),"",MAX(D$4:D16)+1)<=D$3,IF(ISNUMBER(B17),"",MAX(D$4:D16)+1),"") -> 5 | E17: =IF(M17<=D$3,MATCH(M17,D$5:D$1000,0),"") -> 35 | F17: =IF(ISNUMBER(E17),INDEX($N$5:$N$1000,E17,1),"") -> sfr.reach31.csv | G17: =IF(ISNUMBER(C17),N17,IF(ISTEXT(N17),INDEX($F$5:$F$1000,MATCH(M17,$E$5:$E$1000,0),1),"")) -> .mvr.bud | H17: =IF(O17="","",IF(ISNUMBER(MATCH(O17,$G$5:$G$1000,0)),"",IF(D17=1,C$3,0)+MAX(H$4:H16)+1)) -> 27 | I17: =IF(O17="","",IF(ISNUMBER(MATCH(O17,$G$5:$G$1000,0)),"",IF(D17=1,B$4,0)+MAX(I$4:I16)+1)) -> 41 | J17: =IF(ISNUMBER(MATCH(M17,$I$5:$I$1000,0)),INDEX($O$5:$O$1000,MATCH(M17,$I$5:$I$1000,0),1),"") | K17: =IF(P17="",0,1) -> 1 | M17: =IF(ROW()-ROW(M$4)<=1000,ROW()-ROW(M$4),"") -> 13 | N17: .mvr.bud | O17: .lak.obs.csv | P17: =IF(M17<=$B$4,IF(ISTEXT(G17),G17,""),IF(ISTEXT(J17),J17,"")) -> .mvr.bud | R17: =IF(ROW()-ROW(R$4)<=AH$3,ROW()-ROW(R$4),"") -> 13 | S17: =IF(ROW()-ROW(S$4)<=AI$3,ROW()-ROW(S$4),"") -> 13 | T17: =IF(ROW()-ROW(T$4)<=AJ$3,ROW()-ROW(T$4),"") -> 13 | U17: =IF(ROW()-ROW(U$4)<=AK$3,ROW()-ROW(U$4),"") -> 13 | V17: =IF(ROW()-ROW(V$4)<=AL$3,ROW()-ROW(V$4),"") -> 13 | W17: =IF(ROW()-ROW(W$4)<=AM$3,ROW()-ROW(W$4),"") -> 13 | X17: =IF(ROW()-ROW(X$4)<=AN$3,ROW()-ROW(X$4),"") | Z17: =IF(ISNUMBER(R17),INDEX($BE$5:$BE$2999,MATCH(R17,AH$5:AH$2999,0),1),"") -> .dis.grb | AA17: =IF(ISNUMBER(S17),INDEX($BE$5:$BE$2999,MATCH(S17,AI$5:AI$2999,0),1),"") -> .dis.grb | AB17: =IF(ISNUMBER(T17),INDEX($BE$5:$BE$2999,MATCH(T17,AJ$5:AJ$2999,0),1),"") -> .mvr | AC17: =IF(ISNUMBER(U17),INDEX($BE$5:$BE$2999,MATCH(U17,AK$5:AK$2999,0),1),"") -> mfsim.lst | AD17: =IF(ISNUMBER(V17),INDEX($BE$5:$BE$2999,MATCH(V17,AL$5:AL$2999,0),1),"") -> .nam | AE17: =IF(ISNUMBER(W17),INDEX($BE$5:$BE$2999,MATCH(W17,AM$5:AM$2999,0),1),"") -> .lak | AF17: =IF(ISNUMBER(X17),INDEX($BE$5:$BE$2999,MATCH(X17,AN$5:AN$2999,0),1),"") | AH17: =IF($BE17="","",IF(ISNUMBER(MATCH($BE17,AP$5:AP$29999,0)),MAX(AH$4:AH16)+1,0)) -> 0 | AI17: =IF($BE17="","",IF(ISNUMBER(MATCH($BE17,AQ$5:AQ$29999,0)),MAX(AI$4:AI16)+1,0)) -> 0 | AJ17: =IF($BE17="","",IF(ISNUMBER(MATCH($BE17,AR$5:AR$29999,0)),MAX(AJ$4:AJ16)+1,0)) -> 10 | AK17: =IF($BE17="","",IF(ISNUMBER(MATCH($BE17,AS$5:AS$29999,0)),MAX(AK$4:AK16)+1,0)) -> 8 | AL17: =IF($BE17="","",IF(ISNUMBER(MATCH($BE17,AT$5:AT$29999,0)),MAX(AL$4:AL16)+1,0)) -> 9 | AM17: =IF($BE17="","",IF(ISNUMBER(MATCH($BE17,AU$5:AU$29999,0)),MAX(AM$4:AM16)+1,0)) -> 13 | AN17: =IF($BE17="","",IF(ISNUMBER(MATCH($BE17,AV$5:AV$29999,0)),MAX(AN$4:AN16)+1,0)) -> 0 | AP17: .rcha | AQ17: .sto | AR17: .mvr.bud | AS17: .lak.obs.csv | AT17: .lak.obs.csv | AU17: .mvr.bud | AW17: .lak.obs.csv | AY17: .lak | AZ17: .lak | BB17: =IF(ISTEXT(AW17),IF(ISNUMBER(MATCH(AW17,$AY$5:$AY$100,0)),0,MAX(BB$4:BB16)+1),"") -> 0 | BC17: =IF(ISTEXT(AY17),MATCH(AY17,$AW$5:$AW$127,0),"") -> 11 | BD17: =IF(ISNUMBER(BC17),AY17,ROW()-SUM($BC$4:$BD$4)) -> .lak | BE17: =IF(ISTEXT(AW17),IF(ISNUMBER(BC17),AY17,INDEX($AW$5:$AW$140,MATCH(BD17,$BB$5:$BB$185,0),1)),"") -> .lak | BG17: =IF(ISNUMBER(MATCH($BE17,Z$5:Z$501,0)),INDEX(Z$5:Z$501,MATCH($BE17,Z$5:Z$501,0),1),"") | BH17: =IF(ISNUMBER(MATCH($BE17,AA$5:AA$501,0)),INDEX(AA$5:AA$501,MATCH($BE17,AA$5:AA$501,0),1),"") | BI17: =IF(ISNUMBER(MATCH($BE17,AB$5:AB$501,0)),INDEX(AB$5:AB$501,MATCH($BE17,AB$5:AB$501,0),1),"") -> .lak | BJ17: =IF(ISNUMBER(MATCH($BE17,AC$5:AC$501,0)),INDEX(AC$5:AC$501,MATCH($BE17,AC$5:AC$501,0),1),"") -> .lak | BK17: =IF(ISNUMBER(MATCH($BE17,AD$5:AD$501,0)),INDEX(AD$5:AD$501,MATCH($BE17,AD$5:AD$501,0),1),"") -> .lak | BL17: =IF(ISNUMBER(MATCH($BE17,AE$5:AE$501,0)),INDEX(AE$5:AE$501,MATCH($BE17,AE$5:AE$501,0),1),"") -> .lak | BM17: =IF(ISNUMBER(MATCH($BE17,AF$5:AF$501,0)),INDEX(AF$5:AF$501,MATCH($BE17,AF$5:AF$501,0),1),"")
... B20: =IF(ISNUMBER(MATCH(O20,$N$5:$N$1000,0)),MATCH(O20,$N$5:$N$1000,0),"") -> 14 | C20: =IF(ISNUMBER(B20),MAX(C$4:C19)+1,"") -> 11 | D20: =IF(IF(ISNUMBER(B20),"",MAX(D$4:D19)+1)<=D$3,IF(ISNUMBER(B20),"",MAX(D$4:D19)+1),"") | E20: =IF(M20<=D$3,MATCH(M20,D$5:D$1000,0),"") | F20: =IF(ISNUMBER(E20),INDEX($N$5:$N$1000,E20,1),"") | G20: =IF(ISNUMBER(C20),N20,IF(ISTEXT(N20),INDEX($F$5:$F$1000,MATCH(M20,$E$5:$E$1000,0),1),"")) -> .oc | H20: =IF(O20="","",IF(ISNUMBER(MATCH(O20,$G$5:$G$1000,0)),"",IF(D20=1,C$3,0)+MAX(H$4:H19)+1)) | I20: =IF(O20="","",IF(ISNUMBER(MATCH(O20,$G$5:$G$1000,0)),"",IF(D20=1,B$4,0)+MAX(I$4:I19)+1)) | J20: =IF(ISNUMBER(MATCH(M20,$I$5:$I$1000,0)),INDEX($O$5:$O$1000,MATCH(M20,$I$5:$I$1000,0),1),"") | K20: =IF(P20="",0,1) -> 1 | M20: =IF(ROW()-ROW(M$4)<=1000,ROW()-ROW(M$4),"") -> 16 | N20: .oc | O20: .nam | P20: =IF(M20<=$B$4,IF(ISTEXT(G20),G20,""),IF(ISTEXT(J20),J20,"")) -> .oc | R20: =IF(ROW()-ROW(R$4)<=AH$3,ROW()-ROW(R$4),"") -> 16 | S20: =IF(ROW()-ROW(S$4)<=AI$3,ROW()-ROW(S$4),"") | T20: =IF(ROW()-ROW(T$4)<=AJ$3,ROW()-ROW(T$4),"") -> 16 | U20: =IF(ROW()-ROW(U$4)<=AK$3,ROW()-ROW(U$4),"") -> 16 | V20: =IF(ROW()-ROW(V$4)<=AL$3,ROW()-ROW(V$4),"") -> 16 | W20: =IF(ROW()-ROW(W$4)<=AM$3,ROW()-ROW(W$4),"") -> 16 | X20: =IF(ROW()-ROW(X$4)<=AN$3,ROW()-ROW(X$4),"") | Z20: =IF(ISNUMBER(R20),INDEX($BE$5:$BE$2999,MATCH(R20,AH$5:AH$2999,0),1),"") -> .evta | AA20: =IF(ISNUMBER(S20),INDEX($BE$5:$BE$2999,MATCH(S20,AI$5:AI$2999,0),1),"") | AB20: =IF(ISNUMBER(T20),INDEX($BE$5:$BE$2999,MATCH(T20,AJ$5:AJ$2999,0),1),"") -> .uzf.bud | AC20: =IF(ISNUMBER(U20),INDEX($BE$5:$BE$2999,MATCH(U20,AK$5:AK$2999,0),1),"") -> .sto | AD20: =IF(ISNUMBER(V20),INDEX($BE$5:$BE$2999,MATCH(V20,AL$5:AL$2999,0),1),"") -> .dis.grb | AE20: =IF(ISNUMBER(W20),INDEX($BE$5:$BE$2999,MATCH(W20,AM$5:AM$2999,0),1),"") -> .mvr | AF20: =IF(ISNUMBER(X20),INDEX($BE$5:$BE$2999,MATCH(X20,AN$5:AN$2999,0),1),"") | AH20: =IF($BE20="","",IF(ISNUMBER(MATCH($BE20,AP$5:AP$29999,0)),MAX(AH$4:AH19)+1,0)) -> 0 | AI20: =IF($BE20="","",IF(ISNUMBER(MATCH($BE20,AQ$5:AQ$29999,0)),MAX(AI$4:AI19)+1,0)) -> 0 | AJ20: =IF($BE20="","",IF(ISNUMBER(MATCH($BE20,AR$5:AR$29999,0)),MAX(AJ$4:AJ19)+1,0)) -> 12 | AK20: =IF($BE20="","",IF(ISNUMBER(MATCH($BE20,AS$5:AS$29999,0)),MAX(AK$4:AK19)+1,0)) -> 0 | AL20: =IF($BE20="","",IF(ISNUMBER(MATCH($BE20,AT$5:AT$29999,0)),MAX(AL$4:AL19)+1,0)) -> 0 | AM20: =IF($BE20="","",IF(ISNUMBER(MATCH($BE20,AU$5:AU$29999,0)),MAX(AM$4:AM19)+1,0)) -> 14 | AN20: =IF($BE20="","",IF(ISNUMBER(MATCH($BE20,AV$5:AV$29999,0)),MAX(AN$4:AN19)+1,0)) -> 0 | AP20: .sfr.obs.csv | AQ20: mfsim.nam | AR20: .oc | AS20: .npf | AT20: .nam | AU20: .oc | AW20: .nam | AY20: .lak.bud | AZ20: .lak.bud | BB20: =IF(ISTEXT(AW20),IF(ISNUMBER(MATCH(AW20,$AY$5:$AY$100,0)),0,MAX(BB$4:BB19)+1),"") -> 0 | BC20: =IF(ISTEXT(AY20),MATCH(AY20,$AW$5:$AW$127,0),"") -> 27 | BD20: =IF(ISNUMBER(BC20),AY20,ROW()-SUM($BC$4:$BD$4)) -> .lak.bud | BE20: =IF(ISTEXT(AW20),IF(ISNUMBER(BC20),AY20,INDEX($AW$5:$AW$140,MATCH(BD20,$BB$5:$BB$185,0),1)),"") -> .lak.bud | BG20: =IF(ISNUMBER(MATCH($BE20,Z$5:Z$501,0)),INDEX(Z$5:Z$501,MATCH($BE20,Z$5:Z$501,0),1),"") | BH20: =IF(ISNUMBER(MATCH($BE20,AA$5:AA$501,0)),INDEX(AA$5:AA$501,MATCH($BE20,AA$5:AA$501,0),1),"") | BI20: =IF(ISNUMBER(MATCH($BE20,AB$5:AB$501,0)),INDEX(AB$5:AB$501,MATCH($BE20,AB$5:AB$501,0),1),"") -> .lak.bud | BJ20: =IF(ISNUMBER(MATCH($BE20,AC$5:AC$501,0)),INDEX(AC$5:AC$501,MATCH($BE20,AC$5:AC$501,0),1),"") | BK20: =IF(ISNUMBER(MATCH($BE20,AD$5:AD$501,0)),INDEX(AD$5:AD$501,MATCH($BE20,AD$5:AD$501,0),1),"") | BL20: =IF(ISNUMBER(MATCH($BE20,AE$5:AE$501,0)),INDEX(AE$5:AE$501,MATCH($BE20,AE$5:AE$501,0),1),"") -> .lak.bud | BM20: =IF(ISNUMBER(MATCH($BE20,AF$5:AF$501,0)),INDEX(AF$5:AF$501,MATCH($BE20,AF$5:AF$501,0),1),"")
B21: =IF(ISNUMBER(MATCH(O21,$N$5:$N$1000,0)),MATCH(O21,$N$5:$N$1000,0),"") -> 15 | C21: =IF(ISNUMBER(B21),MAX(C$4:C20)+1,"") -> 12 | D21: =IF(IF(ISNUMBER(B21),"",MAX(D$4:D20)+1)<=D$3,IF(ISNUMBER(B21),"",MAX(D$4:D20)+1),"") | E21: =IF(M21<=D$3,MATCH(M21,D$5:D$1000,0),"") | F21: =IF(ISNUMBER(E21),INDEX($N$5:$N$1000,E21,1),"") | G21: =IF(ISNUMBER(C21),N21,IF(ISTEXT(N21),INDEX($F$5:$F$1000,MATCH(M21,$E$5:$E$1000,0),1),"")) -> .sfr | H21: =IF(O21="","",IF(ISNUMBER(MATCH(O21,$G$5:$G$1000,0)),"",IF(D21=1,C$3,0)+MAX(H$4:H20)+1)) | I21: =IF(O21="","",IF(ISNUMBER(MATCH(O21,$G$5:$G$1000,0)),"",IF(D21=1,B$4,0)+MAX(I$4:I20)+1)) | J21: =IF(ISNUMBER(MATCH(M21,$I$5:$I$1000,0)),INDEX($O$5:$O$1000,MATCH(M21,$I$5:$I$1000,0),1),"") | K21: =IF(P21="",0,1) -> 1 | M21: =IF(ROW()-ROW(M$4)<=1000,ROW()-ROW(M$4),"") -> 17 | N21: .sfr | O21: .npf | P21: =IF(M21<=$B$4,IF(ISTEXT(G21),G21,""),IF(ISTEXT(J21),J21,"")) -> .sfr | R21: =IF(ROW()-ROW(R$4)<=AH$3,ROW()-ROW(R$4),"") -> 17 | S21: =IF(ROW()-ROW(S$4)<=AI$3,ROW()-ROW(S$4),"") | T21: =IF(ROW()-ROW(T$4)<=AJ$3,ROW()-ROW(T$4),"") -> 17 | U21: =IF(ROW()-ROW(U$4)<=AK$3,ROW()-ROW(U$4),"") -> 17 | V21: =IF(ROW()-ROW(V$4)<=AL$3,ROW()-ROW(V$4),"") -> 17 | W21: =IF(ROW()-ROW(W$4)<=AM$3,ROW()-ROW(W$4),"") -> 17 | X21: =IF(ROW()-ROW(X$4)<=AN$3,ROW()-ROW(X$4),"") | Z21: =IF(ISNUMBER(R21),INDEX($BE$5:$BE$2999,MATCH(R21,AH$5:AH$2999,0),1),"") -> .cbc | AA21: =IF(ISNUMBER(S21),INDEX($BE$5:$BE$2999,MATCH(S21,AI$5:AI$2999,0),1),"") | AB21: =IF(ISNUMBER(T21),INDEX($BE$5:$BE$2999,MATCH(T21,AJ$5:AJ$2999,0),1),"") -> .uzf.obs | AC21: =IF(ISNUMBER(U21),INDEX($BE$5:$BE$2999,MATCH(U21,AK$5:AK$2999,0),1),"") -> .evta | AD21: =IF(ISNUMBER(V21),INDEX($BE$5:$BE$2999,MATCH(V21,AL$5:AL$2999,0),1),"") -> mfsim.nam | AE21: =IF(ISNUMBER(W21),INDEX($BE$5:$BE$2999,MATCH(W21,AM$5:AM$2999,0),1),"") -> .mvr.bud | AF21: =IF(ISNUMBER(X21),INDEX($BE$5:$BE$2999,MATCH(X21,AN$5:AN$2999,0),1),"") | AH21: =IF($BE21="","",IF(ISNUMBER(MATCH($BE21,AP$5:AP$29999,0)),MAX(AH$4:AH20)+1,0)) -> 0 | AI21: =IF($BE21="","",IF(ISNUMBER(MATCH($BE21,AQ$5:AQ$29999,0)),MAX(AI$4:AI20)+1,0)) -> 0 | AJ21: =IF($BE21="","",IF(ISNUMBER(MATCH($BE21,AR$5:AR$29999,0)),MAX(AJ$4:AJ20)+1,0)) -> 0 | AK21: =IF($BE21="","",IF(ISNUMBER(MATCH($BE21,AS$5:AS$29999,0)),MAX(AK$4:AK20)+1,0)) -> 0 | AL21: =IF($BE21="","",IF(ISNUMBER(MATCH($BE21,AT$5:AT$29999,0)),MAX(AL$4:AL20)+1,0)) -> 0 | AM21: =IF($BE21="","",IF(ISNUMBER(MATCH($BE21,AU$5:AU$29999,0)),MAX(AM$4:AM20)+1,0)) -> 15 | AN21: =IF($BE21="","",IF(ISNUMBER(MATCH($BE21,AV$5:AV$29999,0)),MAX(AN$4:AN20)+1,0)) -> 0 | AP21: .sto | AR21: .sfr | AS21: .oc | AT21: .npf | AU21: .rcha | AW21: .npf | AY21: .lak.bin | AZ21: .lak.bin | BB21: =IF(ISTEXT(AW21),IF(ISNUMBER(MATCH(AW21,$AY$5:$AY$100,0)),0,MAX(BB$4:BB20)+1),"") -> 0 | BC21: =IF(ISTEXT(AY21),MATCH(AY21,$AW$5:$AW$127,0),"") -> 26 | BD21: =IF(ISNUMBER(BC21),AY21,ROW()-SUM($BC$4:$BD$4)) -> .lak.bin | BE21: =IF(ISTEXT(AW21),IF(ISNUMBER(BC21),AY21,INDEX($AW$5:$AW$140,MATCH(BD21,$BB$5:$BB$185,0),1)),"") -> .lak.bin | BG21: =IF(ISNUMBER(MATCH($BE21,Z$5:Z$501,0)),INDEX(Z$5:Z$501,MATCH($BE21,Z$5:Z$501,0),1),"") | BH21: =IF(ISNUMBER(MATCH($BE21,AA$5:AA$501,0)),INDEX(AA$5:AA$501,MATCH($BE21,AA$5:AA$501,0),1),"") | BI21: =IF(ISNUMBER(MATCH($BE21,AB$5:AB$501,0)),INDEX(AB$5:AB$501,MATCH($BE21,AB$5:AB$501,0),1),"") | BJ21: =IF(ISNUMBER(MATCH($BE21,AC$5:AC$501,0)),INDEX(AC$5:AC$501,MATCH($BE21,AC$5:AC$501,0),1),"") | BK21: =IF(ISNUMBER(MATCH($BE21,AD$5:AD$501,0)),INDEX(AD$5:AD$501,MATCH($BE21,AD$5:AD$501,0),1),"") | BL21: =IF(ISNUMBER(MATCH($BE21,AE$5:AE$501,0)),INDEX(AE$5:AE$501,MATCH($BE21,AE$5:AE$501,0),1),"") -> .lak.bin | BM21: =IF(ISNUMBER(MATCH($BE21,AF$5:AF$501,0)),INDEX(AF$5:AF$501,MATCH($BE21,AF$5:AF$501,0),1),"")
