Workbook
Name a: #REF!
Name ai: #REF!
Name aq: #REF!
Name AV: #REF!
Name baa: #REF!
Name Coord: #REF!
Name CS: #REF!
Name CZ: #REF!
Name DG: #REF!
Name earlier: #REF!
Name EG: #REF!
Name EI: #REF!
Name HLinst: #REF!
Name HP: #REF!
Name I: #REF!
Name JA: #REF!
Name Mean_A: #REF!
Name mean_X: #REF!
Name mean_X.: #REF!
Name mean_Y: #REF!
Name mean_Y.: #REF!
Name mu: #REF!
Name mu_A: #REF!
Name mu_B: #REF!
Name P1_A: #REF!
Name P2_A: #REF!
Name P3_A: #REF!
Name P4_A: #REF!
Name P5_A: #REF!
Name Rot: #REF!
Name SD_A: #REF!
Name SD_X: #REF!
Name SD_Y: #REF!
Name sigma: #REF!
Name sigma_AB: #REF!
Name sigma2_A: #REF!
Name sigma2_B: #REF!
Name Tab.43: #REF!
Name Tab.44: #REF!
Name Target_P: #REF!
Name Total_Mass: #REF!
Name Variance_A: #REF!
Name X: #REF!
Name x_A: #REF!
Name x_B: #REF!
Name Xo: #REF!
Name Yo.1: #REF!
Name Yo.2: #REF!
Name yt: #REF!

Sheet Jocope
B1: out_toCSV | G1: =COUNT(Jocope!AZ6:AZ25) -> 20
B2: - | C2: 1 | D2: 2 | E2: 3 | G2: =COUNT(Jocope!BB5:CO5) -> 40 | CQ2: a5_temp | CR2: 1 | CS2: Tidal | CU2: 3 | CV2: 60 | CW2: Madson | CY2: Madson | DA2: Jacope
B3: ↓ | D3: ↓ | G3: =MAX(B6:B29)+1 -> 20 | CQ3: 1 | CR3: 120 | CS3: =SUM(CR$2:CR3) -> 121 | CU3: 58 | CV3: 60 | CW3: =CW107 -> 60 | CY3: II
B4: y Z | C4: i2 | D4: x | E4: va | G4: =MAX(D6:D29)+1 -> 40 | AZ4: K | CQ4: 2 | CR4: 120 | CS4: =SUM(CR$2:CR4) -> 241 | CU4: =CU2*CV2 -> 180 | CV4: =COUNT(CV6:CV108) -> 102 | CW4: MIN | CY4: cm/s | DB4: dia
B5: 0 | C5: 1 | D5: 2 | E5: 3 | I5: XY | J5: =J27 -> 1 | K5: =J5+1 -> 2 | L5: =K5+1 -> 3 | M5: =L5+1 -> 4 | N5: =M5+1 -> 5 | O5: =N5+1 -> 6 | P5: =O5+1 -> 7 | Q5: =P5+1 -> 8 | R5: =Q5+1 -> 9 | ... AW5: =AV5+1 -> 40 | AX5: 0 | AZ5: XY | BA5: =BA27 -> 0 | BB5: =BA5+1 -> 1 | BC5: =BB5+1 -> 2 | BD5: =BC5+1 -> 3 | BE5: =BD5+1 -> 4 | BF5: =BE5+1 -> 5 | BG5: =BF5+1 -> 6 | BH5: =BG5+1 -> 7 | BI5: =BH5+1 -> 8 | ... CN5: =CM5+1 -> 39 | CO5: 0 | CQ5: 3 | CR5: 120 | CS5: =SUM(CR$2:CR5) -> 361 | CU5: =CU3*CV3 -> 3480 | CW5: 60 | DB5: =60*60*24 -> 86400
A6: 1 | B6: 1 | C6: 0 | D6: 0 | E6: 0 | G6: =_xlfn.CONCAT(D6+1,",",B6+1) -> 1,2 | I6: 1 | J6: =IF(ISNUMBER(MATCH(J29,$G$25:$G$29,0)),$D$2,IF(ISNUMBER(MATCH(J29,$G$32:$G$33,0)),$E$2,IF(ISNUMBER(MATCH(J29,$G$6:$G$24,0)),$C$2,$B$2))) -> - | K6: =IF(ISNUMBER(MATCH(K29,$G$25:$G$29,0)),$D$2,IF(ISNUMBER(MATCH(K29,$G$32:$G$33,0)),$E$2,IF(ISNUMBER(MATCH(K29,$G$6:$G$24,0)),$C$2,$B$2))) -> - | L6: =IF(ISNUMBER(MATCH(L29,$G$25:$G$29,0)),$D$2,IF(ISNUMBER(MATCH(L29,$G$32:$G$33,0)),$E$2,IF(ISNUMBER(MATCH(L29,$G$6:$G$24,0)),$C$2,$B$2))) -> - | M6: =IF(ISNUMBER(MATCH(M29,$G$25:$G$29,0)),$D$2,IF(ISNUMBER(MATCH(M29,$G$32:$G$33,0)),$E$2,IF(ISNUMBER(MATCH(M29,$G$6:$G$24,0)),$C$2,$B$2))) -> - | N6: =IF(ISNUMBER(MATCH(N29,$G$25:$G$29,0)),$D$2,IF(ISNUMBER(MATCH(N29,$G$32:$G$33,0)),$E$2,IF(ISNUMBER(MATCH(N29,$G$6:$G$24,0)),$C$2,$B$2))) -> - | O6: =IF(ISNUMBER(MATCH(O29,$G$25:$G$29,0)),$D$2,IF(ISNUMBER(MATCH(O29,$G$32:$G$33,0)),$E$2,IF(ISNUMBER(MATCH(O29,$G$6:$G$24,0)),$C$2,$B$2))) -> - | P6: =IF(ISNUMBER(MATCH(P29,$G$25:$G$29,0)),$D$2,IF(ISNUMBER(MATCH(P29,$G$32:$G$33,0)),$E$2,IF(ISNUMBER(MATCH(P29,$G$6:$G$24,0)),$C$2,$B$2))) -> - | Q6: =IF(ISNUMBER(MATCH(Q29,$G$25:$G$29,0)),$D$2,IF(ISNUMBER(MATCH(Q29,$G$32:$G$33,0)),$E$2,IF(ISNUMBER(MATCH(Q29,$G$6:$G$24,0)),$C$2,$B$2))) -> - | ... AW6: =IF(ISNUMBER(MATCH(AW29,$G$25:$G$29,0)),$D$2,IF(ISNUMBER(MATCH(AW29,$G$32:$G$33,0)),$E$2,IF(ISNUMBER(MATCH(AW29,$G$6:$G$24,0)),$C$2,$B$2))) -> - | AX6: =AX5+1 -> 1 | AZ6: 0 | BA6: -2e+20 | BB6: -2e+20 | BC6: -2e+20 | BD6: -2e+20 | BE6: -2e+20 | BF6: -2e+20 | BG6: -2e+20 | BH6: -2e+20 | BI6: -2e+20 | BJ6: -2e+20 | BK6: -2e+20 | BL6: -2e+20 | BM6: -2e+20 | BN6: -2e+20 | BO6: -2e+20 | BP6: -2e+20 | BQ6: -2e+20 | BR6: -2e+20 | BS6: -2e+20 | BT6: -2e+20 | BU6: -2e+20 | BV6: -2e+20 | BW6: -2e+20 | BX6: -2e+20 | BY6: -2e+20 | BZ6: -2e+20 | CA6: -2e+20 | CB6: -2e+20 | CC6: -2e+20 | CD6: -2e+20 | CE6: -2e+20 | CF6: -2e+20 | CG6: -2e+20 | CH6: -2e+20 | CI6: -2e+20 | CJ6: -2e+20 | CK6: -2e+20 | CL6: -2e+20 | CM6: -2e+20 | CN6: -2e+20 | CO6: -2e+20 | CQ6: =_xlfn.IFS(CR6<=$CS$3,1,CR6<=$CS$4,2,CR6<=$CS$5,3) -> 1 | CR6: 1 | CS6: 1 | CU6: =IF(CV6<=CU$4,1,2) -> 1 | CV6: 0 | CW6: =IF(CV6=0,0,(CV6/CW$5)-1) -> 0 | CY6: 30 | DA6: 1 | DB6: 1 | 0 | DD6: 10800 | DE6: =Jocope!$DA$8/Jocope!DD6 -> 233760
A7: =A6+1 -> 2 | B7: 2 | C7: 0 | D7: 0 | E7: 0 | G7: =_xlfn.CONCAT(D7+1,",",B7+1) -> 1,3 | I7: =I6+1 -> 2 | J7: =IF(ISNUMBER(MATCH(J30,$G$25:$G$29,0)),$D$2,IF(ISNUMBER(MATCH(J30,$G$32:$G$33,0)),$E$2,IF(ISNUMBER(MATCH(J30,$G$6:$G$24,0)),$C$2,$B$2))) -> 1 | K7: =IF(ISNUMBER(MATCH(K30,$G$25:$G$29,0)),$D$2,IF(ISNUMBER(MATCH(K30,$G$32:$G$33,0)),$E$2,IF(ISNUMBER(MATCH(K30,$G$6:$G$24,0)),$C$2,$B$2))) -> - | L7: =IF(ISNUMBER(MATCH(L30,$G$25:$G$29,0)),$D$2,IF(ISNUMBER(MATCH(L30,$G$32:$G$33,0)),$E$2,IF(ISNUMBER(MATCH(L30,$G$6:$G$24,0)),$C$2,$B$2))) -> - | M7: =IF(ISNUMBER(MATCH(M30,$G$25:$G$29,0)),$D$2,IF(ISNUMBER(MATCH(M30,$G$32:$G$33,0)),$E$2,IF(ISNUMBER(MATCH(M30,$G$6:$G$24,0)),$C$2,$B$2))) -> - | N7: =IF(ISNUMBER(MATCH(N30,$G$25:$G$29,0)),$D$2,IF(ISNUMBER(MATCH(N30,$G$32:$G$33,0)),$E$2,IF(ISNUMBER(MATCH(N30,$G$6:$G$24,0)),$C$2,$B$2))) -> - | O7: =IF(ISNUMBER(MATCH(O30,$G$25:$G$29,0)),$D$2,IF(ISNUMBER(MATCH(O30,$G$32:$G$33,0)),$E$2,IF(ISNUMBER(MATCH(O30,$G$6:$G$24,0)),$C$2,$B$2))) -> - | P7: =IF(ISNUMBER(MATCH(P30,$G$25:$G$29,0)),$D$2,IF(ISNUMBER(MATCH(P30,$G$32:$G$33,0)),$E$2,IF(ISNUMBER(MATCH(P30,$G$6:$G$24,0)),$C$2,$B$2))) -> - | Q7: =IF(ISNUMBER(MATCH(Q30,$G$25:$G$29,0)),$D$2,IF(ISNUMBER(MATCH(Q30,$G$32:$G$33,0)),$E$2,IF(ISNUMBER(MATCH(Q30,$G$6:$G$24,0)),$C$2,$B$2))) -> - | ... AW7: =IF(ISNUMBER(MATCH(AW30,$G$25:$G$29,0)),$D$2,IF(ISNUMBER(MATCH(AW30,$G$32:$G$33,0)),$E$2,IF(ISNUMBER(MATCH(AW30,$G$6:$G$24,0)),$C$2,$B$2))) -> - | AX7: =AX6+1 -> 2 | AZ7: 1 | BA7: 500 | BB7: 498.99866 | BC7: 497.94836 | BD7: 496.87592 | BE7: 495.8187 | BF7: 494.91412 | BG7: -2e+20 | BH7: -2e+20 | BI7: -2e+20 | BJ7: -2e+20 | BK7: -2e+20 | BL7: -2e+20 | BM7: -2e+20 | BN7: -2e+20 | BO7: -2e+20 | BP7: -2e+20 | BQ7: -2e+20 | BR7: -2e+20 | BS7: -2e+20 | BT7: -2e+20 | BU7: -2e+20 | BV7: -2e+20 | BW7: -2e+20 | BX7: -2e+20 | BY7: -2e+20 | BZ7: -2e+20 | CA7: -2e+20 | CB7: -2e+20 | CC7: -2e+20 | CD7: -2e+20 | CE7: -2e+20 | CF7: -2e+20 | CG7: -2e+20 | CH7: -2e+20 | CI7: -2e+20 | CJ7: -2e+20 | CK7: -2e+20 | CL7: -2e+20 | CM7: -2e+20 | CN7: -2e+20 | CO7: -2e+20 | CQ7: =_xlfn.IFS(CR7<=$CS$3,1,CR7<=$CS$4,2,CR7<=$CS$5,3) -> 1 | CR7: =CR6+1 -> 2 | CS7: 1.0833333 | CU7: =IF(CV7<=CU$4,1,2) -> 1 | CV7: 36.6 | CW7: =IF(CV7=0,0,(CV7/CW$5)-1) -> -0.39 | CY7: 60 | DA7: 864001 | DB7: =DA7/DB$5 -> 10.000012 | DD7: 1728000 | DE7: =Jocope!$DA$8/Jocope!DD7 -> 1461
A8: =A7+1 -> 3 | B8: 3 | C8: 0 | D8: 0 | E8: 0 | G8: =_xlfn.CONCAT(D8+1,",",B8+1) -> 1,4 | I8: =I7+1 -> 3 | J8: =IF(ISNUMBER(MATCH(J31,$G$25:$G$29,0)),$D$2,IF(ISNUMBER(MATCH(J31,$G$32:$G$33,0)),$E$2,IF(ISNUMBER(MATCH(J31,$G$6:$G$24,0)),$C$2,$B$2))) -> 1 | K8: =IF(ISNUMBER(MATCH(K31,$G$25:$G$29,0)),$D$2,IF(ISNUMBER(MATCH(K31,$G$32:$G$33,0)),$E$2,IF(ISNUMBER(MATCH(K31,$G$6:$G$24,0)),$C$2,$B$2))) -> - | L8: =IF(ISNUMBER(MATCH(L31,$G$25:$G$29,0)),$D$2,IF(ISNUMBER(MATCH(L31,$G$32:$G$33,0)),$E$2,IF(ISNUMBER(MATCH(L31,$G$6:$G$24,0)),$C$2,$B$2))) -> - | M8: =IF(ISNUMBER(MATCH(M31,$G$25:$G$29,0)),$D$2,IF(ISNUMBER(MATCH(M31,$G$32:$G$33,0)),$E$2,IF(ISNUMBER(MATCH(M31,$G$6:$G$24,0)),$C$2,$B$2))) -> - | N8: =IF(ISNUMBER(MATCH(N31,$G$25:$G$29,0)),$D$2,IF(ISNUMBER(MATCH(N31,$G$32:$G$33,0)),$E$2,IF(ISNUMBER(MATCH(N31,$G$6:$G$24,0)),$C$2,$B$2))) -> - | O8: =IF(ISNUMBER(MATCH(O31,$G$25:$G$29,0)),$D$2,IF(ISNUMBER(MATCH(O31,$G$32:$G$33,0)),$E$2,IF(ISNUMBER(MATCH(O31,$G$6:$G$24,0)),$C$2,$B$2))) -> - | P8: =IF(ISNUMBER(MATCH(P31,$G$25:$G$29,0)),$D$2,IF(ISNUMBER(MATCH(P31,$G$32:$G$33,0)),$E$2,IF(ISNUMBER(MATCH(P31,$G$6:$G$24,0)),$C$2,$B$2))) -> - | Q8: =IF(ISNUMBER(MATCH(Q31,$G$25:$G$29,0)),$D$2,IF(ISNUMBER(MATCH(Q31,$G$32:$G$33,0)),$E$2,IF(ISNUMBER(MATCH(Q31,$G$6:$G$24,0)),$C$2,$B$2))) -> - | ... AW8: =IF(ISNUMBER(MATCH(AW31,$G$25:$G$29,0)),$D$2,IF(ISNUMBER(MATCH(AW31,$G$32:$G$33,0)),$E$2,IF(ISNUMBER(MATCH(AW31,$G$6:$G$24,0)),$C$2,$B$2))) -> - | AX8: =AX7+1 -> 3 | AZ8: 2 | BA8: 500 | BB8: 498.93973 | BC8: 497.86237 | BD8: 496.771 | BE8: 495.67285 | BF8: 494.5547 | BG8: 493.1801 | BH8: 491.91226 | BI8: 490.7233 | BJ8: 489.60666 | BK8: 488.56424 | BL8: 487.73605 | BM8: -2e+20 | BN8: -2e+20 | BO8: -2e+20 | BP8: -2e+20 | BQ8: -2e+20 | BR8: -2e+20 | BS8: -2e+20 | BT8: -2e+20 | BU8: -2e+20 | BV8: -2e+20 | BW8: -2e+20 | BX8: -2e+20 | BY8: -2e+20 | BZ8: -2e+20 | CA8: -2e+20 | CB8: -2e+20 | CC8: -2e+20 | CD8: -2e+20 | CE8: -2e+20 | CF8: -2e+20 | CG8: -2e+20 | CH8: -2e+20 | CI8: -2e+20 | CJ8: -2e+20 | CK8: -2e+20 | CL8: -2e+20 | CM8: -2e+20 | CN8: -2e+20 | CO8: -2e+20 | CQ8: =_xlfn.IFS(CR8<=$CS$3,1,CR8<=$CS$4,2,CR8<=$CS$5,3) -> 1 | CR8: =CR7+1 -> 3 | CS8: 1.1666667 | CU8: =IF(CV8<=CU$4,1,2) -> 1 | CV8: 73.2 | CW8: =IF(CV8=0,0,(CV8/CW$5)-1) -> 0.22 | CY8: 90 | DA8: 2524608000 | DB8: =DA8/DB$5 -> 29220 | DD8: 4320000 | DE8: =Jocope!$DA$8/Jocope!DD8 -> 584.4
A9: =A8+1 -> 4 | B9: 4 | C9: 0 | D9: 0 | E9: 0 | G9: =_xlfn.CONCAT(D9+1,",",B9+1) -> 1,5 | I9: =I8+1 -> 4 | J9: =IF(ISNUMBER(MATCH(J32,$G$25:$G$29,0)),$D$2,IF(ISNUMBER(MATCH(J32,$G$32:$G$33,0)),$E$2,IF(ISNUMBER(MATCH(J32,$G$6:$G$24,0)),$C$2,$B$2))) -> 1 | K9: =IF(ISNUMBER(MATCH(K32,$G$25:$G$29,0)),$D$2,IF(ISNUMBER(MATCH(K32,$G$32:$G$33,0)),$E$2,IF(ISNUMBER(MATCH(K32,$G$6:$G$24,0)),$C$2,$B$2))) -> - | L9: =IF(ISNUMBER(MATCH(L32,$G$25:$G$29,0)),$D$2,IF(ISNUMBER(MATCH(L32,$G$32:$G$33,0)),$E$2,IF(ISNUMBER(MATCH(L32,$G$6:$G$24,0)),$C$2,$B$2))) -> - | M9: =IF(ISNUMBER(MATCH(M32,$G$25:$G$29,0)),$D$2,IF(ISNUMBER(MATCH(M32,$G$32:$G$33,0)),$E$2,IF(ISNUMBER(MATCH(M32,$G$6:$G$24,0)),$C$2,$B$2))) -> - | N9: =IF(ISNUMBER(MATCH(N32,$G$25:$G$29,0)),$D$2,IF(ISNUMBER(MATCH(N32,$G$32:$G$33,0)),$E$2,IF(ISNUMBER(MATCH(N32,$G$6:$G$24,0)),$C$2,$B$2))) -> - | O9: =IF(ISNUMBER(MATCH(O32,$G$25:$G$29,0)),$D$2,IF(ISNUMBER(MATCH(O32,$G$32:$G$33,0)),$E$2,IF(ISNUMBER(MATCH(O32,$G$6:$G$24,0)),$C$2,$B$2))) -> - | P9: =IF(ISNUMBER(MATCH(P32,$G$25:$G$29,0)),$D$2,IF(ISNUMBER(MATCH(P32,$G$32:$G$33,0)),$E$2,IF(ISNUMBER(MATCH(P32,$G$6:$G$24,0)),$C$2,$B$2))) -> - | Q9: =IF(ISNUMBER(MATCH(Q32,$G$25:$G$29,0)),$D$2,IF(ISNUMBER(MATCH(Q32,$G$32:$G$33,0)),$E$2,IF(ISNUMBER(MATCH(Q32,$G$6:$G$24,0)),$C$2,$B$2))) -> - | ... AW9: =IF(ISNUMBER(MATCH(AW32,$G$25:$G$29,0)),$D$2,IF(ISNUMBER(MATCH(AW32,$G$32:$G$33,0)),$E$2,IF(ISNUMBER(MATCH(AW32,$G$6:$G$24,0)),$C$2,$B$2))) -> - | AX9: =AX8+1 -> 4 | AZ9: 3 | BA9: 500 | BB9: 498.89484 | BC9: 497.78058 | BD9: 496.65338 | BE9: 495.5085 | BF9: 494.3291 | BG9: 493.0734 | BH9: 491.8334 | BI9: 490.6285 | BJ9: 489.45935 | BK9: 488.31296 | BL9: 487.139 | BM9: 485.6169 | BN9: 484.25302 | BO9: 483.0116 | BP9: 481.92758 | BQ9: 481.14746 | BR9: -2e+20 | BS9: -2e+20 | BT9: -2e+20 | BU9: -2e+20 | BV9: -2e+20 | BW9: -2e+20 | BX9: -2e+20 | BY9: -2e+20 | BZ9: -2e+20 | CA9: -2e+20 | CB9: -2e+20 | CC9: -2e+20 | CD9: -2e+20 | CE9: -2e+20 | CF9: -2e+20 | CG9: -2e+20 | CH9: -2e+20 | CI9: -2e+20 | CJ9: -2e+20 | CK9: -2e+20 | CL9: -2e+20 | CM9: -2e+20 | CN9: -2e+20 | CO9: -2e+20 | CQ9: =_xlfn.IFS(CR9<=$CS$3,1,CR9<=$CS$4,2,CR9<=$CS$5,3) -> 1 | CR9: =CR8+1 -> 4 | CS9: 1.25 | CU9: =IF(CV9<=CU$4,1,2) -> 1 | CV9: 109.8 | CW9: =IF(CV9=0,0,(CV9/CW$5)-1) -> 0.83 | CY9: 120 | DD9: 7776000 | DE9: =Jocope!$DA$8/Jocope!DD9 -> 324.66667
A10: =A9+1 -> 5 | B10: 5 | C10: 0 | D10: 0 | E10: 0 | G10: =_xlfn.CONCAT(D10+1,",",B10+1) -> 1,6 | I10: =I9+1 -> 5 | J10: =IF(ISNUMBER(MATCH(J33,$G$25:$G$29,0)),$D$2,IF(ISNUMBER(MATCH(J33,$G$32:$G$33,0)),$E$2,IF(ISNUMBER(MATCH(J33,$G$6:$G$24,0)),$C$2,$B$2))) -> 1 | K10: =IF(ISNUMBER(MATCH(K33,$G$25:$G$29,0)),$D$2,IF(ISNUMBER(MATCH(K33,$G$32:$G$33,0)),$E$2,IF(ISNUMBER(MATCH(K33,$G$6:$G$24,0)),$C$2,$B$2))) -> - | L10: =IF(ISNUMBER(MATCH(L33,$G$25:$G$29,0)),$D$2,IF(ISNUMBER(MATCH(L33,$G$32:$G$33,0)),$E$2,IF(ISNUMBER(MATCH(L33,$G$6:$G$24,0)),$C$2,$B$2))) -> - | M10: =IF(ISNUMBER(MATCH(M33,$G$25:$G$29,0)),$D$2,IF(ISNUMBER(MATCH(M33,$G$32:$G$33,0)),$E$2,IF(ISNUMBER(MATCH(M33,$G$6:$G$24,0)),$C$2,$B$2))) -> - | N10: =IF(ISNUMBER(MATCH(N33,$G$25:$G$29,0)),$D$2,IF(ISNUMBER(MATCH(N33,$G$32:$G$33,0)),$E$2,IF(ISNUMBER(MATCH(N33,$G$6:$G$24,0)),$C$2,$B$2))) -> - | O10: =IF(ISNUMBER(MATCH(O33,$G$25:$G$29,0)),$D$2,IF(ISNUMBER(MATCH(O33,$G$32:$G$33,0)),$E$2,IF(ISNUMBER(MATCH(O33,$G$6:$G$24,0)),$C$2,$B$2))) -> - | P10: =IF(ISNUMBER(MATCH(P33,$G$25:$G$29,0)),$D$2,IF(ISNUMBER(MATCH(P33,$G$32:$G$33,0)),$E$2,IF(ISNUMBER(MATCH(P33,$G$6:$G$24,0)),$C$2,$B$2))) -> - | Q10: =IF(ISNUMBER(MATCH(Q33,$G$25:$G$29,0)),$D$2,IF(ISNUMBER(MATCH(Q33,$G$32:$G$33,0)),$E$2,IF(ISNUMBER(MATCH(Q33,$G$6:$G$24,0)),$C$2,$B$2))) -> - | ... AW10: =IF(ISNUMBER(MATCH(AW33,$G$25:$G$29,0)),$D$2,IF(ISNUMBER(MATCH(AW33,$G$32:$G$33,0)),$E$2,IF(ISNUMBER(MATCH(AW33,$G$6:$G$24,0)),$C$2,$B$2))) -> - | AX10: =AX9+1 -> 5 | AZ10: 4 | BA10: 500 | BB10: 498.85898 | BC10: 497.71176 | BD10: 496.55344 | BE10: 495.3787 | BF10: 494.17975 | BG10: 492.951 | BH10: 491.71945 | BI10: 490.49805 | BJ10: 489.28625 | BK10: 488.06985 | BL10: 486.81393 | BM10: 485.45868 | BN10: 484.13055 | BO10: 482.85416 | BP10: 481.62372 | BQ10: 480.3673 | BR10: 478.70035 | BS10: 477.20154 | BT10: 475.81226 | BU10: 474.53064 | BV10: 473.4053 | BW10: 472.59357 | BX10: -2e+20 | BY10: -2e+20 | BZ10: -2e+20 | CA10: -2e+20 | CB10: -2e+20 | CC10: -2e+20 | CD10: -2e+20 | CE10: -2e+20 | CF10: -2e+20 | CG10: -2e+20 | CH10: -2e+20 | CI10: -2e+20 | CJ10: -2e+20 | CK10: -2e+20 | CL10: -2e+20 | CM10: -2e+20 | CN10: -2e+20 | CO10: -2e+20 | CQ10: =_xlfn.IFS(CR10<=$CS$3,1,CR10<=$CS$4,2,CR10<=$CS$5,3) -> 1 | CR10: =CR9+1 -> 5 | CS10: 1.3333333 | CU10: =IF(CV10<=CU$4,1,2) -> 1 | CV10: 146.4 | CW10: =IF(CV10=0,0,(CV10/CW$5)-1) -> 1.44 | CY10: 150 | DD10: 15552000 | DE10: =Jocope!$DA$8/Jocope!DD10 -> 162.33333
A11: =A10+1 -> 6 | B11: 6 | C11: 0 | D11: 0 | E11: 0 | G11: =_xlfn.CONCAT(D11+1,",",B11+1) -> 1,7 | I11: =I10+1 -> 6 | J11: =IF(ISNUMBER(MATCH(J34,$G$25:$G$29,0)),$D$2,IF(ISNUMBER(MATCH(J34,$G$32:$G$33,0)),$E$2,IF(ISNUMBER(MATCH(J34,$G$6:$G$24,0)),$C$2,$B$2))) -> 1 | K11: =IF(ISNUMBER(MATCH(K34,$G$25:$G$29,0)),$D$2,IF(ISNUMBER(MATCH(K34,$G$32:$G$33,0)),$E$2,IF(ISNUMBER(MATCH(K34,$G$6:$G$24,0)),$C$2,$B$2))) -> - | L11: =IF(ISNUMBER(MATCH(L34,$G$25:$G$29,0)),$D$2,IF(ISNUMBER(MATCH(L34,$G$32:$G$33,0)),$E$2,IF(ISNUMBER(MATCH(L34,$G$6:$G$24,0)),$C$2,$B$2))) -> - | M11: =IF(ISNUMBER(MATCH(M34,$G$25:$G$29,0)),$D$2,IF(ISNUMBER(MATCH(M34,$G$32:$G$33,0)),$E$2,IF(ISNUMBER(MATCH(M34,$G$6:$G$24,0)),$C$2,$B$2))) -> - | N11: =IF(ISNUMBER(MATCH(N34,$G$25:$G$29,0)),$D$2,IF(ISNUMBER(MATCH(N34,$G$32:$G$33,0)),$E$2,IF(ISNUMBER(MATCH(N34,$G$6:$G$24,0)),$C$2,$B$2))) -> - | O11: =IF(ISNUMBER(MATCH(O34,$G$25:$G$29,0)),$D$2,IF(ISNUMBER(MATCH(O34,$G$32:$G$33,0)),$E$2,IF(ISNUMBER(MATCH(O34,$G$6:$G$24,0)),$C$2,$B$2))) -> - | P11: =IF(ISNUMBER(MATCH(P34,$G$25:$G$29,0)),$D$2,IF(ISNUMBER(MATCH(P34,$G$32:$G$33,0)),$E$2,IF(ISNUMBER(MATCH(P34,$G$6:$G$24,0)),$C$2,$B$2))) -> - | Q11: =IF(ISNUMBER(MATCH(Q34,$G$25:$G$29,0)),$D$2,IF(ISNUMBER(MATCH(Q34,$G$32:$G$33,0)),$E$2,IF(ISNUMBER(MATCH(Q34,$G$6:$G$24,0)),$C$2,$B$2))) -> - | ... AW11: =IF(ISNUMBER(MATCH(AW34,$G$25:$G$29,0)),$D$2,IF(ISNUMBER(MATCH(AW34,$G$32:$G$33,0)),$E$2,IF(ISNUMBER(MATCH(AW34,$G$6:$G$24,0)),$C$2,$B$2))) -> - | AX11: =AX10+1 -> 6 | AZ11: 5 | BA11: 500 | BB11: 498.8293 | BC11: 497.65402 | BD11: 496.4699 | BE11: 495.2731 | BF11: 494.06024 | BG11: 492.83136 | BH11: 491.5954 | BI11: 490.35794 | BJ11: 489.1178 | BK11: 487.8662 | BL11: 486.5882 | BM11: 485.2733 | BN11: 483.9564 | BO11: 482.6508 | BP11: 481.3458 | BQ11: 479.99777 | BR11: 478.53214 | BS11: 477.09204 | BT11: 475.7046 | BU11: 474.37433 | BV11: 473.0917 | BW11: 471.78183 | BX11: 470.04443 | BY11: 468.48282 | BZ11: 467.03653 | CA11: 465.70392 | CB11: 464.53574 | CC11: 463.6947 | CD11: -2e+20 | CE11: -2e+20 | CF11: -2e+20 | CG11: -2e+20 | CH11: -2e+20 | CI11: -2e+20 | CJ11: -2e+20 | CK11: -2e+20 | CL11: -2e+20 | CM11: -2e+20 | CN11: -2e+20 | CO11: -2e+20 | CQ11: =_xlfn.IFS(CR11<=$CS$3,1,CR11<=$CS$4,2,CR11<=$CS$5,3) -> 1 | CR11: =CR10+1 -> 6 | CS11: 1.4166667 | CU11: =IF(CV11<=CU$4,1,2) -> 1 | CV11: 180 | CW11: =IF(CV11=0,0,(CV11/CW$5)-1) -> 2 | CY11: 180 | DA11: ? | DB11: 365 | DD11: 31536000 | DE11: =Jocope!$DA$8/Jocope!DD11 -> 80.054795
A12: =A11+1 -> 7 | B12: 7 | C12: 0 | D12: 0 | E12: 0 | G12: =_xlfn.CONCAT(D12+1,",",B12+1) -> 1,8 | I12: =I11+1 -> 7 | J12: =IF(ISNUMBER(MATCH(J35,$G$25:$G$29,0)),$D$2,IF(ISNUMBER(MATCH(J35,$G$32:$G$33,0)),$E$2,IF(ISNUMBER(MATCH(J35,$G$6:$G$24,0)),$C$2,$B$2))) -> 1 | K12: =IF(ISNUMBER(MATCH(K35,$G$25:$G$29,0)),$D$2,IF(ISNUMBER(MATCH(K35,$G$32:$G$33,0)),$E$2,IF(ISNUMBER(MATCH(K35,$G$6:$G$24,0)),$C$2,$B$2))) -> - | L12: =IF(ISNUMBER(MATCH(L35,$G$25:$G$29,0)),$D$2,IF(ISNUMBER(MATCH(L35,$G$32:$G$33,0)),$E$2,IF(ISNUMBER(MATCH(L35,$G$6:$G$24,0)),$C$2,$B$2))) -> - | M12: =IF(ISNUMBER(MATCH(M35,$G$25:$G$29,0)),$D$2,IF(ISNUMBER(MATCH(M35,$G$32:$G$33,0)),$E$2,IF(ISNUMBER(MATCH(M35,$G$6:$G$24,0)),$C$2,$B$2))) -> - | N12: =IF(ISNUMBER(MATCH(N35,$G$25:$G$29,0)),$D$2,IF(ISNUMBER(MATCH(N35,$G$32:$G$33,0)),$E$2,IF(ISNUMBER(MATCH(N35,$G$6:$G$24,0)),$C$2,$B$2))) -> - | O12: =IF(ISNUMBER(MATCH(O35,$G$25:$G$29,0)),$D$2,IF(ISNUMBER(MATCH(O35,$G$32:$G$33,0)),$E$2,IF(ISNUMBER(MATCH(O35,$G$6:$G$24,0)),$C$2,$B$2))) -> - | P12: =IF(ISNUMBER(MATCH(P35,$G$25:$G$29,0)),$D$2,IF(ISNUMBER(MATCH(P35,$G$32:$G$33,0)),$E$2,IF(ISNUMBER(MATCH(P35,$G$6:$G$24,0)),$C$2,$B$2))) -> - | Q12: =IF(ISNUMBER(MATCH(Q35,$G$25:$G$29,0)),$D$2,IF(ISNUMBER(MATCH(Q35,$G$32:$G$33,0)),$E$2,IF(ISNUMBER(MATCH(Q35,$G$6:$G$24,0)),$C$2,$B$2))) -> - | ... AW12: =IF(ISNUMBER(MATCH(AW35,$G$25:$G$29,0)),$D$2,IF(ISNUMBER(MATCH(AW35,$G$32:$G$33,0)),$E$2,IF(ISNUMBER(MATCH(AW35,$G$6:$G$24,0)),$C$2,$B$2))) -> - | AX12: =AX11+1 -> 7 | AZ12: 6 | BA12: 500 | BB12: 498.8043 | BC12: 497.60507 | BD12: 496.39908 | BE12: 495.18356 | BF12: 493.95673 | BG12: 492.71884 | BH12: 491.4728 | BI12: 490.22055 | BJ12: 488.96082 | BK12: 487.68906 | BL12: 486.3993 | BM12: 485.0899 | BN12: 483.77094 | BO12: 482.44684 | BP12: 481.1109 | BQ12: 479.7458 | BR12: 478.33847 | BS12: 476.92984 | BT12: 475.53976 | BU12: 474.17035 | BV12: 472.80542 | BW12: 471.39758 | BX12: 469.86865 | BY12: 468.36752 | BZ12: 466.92282 | CA12: 465.53955 | CB12: 464.20853 | CC12: 462.8537 | CD12: 461.065 | CE12: 459.47372 | CF12: 458.03204 | CG12: 456.77722 | CH12: 455.87616 | CI12: -2e+20 | CJ12: -2e+20 | CK12: -2e+20 | CL12: -2e+20 | CM12: -2e+20 | CN12: -2e+20 | CO12: -2e+20 | CQ12: =_xlfn.IFS(CR12<=$CS$3,1,CR12<=$CS$4,2,CR12<=$CS$5,3) -> 1 | CR12: =CR11+1 -> 7 | CS12: 1.5 | CU12: =IF(CV12<=CU$4,1,2) -> 2 | CV12: 183 | CW12: =IF(CV12=0,0,(CV12/CW$5)-1) -> 2.05 | CY12: 216.25 | DA12: =DA8/DA7 -> 2921.9966 | DB12: =DB8/DB11 -> 80.054795 | DD12: 94672800 | DE12: =Jocope!$DA$8/Jocope!DD12 -> 26.666667
A13: =A12+1 -> 8 | B13: 8 | C13: 0 | D13: 0 | E13: 0 | G13: =_xlfn.CONCAT(D13+1,",",B13+1) -> 1,9 | I13: =I12+1 -> 8 | J13: =IF(ISNUMBER(MATCH(J36,$G$25:$G$29,0)),$D$2,IF(ISNUMBER(MATCH(J36,$G$32:$G$33,0)),$E$2,IF(ISNUMBER(MATCH(J36,$G$6:$G$24,0)),$C$2,$B$2))) -> 1 | K13: =IF(ISNUMBER(MATCH(K36,$G$25:$G$29,0)),$D$2,IF(ISNUMBER(MATCH(K36,$G$32:$G$33,0)),$E$2,IF(ISNUMBER(MATCH(K36,$G$6:$G$24,0)),$C$2,$B$2))) -> - | L13: =IF(ISNUMBER(MATCH(L36,$G$25:$G$29,0)),$D$2,IF(ISNUMBER(MATCH(L36,$G$32:$G$33,0)),$E$2,IF(ISNUMBER(MATCH(L36,$G$6:$G$24,0)),$C$2,$B$2))) -> - | M13: =IF(ISNUMBER(MATCH(M36,$G$25:$G$29,0)),$D$2,IF(ISNUMBER(MATCH(M36,$G$32:$G$33,0)),$E$2,IF(ISNUMBER(MATCH(M36,$G$6:$G$24,0)),$C$2,$B$2))) -> - | N13: =IF(ISNUMBER(MATCH(N36,$G$25:$G$29,0)),$D$2,IF(ISNUMBER(MATCH(N36,$G$32:$G$33,0)),$E$2,IF(ISNUMBER(MATCH(N36,$G$6:$G$24,0)),$C$2,$B$2))) -> - | O13: =IF(ISNUMBER(MATCH(O36,$G$25:$G$29,0)),$D$2,IF(ISNUMBER(MATCH(O36,$G$32:$G$33,0)),$E$2,IF(ISNUMBER(MATCH(O36,$G$6:$G$24,0)),$C$2,$B$2))) -> - | P13: =IF(ISNUMBER(MATCH(P36,$G$25:$G$29,0)),$D$2,IF(ISNUMBER(MATCH(P36,$G$32:$G$33,0)),$E$2,IF(ISNUMBER(MATCH(P36,$G$6:$G$24,0)),$C$2,$B$2))) -> - | Q13: =IF(ISNUMBER(MATCH(Q36,$G$25:$G$29,0)),$D$2,IF(ISNUMBER(MATCH(Q36,$G$32:$G$33,0)),$E$2,IF(ISNUMBER(MATCH(Q36,$G$6:$G$24,0)),$C$2,$B$2))) -> - | ... AW13: =IF(ISNUMBER(MATCH(AW36,$G$25:$G$29,0)),$D$2,IF(ISNUMBER(MATCH(AW36,$G$32:$G$33,0)),$E$2,IF(ISNUMBER(MATCH(AW36,$G$6:$G$24,0)),$C$2,$B$2))) -> - | AX13: =AX12+1 -> 8 | AZ13: 7 | BA13: 500 | BB13: 498.7828 | BC13: 497.5629 | BD13: 496.33774 | BE13: 495.10532 | BF13: 493.86432 | BG13: 492.61444 | BH13: 491.35645 | BI13: 490.09058 | BJ13: 488.81586 | BK13: 487.52985 | BL13: 486.23007 | BM13: 484.91605 | BN13: 483.5906 | BO13: 482.25473 | BP13: 480.90515 | BQ13: 479.536 | BR13: 478.14615 | BS13: 476.74908 | BT13: 475.35425 | BU13: 473.96194 | BV13: 472.56195 | BW13: 471.1345 | BX13: 469.66504 | BY13: 468.19586 | BZ13: 466.74765 | CA13: 465.32288 | CB13: 463.90518 | CC13: 462.44653 | CD13: 460.86758 | CE13: 459.3241 | CF13: 457.8452 | CG13: 456.42346 | CH13: 454.97507 | CI13: 453.0561 | CJ13: 451.3337 | CK13: 449.7392 | CL13: 448.26962 | CM13: 446.98007 | CN13: 446.0503 | CO13: -2e+20 | CQ13: =_xlfn.IFS(CR13<=$CS$3,1,CR13<=$CS$4,2,CR13<=$CS$5,3) -> 1 | CR13: =CR12+1 -> 8 | CS13: 1.5833333 | CU13: =IF(CV13<=CU$4,1,2) -> 2 | CV13: 219.6 | CW13: =IF(CV13=0,0,(CV13/CW$5)-1) -> 2.66 | CY13: 252.5 | DD13: 157788000 | DE13: =Jocope!$DA$8/Jocope!DD13 -> 16
A14: =A13+1 -> 9 | B14: 9 | C14: 0 | D14: 0 | E14: 0 | G14: =_xlfn.CONCAT(D14+1,",",B14+1) -> 1,10 | I14: =I13+1 -> 9 | J14: =IF(ISNUMBER(MATCH(J37,$G$25:$G$29,0)),$D$2,IF(ISNUMBER(MATCH(J37,$G$32:$G$33,0)),$E$2,IF(ISNUMBER(MATCH(J37,$G$6:$G$24,0)),$C$2,$B$2))) -> 1 | K14: =IF(ISNUMBER(MATCH(K37,$G$25:$G$29,0)),$D$2,IF(ISNUMBER(MATCH(K37,$G$32:$G$33,0)),$E$2,IF(ISNUMBER(MATCH(K37,$G$6:$G$24,0)),$C$2,$B$2))) -> - | L14: =IF(ISNUMBER(MATCH(L37,$G$25:$G$29,0)),$D$2,IF(ISNUMBER(MATCH(L37,$G$32:$G$33,0)),$E$2,IF(ISNUMBER(MATCH(L37,$G$6:$G$24,0)),$C$2,$B$2))) -> - | M14: =IF(ISNUMBER(MATCH(M37,$G$25:$G$29,0)),$D$2,IF(ISNUMBER(MATCH(M37,$G$32:$G$33,0)),$E$2,IF(ISNUMBER(MATCH(M37,$G$6:$G$24,0)),$C$2,$B$2))) -> - | N14: =IF(ISNUMBER(MATCH(N37,$G$25:$G$29,0)),$D$2,IF(ISNUMBER(MATCH(N37,$G$32:$G$33,0)),$E$2,IF(ISNUMBER(MATCH(N37,$G$6:$G$24,0)),$C$2,$B$2))) -> - | O14: =IF(ISNUMBER(MATCH(O37,$G$25:$G$29,0)),$D$2,IF(ISNUMBER(MATCH(O37,$G$32:$G$33,0)),$E$2,IF(ISNUMBER(MATCH(O37,$G$6:$G$24,0)),$C$2,$B$2))) -> - | P14: =IF(ISNUMBER(MATCH(P37,$G$25:$G$29,0)),$D$2,IF(ISNUMBER(MATCH(P37,$G$32:$G$33,0)),$E$2,IF(ISNUMBER(MATCH(P37,$G$6:$G$24,0)),$C$2,$B$2))) -> - | Q14: =IF(ISNUMBER(MATCH(Q37,$G$25:$G$29,0)),$D$2,IF(ISNUMBER(MATCH(Q37,$G$32:$G$33,0)),$E$2,IF(ISNUMBER(MATCH(Q37,$G$6:$G$24,0)),$C$2,$B$2))) -> - | ... AW14: =IF(ISNUMBER(MATCH(AW37,$G$25:$G$29,0)),$D$2,IF(ISNUMBER(MATCH(AW37,$G$32:$G$33,0)),$E$2,IF(ISNUMBER(MATCH(AW37,$G$6:$G$24,0)),$C$2,$B$2))) -> - | AX14: =AX13+1 -> 9 | AZ14: 8 | BA14: 500 | BB14: 498.76404 | BC14: 497.52594 | BD14: 496.28372 | BE14: 495.03568 | BF14: 493.7807 | BG14: 492.5182 | BH14: 491.24792 | BI14: 489.96954 | BJ14: 488.68216 | BK14: 487.38443 | BL14: 486.07504 | BM14: 484.75363 | BN14: 483.42075 | BO14: 482.07632 | BP14: 480.719 | BQ14: 479.34695 | BR14: 477.96097 | BS14: 476.56607 | BT14: 475.16623 | BU14: 473.7612 | BV14: 472.346 | BW14: 470.91333 | BX14: 469.46115 | BY14: 468.0032 | BZ14: 466.54907 | CA14: 465.0991 | CB14: 463.6428 | CC14: 462.15973 | CD14: 460.6347 | CE14: 459.10986 | CF14: 457.60126 | CG14: 456.09637 | CH14: 454.5446 | CI14: 452.85953 | CJ14: 451.20584 | CK14: 449.6143 | CL14: 448.08957 | CM14: 446.62033 | CN14: 445.12048 | CO14: 443.1315 | CQ14: =_xlfn.IFS(CR14<=$CS$3,1,CR14<=$CS$4,2,CR14<=$CS$5,3) -> 1 | CR14: =CR13+1 -> 9 | CS14: 1.6666667 | CU14: =IF(CV14<=CU$4,1,2) -> 2 | CV14: 256.2 | CW14: =IF(CV14=0,0,(CV14/CW$5)-1) -> 3.27 | CY14: 288.75 | DD14: 220903200 | DE14: =Jocope!$DA$8/Jocope!DD14 -> 11.428571
A15: =A14+1 -> 10 | B15: 10 | C15: 0 | D15: 0 | E15: 0 | G15: =_xlfn.CONCAT(D15+1,",",B15+1) -> 1,11 | I15: =I14+1 -> 10 | J15: =IF(ISNUMBER(MATCH(J38,$G$25:$G$29,0)),$D$2,IF(ISNUMBER(MATCH(J38,$G$32:$G$33,0)),$E$2,IF(ISNUMBER(MATCH(J38,$G$6:$G$24,0)),$C$2,$B$2))) -> 1 | K15: =IF(ISNUMBER(MATCH(K38,$G$25:$G$29,0)),$D$2,IF(ISNUMBER(MATCH(K38,$G$32:$G$33,0)),$E$2,IF(ISNUMBER(MATCH(K38,$G$6:$G$24,0)),$C$2,$B$2))) -> - | L15: =IF(ISNUMBER(MATCH(L38,$G$25:$G$29,0)),$D$2,IF(ISNUMBER(MATCH(L38,$G$32:$G$33,0)),$E$2,IF(ISNUMBER(MATCH(L38,$G$6:$G$24,0)),$C$2,$B$2))) -> - | M15: =IF(ISNUMBER(MATCH(M38,$G$25:$G$29,0)),$D$2,IF(ISNUMBER(MATCH(M38,$G$32:$G$33,0)),$E$2,IF(ISNUMBER(MATCH(M38,$G$6:$G$24,0)),$C$2,$B$2))) -> - | N15: =IF(ISNUMBER(MATCH(N38,$G$25:$G$29,0)),$D$2,IF(ISNUMBER(MATCH(N38,$G$32:$G$33,0)),$E$2,IF(ISNUMBER(MATCH(N38,$G$6:$G$24,0)),$C$2,$B$2))) -> - | O15: =IF(ISNUMBER(MATCH(O38,$G$25:$G$29,0)),$D$2,IF(ISNUMBER(MATCH(O38,$G$32:$G$33,0)),$E$2,IF(ISNUMBER(MATCH(O38,$G$6:$G$24,0)),$C$2,$B$2))) -> - | P15: =IF(ISNUMBER(MATCH(P38,$G$25:$G$29,0)),$D$2,IF(ISNUMBER(MATCH(P38,$G$32:$G$33,0)),$E$2,IF(ISNUMBER(MATCH(P38,$G$6:$G$24,0)),$C$2,$B$2))) -> - | Q15: =IF(ISNUMBER(MATCH(Q38,$G$25:$G$29,0)),$D$2,IF(ISNUMBER(MATCH(Q38,$G$32:$G$33,0)),$E$2,IF(ISNUMBER(MATCH(Q38,$G$6:$G$24,0)),$C$2,$B$2))) -> - | ... AW15: =IF(ISNUMBER(MATCH(AW38,$G$25:$G$29,0)),$D$2,IF(ISNUMBER(MATCH(AW38,$G$32:$G$33,0)),$E$2,IF(ISNUMBER(MATCH(AW38,$G$6:$G$24,0)),$C$2,$B$2))) -> - | AX15: =AX14+1 -> 10 | AZ15: 9 | BA15: 500 | BB15: 498.74744 | BC15: 497.49313 | BD15: 496.23544 | BE15: 494.973 | BF15: 493.70468 | BG15: 492.4297 | BH15: 491.1475 | BI15: 489.85745 | BJ15: 488.55884 | BK15: 487.25064 | BL15: 485.9321 | BM15: 484.60272 | BN15: 483.2624 | BO15: 481.91086 | BP15: 480.54752 | BQ15: 479.1719 | BR15: 477.78473 | BS15: 476.38803 | BT15: 474.9834 | BU15: 473.57065 | BV15: 472.14758 | BW15: 470.71167 | BX15: 469.26306 | BY15: 467.80667 | BZ15: 466.34637 | CA15: 464.88165 | CB15: 463.40717 | CC15: 461.91483 | CD15: 460.4016 | CE15: 458.8794 | CF15: 457.35352 | CG15: 455.81622 | CH15: 454.24734 | CI15: 452.6316 | CJ15: 451.01578 | CK15: 449.42255 | CL15: 447.854 | CM15: 446.29123 | CN15: 444.67984 | CO15: 442.93 | CQ15: =_xlfn.IFS(CR15<=$CS$3,1,CR15<=$CS$4,2,CR15<=$CS$5,3) -> 1 | CR15: =CR14+1 -> 10 | CS15: 1.75 | CU15: =IF(CV15<=CU$4,1,2) -> 2 | CV15: 292.8 | CW15: =IF(CV15=0,0,(CV15/CW$5)-1) -> 3.88 | CY15: 325 | DD15: 946728000 | DE15: =Jocope!$DA$8/Jocope!DD15 -> 2.6666667
A16: =A15+1 -> 11 | B16: 11 | C16: 0 | D16: 0 | E16: 0 | G16: =_xlfn.CONCAT(D16+1,",",B16+1) -> 1,12 | I16: =I15+1 -> 11 | J16: =IF(ISNUMBER(MATCH(J39,$G$25:$G$29,0)),$D$2,IF(ISNUMBER(MATCH(J39,$G$32:$G$33,0)),$E$2,IF(ISNUMBER(MATCH(J39,$G$6:$G$24,0)),$C$2,$B$2))) -> 1 | K16: =IF(ISNUMBER(MATCH(K39,$G$25:$G$29,0)),$D$2,IF(ISNUMBER(MATCH(K39,$G$32:$G$33,0)),$E$2,IF(ISNUMBER(MATCH(K39,$G$6:$G$24,0)),$C$2,$B$2))) -> - | L16: =IF(ISNUMBER(MATCH(L39,$G$25:$G$29,0)),$D$2,IF(ISNUMBER(MATCH(L39,$G$32:$G$33,0)),$E$2,IF(ISNUMBER(MATCH(L39,$G$6:$G$24,0)),$C$2,$B$2))) -> - | M16: =IF(ISNUMBER(MATCH(M39,$G$25:$G$29,0)),$D$2,IF(ISNUMBER(MATCH(M39,$G$32:$G$33,0)),$E$2,IF(ISNUMBER(MATCH(M39,$G$6:$G$24,0)),$C$2,$B$2))) -> - | N16: =IF(ISNUMBER(MATCH(N39,$G$25:$G$29,0)),$D$2,IF(ISNUMBER(MATCH(N39,$G$32:$G$33,0)),$E$2,IF(ISNUMBER(MATCH(N39,$G$6:$G$24,0)),$C$2,$B$2))) -> - | O16: =IF(ISNUMBER(MATCH(O39,$G$25:$G$29,0)),$D$2,IF(ISNUMBER(MATCH(O39,$G$32:$G$33,0)),$E$2,IF(ISNUMBER(MATCH(O39,$G$6:$G$24,0)),$C$2,$B$2))) -> - | P16: =IF(ISNUMBER(MATCH(P39,$G$25:$G$29,0)),$D$2,IF(ISNUMBER(MATCH(P39,$G$32:$G$33,0)),$E$2,IF(ISNUMBER(MATCH(P39,$G$6:$G$24,0)),$C$2,$B$2))) -> - | Q16: =IF(ISNUMBER(MATCH(Q39,$G$25:$G$29,0)),$D$2,IF(ISNUMBER(MATCH(Q39,$G$32:$G$33,0)),$E$2,IF(ISNUMBER(MATCH(Q39,$G$6:$G$24,0)),$C$2,$B$2))) -> - | ... AW16: =IF(ISNUMBER(MATCH(AW39,$G$25:$G$29,0)),$D$2,IF(ISNUMBER(MATCH(AW39,$G$32:$G$33,0)),$E$2,IF(ISNUMBER(MATCH(AW39,$G$6:$G$24,0)),$C$2,$B$2))) -> - | AX16: =AX15+1 -> 11 | AZ16: 10 | BA16: 500 | BB16: 498.73257 | BC16: 497.4637 | BD16: 496.192 | BE16: 494.9162 | BF16: 493.63528 | BG16: 492.34842 | BH16: 491.0549 | BI16: 489.754 | BJ16: 488.44504 | BK16: 487.12723 | BL16: 485.79996 | BM16: 484.4627 | BN16: 483.11523 | BO16: 481.75717 | BP16: 480.38828 | BQ16: 479.0084 | BR16: 477.61798 | BS16: 476.2179 | BT16: 474.80872 | BU16: 473.39038 | BV16: 471.96198 | BW16: 470.52267 | BX16: 469.07278 | BY16: 467.6141 | BZ16: 466.14804 | CA16: 464.674 | CB16: 463.18936 | CC16: 461.69086 | CD16: 460.17752 | CE16: 458.6526 | CF16: 457.11722 | CG16: 455.56766 | CH16: 453.99698 | CI16: 452.4037 | CJ16: 450.8032 | CK16: 449.20615 | CL16: 447.61264 | CM16: 446.01077 | CN16: 444.3777 | CO16: 442.69656 | CQ16: =_xlfn.IFS(CR16<=$CS$3,1,CR16<=$CS$4,2,CR16<=$CS$5,3) -> 1 | CR16: =CR15+1 -> 11 | CS16: 1.8333333 | CU16: =IF(CV16<=CU$4,1,2) -> 2 | CV16: 329.4 | CW16: =IF(CV16=0,0,(CV16/CW$5)-1) -> 4.49 | CY16: 361.25 | DD16: 1105000000 | DE16: =Jocope!$DA$8/Jocope!DD16 -> 2.2847131
A17: =A16+1 -> 12 | B17: 12 | C17: 0 | D17: 0 | E17: 0 | G17: =_xlfn.CONCAT(D17+1,",",B17+1) -> 1,13 | I17: =I16+1 -> 12 | J17: =IF(ISNUMBER(MATCH(J40,$G$25:$G$29,0)),$D$2,IF(ISNUMBER(MATCH(J40,$G$32:$G$33,0)),$E$2,IF(ISNUMBER(MATCH(J40,$G$6:$G$24,0)),$C$2,$B$2))) -> 1 | K17: =IF(ISNUMBER(MATCH(K40,$G$25:$G$29,0)),$D$2,IF(ISNUMBER(MATCH(K40,$G$32:$G$33,0)),$E$2,IF(ISNUMBER(MATCH(K40,$G$6:$G$24,0)),$C$2,$B$2))) -> - | L17: =IF(ISNUMBER(MATCH(L40,$G$25:$G$29,0)),$D$2,IF(ISNUMBER(MATCH(L40,$G$32:$G$33,0)),$E$2,IF(ISNUMBER(MATCH(L40,$G$6:$G$24,0)),$C$2,$B$2))) -> - | M17: =IF(ISNUMBER(MATCH(M40,$G$25:$G$29,0)),$D$2,IF(ISNUMBER(MATCH(M40,$G$32:$G$33,0)),$E$2,IF(ISNUMBER(MATCH(M40,$G$6:$G$24,0)),$C$2,$B$2))) -> - | N17: =IF(ISNUMBER(MATCH(N40,$G$25:$G$29,0)),$D$2,IF(ISNUMBER(MATCH(N40,$G$32:$G$33,0)),$E$2,IF(ISNUMBER(MATCH(N40,$G$6:$G$24,0)),$C$2,$B$2))) -> - | O17: =IF(ISNUMBER(MATCH(O40,$G$25:$G$29,0)),$D$2,IF(ISNUMBER(MATCH(O40,$G$32:$G$33,0)),$E$2,IF(ISNUMBER(MATCH(O40,$G$6:$G$24,0)),$C$2,$B$2))) -> - | P17: =IF(ISNUMBER(MATCH(P40,$G$25:$G$29,0)),$D$2,IF(ISNUMBER(MATCH(P40,$G$32:$G$33,0)),$E$2,IF(ISNUMBER(MATCH(P40,$G$6:$G$24,0)),$C$2,$B$2))) -> - | Q17: =IF(ISNUMBER(MATCH(Q40,$G$25:$G$29,0)),$D$2,IF(ISNUMBER(MATCH(Q40,$G$32:$G$33,0)),$E$2,IF(ISNUMBER(MATCH(Q40,$G$6:$G$24,0)),$C$2,$B$2))) -> - | ... AW17: =IF(ISNUMBER(MATCH(AW40,$G$25:$G$29,0)),$D$2,IF(ISNUMBER(MATCH(AW40,$G$32:$G$33,0)),$E$2,IF(ISNUMBER(MATCH(AW40,$G$6:$G$24,0)),$C$2,$B$2))) -> - | AX17: =AX16+1 -> 12 | AZ17: 11 | BA17: 500 | BB17: 498.71918 | BC17: 497.4371 | BD17: 496.1526 | BE17: 494.86447 | BF17: 493.57184 | BG17: 492.27383 | BH17: 490.96967 | BI17: 489.65863 | BJ17: 488.34006 | BK17: 487.0133 | BL17: 485.67776 | BM17: 484.333 | BN17: 482.97864 | BO17: 481.61438 | BP17: 480.24 | BQ17: 478.85547 | BR17: 477.46094 | BS17: 476.0568 | BT17: 474.64322 | BU17: 473.22018 | BV17: 471.7873 | BW17: 470.34427 | BX17: 468.89127 | BY17: 467.42896 | BZ17: 465.95767 | CA17: 464.47696 | CB17: 462.98544 | CC17: 461.4817 | CD17: 459.96506 | CE17: 458.43622 | CF17: 456.89514 | CG17: 455.34018 | CH17: 453.76923 | CI17: 452.18298 | CJ17: 450.58716 | CK17: 448.98618 | CL17: 447.3796 | CM17: 445.76157 | CN17: 444.1235 | CO17: 442.46298 | CQ17: =_xlfn.IFS(CR17<=$CS$3,1,CR17<=$CS$4,2,CR17<=$CS$5,3) -> 1 | CR17: =CR16+1 -> 12 | CS17: 1.9166667 | CU17: =IF(CV17<=CU$4,1,2) -> 2 | CV17: 366 | CW17: =IF(CV17=0,0,(CV17/CW$5)-1) -> 5.1 | CY17: 397.5 | DD17: 1578000000 | DE17: =Jocope!$DA$8/Jocope!DD17 -> 1.5998783
A18: =A17+1 -> 13 | B18: 13 | C18: 0 | D18: 0 | E18: 0 | G18: =_xlfn.CONCAT(D18+1,",",B18+1) -> 1,14 | I18: =I17+1 -> 13 | J18: =IF(ISNUMBER(MATCH(J41,$G$25:$G$29,0)),$D$2,IF(ISNUMBER(MATCH(J41,$G$32:$G$33,0)),$E$2,IF(ISNUMBER(MATCH(J41,$G$6:$G$24,0)),$C$2,$B$2))) -> 1 | K18: =IF(ISNUMBER(MATCH(K41,$G$25:$G$29,0)),$D$2,IF(ISNUMBER(MATCH(K41,$G$32:$G$33,0)),$E$2,IF(ISNUMBER(MATCH(K41,$G$6:$G$24,0)),$C$2,$B$2))) -> - | L18: =IF(ISNUMBER(MATCH(L41,$G$25:$G$29,0)),$D$2,IF(ISNUMBER(MATCH(L41,$G$32:$G$33,0)),$E$2,IF(ISNUMBER(MATCH(L41,$G$6:$G$24,0)),$C$2,$B$2))) -> - | M18: =IF(ISNUMBER(MATCH(M41,$G$25:$G$29,0)),$D$2,IF(ISNUMBER(MATCH(M41,$G$32:$G$33,0)),$E$2,IF(ISNUMBER(MATCH(M41,$G$6:$G$24,0)),$C$2,$B$2))) -> - | N18: =IF(ISNUMBER(MATCH(N41,$G$25:$G$29,0)),$D$2,IF(ISNUMBER(MATCH(N41,$G$32:$G$33,0)),$E$2,IF(ISNUMBER(MATCH(N41,$G$6:$G$24,0)),$C$2,$B$2))) -> - | O18: =IF(ISNUMBER(MATCH(O41,$G$25:$G$29,0)),$D$2,IF(ISNUMBER(MATCH(O41,$G$32:$G$33,0)),$E$2,IF(ISNUMBER(MATCH(O41,$G$6:$G$24,0)),$C$2,$B$2))) -> - | P18: =IF(ISNUMBER(MATCH(P41,$G$25:$G$29,0)),$D$2,IF(ISNUMBER(MATCH(P41,$G$32:$G$33,0)),$E$2,IF(ISNUMBER(MATCH(P41,$G$6:$G$24,0)),$C$2,$B$2))) -> - | Q18: =IF(ISNUMBER(MATCH(Q41,$G$25:$G$29,0)),$D$2,IF(ISNUMBER(MATCH(Q41,$G$32:$G$33,0)),$E$2,IF(ISNUMBER(MATCH(Q41,$G$6:$G$24,0)),$C$2,$B$2))) -> - | ... AW18: =IF(ISNUMBER(MATCH(AW41,$G$25:$G$29,0)),$D$2,IF(ISNUMBER(MATCH(AW41,$G$32:$G$33,0)),$E$2,IF(ISNUMBER(MATCH(AW41,$G$6:$G$24,0)),$C$2,$B$2))) -> - | AX18: =AX17+1 -> 13 | AZ18: 12 | BA18: 500 | BB18: 498.70703 | BC18: 497.41296 | BD18: 496.11673 | BE18: 494.81732 | BF18: 493.51382 | BG18: 492.20538 | BH18: 490.8913 | BI18: 489.5708 | BJ18: 488.2433 | BK18: 486.90814 | BL18: 485.56482 | BM18: 484.2129 | BN18: 482.85193 | BO18: 481.48166 | BP18: 480.1019 | BQ18: 478.71252 | BR18: 477.31354 | BS18: 475.9051 | BT18: 474.4872 | BU18: 473.0598 | BV18: 471.6227 | BW18: 470.1758 | BX18: 468.7191 | BY18: 467.25275 | BZ18: 465.77673 | CA18: 464.29068 | CB18: 462.79382 | CC18: 461.28534 | CD18: 459.7648 | CE18: 458.2321 | CF18: 456.68695 | CG18: 455.12866 | CH18: 453.55673 | CI18: 451.97186 | CJ18: 450.37628 | CK18: 448.77182 | CL18: 447.15805 | CM18: 445.53238 | CN18: 443.89178 | CO18: 442.23633 | CQ18: =_xlfn.IFS(CR18<=$CS$3,1,CR18<=$CS$4,2,CR18<=$CS$5,3) -> 1 | CR18: =CR17+1 -> 13 | CS18: 2 | CU18: =IF(CV18<=CU$4,1,2) -> 2 | CV18: 402.6 | CW18: =IF(CV18=0,0,(CV18/CW$5)-1) -> 5.71 | CY18: 433.75
A19: =A18+1 -> 14 | B19: 14 | C19: 0 | D19: 0 | E19: 0 | G19: =_xlfn.CONCAT(D19+1,",",B19+1) -> 1,15 | I19: =I18+1 -> 14 | J19: =IF(ISNUMBER(MATCH(J42,$G$25:$G$29,0)),$D$2,IF(ISNUMBER(MATCH(J42,$G$32:$G$33,0)),$E$2,IF(ISNUMBER(MATCH(J42,$G$6:$G$24,0)),$C$2,$B$2))) -> 1 | K19: =IF(ISNUMBER(MATCH(K42,$G$25:$G$29,0)),$D$2,IF(ISNUMBER(MATCH(K42,$G$32:$G$33,0)),$E$2,IF(ISNUMBER(MATCH(K42,$G$6:$G$24,0)),$C$2,$B$2))) -> - | L19: =IF(ISNUMBER(MATCH(L42,$G$25:$G$29,0)),$D$2,IF(ISNUMBER(MATCH(L42,$G$32:$G$33,0)),$E$2,IF(ISNUMBER(MATCH(L42,$G$6:$G$24,0)),$C$2,$B$2))) -> - | M19: =IF(ISNUMBER(MATCH(M42,$G$25:$G$29,0)),$D$2,IF(ISNUMBER(MATCH(M42,$G$32:$G$33,0)),$E$2,IF(ISNUMBER(MATCH(M42,$G$6:$G$24,0)),$C$2,$B$2))) -> - | N19: =IF(ISNUMBER(MATCH(N42,$G$25:$G$29,0)),$D$2,IF(ISNUMBER(MATCH(N42,$G$32:$G$33,0)),$E$2,IF(ISNUMBER(MATCH(N42,$G$6:$G$24,0)),$C$2,$B$2))) -> - | O19: =IF(ISNUMBER(MATCH(O42,$G$25:$G$29,0)),$D$2,IF(ISNUMBER(MATCH(O42,$G$32:$G$33,0)),$E$2,IF(ISNUMBER(MATCH(O42,$G$6:$G$24,0)),$C$2,$B$2))) -> - | P19: =IF(ISNUMBER(MATCH(P42,$G$25:$G$29,0)),$D$2,IF(ISNUMBER(MATCH(P42,$G$32:$G$33,0)),$E$2,IF(ISNUMBER(MATCH(P42,$G$6:$G$24,0)),$C$2,$B$2))) -> - | Q19: =IF(ISNUMBER(MATCH(Q42,$G$25:$G$29,0)),$D$2,IF(ISNUMBER(MATCH(Q42,$G$32:$G$33,0)),$E$2,IF(ISNUMBER(MATCH(Q42,$G$6:$G$24,0)),$C$2,$B$2))) -> - | ... AW19: =IF(ISNUMBER(MATCH(AW42,$G$25:$G$29,0)),$D$2,IF(ISNUMBER(MATCH(AW42,$G$32:$G$33,0)),$E$2,IF(ISNUMBER(MATCH(AW42,$G$6:$G$24,0)),$C$2,$B$2))) -> - | AX19: =AX18+1 -> 14 | AZ19: 13 | BA19: 500 | BB19: 498.69598 | BC19: 497.391 | BD19: 496.08405 | BE19: 494.77423 | BF19: 493.4607 | BG19: 492.1426 | BH19: 490.81927 | BI19: 489.49 | BJ19: 488.15417 | BK19: 486.81116 | BL19: 485.4605 | BM19: 484.10175 | BN19: 482.7345 | BO19: 481.35846 | BP19: 479.9734 | BQ19: 478.57913 | BR19: 477.17563 | BS19: 475.76285 | BT19: 474.3407 | BU19: 472.90915 | BV19: 471.468 | BW19: 470.01715 | BX19: 468.55658 | BY19: 467.08618 | BZ19: 465.60583 | CA19: 464.1152 | CB19: 462.6138 | CC19: 461.1011 | CD19: 459.57672 | CE19: 458.0404 | CF19: 456.49188 | CG19: 454.93085 | CH19: 453.3572 | CI19: 451.7714 | CJ19: 450.17435 | CK19: 448.56674 | CL19: 446.94836 | CM19: 445.3181 | CN19: 443.67493 | CO19: 442.01904 | CQ19: =_xlfn.IFS(CR19<=$CS$3,1,CR19<=$CS$4,2,CR19<=$CS$5,3) -> 1 | CR19: =CR18+1 -> 14 | CS19: 2.0833333 | CU19: =IF(CV19<=CU$4,1,2) -> 2 | CV19: 439.2 | CW19: =IF(CV19=0,0,(CV19/CW$5)-1) -> 6.32 | CY19: 470
A20: =A19+1 -> 15 | B20: 15 | C20: 0 | D20: 0 | E20: 0 | G20: =_xlfn.CONCAT(D20+1,",",B20+1) -> 1,16 | I20: =I19+1 -> 15 | J20: =IF(ISNUMBER(MATCH(J43,$G$25:$G$29,0)),$D$2,IF(ISNUMBER(MATCH(J43,$G$32:$G$33,0)),$E$2,IF(ISNUMBER(MATCH(J43,$G$6:$G$24,0)),$C$2,$B$2))) -> 1 | K20: =IF(ISNUMBER(MATCH(K43,$G$25:$G$29,0)),$D$2,IF(ISNUMBER(MATCH(K43,$G$32:$G$33,0)),$E$2,IF(ISNUMBER(MATCH(K43,$G$6:$G$24,0)),$C$2,$B$2))) -> - | L20: =IF(ISNUMBER(MATCH(L43,$G$25:$G$29,0)),$D$2,IF(ISNUMBER(MATCH(L43,$G$32:$G$33,0)),$E$2,IF(ISNUMBER(MATCH(L43,$G$6:$G$24,0)),$C$2,$B$2))) -> - | M20: =IF(ISNUMBER(MATCH(M43,$G$25:$G$29,0)),$D$2,IF(ISNUMBER(MATCH(M43,$G$32:$G$33,0)),$E$2,IF(ISNUMBER(MATCH(M43,$G$6:$G$24,0)),$C$2,$B$2))) -> - | N20: =IF(ISNUMBER(MATCH(N43,$G$25:$G$29,0)),$D$2,IF(ISNUMBER(MATCH(N43,$G$32:$G$33,0)),$E$2,IF(ISNUMBER(MATCH(N43,$G$6:$G$24,0)),$C$2,$B$2))) -> - | O20: =IF(ISNUMBER(MATCH(O43,$G$25:$G$29,0)),$D$2,IF(ISNUMBER(MATCH(O43,$G$32:$G$33,0)),$E$2,IF(ISNUMBER(MATCH(O43,$G$6:$G$24,0)),$C$2,$B$2))) -> - | P20: =IF(ISNUMBER(MATCH(P43,$G$25:$G$29,0)),$D$2,IF(ISNUMBER(MATCH(P43,$G$32:$G$33,0)),$E$2,IF(ISNUMBER(MATCH(P43,$G$6:$G$24,0)),$C$2,$B$2))) -> - | Q20: =IF(ISNUMBER(MATCH(Q43,$G$25:$G$29,0)),$D$2,IF(ISNUMBER(MATCH(Q43,$G$32:$G$33,0)),$E$2,IF(ISNUMBER(MATCH(Q43,$G$6:$G$24,0)),$C$2,$B$2))) -> - | ... AW20: =IF(ISNUMBER(MATCH(AW43,$G$25:$G$29,0)),$D$2,IF(ISNUMBER(MATCH(AW43,$G$32:$G$33,0)),$E$2,IF(ISNUMBER(MATCH(AW43,$G$6:$G$24,0)),$C$2,$B$2))) -> - | AX20: =AX19+1 -> 15 | AZ20: 14 | BA20: 500 | BB20: 498.68594 | BC20: 497.371 | BD20: 496.05426 | BE20: 494.7349 | BF20: 493.4121 | BG20: 492.0851 | BH20: 490.7532 | BI20: 489.41577 | BJ20: 488.07217 | BK20: 486.72186 | BL20: 485.36432 | BM20: 483.9991 | BN20: 482.6259 | BO20: 481.2443 | BP20: 479.85406 | BQ20: 478.45502 | BR20: 477.04703 | BS20: 475.62994 | BT20: 474.20364 | BU20: 472.76804 | BV20: 471.32294 | BW20: 469.86826 | BX20: 468.40384 | BY20: 466.92957 | BZ20: 465.44522 | CA20: 463.9505 | CB20: 462.44507 | CC20: 460.92853 | CD20: 459.40057 | CE20: 457.8609 | CF20: 456.30933 | CG20: 454.74564 | CH20: 453.16986 | CI20: 451.58215 | CJ20: 449.98294 | CK20: 448.37247 | CL20: 446.75058 | CM20: 445.1168 | CN20: 443.47073 | CO20: 441.8125 | CQ20: =_xlfn.IFS(CR20<=$CS$3,1,CR20<=$CS$4,2,CR20<=$CS$5,3) -> 1 | CR20: =CR19+1 -> 15 | CS20: 2.1666667 | CU20: =IF(CV20<=CU$4,1,2) -> 2 | CV20: 475.8 | CW20: =IF(CV20=0,0,(CV20/CW$5)-1) -> 6.93 | CY20: 506.25
A21: =A20+1 -> 16 | B21: 16 | C21: 0 | D21: 0 | E21: 0 | G21: =_xlfn.CONCAT(D21+1,",",B21+1) -> 1,17 | I21: =I20+1 -> 16 | J21: =IF(ISNUMBER(MATCH(J44,$G$25:$G$29,0)),$D$2,IF(ISNUMBER(MATCH(J44,$G$32:$G$33,0)),$E$2,IF(ISNUMBER(MATCH(J44,$G$6:$G$24,0)),$C$2,$B$2))) -> 1 | K21: =IF(ISNUMBER(MATCH(K44,$G$25:$G$29,0)),$D$2,IF(ISNUMBER(MATCH(K44,$G$32:$G$33,0)),$E$2,IF(ISNUMBER(MATCH(K44,$G$6:$G$24,0)),$C$2,$B$2))) -> - | L21: =IF(ISNUMBER(MATCH(L44,$G$25:$G$29,0)),$D$2,IF(ISNUMBER(MATCH(L44,$G$32:$G$33,0)),$E$2,IF(ISNUMBER(MATCH(L44,$G$6:$G$24,0)),$C$2,$B$2))) -> - | M21: =IF(ISNUMBER(MATCH(M44,$G$25:$G$29,0)),$D$2,IF(ISNUMBER(MATCH(M44,$G$32:$G$33,0)),$E$2,IF(ISNUMBER(MATCH(M44,$G$6:$G$24,0)),$C$2,$B$2))) -> - | N21: =IF(ISNUMBER(MATCH(N44,$G$25:$G$29,0)),$D$2,IF(ISNUMBER(MATCH(N44,$G$32:$G$33,0)),$E$2,IF(ISNUMBER(MATCH(N44,$G$6:$G$24,0)),$C$2,$B$2))) -> - | O21: =IF(ISNUMBER(MATCH(O44,$G$25:$G$29,0)),$D$2,IF(ISNUMBER(MATCH(O44,$G$32:$G$33,0)),$E$2,IF(ISNUMBER(MATCH(O44,$G$6:$G$24,0)),$C$2,$B$2))) -> - | P21: =IF(ISNUMBER(MATCH(P44,$G$25:$G$29,0)),$D$2,IF(ISNUMBER(MATCH(P44,$G$32:$G$33,0)),$E$2,IF(ISNUMBER(MATCH(P44,$G$6:$G$24,0)),$C$2,$B$2))) -> - | Q21: =IF(ISNUMBER(MATCH(Q44,$G$25:$G$29,0)),$D$2,IF(ISNUMBER(MATCH(Q44,$G$32:$G$33,0)),$E$2,IF(ISNUMBER(MATCH(Q44,$G$6:$G$24,0)),$C$2,$B$2))) -> - | ... AW21: =IF(ISNUMBER(MATCH(AW44,$G$25:$G$29,0)),$D$2,IF(ISNUMBER(MATCH(AW44,$G$32:$G$33,0)),$E$2,IF(ISNUMBER(MATCH(AW44,$G$6:$G$24,0)),$C$2,$B$2))) -> 2 | AX21: =AX20+1 -> 16 | AZ21: 15 | BA21: 500 | BB21: 498.6768 | BC21: 497.35278 | BD21: 496.0271 | BE21: 494.69897 | BF21: 493.3677 | BG21: 492.0325 | BH21: 490.6927 | BI21: 489.3477 | BJ21: 487.9969 | BK21: 486.63974 | BL21: 485.2758 | BM21: 483.90454 | BN21: 482.52563 | BO21: 481.13873 | BP21: 479.74356 | BQ21: 478.33987 | BR21: 476.9275 | BS21: 475.50623 | BT21: 474.0759 | BU21: 472.63638 | BV21: 471.1875 | BW21: 469.7291 | BX21: 468.26102 | BY21: 466.78302 | BZ21: 465.29495 | CA21: 463.79654 | CB21: 462.28745 | CC21: 460.7674 | CD21: 459.23608 | CE21: 457.69333 | CF21: 456.13885 | CG21: 454.57257 | CH21: 452.99442 | CI21: 451.40445 | CJ21: 449.80283 | CK21: 448.1896 | CL21: 446.56467 | CM21: 444.92776 | CN21: 443.27872 | CO21: 441.6175 | CQ21: =_xlfn.IFS(CR21<=$CS$3,1,CR21<=$CS$4,2,CR21<=$CS$5,3) -> 1 | CR21: =CR20+1 -> 16 | CS21: 2.25 | CU21: =IF(CV21<=CU$4,1,2) -> 2 | CV21: 512.4 | CW21: =IF(CV21=0,0,(CV21/CW$5)-1) -> 7.54 | CY21: 542.5
A22: =A21+1 -> 17 | B22: 17 | C22: 0 | D22: 0 | E22: 0 | G22: =_xlfn.CONCAT(D22+1,",",B22+1) -> 1,18 | I22: =I21+1 -> 17 | J22: =IF(ISNUMBER(MATCH(J45,$G$25:$G$29,0)),$D$2,IF(ISNUMBER(MATCH(J45,$G$32:$G$33,0)),$E$2,IF(ISNUMBER(MATCH(J45,$G$6:$G$24,0)),$C$2,$B$2))) -> 3 | K22: =IF(ISNUMBER(MATCH(K45,$G$25:$G$29,0)),$D$2,IF(ISNUMBER(MATCH(K45,$G$32:$G$33,0)),$E$2,IF(ISNUMBER(MATCH(K45,$G$6:$G$24,0)),$C$2,$B$2))) -> - | L22: =IF(ISNUMBER(MATCH(L45,$G$25:$G$29,0)),$D$2,IF(ISNUMBER(MATCH(L45,$G$32:$G$33,0)),$E$2,IF(ISNUMBER(MATCH(L45,$G$6:$G$24,0)),$C$2,$B$2))) -> - | M22: =IF(ISNUMBER(MATCH(M45,$G$25:$G$29,0)),$D$2,IF(ISNUMBER(MATCH(M45,$G$32:$G$33,0)),$E$2,IF(ISNUMBER(MATCH(M45,$G$6:$G$24,0)),$C$2,$B$2))) -> - | N22: =IF(ISNUMBER(MATCH(N45,$G$25:$G$29,0)),$D$2,IF(ISNUMBER(MATCH(N45,$G$32:$G$33,0)),$E$2,IF(ISNUMBER(MATCH(N45,$G$6:$G$24,0)),$C$2,$B$2))) -> - | O22: =IF(ISNUMBER(MATCH(O45,$G$25:$G$29,0)),$D$2,IF(ISNUMBER(MATCH(O45,$G$32:$G$33,0)),$E$2,IF(ISNUMBER(MATCH(O45,$G$6:$G$24,0)),$C$2,$B$2))) -> - | P22: =IF(ISNUMBER(MATCH(P45,$G$25:$G$29,0)),$D$2,IF(ISNUMBER(MATCH(P45,$G$32:$G$33,0)),$E$2,IF(ISNUMBER(MATCH(P45,$G$6:$G$24,0)),$C$2,$B$2))) -> - | Q22: =IF(ISNUMBER(MATCH(Q45,$G$25:$G$29,0)),$D$2,IF(ISNUMBER(MATCH(Q45,$G$32:$G$33,0)),$E$2,IF(ISNUMBER(MATCH(Q45,$G$6:$G$24,0)),$C$2,$B$2))) -> - | ... AW22: =IF(ISNUMBER(MATCH(AW45,$G$25:$G$29,0)),$D$2,IF(ISNUMBER(MATCH(AW45,$G$32:$G$33,0)),$E$2,IF(ISNUMBER(MATCH(AW45,$G$6:$G$24,0)),$C$2,$B$2))) -> 2 | AX22: =AX21+1 -> 17 | AZ22: 16 | BA22: 500 | BB22: 498.6685 | BC22: 497.33618 | BD22: 496.00235 | BE22: 494.66626 | BF22: 493.3272 | BG22: 491.98447 | BH22: 490.6374 | BI22: 489.28543 | BJ22: 487.92795 | BK22: 486.56448 | BL22: 485.19452 | BM22: 483.8176 | BN22: 482.43338 | BO22: 481.04147 | BP22: 479.64157 | BQ22: 478.23346 | BR22: 476.81683 | BS22: 475.39154 | BT22: 473.95737 | BU22: 472.51413 | BV22: 471.0616 | BW22: 469.59964 | BX22: 468.12802 | BY22: 466.64658 | BZ22: 465.15506 | CA22: 463.65323 | CB22: 462.14078 | CC22: 460.61752 | CD22: 459.08313 | CE22: 457.5374 | CF22: 455.9802 | CG22: 454.41135 | CH22: 452.83075 | CI22: 451.2384 | CJ22: 449.63434 | CK22: 448.01846 | CL22: 446.39072 | CM22: 444.75092 | CN22: 443.09888 | CO22: 441.43454 | CQ22: =_xlfn.IFS(CR22<=$CS$3,1,CR22<=$CS$4,2,CR22<=$CS$5,3) -> 1 | CR22: =CR21+1 -> 17 | CS22: 2.3333333 | CU22: =IF(CV22<=CU$4,1,2) -> 2 | CV22: 549 | CW22: =IF(CV22=0,0,(CV22/CW$5)-1) -> 8.15 | CY22: 578.75
A23: =A22+1 -> 18 | B23: 18 | C23: 0 | D23: 0 | E23: 0 | G23: =_xlfn.CONCAT(D23+1,",",B23+1) -> 1,19 | I23: =I22+1 -> 18 | J23: =IF(ISNUMBER(MATCH(J46,$G$25:$G$29,0)),$D$2,IF(ISNUMBER(MATCH(J46,$G$32:$G$33,0)),$E$2,IF(ISNUMBER(MATCH(J46,$G$6:$G$24,0)),$C$2,$B$2))) -> 3 | K23: =IF(ISNUMBER(MATCH(K46,$G$25:$G$29,0)),$D$2,IF(ISNUMBER(MATCH(K46,$G$32:$G$33,0)),$E$2,IF(ISNUMBER(MATCH(K46,$G$6:$G$24,0)),$C$2,$B$2))) -> - | L23: =IF(ISNUMBER(MATCH(L46,$G$25:$G$29,0)),$D$2,IF(ISNUMBER(MATCH(L46,$G$32:$G$33,0)),$E$2,IF(ISNUMBER(MATCH(L46,$G$6:$G$24,0)),$C$2,$B$2))) -> - | M23: =IF(ISNUMBER(MATCH(M46,$G$25:$G$29,0)),$D$2,IF(ISNUMBER(MATCH(M46,$G$32:$G$33,0)),$E$2,IF(ISNUMBER(MATCH(M46,$G$6:$G$24,0)),$C$2,$B$2))) -> - | N23: =IF(ISNUMBER(MATCH(N46,$G$25:$G$29,0)),$D$2,IF(ISNUMBER(MATCH(N46,$G$32:$G$33,0)),$E$2,IF(ISNUMBER(MATCH(N46,$G$6:$G$24,0)),$C$2,$B$2))) -> - | O23: =IF(ISNUMBER(MATCH(O46,$G$25:$G$29,0)),$D$2,IF(ISNUMBER(MATCH(O46,$G$32:$G$33,0)),$E$2,IF(ISNUMBER(MATCH(O46,$G$6:$G$24,0)),$C$2,$B$2))) -> - | P23: =IF(ISNUMBER(MATCH(P46,$G$25:$G$29,0)),$D$2,IF(ISNUMBER(MATCH(P46,$G$32:$G$33,0)),$E$2,IF(ISNUMBER(MATCH(P46,$G$6:$G$24,0)),$C$2,$B$2))) -> - | Q23: =IF(ISNUMBER(MATCH(Q46,$G$25:$G$29,0)),$D$2,IF(ISNUMBER(MATCH(Q46,$G$32:$G$33,0)),$E$2,IF(ISNUMBER(MATCH(Q46,$G$6:$G$24,0)),$C$2,$B$2))) -> - | ... AW23: =IF(ISNUMBER(MATCH(AW46,$G$25:$G$29,0)),$D$2,IF(ISNUMBER(MATCH(AW46,$G$32:$G$33,0)),$E$2,IF(ISNUMBER(MATCH(AW46,$G$6:$G$24,0)),$C$2,$B$2))) -> 2 | AX23: =AX22+1 -> 18 | AZ23: 17 | BA23: 500 | BB23: 498.66092 | BC23: 497.32114 | BD23: 495.9799 | BE23: 494.63654 | BF23: 493.29037 | BG23: 491.94073 | BH23: 490.587 | BI23: 489.22864 | BJ23: 487.86505 | BK23: 486.49573 | BL23: 485.12018 | BM23: 483.738 | BN23: 482.3488 | BO23: 480.95218 | BP23: 479.54782 | BQ23: 478.1355 | BR23: 476.71487 | BS23: 475.28577 | BT23: 473.8479 | BU23: 472.4011 | BV23: 470.94513 | BW23: 469.47983 | BX23: 468.0049 | BY23: 466.5202 | BZ23: 465.02548 | CA23: 463.52048 | CB23: 462.00497 | CC23: 460.47873 | CD23: 458.94147 | CE23: 457.39304 | CF23: 455.8332 | CG23: 454.26184 | CH23: 452.67883 | CI23: 451.0841 | CJ23: 449.4776 | CK23: 447.8592 | CL23: 446.2288 | CM23: 444.58624 | CN23: 442.93137 | CO23: 441.264 | CQ23: =_xlfn.IFS(CR23<=$CS$3,1,CR23<=$CS$4,2,CR23<=$CS$5,3) -> 1 | CR23: =CR22+1 -> 18 | CS23: 2.4166667 | CU23: =IF(CV23<=CU$4,1,2) -> 2 | CV23: 585.6 | CW23: =IF(CV23=0,0,(CV23/CW$5)-1) -> 8.76 | CY23: 615
A24: =A23+1 -> 19 | B24: 19 | C24: 0 | D24: 0 | E24: 0 | G24: =_xlfn.CONCAT(D24+1,",",B24+1) -> 1,20 | I24: =I23+1 -> 19 | J24: =IF(ISNUMBER(MATCH(J47,$G$25:$G$29,0)),$D$2,IF(ISNUMBER(MATCH(J47,$G$32:$G$33,0)),$E$2,IF(ISNUMBER(MATCH(J47,$G$6:$G$24,0)),$C$2,$B$2))) -> 1 | K24: =IF(ISNUMBER(MATCH(K47,$G$25:$G$29,0)),$D$2,IF(ISNUMBER(MATCH(K47,$G$32:$G$33,0)),$E$2,IF(ISNUMBER(MATCH(K47,$G$6:$G$24,0)),$C$2,$B$2))) -> - | L24: =IF(ISNUMBER(MATCH(L47,$G$25:$G$29,0)),$D$2,IF(ISNUMBER(MATCH(L47,$G$32:$G$33,0)),$E$2,IF(ISNUMBER(MATCH(L47,$G$6:$G$24,0)),$C$2,$B$2))) -> - | M24: =IF(ISNUMBER(MATCH(M47,$G$25:$G$29,0)),$D$2,IF(ISNUMBER(MATCH(M47,$G$32:$G$33,0)),$E$2,IF(ISNUMBER(MATCH(M47,$G$6:$G$24,0)),$C$2,$B$2))) -> - | N24: =IF(ISNUMBER(MATCH(N47,$G$25:$G$29,0)),$D$2,IF(ISNUMBER(MATCH(N47,$G$32:$G$33,0)),$E$2,IF(ISNUMBER(MATCH(N47,$G$6:$G$24,0)),$C$2,$B$2))) -> - | O24: =IF(ISNUMBER(MATCH(O47,$G$25:$G$29,0)),$D$2,IF(ISNUMBER(MATCH(O47,$G$32:$G$33,0)),$E$2,IF(ISNUMBER(MATCH(O47,$G$6:$G$24,0)),$C$2,$B$2))) -> - | P24: =IF(ISNUMBER(MATCH(P47,$G$25:$G$29,0)),$D$2,IF(ISNUMBER(MATCH(P47,$G$32:$G$33,0)),$E$2,IF(ISNUMBER(MATCH(P47,$G$6:$G$24,0)),$C$2,$B$2))) -> - | Q24: =IF(ISNUMBER(MATCH(Q47,$G$25:$G$29,0)),$D$2,IF(ISNUMBER(MATCH(Q47,$G$32:$G$33,0)),$E$2,IF(ISNUMBER(MATCH(Q47,$G$6:$G$24,0)),$C$2,$B$2))) -> - | ... AW24: =IF(ISNUMBER(MATCH(AW47,$G$25:$G$29,0)),$D$2,IF(ISNUMBER(MATCH(AW47,$G$32:$G$33,0)),$E$2,IF(ISNUMBER(MATCH(AW47,$G$6:$G$24,0)),$C$2,$B$2))) -> 2 | AX24: =AX23+1 -> 19 | AZ24: 18 | BA24: 500 | BB24: 498.65408 | BC24: 497.30753 | BD24: 495.95956 | BE24: 494.60962 | BF24: 493.257 | BG24: 491.9011 | BH24: 490.5413 | BI24: 489.17706 | BJ24: 487.80786 | BK24: 486.43314 | BL24: 485.0525 | BM24: 483.66544 | BN24: 482.2716 | BO24: 480.8706 | BP24: 479.4621 | BQ24: 478.0458 | BR24: 476.62143 | BS24: 475.1887 | BT24: 473.74738 | BU24: 472.29724 | BV24: 470.83804 | BW24: 469.36957 | BX24: 467.89157 | BY24: 466.40387 | BZ24: 464.90616 | CA24: 463.3983 | CB24: 461.87994 | CC24: 460.35092 | CD24: 458.81104 | CE24: 457.26 | CF24: 455.69772 | CG24: 454.12396 | CH24: 452.53864 | CI24: 450.94162 | CJ24: 449.33276 | CK24: 447.71194 | CL24: 446.07904 | CM24: 444.4339 | CN24: 442.77634 | CO24: 441.10617 | CQ24: =_xlfn.IFS(CR24<=$CS$3,1,CR24<=$CS$4,2,CR24<=$CS$5,3) -> 1 | CR24: =CR23+1 -> 19 | CS24: 2.5 | CU24: =IF(CV24<=CU$4,1,2) -> 2 | CV24: 622.2 | CW24: =IF(CV24=0,0,(CV24/CW$5)-1) -> 9.37 | CY24: 651.25
A25: =A24+1 -> 20 | B25: 15 | C25: 0 | D25: 39 | E25: -0.2 | G25: =_xlfn.CONCAT(D25+1,",",B25+1) -> 40,16 | I25: =I24+1 -> 20 | J25: =IF(ISNUMBER(MATCH(J48,$G$25:$G$29,0)),$D$2,IF(ISNUMBER(MATCH(J48,$G$32:$G$33,0)),$E$2,IF(ISNUMBER(MATCH(J48,$G$6:$G$24,0)),$C$2,$B$2))) -> 1 | K25: =IF(ISNUMBER(MATCH(K48,$G$25:$G$29,0)),$D$2,IF(ISNUMBER(MATCH(K48,$G$32:$G$33,0)),$E$2,IF(ISNUMBER(MATCH(K48,$G$6:$G$24,0)),$C$2,$B$2))) -> - | L25: =IF(ISNUMBER(MATCH(L48,$G$25:$G$29,0)),$D$2,IF(ISNUMBER(MATCH(L48,$G$32:$G$33,0)),$E$2,IF(ISNUMBER(MATCH(L48,$G$6:$G$24,0)),$C$2,$B$2))) -> - | M25: =IF(ISNUMBER(MATCH(M48,$G$25:$G$29,0)),$D$2,IF(ISNUMBER(MATCH(M48,$G$32:$G$33,0)),$E$2,IF(ISNUMBER(MATCH(M48,$G$6:$G$24,0)),$C$2,$B$2))) -> - | N25: =IF(ISNUMBER(MATCH(N48,$G$25:$G$29,0)),$D$2,IF(ISNUMBER(MATCH(N48,$G$32:$G$33,0)),$E$2,IF(ISNUMBER(MATCH(N48,$G$6:$G$24,0)),$C$2,$B$2))) -> - | O25: =IF(ISNUMBER(MATCH(O48,$G$25:$G$29,0)),$D$2,IF(ISNUMBER(MATCH(O48,$G$32:$G$33,0)),$E$2,IF(ISNUMBER(MATCH(O48,$G$6:$G$24,0)),$C$2,$B$2))) -> - | P25: =IF(ISNUMBER(MATCH(P48,$G$25:$G$29,0)),$D$2,IF(ISNUMBER(MATCH(P48,$G$32:$G$33,0)),$E$2,IF(ISNUMBER(MATCH(P48,$G$6:$G$24,0)),$C$2,$B$2))) -> - | Q25: =IF(ISNUMBER(MATCH(Q48,$G$25:$G$29,0)),$D$2,IF(ISNUMBER(MATCH(Q48,$G$32:$G$33,0)),$E$2,IF(ISNUMBER(MATCH(Q48,$G$6:$G$24,0)),$C$2,$B$2))) -> - | ... AW25: =IF(ISNUMBER(MATCH(AW48,$G$25:$G$29,0)),$D$2,IF(ISNUMBER(MATCH(AW48,$G$32:$G$33,0)),$E$2,IF(ISNUMBER(MATCH(AW48,$G$6:$G$24,0)),$C$2,$B$2))) -> 2 | AX25: =AX24+1 -> 20 | AZ25: 19 | BA25: 500 | BB25: 498.64795 | BC25: 497.29526 | BD25: 495.94125 | BE25: 494.58536 | BF25: 493.2269 | BG25: 491.86533 | BH25: 490.50003 | BI25: 489.1305 | BJ25: 487.75616 | BK25: 486.37656 | BL25: 484.99118 | BM25: 483.59967 | BN25: 482.20157 | BO25: 480.7965 | BP25: 479.38416 | BQ25: 477.9642 | BR25: 476.53632 | BS25: 475.10022 | BT25: 473.6557 | BU25: 472.20245 | BV25: 470.74023 | BW25: 469.26883 | BX25: 467.788 | BY25: 466.2975 | BZ25: 464.79706 | CA25: 463.2865 | CB25: 461.76556 | CC25: 460.23404 | CD25: 458.69168 | CE25: 457.1383 | CF25: 455.5737 | CG25: 453.9977 | CH25: 452.41016 | CI25: 450.8109 | CJ25: 449.19986 | CK25: 447.57678 | CL25: 445.94156 | CM25: 444.294 | CN25: 442.63394 | CO25: 440.96115 | CQ25: =_xlfn.IFS(CR25<=$CS$3,1,CR25<=$CS$4,2,CR25<=$CS$5,3) -> 1 | CR25: =CR24+1 -> 20 | CS25: 2.5833333 | CU25: =IF(CV25<=CU$4,1,2) -> 2 | CV25: 658.8 | CW25: =IF(CV25=0,0,(CV25/CW$5)-1) -> 9.98 | CY25: 687.5
A26: =A25+1 -> 21 | B26: 16 | C26: 0 | D26: 39 | E26: -0.2 | G26: =_xlfn.CONCAT(D26+1,",",B26+1) -> 40,17 | CQ26: =_xlfn.IFS(CR26<=$CS$3,1,CR26<=$CS$4,2,CR26<=$CS$5,3) -> 1 | CR26: =CR25+1 -> 21 | CS26: 2.6666667 | CU26: =IF(CV26<=CU$4,1,2) -> 2 | CV26: 695.4 | CW26: =IF(CV26=0,0,(CV26/CW$5)-1) -> 10.59 | CY26: 723.75
A27: =A26+1 -> 22 | B27: 17 | C27: 0 | D27: 39 | E27: -0.2 | G27: =_xlfn.CONCAT(D27+1,",",B27+1) -> 40,18 | I27: =COUNT(J5:AW5) -> 40 | J27: 1 | K27: =IF(ISNUMBER(K28),J27+1,"") -> 2 | L27: =IF(ISNUMBER(L28),K27+1,"") -> 3 | M27: =IF(ISNUMBER(M28),L27+1,"") -> 4 | N27: =IF(ISNUMBER(N28),M27+1,"") -> 5 | O27: =IF(ISNUMBER(O28),N27+1,"") -> 6 | P27: =IF(ISNUMBER(P28),O27+1,"") -> 7 | Q27: =IF(ISNUMBER(Q28),P27+1,"") -> 8 | R27: =IF(ISNUMBER(R28),Q27+1,"") -> 9 | ... AW27: =IF(ISNUMBER(AW28),AV27+1,"") -> 40 | AZ27: K | CQ27: =_xlfn.IFS(CR27<=$CS$3,1,CR27<=$CS$4,2,CR27<=$CS$5,3) -> 1 | CR27: =CR26+1 -> 22 | CS27: 2.75 | CU27: =IF(CV27<=CU$4,1,2) -> 2 | CV27: 732 | CW27: =IF(CV27=0,0,(CV27/CW$5)-1) -> 11.2 | CY27: 760
A28: =A27+1 -> 23 | B28: 18 | C28: 0 | D28: 39 | E28: -0.2 | G28: =_xlfn.CONCAT(D28+1,",",B28+1) -> 40,19 | I28: =COUNT(I6:I25) -> 20 | J28: =ROW() -> 28 | K28: =ROW() -> 28 | L28: =ROW() -> 28 | M28: =ROW() -> 28 | N28: =ROW() -> 28 | O28: =ROW() -> 28 | P28: =ROW() -> 28 | Q28: =ROW() -> 28 | ... AW28: =ROW() -> 28 | AZ28: XY | BA28: =BA50 -> 0 | BB28: =BA28+1 -> 1 | BC28: =BB28+1 -> 2 | BD28: =BC28+1 -> 3 | BE28: =BD28+1 -> 4 | BF28: =BE28+1 -> 5 | BG28: =BF28+1 -> 6 | BH28: =BG28+1 -> 7 | BI28: =BH28+1 -> 8 | ... CN28: =CM28+1 -> 39 | CO28: 0 | CQ28: =_xlfn.IFS(CR28<=$CS$3,1,CR28<=$CS$4,2,CR28<=$CS$5,3) -> 1 | CR28: =CR27+1 -> 23 | CS28: 2.8333333 | CU28: =IF(CV28<=CU$4,1,2) -> 2 | CV28: 768.6 | CW28: =IF(CV28=0,0,(CV28/CW$5)-1) -> 11.81 | CY28: 796.25
A29: =A28+1 -> 24 | B29: 19 | C29: 0 | D29: 39 | E29: -0.2 | G29: =_xlfn.CONCAT(D29+1,",",B29+1) -> 40,20 | I29: =COLUMN() -> 9 | J29: =_xlfn.CONCAT(COLUMN()-$I29,",",ROW()-J$28) -> 1,1 | K29: =_xlfn.CONCAT(COLUMN()-$I29,",",ROW()-K$28) -> 2,1 | L29: =_xlfn.CONCAT(COLUMN()-$I29,",",ROW()-L$28) -> 3,1 | M29: =_xlfn.CONCAT(COLUMN()-$I29,",",ROW()-M$28) -> 4,1 | N29: =_xlfn.CONCAT(COLUMN()-$I29,",",ROW()-N$28) -> 5,1 | O29: =_xlfn.CONCAT(COLUMN()-$I29,",",ROW()-O$28) -> 6,1 | P29: =_xlfn.CONCAT(COLUMN()-$I29,",",ROW()-P$28) -> 7,1 | Q29: =_xlfn.CONCAT(COLUMN()-$I29,",",ROW()-Q$28) -> 8,1 | ... AW29: =_xlfn.CONCAT(COLUMN()-$I29,",",ROW()-AW$28) -> 40,1 | AX29: =AX28+1 -> 1 | AZ29: 0 | BA29: 0 | BB29: 0 | BC29: 0 | BD29: 0 | BE29: 0 | BF29: 0 | BG29: 0 | BH29: 0 | BI29: 0 | BJ29: 0 | BK29: 0 | BL29: 0 | BM29: 0 | BN29: 0 | BO29: 0 | BP29: 0 | BQ29: 0 | BR29: 0 | BS29: 0 | BT29: 0 | BU29: 0 | BV29: 0 | BW29: 0 | BX29: 0 | BY29: 0 | BZ29: 0 | CA29: 0 | CB29: 0 | CC29: 0 | CD29: 0 | CE29: 0 | CF29: 0 | CG29: 0 | CH29: 0 | CI29: 0 | CJ29: 0 | CK29: 0 | CL29: 0 | CM29: 0 | CN29: 0 | CO29: 0 | CQ29: =_xlfn.IFS(CR29<=$CS$3,1,CR29<=$CS$4,2,CR29<=$CS$5,3) -> 1 | CR29: =CR28+1 -> 24 | CS29: 2.9166667 | CU29: =IF(CV29<=CU$4,1,2) -> 2 | CV29: 805.2 | CW29: =IF(CV29=0,0,(CV29/CW$5)-1) -> 12.42 | CY29: 832.5
B30: =B29+1 -> 20 | E30: =_xlfn.CONCAT("[",B29,",",C29,",",D29,",",E29,"]") -> [19,0,39,-0.2] | I30: =COLUMN() -> 9 | J30: =_xlfn.CONCAT(COLUMN()-$I30,",",ROW()-J$28) -> 1,2 | K30: =_xlfn.CONCAT(COLUMN()-$I30,",",ROW()-K$28) -> 2,2 | L30: =_xlfn.CONCAT(COLUMN()-$I30,",",ROW()-L$28) -> 3,2 | M30: =_xlfn.CONCAT(COLUMN()-$I30,",",ROW()-M$28) -> 4,2 | N30: =_xlfn.CONCAT(COLUMN()-$I30,",",ROW()-N$28) -> 5,2 | O30: =_xlfn.CONCAT(COLUMN()-$I30,",",ROW()-O$28) -> 6,2 | P30: =_xlfn.CONCAT(COLUMN()-$I30,",",ROW()-P$28) -> 7,2 | Q30: =_xlfn.CONCAT(COLUMN()-$I30,",",ROW()-Q$28) -> 8,2 | ... AW30: =_xlfn.CONCAT(COLUMN()-$I30,",",ROW()-AW$28) -> 40,2 | AX30: =AX29+1 -> 2 | AZ30: 1 | BA30: 0.948572 | BB30: 0.88655335 | BC30: 0.79074395 | BD30: 0.66638976 | BE30: 0.48199278 | BF30: 0 | BG30: 0 | BH30: 0 | BI30: 0 | BJ30: 0 | BK30: 0 | BL30: 0 | BM30: 0 | BN30: 0 | BO30: 0 | BP30: 0 | BQ30: 0 | BR30: 0 | BS30: 0 | BT30: 0 | BU30: 0 | BV30: 0 | BW30: 0 | BX30: 0 | BY30: 0 | BZ30: 0 | CA30: 0 | CB30: 0 | CC30: 0 | CD30: 0 | CE30: 0 | CF30: 0 | CG30: 0 | CH30: 0 | CI30: 0 | CJ30: 0 | CK30: 0 | CL30: 0 | CM30: 0 | CN30: 0 | CO30: 0 | CQ30: =_xlfn.IFS(CR30<=$CS$3,1,CR30<=$CS$4,2,CR30<=$CS$5,3) -> 1 | CR30: =CR29+1 -> 25 | CS30: 3 | CU30: =IF(CV30<=CU$4,1,2) -> 2 | CV30: 841.8 | CW30: =IF(CV30=0,0,(CV30/CW$5)-1) -> 13.03 | CY30: 868.75
E31: AT("[",B29,",",C29,",",D29,",",E29,"]") | I31: =COLUMN() -> 9 | J31: =_xlfn.CONCAT(COLUMN()-$I31,",",ROW()-J$28) -> 1,3 | K31: =_xlfn.CONCAT(COLUMN()-$I31,",",ROW()-K$28) -> 2,3 | L31: =_xlfn.CONCAT(COLUMN()-$I31,",",ROW()-L$28) -> 3,3 | M31: =_xlfn.CONCAT(COLUMN()-$I31,",",ROW()-M$28) -> 4,3 | N31: =_xlfn.CONCAT(COLUMN()-$I31,",",ROW()-N$28) -> 5,3 | O31: =_xlfn.CONCAT(COLUMN()-$I31,",",ROW()-O$28) -> 6,3 | P31: =_xlfn.CONCAT(COLUMN()-$I31,",",ROW()-P$28) -> 7,3 | Q31: =_xlfn.CONCAT(COLUMN()-$I31,",",ROW()-Q$28) -> 8,3 | ... AW31: =_xlfn.CONCAT(COLUMN()-$I31,",",ROW()-AW$28) -> 40,3 | AX31: =AX30+1 -> 3 | AZ31: 2 | BA31: 1.0602626 | BB31: 1.0773662 | BC31: 1.091384 | BD31: 1.0981272 | BE31: 1.1181705 | BF31: 1.3745644 | BG31: 1.267848 | BH31: 1.1889902 | BI31: 1.0942284 | BJ31: 0.9439585 | BK31: 0.673248 | BL31: 0 | BM31: 0 | BN31: 0 | BO31: 0 | BP31: 0 | BQ31: 0 | BR31: 0 | BS31: 0 | BT31: 0 | BU31: 0 | BV31: 0 | BW31: 0 | BX31: 0 | BY31: 0 | BZ31: 0 | CA31: 0 | CB31: 0 | CC31: 0 | CD31: 0 | CE31: 0 | CF31: 0 | CG31: 0 | CH31: 0 | CI31: 0 | CJ31: 0 | CK31: 0 | CL31: 0 | CM31: 0 | CN31: 0 | CO31: 0 | CQ31: =_xlfn.IFS(CR31<=$CS$3,1,CR31<=$CS$4,2,CR31<=$CS$5,3) -> 1 | CR31: =CR30+1 -> 26 | CS31: 3.0833333 | CU31: =IF(CV31<=CU$4,1,2) -> 2 | CV31: 878.4 | CW31: =IF(CV31=0,0,(CV31/CW$5)-1) -> 13.64 | CY31: 905
G32: =G21 -> 1,17 | I32: =COLUMN() -> 9 | J32: =_xlfn.CONCAT(COLUMN()-$I32,",",ROW()-J$28) -> 1,4 | K32: =_xlfn.CONCAT(COLUMN()-$I32,",",ROW()-K$28) -> 2,4 | L32: =_xlfn.CONCAT(COLUMN()-$I32,",",ROW()-L$28) -> 3,4 | M32: =_xlfn.CONCAT(COLUMN()-$I32,",",ROW()-M$28) -> 4,4 | N32: =_xlfn.CONCAT(COLUMN()-$I32,",",ROW()-N$28) -> 5,4 | O32: =_xlfn.CONCAT(COLUMN()-$I32,",",ROW()-O$28) -> 6,4 | P32: =_xlfn.CONCAT(COLUMN()-$I32,",",ROW()-P$28) -> 7,4 | Q32: =_xlfn.CONCAT(COLUMN()-$I32,",",ROW()-Q$28) -> 8,4 | ... AR32: =_xlfn.CONCAT(COLUMN()-$I32,",",ROW()-AR$28) -> 35,4 | AT32: =_xlfn.CONCAT(COLUMN()-$I32,",",ROW()-AT$28) -> 37,4 | AU32: =_xlfn.CONCAT(COLUMN()-$I32,",",ROW()-AU$28) -> 38,4 | AV32: =_xlfn.CONCAT(COLUMN()-$I32,",",ROW()-AV$28) -> 39,4 | AW32: =_xlfn.CONCAT(COLUMN()-$I32,",",ROW()-AW$28) -> 40,4 | AX32: =AX31+1 -> 4 | AZ32: 3 | BA32: 1.1051775 | BB32: 1.1142429 | BC32: 1.1272035 | BD32: 1.1448698 | BE32: 1.1794158 | BF32: 1.2556818 | BG32: 1.2399895 | BH32: 1.2048945 | BI32: 1.1691822 | BJ32: 1.1463714 | BK32: 1.1739556 | BL32: 1.5221155 | BM32: 1.3638835 | BN32: 1.241428 | BO32: 1.0840049 | BP32: 0.7801348 | BQ32: 0 | BR32: 0 | BS32: 0 | BT32: 0 | BU32: 0 | BV32: 0 | BW32: 0 | BX32: 0 | BY32: 0 | BZ32: 0 | CA32: 0 | CB32: 0 | CC32: 0 | CD32: 0 | CE32: 0 | CF32: 0 | CG32: 0 | CH32: 0 | CI32: 0 | CJ32: 0 | CK32: 0 | CL32: 0 | CM32: 0 | CN32: 0 | CO32: 0 | CQ32: =_xlfn.IFS(CR32<=$CS$3,1,CR32<=$CS$4,2,CR32<=$CS$5,3) -> 1 | CR32: =CR31+1 -> 27 | CS32: 3.1666667 | CU32: =IF(CV32<=CU$4,1,2) -> 2 | CV32: 915 | CW32: =IF(CV32=0,0,(CV32/CW$5)-1) -> 14.25 | CY32: 941.25
G33: =G22 -> 1,18 | I33: =COLUMN() -> 9 | J33: =_xlfn.CONCAT(COLUMN()-$I33,",",ROW()-J$28) -> 1,5 | K33: =_xlfn.CONCAT(COLUMN()-$I33,",",ROW()-K$28) -> 2,5 | L33: =_xlfn.CONCAT(COLUMN()-$I33,",",ROW()-L$28) -> 3,5 | M33: =_xlfn.CONCAT(COLUMN()-$I33,",",ROW()-M$28) -> 4,5 | N33: =_xlfn.CONCAT(COLUMN()-$I33,",",ROW()-N$28) -> 5,5 | O33: =_xlfn.CONCAT(COLUMN()-$I33,",",ROW()-O$28) -> 6,5 | P33: =_xlfn.CONCAT(COLUMN()-$I33,",",ROW()-P$28) -> 7,5 | Q33: =_xlfn.CONCAT(COLUMN()-$I33,",",ROW()-Q$28) -> 8,5 | ... AW33: =_xlfn.CONCAT(COLUMN()-$I33,",",ROW()-AW$28) -> 40,5 | AX33: =AX32+1 -> 5 | AZ33: 4 | BA33: 1.141027 | BB33: 1.1472244 | BC33: 1.1583171 | BD33: 1.1747329 | BE33: 1.1989415 | BF33: 1.2287571 | BG33: 1.2315336 | BH33: 1.2214161 | BI33: 1.2117884 | BJ33: 1.216417 | BK33: 1.2559175 | BL33: 1.3552593 | BM33: 1.3281069 | BN33: 1.2763958 | BO33: 1.2304517 | BP33: 1.2563995 | BQ33: 1.6669804 | BR33: 1.4987962 | BS33: 1.3892868 | BT33: 1.2816262 | BU33: 1.1253238 | BV33: 0.8117372 | BW33: 0 | BX33: 0 | BY33: 0 | BZ33: 0 | CA33: 0 | CB33: 0 | CC33: 0 | CD33: 0 | CE33: 0 | CF33: 0 | CG33: 0 | CH33: 0 | CI33: 0 | CJ33: 0 | CK33: 0 | CL33: 0 | CM33: 0 | CN33: 0 | CO33: 0 | CQ33: =_xlfn.IFS(CR33<=$CS$3,1,CR33<=$CS$4,2,CR33<=$CS$5,3) -> 1 | CR33: =CR32+1 -> 28 | CS33: 3.25 | CU33: =IF(CV33<=CU$4,1,2) -> 2 | CV33: 951.6 | CW33: =IF(CV33=0,0,(CV33/CW$5)-1) -> 14.86 | CY33: 977.5
