Workbook
Name a: #REF!
Name ai: #REF!
Name aq: #REF!
Name AV: #REF!
Name baa: #REF!
Name Coord: #REF!
Name CS: #REF!
Name CZ: #REF!
Name DG: #REF!
Name earlier: #REF!
Name EG: #REF!
Name EI: #REF!
Name HLinst: #REF!
Name HP: #REF!
Name I: #REF!
Name JA: #REF!
Name Mean_A: #REF!
Name mean_X: #REF!
Name mean_X.: #REF!
Name mean_Y: #REF!
Name mean_Y.: #REF!
Name mu: #REF!
Name mu_A: #REF!
Name mu_B: #REF!
Name P1_A: #REF!
Name P2_A: #REF!
Name P3_A: #REF!
Name P4_A: #REF!
Name P5_A: #REF!
Name Rot: #REF!
Name SD_A: #REF!
Name SD_X: #REF!
Name SD_Y: #REF!
Name sigma: #REF!
Name sigma_AB: #REF!
Name sigma2_A: #REF!
Name sigma2_B: #REF!
Name Tab.43: #REF!
Name Tab.44: #REF!
Name Target_P: #REF!
Name Total_Mass: #REF!
Name Variance_A: #REF!
Name X: #REF!
Name x_A: #REF!
Name x_B: #REF!
Name Xo: #REF!
Name Yo.1: #REF!
Name Yo.2: #REF!
Name yt: #REF!

Sheet T1
K1: =COLUMN() -> 11 | M1: =COLUMN() -> 13 | AD1: =COLUMN() -> 30 | AT1: =COLUMN() -> 46 | BE1: =COLUMN() -> 57
B2: DRN_L.csv | J2: Tacho
K3: =MAX(L3:V3) -> 7 | M3: =MAX(O3:X3) -> 7 | O3: =IF(ISNUMBER(O5),O4,"") -> 1 | P3: =IF(ISNUMBER(P5),P4,"") -> 2 | Q3: =IF(ISNUMBER(Q5),Q4,"") -> 3 | R3: =IF(ISNUMBER(R5),R4,"") -> 4 | S3: =IF(ISNUMBER(S5),S4,"") -> 5 | T3: =IF(ISNUMBER(T5),T4,"") -> 6 | U3: =IF(ISNUMBER(U5),U4,"") -> 7 | V3: =IF(ISNUMBER(V5),V4,"") | ... X3: =IF(ISNUMBER(X5),X4,"") | Y3: 1 | AB3: =IF(AB4=$CO$2,AB4,"") | AC3: =IF(AC4=$Y3,AC4,"") | AH3: =IF(AH4=$Y3,AH4,"") | BF3: =IF(BF4=$Y3,BF4,"") -> 1 | BH3: =IF(BH4=$Y3,BH4,"") | BI3: =IF(BI4=$Y3,BI4,"") | BJ3: =IF(BJ4=$Y3,BJ4,"")
O4: 1 | P4: =O4+1 -> 2 | Q4: =P4+1 -> 3 | R4: =Q4+1 -> 4 | S4: =R4+1 -> 5 | T4: =S4+1 -> 6 | U4: =T4+1 -> 7 | V4: =U4+1 -> 8 | W4: =V4+1 -> 9 | X4: =W4+1 -> 10 | AB4: 2 | AC4: 2 | AE4: i | AF4: i | AG4: 3 | AH4: 3 | AJ4: =COUNTIF($AB7:$AB42,"="&AJ5) -> 5 | AK4: =COUNTIF($AB7:$AB42,"="&AK5) -> 3 | AL4: =COUNTIF($AB7:$AB42,"="&AL5) -> 4 | AM4: =COUNTIF($AB7:$AB42,"="&AM5) -> 4 | AN4: =COUNTIF($AB7:$AB42,"="&AN5) -> 6 | AO4: =COUNTIF($AB7:$AB42,"="&AO5) -> 5 | AP4: =COUNTIF($AB7:$AB42,"="&AP5) -> 2 | AQ4: =COUNTIF($AB7:$AB42,"="&AQ5) -> 0 | ... AS4: =COUNTIF($AB7:$AB42,"="&AS5) -> 0 | AU4: 1 | AV4: 1 | AW4: 1 | AX4: 1 | AY4: 1 | AZ4: 1 | BA4: 1 | BB4: 1 | BC4: 1 | BD4: 1 | BF4: 1 | BH4: 4 | BI4: 5 | BJ4: 6
B5: REF. | D5: B | F5: new tests | O5: 1 | P5: 1 | Q5: 1 | R5: 1 | S5: 1 | T5: 1 | U5: 1 | AB5: =MAX(AB7:AB42) -> 7 | AE5: 0 | AF5: 0 | AG5: =MAX(AG7:AG42) -> 10 | AJ5: 1 | AK5: =AJ5+1 -> 2 | AL5: =AK5+1 -> 3 | AM5: =AL5+1 -> 4 | AN5: =AM5+1 -> 5 | AO5: =AN5+1 -> 6 | AP5: =AO5+1 -> 7 | AQ5: =AP5+1 -> 8 | AR5: =AQ5+1 -> 9 | AS5: =AR5+1 -> 10 | AU5: =AT4+1 -> 1 | AV5: =AU5+1 -> 2 | AW5: =AV5+1 -> 3 | AX5: =AW5+1 -> 4 | AY5: =AX5+1 -> 5 | AZ5: =AY5+1 -> 6 | BA5: =AZ5+1 -> 7 | BB5: =BA5+1 -> 8 | BC5: =BB5+1 -> 9 | BD5: =BC5+1 -> 10 | BF5: S_D
F6: X | G6: Y | H6: geometry | I6: Z | J6: Z | R6: X | S6: Y | T6: geometry | U6: Z | V6: Z2 | AA6: 1 | AB6: =IF(AA6=0,AB5,AA6) -> 1 | AE6: 0 | AF6: 0 | AG6: =IF(AD6=0,AG5,AD6) -> 10 | AJ6: =MAX(AJ7:AJ15) -> 5 | AK6: =MAX(AK7:AK15) -> 8 | AL6: =MAX(AL7:AL15) -> 12 | AM6: =MAX(AM7:AM15) -> 16 | AN6: =MAX(AN7:AN15) -> 22 | AO6: =MAX(AO7:AO15) -> 27 | AP6: =MAX(AP7:AP15) -> 29 | AQ6: =MAX(AQ7:AQ15) -> 0 | ... AS6: =MAX(AS7:AS15) -> 0 | AU6: x | AV6: x | AW6: x | AX6: x | AY6: x | AZ6: x | BA6: x | BB6: x | BC6: x | BD6: x | BG6: 0 | BH6: 1 | BI6: 2 | BJ6: 3
B7: =IF(ISNUMBER(C7),B6+1,"") -> 1 | C7: 471134.78 | D7: 7613992.8 | F7: 467509.78 | G7: 7616967.8 | H7: POINT (467509.7813 7616967.75) | I7: [989] | J7: 989 | L7: - | N7: =IF(ISNUMBER(O7),O7-1,"") -> 0 | O7: =IF(ISNUMBER(Q7),ROW()-ROW(O$6),"") -> 1 | P7: =IF($AB7=M$3,O7,"") | Q7: =IF(ISNUMBER(R7),Q6+1,"") -> 1 | R7: 467509.78 | S7: 7616967.8 | T7: POINT (467509.7813 7616967.75) | U7: [989] | V7: 989 | W7: =IF(ISNUMBER(R7),R7-MIN(R$7:R$42),"") -> 3337.5 | X7: =IF(ISNUMBER(R7),S7-MIN(S$7:S$42),"") -> 9037.5 | Y7: =IF(ISNUMBER(R7),_xlfn.IFS($Y$3=0,_xlfn.CONCAT(ROUND(W7,0),", ",ROUND(X7,0)),$Y$3=1,N7,$Y$3=2,_xlfn.CONCAT(AB7,AC7),$Y$3=3,_xlfn.CONCAT(AG7,AH7),$Y$3=4,BH7,$Y$3=5,BI7,$Y$3=6,BJ7),"") -> 0 | Z7: =Z8-Z8/3 -> 18.666667 | AA7: =IF(Z7<0,MAX(AA$6:AA6)+1,0) -> 0 | AB7: =IF(ISNUMBER(R7),IF(AA7=0,AB6,AA7),"") -> 1 | AC7: 1 | AE7: 0 | AF7: 0 | AG7: =IF(ISNUMBER(R7),AB7+AE7,"") -> 1 | AH7: =IF(ISNUMBER(S7),AC7+AF7,"") -> 1 | AJ7: =IF($O7<=AJ$4,$O7+AD$6,"") -> 1 | AK7: =IF($O7<=AK$4,$O7+AJ$6,"") -> 6 | AL7: =IF($O7<=AL$4,$O7+AK$6,"") -> 9 | AM7: =IF($O7<=AM$4,$O7+AL$6,"") -> 13 | AN7: =IF($O7<=AN$4,$O7+AM$6,"") -> 17 | AO7: =IF($O7<=AO$4,$O7+AN$6,"") -> 23 | AP7: =IF($O7<=AP$4,$O7+AO$6,"") -> 28 | AQ7: =IF($O7<=AQ$4,$O7+AP$6,"") | AR7: =IF($O7<=AR$4,$O7+AQ$6,"") | AS7: =IF($O7<=AS$4,$O7+AR$6,"") | AU7: =IF(ISNUMBER(AJ7),INDEX($R$7:$S$42,AJ7,AU$4),AU6) -> 467509.78 | AV7: =IF(ISNUMBER(AK7),INDEX($R$7:$S$42,AK7,AV$4),AV6) -> 471134.78 | AW7: =IF(ISNUMBER(AL7),INDEX($R$7:$S$42,AL7,AW$4),AW6) -> 469934.78 | AX7: =IF(ISNUMBER(AM7),INDEX($R$7:$S$42,AM7,AX$4),AX6) -> 468434.78 | AY7: =IF(ISNUMBER(AN7),INDEX($R$7:$S$42,AN7,AY$4),AY6) -> 464872.28 | AZ7: =IF(ISNUMBER(AO7),INDEX($R$7:$S$42,AO7,AZ$4),AZ6) -> 468284.78 | BA7: =IF(ISNUMBER(AP7),INDEX($R$7:$S$42,AP7,BA$4),BA6) -> 464822.28 | BB7: =IF(ISNUMBER(AQ7),INDEX($R$7:$S$42,AQ7,BB$4),BB6) -> x | ... BD7: =IF(ISNUMBER(AS7),INDEX($R$7:$S$42,AS7,BD$4),BD6) -> x | BF7: 0 | BG7: 0 | BH7: 0 | BI7: ←
B8: =IF(ISNUMBER(C8),B7+1,"") -> 2 | C8: 469922.28 | D8: 7614405.2 | F8: 468059.78 | G8: 7616642.8 | H8: POINT (468059.7813 7616642.75) | I8: [961] | J8: 961 | L8: =IF(ISNUMBER(R8),SQRT((R8-R7)^2+(S8-S7)^2),"") -> 638.84662 | N8: =IF(ISNUMBER(O8),O8-1,"") -> 1 | O8: =IF(ISNUMBER(Q8),ROW()-ROW(O$6),"") -> 2 | P8: =IF($AB8=M$3,O8,"") | Q8: =IF(ISNUMBER(R8),Q7+1,"") -> 2 | R8: 468059.78 | S8: 7616642.8 | T8: POINT (468059.7813 7616642.75) | U8: [961] | V8: 961 | W8: =IF(ISNUMBER(R8),R8-MIN(R$7:R$42),"") -> 3887.5 | X8: =IF(ISNUMBER(R8),S8-MIN(S$7:S$42),"") -> 8712.5 | Y8: =IF(ISNUMBER(R8),_xlfn.IFS($Y$3=0,_xlfn.CONCAT(ROUND(W8,0),", ",ROUND(X8,0)),$Y$3=1,N8,$Y$3=2,_xlfn.CONCAT(AB8,AC8),$Y$3=3,_xlfn.CONCAT(AG8,AH8),$Y$3=4,BH8,$Y$3=5,BI8,$Y$3=6,BJ8),"") -> 1 | Z8: =IF(ISNUMBER(R8),V7-V8,"") -> 28 | AA8: =IF(Z8<0,MAX(AA$6:AA7)+1,0) -> 0 | AB8: =IF(ISNUMBER(R8),IF(AA8=0,AB7,AA8),"") -> 1 | AC8: =IF(ISNUMBER(R7),IF(AA8<>0,1,AC7+1),"") -> 2 | AE8: 0 | AF8: 0 | AG8: =IF(ISNUMBER(R8),AB8+AE8,"") -> 1 | AH8: =IF(ISNUMBER(S8),AC8+AF8,"") -> 2 | AJ8: =IF($O8<=AJ$4,$O8+AD$6,"") -> 2 | AK8: =IF($O8<=AK$4,$O8+AJ$6,"") -> 7 | AL8: =IF($O8<=AL$4,$O8+AK$6,"") -> 10 | AM8: =IF($O8<=AM$4,$O8+AL$6,"") -> 14 | AN8: =IF($O8<=AN$4,$O8+AM$6,"") -> 18 | AO8: =IF($O8<=AO$4,$O8+AN$6,"") -> 24 | AP8: =IF($O8<=AP$4,$O8+AO$6,"") -> 29 | AQ8: =IF($O8<=AQ$4,$O8+AP$6,"") | AR8: =IF($O8<=AR$4,$O8+AQ$6,"") | AS8: =IF($O8<=AS$4,$O8+AR$6,"") | AU8: =IF(ISNUMBER(AJ8),INDEX($R$7:$S$42,AJ8,AU$4),AU7) -> 468059.78 | AV8: =IF(ISNUMBER(AK8),INDEX($R$7:$S$42,AK8,AV$4),AV7) -> 469922.28 | AW8: =IF(ISNUMBER(AL8),INDEX($R$7:$S$42,AL8,AW$4),AW7) -> 468797.28 | AX8: =IF(ISNUMBER(AM8),INDEX($R$7:$S$42,AM8,AX$4),AX7) -> 467384.78 | AY8: =IF(ISNUMBER(AN8),INDEX($R$7:$S$42,AN8,AY$4),AY7) -> 465422.28 | AZ8: =IF(ISNUMBER(AO8),INDEX($R$7:$S$42,AO8,AZ$4),AZ7) -> 466622.28 | BA8: =IF(ISNUMBER(AP8),INDEX($R$7:$S$42,AP8,BA$4),BA7) -> 464172.28 | BB8: =IF(ISNUMBER(AQ8),INDEX($R$7:$S$42,AQ8,BB$4),BB7) -> x | ... BD8: =IF(ISNUMBER(AS8),INDEX($R$7:$S$42,AS8,BD$4),BD7) -> x | BF8: 1 | BG8: 1 | BH8: =BH7+1 -> 1 | BI8: -1
B9: =IF(ISNUMBER(C9),B8+1,"") -> 3 | C9: 468834.78 | D9: 7614292.8 | F9: 468334.78 | G9: 7615805.2 | H9: POINT (468334.7813 7615805.25) | I9: [937] | J9: 937 | L9: =IF(ISNUMBER(R9),SQRT((R9-R8)^2+(S9-S8)^2),"") -> 881.49376 | N9: =IF(ISNUMBER(O9),O9-1,"") -> 2 | O9: =IF(ISNUMBER(Q9),ROW()-ROW(O$6),"") -> 3 | P9: =IF($AB9=M$3,O9,"") | Q9: =IF(ISNUMBER(R9),Q8+1,"") -> 3 | R9: 468334.78 | S9: 7615805.2 | T9: POINT (468334.7813 7615805.25) | U9: [937] | V9: 937 | W9: =IF(ISNUMBER(R9),R9-MIN(R$7:R$42),"") -> 4162.5 | X9: =IF(ISNUMBER(R9),S9-MIN(S$7:S$42),"") -> 7875 | Y9: =IF(ISNUMBER(R9),_xlfn.IFS($Y$3=0,_xlfn.CONCAT(ROUND(W9,0),", ",ROUND(X9,0)),$Y$3=1,N9,$Y$3=2,_xlfn.CONCAT(AB9,AC9),$Y$3=3,_xlfn.CONCAT(AG9,AH9),$Y$3=4,BH9,$Y$3=5,BI9,$Y$3=6,BJ9),"") -> 2 | Z9: =IF(ISNUMBER(R9),V8-V9,"") -> 24 | AA9: =IF(Z9<0,MAX(AA$6:AA8)+1,0) -> 0 | AB9: =IF(ISNUMBER(R9),IF(AA9=0,AB8,AA9),"") -> 1 | AC9: =IF(ISNUMBER(R8),IF(AA9<>0,1,AC8+1),"") -> 3 | AE9: 0 | AF9: 0 | AG9: =IF(ISNUMBER(R9),AB9+AE9,"") -> 1 | AH9: =IF(ISNUMBER(S9),AC9+AF9,"") -> 3 | AJ9: =IF($O9<=AJ$4,$O9+AD$6,"") -> 3 | AK9: =IF($O9<=AK$4,$O9+AJ$6,"") -> 8 | AL9: =IF($O9<=AL$4,$O9+AK$6,"") -> 11 | AM9: =IF($O9<=AM$4,$O9+AL$6,"") -> 15 | AN9: =IF($O9<=AN$4,$O9+AM$6,"") -> 19 | AO9: =IF($O9<=AO$4,$O9+AN$6,"") -> 25 | AP9: =IF($O9<=AP$4,$O9+AO$6,"") | AQ9: =IF($O9<=AQ$4,$O9+AP$6,"") | AR9: =IF($O9<=AR$4,$O9+AQ$6,"") | AS9: =IF($O9<=AS$4,$O9+AR$6,"") | AU9: =IF(ISNUMBER(AJ9),INDEX($R$7:$S$42,AJ9,AU$4),AU8) -> 468334.78 | AV9: =IF(ISNUMBER(AK9),INDEX($R$7:$S$42,AK9,AV$4),AV8) -> 468834.78 | AW9: =IF(ISNUMBER(AL9),INDEX($R$7:$S$42,AL9,AW$4),AW8) -> 467797.28 | AX9: =IF(ISNUMBER(AM9),INDEX($R$7:$S$42,AM9,AX$4),AX8) -> 466597.28 | AY9: =IF(ISNUMBER(AN9),INDEX($R$7:$S$42,AN9,AY$4),AY8) -> 465284.78 | AZ9: =IF(ISNUMBER(AO9),INDEX($R$7:$S$42,AO9,AZ$4),AZ8) -> 466097.28 | BA9: =IF(ISNUMBER(AP9),INDEX($R$7:$S$42,AP9,BA$4),BA8) -> 464172.28 | BB9: =IF(ISNUMBER(AQ9),INDEX($R$7:$S$42,AQ9,BB$4),BB8) -> x | ... BD9: =IF(ISNUMBER(AS9),INDEX($R$7:$S$42,AS9,BD$4),BD8) -> x | BF9: 2 | BG9: 2 | BH9: =BH8+1 -> 2 | BI9: =BI8-1 -> -2
B10: =IF(ISNUMBER(C10),B9+1,"") -> 4 | C10: 467509.78 | D10: 7616967.8 | F10: 468397.28 | G10: 7614955.2 | H10: POINT (468397.2813 7614955.25) | I10: [903] | J10: 903 | L10: =IF(ISNUMBER(R10),SQRT((R10-R9)^2+(S10-S9)^2),"") -> 852.2947 | N10: =IF(ISNUMBER(O10),O10-1,"") -> 3 | O10: =IF(ISNUMBER(Q10),ROW()-ROW(O$6),"") -> 4 | P10: =IF($AB10=M$3,O10,"") | Q10: =IF(ISNUMBER(R10),Q9+1,"") -> 4 | R10: 468397.28 | S10: 7614955.2 | T10: POINT (468397.2813 7614955.25) | U10: [903] | V10: 903 | W10: =IF(ISNUMBER(R10),R10-MIN(R$7:R$42),"") -> 4225 | X10: =IF(ISNUMBER(R10),S10-MIN(S$7:S$42),"") -> 7025 | Y10: =IF(ISNUMBER(R10),_xlfn.IFS($Y$3=0,_xlfn.CONCAT(ROUND(W10,0),", ",ROUND(X10,0)),$Y$3=1,N10,$Y$3=2,_xlfn.CONCAT(AB10,AC10),$Y$3=3,_xlfn.CONCAT(AG10,AH10),$Y$3=4,BH10,$Y$3=5,BI10,$Y$3=6,BJ10),"") -> 3 | Z10: =IF(ISNUMBER(R10),V9-V10,"") -> 34 | AA10: =IF(Z10<0,MAX(AA$6:AA9)+1,0) -> 0 | AB10: =IF(ISNUMBER(R10),IF(AA10=0,AB9,AA10),"") -> 1 | AC10: =IF(ISNUMBER(R9),IF(AA10<>0,1,AC9+1),"") -> 4 | AE10: 0 | AF10: 0 | AG10: =IF(ISNUMBER(R10),AB10+AE10,"") -> 1 | AH10: =IF(ISNUMBER(S10),AC10+AF10,"") -> 4 | AJ10: =IF($O10<=AJ$4,$O10+AD$6,"") -> 4 | AK10: =IF($O10<=AK$4,$O10+AJ$6,"") | AL10: =IF($O10<=AL$4,$O10+AK$6,"") -> 12 | AM10: =IF($O10<=AM$4,$O10+AL$6,"") -> 16 | AN10: =IF($O10<=AN$4,$O10+AM$6,"") -> 20 | AO10: =IF($O10<=AO$4,$O10+AN$6,"") -> 26 | AP10: =IF($O10<=AP$4,$O10+AO$6,"") | AQ10: =IF($O10<=AQ$4,$O10+AP$6,"") | AR10: =IF($O10<=AR$4,$O10+AQ$6,"") | AS10: =IF($O10<=AS$4,$O10+AR$6,"") | AU10: =IF(ISNUMBER(AJ10),INDEX($R$7:$S$42,AJ10,AU$4),AU9) -> 468397.28 | AV10: =IF(ISNUMBER(AK10),INDEX($R$7:$S$42,AK10,AV$4),AV9) -> 468834.78 | AW10: =IF(ISNUMBER(AL10),INDEX($R$7:$S$42,AL10,AW$4),AW9) -> 467172.28 | AX10: =IF(ISNUMBER(AM10),INDEX($R$7:$S$42,AM10,AX$4),AX9) -> 465672.28 | AY10: =IF(ISNUMBER(AN10),INDEX($R$7:$S$42,AN10,AY$4),AY9) -> 464384.78 | AZ10: =IF(ISNUMBER(AO10),INDEX($R$7:$S$42,AO10,AZ$4),AZ9) -> 465534.78 | BA10: =IF(ISNUMBER(AP10),INDEX($R$7:$S$42,AP10,BA$4),BA9) -> 464172.28 | BB10: =IF(ISNUMBER(AQ10),INDEX($R$7:$S$42,AQ10,BB$4),BB9) -> x | ... BD10: =IF(ISNUMBER(AS10),INDEX($R$7:$S$42,AS10,BD$4),BD9) -> x | BF10: 3 | BG10: 3 | BH10: =BH9+1 -> 3 | BI10: =BI9-1 -> -3
B11: =IF(ISNUMBER(C11),B10+1,"") -> 5 | C11: 468059.78 | D11: 7616642.8 | F11: 468047.28 | G11: 7614180.2 | H11: POINT (468047.2813 7614180.25) | I11: [889] | J11: 889 | L11: =IF(ISNUMBER(R11),SQRT((R11-R10)^2+(S11-S10)^2),"") -> 850.36757 | N11: =IF(ISNUMBER(O11),O11-1,"") -> 4 | O11: =IF(ISNUMBER(Q11),ROW()-ROW(O$6),"") -> 5 | P11: =IF($AB11=M$3,O11,"") | Q11: =IF(ISNUMBER(R11),Q10+1,"") -> 5 | R11: 468047.28 | S11: 7614180.2 | T11: POINT (468047.2813 7614180.25) | U11: [889] | V11: 889 | W11: =IF(ISNUMBER(R11),R11-MIN(R$7:R$42),"") -> 3875 | X11: =IF(ISNUMBER(R11),S11-MIN(S$7:S$42),"") -> 6250 | Y11: =IF(ISNUMBER(R11),_xlfn.IFS($Y$3=0,_xlfn.CONCAT(ROUND(W11,0),", ",ROUND(X11,0)),$Y$3=1,N11,$Y$3=2,_xlfn.CONCAT(AB11,AC11),$Y$3=3,_xlfn.CONCAT(AG11,AH11),$Y$3=4,BH11,$Y$3=5,BI11,$Y$3=6,BJ11),"") -> 4 | Z11: =IF(ISNUMBER(R11),V10-V11,"") -> 14 | AA11: =IF(Z11<0,MAX(AA$6:AA10)+1,0) -> 0 | AB11: =IF(ISNUMBER(R11),IF(AA11=0,AB10,AA11),"") -> 1 | AC11: =IF(ISNUMBER(R10),IF(AA11<>0,1,AC10+1),"") -> 5 | AE11: 0 | AF11: 0 | AG11: =IF(ISNUMBER(R11),AB11+AE11,"") -> 1 | AH11: =IF(ISNUMBER(S11),AC11+AF11,"") -> 5 | AJ11: =IF($O11<=AJ$4,$O11+AD$6,"") -> 5 | AK11: =IF($O11<=AK$4,$O11+AJ$6,"") | AL11: =IF($O11<=AL$4,$O11+AK$6,"") | AM11: =IF($O11<=AM$4,$O11+AL$6,"") | AN11: =IF($O11<=AN$4,$O11+AM$6,"") -> 21 | AO11: =IF($O11<=AO$4,$O11+AN$6,"") -> 27 | AP11: =IF($O11<=AP$4,$O11+AO$6,"") | AQ11: =IF($O11<=AQ$4,$O11+AP$6,"") | AR11: =IF($O11<=AR$4,$O11+AQ$6,"") | AS11: =IF($O11<=AS$4,$O11+AR$6,"") | AU11: =IF(ISNUMBER(AJ11),INDEX($R$7:$S$42,AJ11,AU$4),AU10) -> 468047.28 | AV11: =IF(ISNUMBER(AK11),INDEX($R$7:$S$42,AK11,AV$4),AV10) -> 468834.78 | AW11: =IF(ISNUMBER(AL11),INDEX($R$7:$S$42,AL11,AW$4),AW10) -> 467172.28 | AX11: =IF(ISNUMBER(AM11),INDEX($R$7:$S$42,AM11,AX$4),AX10) -> 465672.28 | AY11: =IF(ISNUMBER(AN11),INDEX($R$7:$S$42,AN11,AY$4),AY10) -> 464297.28 | AZ11: =IF(ISNUMBER(AO11),INDEX($R$7:$S$42,AO11,AZ$4),AZ10) -> 464909.78 | BA11: =IF(ISNUMBER(AP11),INDEX($R$7:$S$42,AP11,BA$4),BA10) -> 464172.28 | BB11: =IF(ISNUMBER(AQ11),INDEX($R$7:$S$42,AQ11,BB$4),BB10) -> x | ... BD11: =IF(ISNUMBER(AS11),INDEX($R$7:$S$42,AS11,BD$4),BD10) -> x | BF11: 4 | BG11: 4 | BH11: =BH10+1 -> 4 | BI11: =BI10-1 -> -4
B12: =IF(ISNUMBER(C12),B11+1,"") -> 6 | C12: 468334.78 | D12: 7615805.2 | F12: 471134.78 | G12: 7613992.8 | H12: POINT (471134.7813 7613992.75) | I12: [1001] | J12: 1001 | L12: =IF(ISNUMBER(R12),SQRT((R12-R11)^2+(S12-S11)^2),"") -> 3093.1881 | N12: =IF(ISNUMBER(O12),O12-1,"") -> 5 | O12: =IF(ISNUMBER(Q12),ROW()-ROW(O$6),"") -> 6 | P12: =IF($AB12=M$3,O12,"") | Q12: =IF(ISNUMBER(R12),Q11+1,"") -> 6 | R12: 471134.78 | S12: 7613992.8 | T12: POINT (471134.7813 7613992.75) | U12: [1001] | V12: 1001 | W12: =IF(ISNUMBER(R12),R12-MIN(R$7:R$42),"") -> 6962.5 | X12: =IF(ISNUMBER(R12),S12-MIN(S$7:S$42),"") -> 6062.5 | Y12: =IF(ISNUMBER(R12),_xlfn.IFS($Y$3=0,_xlfn.CONCAT(ROUND(W12,0),", ",ROUND(X12,0)),$Y$3=1,N12,$Y$3=2,_xlfn.CONCAT(AB12,AC12),$Y$3=3,_xlfn.CONCAT(AG12,AH12),$Y$3=4,BH12,$Y$3=5,BI12,$Y$3=6,BJ12),"") -> 5 | Z12: =IF(ISNUMBER(R12),V11-V12,"") -> -112 | AA12: =IF(Z12<0,MAX(AA$6:AA11)+1,0) -> 2 | AB12: =IF(ISNUMBER(R12),IF(AA12=0,AB11,AA12),"") -> 2 | AC12: =IF(ISNUMBER(R11),IF(AA12<>0,1,AC11+1),"") -> 1 | AE12: 0 | AF12: 0 | AG12: =IF(ISNUMBER(R12),AB12+AE12,"") -> 2 | AH12: =IF(ISNUMBER(S12),AC12+AF12,"") -> 1 | AJ12: =IF($O12<=AJ$4,$O12+AD$6,"") | AK12: =IF($O12<=AK$4,$O12+AJ$6,"") | AL12: =IF($O12<=AL$4,$O12+AK$6,"") | AM12: =IF($O12<=AM$4,$O12+AL$6,"") | AN12: =IF($O12<=AN$4,$O12+AM$6,"") -> 22 | AO12: =IF($O12<=AO$4,$O12+AN$6,"") | AP12: =IF($O12<=AP$4,$O12+AO$6,"") | AQ12: =IF($O12<=AQ$4,$O12+AP$6,"") | AR12: =IF($O12<=AR$4,$O12+AQ$6,"") | AS12: =IF($O12<=AS$4,$O12+AR$6,"") | AU12: =IF(ISNUMBER(AJ12),INDEX($R$7:$S$42,AJ12,AU$4),AU11) -> 468047.28 | AV12: =IF(ISNUMBER(AK12),INDEX($R$7:$S$42,AK12,AV$4),AV11) -> 468834.78 | AW12: =IF(ISNUMBER(AL12),INDEX($R$7:$S$42,AL12,AW$4),AW11) -> 467172.28 | AX12: =IF(ISNUMBER(AM12),INDEX($R$7:$S$42,AM12,AX$4),AX11) -> 465672.28 | AY12: =IF(ISNUMBER(AN12),INDEX($R$7:$S$42,AN12,AY$4),AY11) -> 464784.78 | AZ12: =IF(ISNUMBER(AO12),INDEX($R$7:$S$42,AO12,AZ$4),AZ11) -> 464909.78 | BA12: =IF(ISNUMBER(AP12),INDEX($R$7:$S$42,AP12,BA$4),BA11) -> 464172.28 | BB12: =IF(ISNUMBER(AQ12),INDEX($R$7:$S$42,AQ12,BB$4),BB11) -> x | ... BD12: =IF(ISNUMBER(AS12),INDEX($R$7:$S$42,AS12,BD$4),BD11) -> x | BF12: 5 | BG12: 5 | BH12: 5 | BI12: =BI11-1 -> -5
B13: =IF(ISNUMBER(C13),B12+1,"") -> 7 | C13: 468397.28 | D13: 7614955.2 | F13: 469922.28 | G13: 7614405.2 | H13: POINT (469922.2813 7614405.25) | I13: [976] | J13: 976 | L13: =IF(ISNUMBER(R13),SQRT((R13-R12)^2+(S13-S12)^2),"") -> 1280.7469 | N13: =IF(ISNUMBER(O13),O13-1,"") -> 6 | O13: =IF(ISNUMBER(Q13),ROW()-ROW(O$6),"") -> 7 | P13: =IF($AB13=M$3,O13,"") | Q13: =IF(ISNUMBER(R13),Q12+1,"") -> 7 | R13: 469922.28 | S13: 7614405.2 | T13: POINT (469922.2813 7614405.25) | U13: [976] | V13: 976 | W13: =IF(ISNUMBER(R13),R13-MIN(R$7:R$42),"") -> 5750 | X13: =IF(ISNUMBER(R13),S13-MIN(S$7:S$42),"") -> 6475 | Y13: =IF(ISNUMBER(R13),_xlfn.IFS($Y$3=0,_xlfn.CONCAT(ROUND(W13,0),", ",ROUND(X13,0)),$Y$3=1,N13,$Y$3=2,_xlfn.CONCAT(AB13,AC13),$Y$3=3,_xlfn.CONCAT(AG13,AH13),$Y$3=4,BH13,$Y$3=5,BI13,$Y$3=6,BJ13),"") -> 6 | Z13: =IF(ISNUMBER(R13),V12-V13,"") -> 25 | AA13: =IF(Z13<0,MAX(AA$6:AA12)+1,0) -> 0 | AB13: =IF(ISNUMBER(R13),IF(AA13=0,AB12,AA13),"") -> 2 | AC13: =IF(ISNUMBER(R12),IF(AA13<>0,1,AC12+1),"") -> 2 | AE13: 0 | AF13: 0 | AG13: =IF(ISNUMBER(R13),AB13+AE13,"") -> 2 | AH13: =IF(ISNUMBER(S13),AC13+AF13,"") -> 2 | AJ13: =IF($O13<=AJ$4,$O13+AD$6,"") | AK13: =IF($O13<=AK$4,$O13+AJ$6,"") | AL13: =IF($O13<=AL$4,$O13+AK$6,"") | AM13: =IF($O13<=AM$4,$O13+AL$6,"") | AN13: =IF($O13<=AN$4,$O13+AM$6,"") | AO13: =IF($O13<=AO$4,$O13+AN$6,"") | AP13: =IF($O13<=AP$4,$O13+AO$6,"") | AQ13: =IF($O13<=AQ$4,$O13+AP$6,"") | AR13: =IF($O13<=AR$4,$O13+AQ$6,"") | AS13: =IF($O13<=AS$4,$O13+AR$6,"") | AU13: =IF(ISNUMBER(AJ13),INDEX($R$7:$S$42,AJ13,AU$4),AU12) -> 468047.28 | AV13: =IF(ISNUMBER(AK13),INDEX($R$7:$S$42,AK13,AV$4),AV12) -> 468834.78 | AW13: =IF(ISNUMBER(AL13),INDEX($R$7:$S$42,AL13,AW$4),AW12) -> 467172.28 | AX13: =IF(ISNUMBER(AM13),INDEX($R$7:$S$42,AM13,AX$4),AX12) -> 465672.28 | AY13: =IF(ISNUMBER(AN13),INDEX($R$7:$S$42,AN13,AY$4),AY12) -> 464784.78 | AZ13: =IF(ISNUMBER(AO13),INDEX($R$7:$S$42,AO13,AZ$4),AZ12) -> 464909.78 | BA13: =IF(ISNUMBER(AP13),INDEX($R$7:$S$42,AP13,BA$4),BA12) -> 464172.28 | BB13: =IF(ISNUMBER(AQ13),INDEX($R$7:$S$42,AQ13,BB$4),BB12) -> x | ... BD13: =IF(ISNUMBER(AS13),INDEX($R$7:$S$42,AS13,BD$4),BD12) -> x | BF13: 6 | BG13: 6 | BH13: 6 | BI13: =BI12-1 -> -6
B14: =IF(ISNUMBER(C14),B13+1,"") -> 8 | C14: 468047.28 | D14: 7614180.2 | F14: 468834.78 | G14: 7614292.8 | H14: POINT (468834.7813 7614292.75) | I14: [907] | J14: 907 | L14: =IF(ISNUMBER(R14),SQRT((R14-R13)^2+(S14-S13)^2),"") -> 1093.3035 | N14: =IF(ISNUMBER(O14),O14-1,"") -> 7 | O14: =IF(ISNUMBER(Q14),ROW()-ROW(O$6),"") -> 8 | P14: =IF($AB14=M$3,O14,"") | Q14: =IF(ISNUMBER(R14),Q13+1,"") -> 8 | R14: 468834.78 | S14: 7614292.8 | T14: POINT (468834.7813 7614292.75) | U14: [907] | V14: 907 | W14: =IF(ISNUMBER(R14),R14-MIN(R$7:R$42),"") -> 4662.5 | X14: =IF(ISNUMBER(R14),S14-MIN(S$7:S$42),"") -> 6362.5 | Y14: =IF(ISNUMBER(R14),_xlfn.IFS($Y$3=0,_xlfn.CONCAT(ROUND(W14,0),", ",ROUND(X14,0)),$Y$3=1,N14,$Y$3=2,_xlfn.CONCAT(AB14,AC14),$Y$3=3,_xlfn.CONCAT(AG14,AH14),$Y$3=4,BH14,$Y$3=5,BI14,$Y$3=6,BJ14),"") -> 7 | Z14: =IF(ISNUMBER(R14),V13-V14,"") -> 69 | AA14: =IF(Z14<0,MAX(AA$6:AA13)+1,0) -> 0 | AB14: =IF(ISNUMBER(R14),IF(AA14=0,AB13,AA14),"") -> 2 | AC14: =IF(ISNUMBER(R13),IF(AA14<>0,1,AC13+1),"") -> 3 | AE14: 0 | AF14: 0 | AG14: =IF(ISNUMBER(R14),AB14+AE14,"") -> 2 | AH14: =IF(ISNUMBER(S14),AC14+AF14,"") -> 3 | AJ14: =IF($O14<=AJ$4,$O14+AD$6,"") | AK14: =IF($O14<=AK$4,$O14+AJ$6,"") | AL14: =IF($O14<=AL$4,$O14+AK$6,"") | AM14: =IF($O14<=AM$4,$O14+AL$6,"") | AN14: =IF($O14<=AN$4,$O14+AM$6,"") | AO14: =IF($O14<=AO$4,$O14+AN$6,"") | AP14: =IF($O14<=AP$4,$O14+AO$6,"") | AQ14: =IF($O14<=AQ$4,$O14+AP$6,"") | AR14: =IF($O14<=AR$4,$O14+AQ$6,"") | AS14: =IF($O14<=AS$4,$O14+AR$6,"") | AU14: =IF(ISNUMBER(AJ14),INDEX($R$7:$S$42,AJ14,AU$4),AU13) -> 468047.28 | AV14: =IF(ISNUMBER(AK14),INDEX($R$7:$S$42,AK14,AV$4),AV13) -> 468834.78 | AW14: =IF(ISNUMBER(AL14),INDEX($R$7:$S$42,AL14,AW$4),AW13) -> 467172.28 | AX14: =IF(ISNUMBER(AM14),INDEX($R$7:$S$42,AM14,AX$4),AX13) -> 465672.28 | AY14: =IF(ISNUMBER(AN14),INDEX($R$7:$S$42,AN14,AY$4),AY13) -> 464784.78 | AZ14: =IF(ISNUMBER(AO14),INDEX($R$7:$S$42,AO14,AZ$4),AZ13) -> 464909.78 | BA14: =IF(ISNUMBER(AP14),INDEX($R$7:$S$42,AP14,BA$4),BA13) -> 464172.28 | BB14: =IF(ISNUMBER(AQ14),INDEX($R$7:$S$42,AQ14,BB$4),BB13) -> x | ... BD14: =IF(ISNUMBER(AS14),INDEX($R$7:$S$42,AS14,BD$4),BD13) -> x | BF14: 7 | BG14: 7 | BH14: 7 | BI14: =BI13-1 -> -7
B15: =IF(ISNUMBER(C15),B14+1,"") -> 9 | C15: 468834.78 | D15: 7614292.8 | F15: 469934.78 | G15: 7612342.8 | H15: POINT (469934.7813 7612342.75) | I15: [969] | J15: 969 | L15: =IF(ISNUMBER(R15),SQRT((R15-R14)^2+(S15-S14)^2),"") -> 2238.8613 | N15: =IF(ISNUMBER(O15),O15-1,"") -> 8 | O15: =IF(ISNUMBER(Q15),ROW()-ROW(O$6),"") -> 9 | P15: =IF($AB15=M$3,O15,"") | Q15: =IF(ISNUMBER(R15),Q14+1,"") -> 9 | R15: 469934.78 | S15: 7612342.8 | T15: POINT (469934.7813 7612342.75) | U15: [969] | V15: 969 | W15: =IF(ISNUMBER(R15),R15-MIN(R$7:R$42),"") -> 5762.5 | X15: =IF(ISNUMBER(R15),S15-MIN(S$7:S$42),"") -> 4412.5 | Y15: =IF(ISNUMBER(R15),_xlfn.IFS($Y$3=0,_xlfn.CONCAT(ROUND(W15,0),", ",ROUND(X15,0)),$Y$3=1,N15,$Y$3=2,_xlfn.CONCAT(AB15,AC15),$Y$3=3,_xlfn.CONCAT(AG15,AH15),$Y$3=4,BH15,$Y$3=5,BI15,$Y$3=6,BJ15),"") -> 8 | Z15: =IF(ISNUMBER(R15),V14-V15,"") -> -62 | AA15: =IF(Z15<0,MAX(AA$6:AA14)+1,0) -> 3 | AB15: =IF(ISNUMBER(R15),IF(AA15=0,AB14,AA15),"") -> 3 | AC15: =IF(ISNUMBER(R14),IF(AA15<>0,1,AC14+1),"") -> 1 | AE15: 0 | AF15: 0 | AG15: =IF(ISNUMBER(R15),AB15+AE15,"") -> 3 | AH15: =IF(ISNUMBER(S15),AC15+AF15,"") -> 1 | AJ15: =IF($O15<=AJ$4,$O15+AD$6,"") | AK15: =IF($O15<=AK$4,$O15+AJ$6,"") | AL15: =IF($O15<=AL$4,$O15+AK$6,"") | AM15: =IF($O15<=AM$4,$O15+AL$6,"") | AN15: =IF($O15<=AN$4,$O15+AM$6,"") | AO15: =IF($O15<=AO$4,$O15+AN$6,"") | AP15: =IF($O15<=AP$4,$O15+AO$6,"") | AQ15: =IF($O15<=AQ$4,$O15+AP$6,"") | AR15: =IF($O15<=AR$4,$O15+AQ$6,"") | AS15: =IF($O15<=AS$4,$O15+AR$6,"") | AU15: =IF(ISNUMBER(AJ15),INDEX($R$7:$S$42,AJ15,AU$4),AU14) -> 468047.28 | AV15: =IF(ISNUMBER(AK15),INDEX($R$7:$S$42,AK15,AV$4),AV14) -> 468834.78 | AW15: =IF(ISNUMBER(AL15),INDEX($R$7:$S$42,AL15,AW$4),AW14) -> 467172.28 | AX15: =IF(ISNUMBER(AM15),INDEX($R$7:$S$42,AM15,AX$4),AX14) -> 465672.28 | AY15: =IF(ISNUMBER(AN15),INDEX($R$7:$S$42,AN15,AY$4),AY14) -> 464784.78 | AZ15: =IF(ISNUMBER(AO15),INDEX($R$7:$S$42,AO15,AZ$4),AZ14) -> 464909.78 | BA15: =IF(ISNUMBER(AP15),INDEX($R$7:$S$42,AP15,BA$4),BA14) -> 464172.28 | BB15: =IF(ISNUMBER(AQ15),INDEX($R$7:$S$42,AQ15,BB$4),BB14) -> x | ... BD15: =IF(ISNUMBER(AS15),INDEX($R$7:$S$42,AS15,BD$4),BD14) -> x | BF15: 8 | BG15: 8 | BH15: 8 | BI15: -9
B16: =IF(ISNUMBER(C16),B15+1,"") -> 10 | C16: 468047.28 | D16: 7614180.2 | F16: 468797.28 | G16: 7612842.8 | H16: POINT (468797.2813 7612842.75) | I16: [911] | J16: 911 | L16: =IF(ISNUMBER(R16),SQRT((R16-R15)^2+(S16-S15)^2),"") -> 1242.5402 | N16: =IF(ISNUMBER(O16),O16-1,"") -> 9 | O16: =IF(ISNUMBER(Q16),ROW()-ROW(O$6),"") -> 10 | P16: =IF($AB16=M$3,O16,"") | Q16: =IF(ISNUMBER(R16),Q15+1,"") -> 10 | R16: 468797.28 | S16: 7612842.8 | T16: POINT (468797.2813 7612842.75) | U16: [911] | V16: 911 | W16: =IF(ISNUMBER(R16),R16-MIN(R$7:R$42),"") -> 4625 | X16: =IF(ISNUMBER(R16),S16-MIN(S$7:S$42),"") -> 4912.5 | Y16: =IF(ISNUMBER(R16),_xlfn.IFS($Y$3=0,_xlfn.CONCAT(ROUND(W16,0),", ",ROUND(X16,0)),$Y$3=1,N16,$Y$3=2,_xlfn.CONCAT(AB16,AC16),$Y$3=3,_xlfn.CONCAT(AG16,AH16),$Y$3=4,BH16,$Y$3=5,BI16,$Y$3=6,BJ16),"") -> 9 | Z16: =IF(ISNUMBER(R16),V15-V16,"") -> 58 | AA16: =IF(Z16<0,MAX(AA$6:AA15)+1,0) -> 0 | AB16: =IF(ISNUMBER(R16),IF(AA16=0,AB15,AA16),"") -> 3 | AC16: =IF(ISNUMBER(R15),IF(AA16<>0,1,AC15+1),"") -> 2 | AE16: 0 | AF16: 0 | AG16: =IF(ISNUMBER(R16),AB16+AE16,"") -> 3 | AH16: =IF(ISNUMBER(S16),AC16+AF16,"") -> 2 | BF16: 9 | BG16: 9 | BH16: 9 | BI16: =BI15-1 -> -10
B17: =IF(ISNUMBER(C17),B16+1,"") -> 11 | C17: 467797.28 | D17: 7613980.2 | F17: 467797.28 | G17: 7613980.2 | H17: POINT (467797.2813 7613980.25) | I17: [888] | J17: 888 | L17: =IF(ISNUMBER(R17),SQRT((R17-R16)^2+(S17-S16)^2),"") -> 1514.5647 | N17: =IF(ISNUMBER(O17),O17-1,"") -> 10 | O17: =IF(ISNUMBER(Q17),ROW()-ROW(O$6),"") -> 11 | P17: =IF($AB17=M$3,O17,"") | Q17: =IF(ISNUMBER(R17),Q16+1,"") -> 11 | R17: 467797.28 | S17: 7613980.2 | T17: POINT (467797.2813 7613980.25) | U17: [888] | V17: 888 | W17: =IF(ISNUMBER(R17),R17-MIN(R$7:R$42),"") -> 3625 | X17: =IF(ISNUMBER(R17),S17-MIN(S$7:S$42),"") -> 6050 | Y17: =IF(ISNUMBER(R17),_xlfn.IFS($Y$3=0,_xlfn.CONCAT(ROUND(W17,0),", ",ROUND(X17,0)),$Y$3=1,N17,$Y$3=2,_xlfn.CONCAT(AB17,AC17),$Y$3=3,_xlfn.CONCAT(AG17,AH17),$Y$3=4,BH17,$Y$3=5,BI17,$Y$3=6,BJ17),"") -> 10 | Z17: =IF(ISNUMBER(R17),V16-V17,"") -> 23 | AA17: =IF(Z17<0,MAX(AA$6:AA16)+1,0) -> 0 | AB17: =IF(ISNUMBER(R17),IF(AA17=0,AB16,AA17),"") -> 3 | AC17: =IF(ISNUMBER(R16),IF(AA17<>0,1,AC16+1),"") -> 3 | AE17: 1 | AF17: -2 | AG17: =IF(ISNUMBER(R17),AB17+AE17,"") -> 4 | AH17: =IF(ISNUMBER(S17),AC17+AF17,"") -> 1 | AU17: 2 | AV17: 2 | AW17: 2 | AX17: 2 | AY17: 2 | AZ17: 2 | BA17: 2 | BB17: 2 | BC17: 2 | BD17: 2 | BF17: 10 | BG17: 10 | BH17: 10 | BI17: -12 | BJ17: -8 | BK17: -11
B18: =IF(ISNUMBER(C18),B17+1,"") -> 12 | C18: 469934.78 | D18: 7612342.8 | F18: 467172.28 | G18: 7613492.8 | H18: POINT (467172.2813 7613492.75) | I18: [880] | J18: 880 | L18: =IF(ISNUMBER(R18),SQRT((R18-R17)^2+(S18-S17)^2),"") -> 792.64194 | N18: =IF(ISNUMBER(O18),O18-1,"") -> 11 | O18: =IF(ISNUMBER(Q18),ROW()-ROW(O$6),"") -> 12 | P18: =IF($AB18=M$3,O18,"") | Q18: =IF(ISNUMBER(R18),Q17+1,"") -> 12 | R18: 467172.28 | S18: 7613492.8 | T18: POINT (467172.2813 7613492.75) | U18: [880] | V18: 880 | W18: =IF(ISNUMBER(R18),R18-MIN(R$7:R$42),"") -> 3000 | X18: =IF(ISNUMBER(R18),S18-MIN(S$7:S$42),"") -> 5562.5 | Y18: =IF(ISNUMBER(R18),_xlfn.IFS($Y$3=0,_xlfn.CONCAT(ROUND(W18,0),", ",ROUND(X18,0)),$Y$3=1,N18,$Y$3=2,_xlfn.CONCAT(AB18,AC18),$Y$3=3,_xlfn.CONCAT(AG18,AH18),$Y$3=4,BH18,$Y$3=5,BI18,$Y$3=6,BJ18),"") -> 11 | Z18: =IF(ISNUMBER(R18),V17-V18,"") -> 8 | AA18: =IF(Z18<0,MAX(AA$6:AA17)+1,0) -> 0 | AB18: =IF(ISNUMBER(R18),IF(AA18=0,AB17,AA18),"") -> 3 | AC18: =IF(ISNUMBER(R17),IF(AA18<>0,1,AC17+1),"") -> 4 | AE18: 1 | AF18: -2 | AG18: =IF(ISNUMBER(R18),AB18+AE18,"") -> 4 | AH18: =IF(ISNUMBER(S18),AC18+AF18,"") -> 2 | AU18: y | AV18: y | AW18: y | AX18: y | AY18: y | AZ18: y | BA18: y | BB18: y | BC18: y | BD18: y | BF18: 11 | BG18: 11 | BH18: 11 | BI18: =BI17-1 -> -13
B19: =IF(ISNUMBER(C19),B18+1,"") -> 13 | C19: 468797.28 | D19: 7612842.8 | F19: 468434.78 | G19: 7611380.2 | H19: POINT (468434.7813 7611380.25) | I19: [911] | J19: 911 | L19: =IF(ISNUMBER(R19),SQRT((R19-R18)^2+(S19-S18)^2),"") -> 2461.0084 | N19: =IF(ISNUMBER(O19),O19-1,"") -> 12 | O19: =IF(ISNUMBER(Q19),ROW()-ROW(O$6),"") -> 13 | P19: =IF($AB19=M$3,O19,"") | Q19: =IF(ISNUMBER(R19),Q18+1,"") -> 13 | R19: 468434.78 | S19: 7611380.2 | T19: POINT (468434.7813 7611380.25) | U19: [911] | V19: 911 | W19: =IF(ISNUMBER(R19),R19-MIN(R$7:R$42),"") -> 4262.5 | X19: =IF(ISNUMBER(R19),S19-MIN(S$7:S$42),"") -> 3450 | Y19: =IF(ISNUMBER(R19),_xlfn.IFS($Y$3=0,_xlfn.CONCAT(ROUND(W19,0),", ",ROUND(X19,0)),$Y$3=1,N19,$Y$3=2,_xlfn.CONCAT(AB19,AC19),$Y$3=3,_xlfn.CONCAT(AG19,AH19),$Y$3=4,BH19,$Y$3=5,BI19,$Y$3=6,BJ19),"") -> 12 | Z19: =IF(ISNUMBER(R19),V18-V19,"") -> -31 | AA19: =IF(Z19<0,MAX(AA$6:AA18)+1,0) -> 4 | AB19: =IF(ISNUMBER(R19),IF(AA19=0,AB18,AA19),"") -> 4 | AC19: =IF(ISNUMBER(R18),IF(AA19<>0,1,AC18+1),"") -> 1 | AE19: 1 | AF19: 0 | AG19: =IF(ISNUMBER(R19),AB19+AE19,"") -> 5 | AH19: =IF(ISNUMBER(S19),AC19+AF19,"") -> 1 | AJ19: =AJ7 -> 1 | AK19: =AK7 -> 6 | AL19: =AL7 -> 9 | AM19: =AM7 -> 13 | AN19: =AN7 -> 17 | AO19: =AO7 -> 23 | AP19: =AP7 -> 28 | AQ19: =AQ7 | ... AS19: =AS7 | AU19: =IF(ISNUMBER(AJ19),INDEX($R$7:$S$42,AJ19,AU$17),AU18) -> 7616967.8 | AV19: =IF(ISNUMBER(AK19),INDEX($R$7:$S$42,AK19,AV$17),AV18) -> 7613992.8 | AW19: =IF(ISNUMBER(AL19),INDEX($R$7:$S$42,AL19,AW$17),AW18) -> 7612342.8 | AX19: =IF(ISNUMBER(AM19),INDEX($R$7:$S$42,AM19,AX$17),AX18) -> 7611380.2 | AY19: =IF(ISNUMBER(AN19),INDEX($R$7:$S$42,AN19,AY$17),AY18) -> 7613880.2 | AZ19: =IF(ISNUMBER(AO19),INDEX($R$7:$S$42,AO19,AZ$17),AZ18) -> 7609942.8 | BA19: =IF(ISNUMBER(AP19),INDEX($R$7:$S$42,AP19,BA$17),BA18) -> 7609305.2 | BB19: =IF(ISNUMBER(AQ19),INDEX($R$7:$S$42,AQ19,BB$17),BB18) -> y | ... BD19: =IF(ISNUMBER(AS19),INDEX($R$7:$S$42,AS19,BD$17),BD18) -> y | BF19: 12 | BG19: 12 | BH19: 11 | BI19: =BI18-1 -> -14
B20: =IF(ISNUMBER(C20),B19+1,"") -> 14 | C20: 467797.28 | D20: 7613980.2 | F20: 467384.78 | G20: 7612080.2 | H20: POINT (467384.7813 7612080.25) | I20: [896] | J20: 896 | L20: =IF(ISNUMBER(R20),SQRT((R20-R19)^2+(S20-S19)^2),"") -> 1261.9429 | N20: =IF(ISNUMBER(O20),O20-1,"") -> 13 | O20: =IF(ISNUMBER(Q20),ROW()-ROW(O$6),"") -> 14 | P20: =IF($AB20=M$3,O20,"") | Q20: =IF(ISNUMBER(R20),Q19+1,"") -> 14 | R20: 467384.78 | S20: 7612080.2 | T20: POINT (467384.7813 7612080.25) | U20: [896] | V20: 896 | W20: =IF(ISNUMBER(R20),R20-MIN(R$7:R$42),"") -> 3212.5 | X20: =IF(ISNUMBER(R20),S20-MIN(S$7:S$42),"") -> 4150 | Y20: =IF(ISNUMBER(R20),_xlfn.IFS($Y$3=0,_xlfn.CONCAT(ROUND(W20,0),", ",ROUND(X20,0)),$Y$3=1,N20,$Y$3=2,_xlfn.CONCAT(AB20,AC20),$Y$3=3,_xlfn.CONCAT(AG20,AH20),$Y$3=4,BH20,$Y$3=5,BI20,$Y$3=6,BJ20),"") -> 13 | Z20: =IF(ISNUMBER(R20),V19-V20,"") -> 15 | AA20: =IF(Z20<0,MAX(AA$6:AA19)+1,0) -> 0 | AB20: =IF(ISNUMBER(R20),IF(AA20=0,AB19,AA20),"") -> 4 | AC20: =IF(ISNUMBER(R19),IF(AA20<>0,1,AC19+1),"") -> 2 | AE20: 1 | AF20: 0 | AG20: =IF(ISNUMBER(R20),AB20+AE20,"") -> 5 | AH20: =IF(ISNUMBER(S20),AC20+AF20,"") -> 2 | AJ20: =AJ8 -> 2 | AK20: =AK8 -> 7 | AL20: =AL8 -> 10 | AM20: =AM8 -> 14 | AN20: =AN8 -> 18 | AO20: =AO8 -> 24 | AP20: =AP8 -> 29 | AQ20: =AQ8 | ... AS20: =AS8 | AU20: =IF(ISNUMBER(AJ20),INDEX($R$7:$S$42,AJ20,AU$17),AU19) -> 7616642.8 | AV20: =IF(ISNUMBER(AK20),INDEX($R$7:$S$42,AK20,AV$17),AV19) -> 7614405.2 | AW20: =IF(ISNUMBER(AL20),INDEX($R$7:$S$42,AL20,AW$17),AW19) -> 7612842.8 | AX20: =IF(ISNUMBER(AM20),INDEX($R$7:$S$42,AM20,AX$17),AX19) -> 7612080.2 | AY20: =IF(ISNUMBER(AN20),INDEX($R$7:$S$42,AN20,AY$17),AY19) -> 7612830.2 | AZ20: =IF(ISNUMBER(AO20),INDEX($R$7:$S$42,AO20,AZ$17),AZ19) -> 7609955.2 | BA20: =IF(ISNUMBER(AP20),INDEX($R$7:$S$42,AP20,BA$17),BA19) -> 7607930.2 | BB20: =IF(ISNUMBER(AQ20),INDEX($R$7:$S$42,AQ20,BB$17),BB19) -> y | ... BD20: =IF(ISNUMBER(AS20),INDEX($R$7:$S$42,AS20,BD$17),BD19) -> y | BF20: 13 | BG20: 13 | BH20: 11 | BI20: =BI19-1 -> -15
B21: =IF(ISNUMBER(C21),B20+1,"") -> 15 | C21: 467172.28 | D21: 7613492.8 | F21: 466597.28 | G21: 7613155.2 | H21: POINT (466597.2813 7613155.25) | I21: [880] | J21: 880 | L21: =IF(ISNUMBER(R21),SQRT((R21-R20)^2+(S21-S20)^2),"") -> 1332.5844 | N21: =IF(ISNUMBER(O21),O21-1,"") -> 14 | O21: =IF(ISNUMBER(Q21),ROW()-ROW(O$6),"") -> 15 | P21: =IF($AB21=M$3,O21,"") | Q21: =IF(ISNUMBER(R21),Q20+1,"") -> 15 | R21: 466597.28 | S21: 7613155.2 | T21: POINT (466597.2813 7613155.25) | U21: [880] | V21: 880 | W21: =IF(ISNUMBER(R21),R21-MIN(R$7:R$42),"") -> 2425 | X21: =IF(ISNUMBER(R21),S21-MIN(S$7:S$42),"") -> 5225 | Y21: =IF(ISNUMBER(R21),_xlfn.IFS($Y$3=0,_xlfn.CONCAT(ROUND(W21,0),", ",ROUND(X21,0)),$Y$3=1,N21,$Y$3=2,_xlfn.CONCAT(AB21,AC21),$Y$3=3,_xlfn.CONCAT(AG21,AH21),$Y$3=4,BH21,$Y$3=5,BI21,$Y$3=6,BJ21),"") -> 14 | Z21: =IF(ISNUMBER(R21),V20-V21,"") -> 16 | AA21: =IF(Z21<0,MAX(AA$6:AA20)+1,0) -> 0 | AB21: =IF(ISNUMBER(R21),IF(AA21=0,AB20,AA21),"") -> 4 | AC21: =IF(ISNUMBER(R20),IF(AA21<>0,1,AC20+1),"") -> 3 | AE21: 2 | AF21: -2 | AG21: =IF(ISNUMBER(R21),AB21+AE21,"") -> 6 | AH21: =IF(ISNUMBER(S21),AC21+AF21,"") -> 1 | AJ21: =AJ9 -> 3 | AK21: =AK9 -> 8 | AL21: =AL9 -> 11 | AM21: =AM9 -> 15 | AN21: =AN9 -> 19 | AO21: =AO9 -> 25 | AP21: =AP9 | AQ21: =AQ9 | ... AS21: =AS9 | AU21: =IF(ISNUMBER(AJ21),INDEX($R$7:$S$42,AJ21,AU$17),AU20) -> 7615805.2 | AV21: =IF(ISNUMBER(AK21),INDEX($R$7:$S$42,AK21,AV$17),AV20) -> 7614292.8 | AW21: =IF(ISNUMBER(AL21),INDEX($R$7:$S$42,AL21,AW$17),AW20) -> 7613980.2 | AX21: =IF(ISNUMBER(AM21),INDEX($R$7:$S$42,AM21,AX$17),AX20) -> 7613155.2 | AY21: =IF(ISNUMBER(AN21),INDEX($R$7:$S$42,AN21,AY$17),AY20) -> 7611667.8 | AZ21: =IF(ISNUMBER(AO21),INDEX($R$7:$S$42,AO21,AZ$17),AZ20) -> 7610467.8 | BA21: =IF(ISNUMBER(AP21),INDEX($R$7:$S$42,AP21,BA$17),BA20) -> 7607930.2 | BB21: =IF(ISNUMBER(AQ21),INDEX($R$7:$S$42,AQ21,BB$17),BB20) -> y | ... BD21: =IF(ISNUMBER(AS21),INDEX($R$7:$S$42,AS21,BD$17),BD20) -> y | BF21: 14 | BG21: 14 | BH21: 11 | BI21: =BI20-1 -> -16 | BJ21: -17
B22: =IF(ISNUMBER(C22),B21+1,"") -> 16 | C22: 466597.28 | D22: 7613155.2 | F22: 465672.28 | G22: 7613092.8 | H22: POINT (465672.2813 7613092.75) | I22: [880] | J22: 880 | L22: =IF(ISNUMBER(R22),SQRT((R22-R21)^2+(S22-S21)^2),"") -> 927.10908 | N22: =IF(ISNUMBER(O22),O22-1,"") -> 15 | O22: =IF(ISNUMBER(Q22),ROW()-ROW(O$6),"") -> 16 | P22: =IF($AB22=M$3,O22,"") | Q22: =IF(ISNUMBER(R22),Q21+1,"") -> 16 | R22: 465672.28 | S22: 7613092.8 | T22: POINT (465672.2813 7613092.75) | U22: [880] | V22: 880 | W22: =IF(ISNUMBER(R22),R22-MIN(R$7:R$42),"") -> 1500 | X22: =IF(ISNUMBER(R22),S22-MIN(S$7:S$42),"") -> 5162.5 | Y22: =IF(ISNUMBER(R22),_xlfn.IFS($Y$3=0,_xlfn.CONCAT(ROUND(W22,0),", ",ROUND(X22,0)),$Y$3=1,N22,$Y$3=2,_xlfn.CONCAT(AB22,AC22),$Y$3=3,_xlfn.CONCAT(AG22,AH22),$Y$3=4,BH22,$Y$3=5,BI22,$Y$3=6,BJ22),"") -> 15 | Z22: =IF(ISNUMBER(R22),V21-V22,"") -> 0 | AA22: =IF(Z22<0,MAX(AA$6:AA21)+1,0) -> 0 | AB22: =IF(ISNUMBER(R22),IF(AA22=0,AB21,AA22),"") -> 4 | AC22: =IF(ISNUMBER(R21),IF(AA22<>0,1,AC21+1),"") -> 4 | AE22: 2 | AF22: -2 | AG22: =IF(ISNUMBER(R22),AB22+AE22,"") -> 6 | AH22: =IF(ISNUMBER(S22),AC22+AF22,"") -> 2 | AJ22: =AJ10 -> 4 | AK22: =AK10 | AL22: =AL10 -> 12 | AM22: =AM10 -> 16 | AN22: =AN10 -> 20 | AO22: =AO10 -> 26 | AP22: =AP10 | AQ22: =AQ10 | ... AS22: =AS10 | AU22: =IF(ISNUMBER(AJ22),INDEX($R$7:$S$42,AJ22,AU$17),AU21) -> 7614955.2 | AV22: =IF(ISNUMBER(AK22),INDEX($R$7:$S$42,AK22,AV$17),AV21) -> 7614292.8 | AW22: =IF(ISNUMBER(AL22),INDEX($R$7:$S$42,AL22,AW$17),AW21) -> 7613492.8 | AX22: =IF(ISNUMBER(AM22),INDEX($R$7:$S$42,AM22,AX$17),AX21) -> 7613092.8 | AY22: =IF(ISNUMBER(AN22),INDEX($R$7:$S$42,AN22,AY$17),AY21) -> 7611405.2 | AZ22: =IF(ISNUMBER(AO22),INDEX($R$7:$S$42,AO22,AZ$17),AZ21) -> 7610505.2 | BA22: =IF(ISNUMBER(AP22),INDEX($R$7:$S$42,AP22,BA$17),BA21) -> 7607930.2 | BB22: =IF(ISNUMBER(AQ22),INDEX($R$7:$S$42,AQ22,BB$17),BB21) -> y | ... BD22: =IF(ISNUMBER(AS22),INDEX($R$7:$S$42,AS22,BD$17),BD21) -> y | BF22: 15 | BG22: 15 | BH22: 11 | BI22: -18
B23: =IF(ISNUMBER(C23),B22+1,"") -> 17 | C23: 468434.78 | D23: 7611380.2 | F23: 464872.28 | G23: 7613880.2 | H23: POINT (464872.2813 7613880.25) | I23: [890] | J23: 890 | L23: =IF(ISNUMBER(R23),SQRT((R23-R22)^2+(S23-S22)^2),"") -> 1122.5668 | N23: =IF(ISNUMBER(O23),O23-1,"") -> 16 | O23: =IF(ISNUMBER(Q23),ROW()-ROW(O$6),"") -> 17 | P23: =IF($AB23=M$3,O23,"") | Q23: =IF(ISNUMBER(R23),Q22+1,"") -> 17 | R23: 464872.28 | S23: 7613880.2 | T23: POINT (464872.2813 7613880.25) | U23: [890] | V23: 890 | W23: =IF(ISNUMBER(R23),R23-MIN(R$7:R$42),"") -> 700 | X23: =IF(ISNUMBER(R23),S23-MIN(S$7:S$42),"") -> 5950 | Y23: =IF(ISNUMBER(R23),_xlfn.IFS($Y$3=0,_xlfn.CONCAT(ROUND(W23,0),", ",ROUND(X23,0)),$Y$3=1,N23,$Y$3=2,_xlfn.CONCAT(AB23,AC23),$Y$3=3,_xlfn.CONCAT(AG23,AH23),$Y$3=4,BH23,$Y$3=5,BI23,$Y$3=6,BJ23),"") -> 16 | Z23: =IF(ISNUMBER(R23),V22-V23,"") -> -10 | AA23: =IF(Z23<0,MAX(AA$6:AA22)+1,0) -> 5 | AB23: =IF(ISNUMBER(R23),IF(AA23=0,AB22,AA23),"") -> 5 | AC23: =IF(ISNUMBER(R22),IF(AA23<>0,1,AC22+1),"") -> 1 | AE23: =AE22 -> 2 | AF23: 0 | AG23: =IF(ISNUMBER(R23),AB23+AE23,"") -> 7 | AH23: =IF(ISNUMBER(S23),AC23+AF23,"") -> 1 | AJ23: =AJ11 -> 5 | AK23: =AK11 | AL23: =AL11 | AM23: =AM11 | AN23: =AN11 -> 21 | AO23: =AO11 -> 27 | AP23: =AP11 | AQ23: =AQ11 | ... AS23: =AS11 | AU23: =IF(ISNUMBER(AJ23),INDEX($R$7:$S$42,AJ23,AU$17),AU22) -> 7614180.2 | AV23: =IF(ISNUMBER(AK23),INDEX($R$7:$S$42,AK23,AV$17),AV22) -> 7614292.8 | AW23: =IF(ISNUMBER(AL23),INDEX($R$7:$S$42,AL23,AW$17),AW22) -> 7613492.8 | AX23: =IF(ISNUMBER(AM23),INDEX($R$7:$S$42,AM23,AX$17),AX22) -> 7613092.8 | AY23: =IF(ISNUMBER(AN23),INDEX($R$7:$S$42,AN23,AY$17),AY22) -> 7610630.2 | AZ23: =IF(ISNUMBER(AO23),INDEX($R$7:$S$42,AO23,AZ$17),AZ22) -> 7609892.8 | BA23: =IF(ISNUMBER(AP23),INDEX($R$7:$S$42,AP23,BA$17),BA22) -> 7607930.2 | BB23: =IF(ISNUMBER(AQ23),INDEX($R$7:$S$42,AQ23,BB$17),BB22) -> y | ... BD23: =IF(ISNUMBER(AS23),INDEX($R$7:$S$42,AS23,BD$17),BD22) -> y | BF23: 16 | BG23: 16 | BH23: 11 | BI23: =BI22-1 -> -19
B24: =IF(ISNUMBER(C24),B23+1,"") -> 18 | C24: 467384.78 | D24: 7612080.2 | F24: 465422.28 | G24: 7612830.2 | H24: POINT (465422.2813 7612830.25) | I24: [877] | J24: 877 | L24: =IF(ISNUMBER(R24),SQRT((R24-R23)^2+(S24-S23)^2),"") -> 1185.327 | N24: =IF(ISNUMBER(O24),O24-1,"") -> 17 | O24: =IF(ISNUMBER(Q24),ROW()-ROW(O$6),"") -> 18 | P24: =IF($AB24=M$3,O24,"") | Q24: =IF(ISNUMBER(R24),Q23+1,"") -> 18 | R24: 465422.28 | S24: 7612830.2 | T24: POINT (465422.2813 7612830.25) | U24: [877] | V24: 877 | W24: =IF(ISNUMBER(R24),R24-MIN(R$7:R$42),"") -> 1250 | X24: =IF(ISNUMBER(R24),S24-MIN(S$7:S$42),"") -> 4900 | Y24: =IF(ISNUMBER(R24),_xlfn.IFS($Y$3=0,_xlfn.CONCAT(ROUND(W24,0),", ",ROUND(X24,0)),$Y$3=1,N24,$Y$3=2,_xlfn.CONCAT(AB24,AC24),$Y$3=3,_xlfn.CONCAT(AG24,AH24),$Y$3=4,BH24,$Y$3=5,BI24,$Y$3=6,BJ24),"") -> 17 | Z24: =IF(ISNUMBER(R24),V23-V24,"") -> 13 | AA24: =IF(Z24<0,MAX(AA$6:AA23)+1,0) -> 0 | AB24: =IF(ISNUMBER(R24),IF(AA24=0,AB23,AA24),"") -> 5 | AC24: =IF(ISNUMBER(R23),IF(AA24<>0,1,AC23+1),"") -> 2 | AE24: 3 | AF24: -1 | AG24: =IF(ISNUMBER(R24),AB24+AE24,"") -> 8 | AH24: =IF(ISNUMBER(S24),AC24+AF24,"") -> 1 | AJ24: =AJ12 | AK24: =AK12 | AL24: =AL12 | AM24: =AM12 | AN24: =AN12 -> 22 | AO24: =AO12 | AP24: =AP12 | AQ24: =AQ12 | ... AS24: =AS12 | AU24: =IF(ISNUMBER(AJ24),INDEX($R$7:$S$42,AJ24,AU$17),AU23) -> 7614180.2 | AV24: =IF(ISNUMBER(AK24),INDEX($R$7:$S$42,AK24,AV$17),AV23) -> 7614292.8 | AW24: =IF(ISNUMBER(AL24),INDEX($R$7:$S$42,AL24,AW$17),AW23) -> 7613492.8 | AX24: =IF(ISNUMBER(AM24),INDEX($R$7:$S$42,AM24,AX$17),AX23) -> 7613092.8 | AY24: =IF(ISNUMBER(AN24),INDEX($R$7:$S$42,AN24,AY$17),AY23) -> 7609967.8 | AZ24: =IF(ISNUMBER(AO24),INDEX($R$7:$S$42,AO24,AZ$17),AZ23) -> 7609892.8 | BA24: =IF(ISNUMBER(AP24),INDEX($R$7:$S$42,AP24,BA$17),BA23) -> 7607930.2 | BB24: =IF(ISNUMBER(AQ24),INDEX($R$7:$S$42,AQ24,BB$17),BB23) -> y | ... BD24: =IF(ISNUMBER(AS24),INDEX($R$7:$S$42,AS24,BD$17),BD23) -> y | BF24: 17 | BG24: 17 | BH24: 11 | BI24: =BI23-1 -> -20
B25: =IF(ISNUMBER(C25),B24+1,"") -> 19 | C25: 466597.28 | D25: 7613155.2 | F25: 465284.78 | G25: 7611667.8 | H25: POINT (465284.7813 7611667.75) | I25: [863] | J25: 863 | L25: =IF(ISNUMBER(R25),SQRT((R25-R24)^2+(S25-S24)^2),"") -> 1170.6035 | N25: =IF(ISNUMBER(O25),O25-1,"") -> 18 | O25: =IF(ISNUMBER(Q25),ROW()-ROW(O$6),"") -> 19 | P25: =IF($AB25=M$3,O25,"") | Q25: =IF(ISNUMBER(R25),Q24+1,"") -> 19 | R25: 465284.78 | S25: 7611667.8 | T25: POINT (465284.7813 7611667.75) | U25: [863] | V25: 863 | W25: =IF(ISNUMBER(R25),R25-MIN(R$7:R$42),"") -> 1112.5 | X25: =IF(ISNUMBER(R25),S25-MIN(S$7:S$42),"") -> 3737.5 | Y25: =IF(ISNUMBER(R25),_xlfn.IFS($Y$3=0,_xlfn.CONCAT(ROUND(W25,0),", ",ROUND(X25,0)),$Y$3=1,N25,$Y$3=2,_xlfn.CONCAT(AB25,AC25),$Y$3=3,_xlfn.CONCAT(AG25,AH25),$Y$3=4,BH25,$Y$3=5,BI25,$Y$3=6,BJ25),"") -> 18 | Z25: =IF(ISNUMBER(R25),V24-V25,"") -> 14 | AA25: =IF(Z25<0,MAX(AA$6:AA24)+1,0) -> 0 | AB25: =IF(ISNUMBER(R25),IF(AA25=0,AB24,AA25),"") -> 5 | AC25: =IF(ISNUMBER(R24),IF(AA25<>0,1,AC24+1),"") -> 3 | AE25: =AE24 -> 3 | AF25: -1 | AG25: =IF(ISNUMBER(R25),AB25+AE25,"") -> 8 | AH25: =IF(ISNUMBER(S25),AC25+AF25,"") -> 2 | AJ25: =AJ13 | AK25: =AK13 | AL25: =AL13 | AM25: =AM13 | AN25: =AN13 | AO25: =AO13 | AP25: =AP13 | AQ25: =AQ13 | ... AS25: =AS13 | AU25: =IF(ISNUMBER(AJ25),INDEX($R$7:$S$42,AJ25,AU$17),AU24) -> 7614180.2 | AV25: =IF(ISNUMBER(AK25),INDEX($R$7:$S$42,AK25,AV$17),AV24) -> 7614292.8 | AW25: =IF(ISNUMBER(AL25),INDEX($R$7:$S$42,AL25,AW$17),AW24) -> 7613492.8 | AX25: =IF(ISNUMBER(AM25),INDEX($R$7:$S$42,AM25,AX$17),AX24) -> 7613092.8 | AY25: =IF(ISNUMBER(AN25),INDEX($R$7:$S$42,AN25,AY$17),AY24) -> 7609967.8 | AZ25: =IF(ISNUMBER(AO25),INDEX($R$7:$S$42,AO25,AZ$17),AZ24) -> 7609892.8 | BA25: =IF(ISNUMBER(AP25),INDEX($R$7:$S$42,AP25,BA$17),BA24) -> 7607930.2 | BB25: =IF(ISNUMBER(AQ25),INDEX($R$7:$S$42,AQ25,BB$17),BB24) -> y | ... BD25: =IF(ISNUMBER(AS25),INDEX($R$7:$S$42,AS25,BD$17),BD24) -> y | BF25: 18 | BG25: 18 | BH25: 11 | BI25: =BI24-1 -> -21 | BJ25: C
B26: =IF(ISNUMBER(C26),B25+1,"") -> 20 | C26: 465672.28 | D26: 7613092.8 | F26: 464384.78 | G26: 7611405.2 | H26: POINT (464384.7813 7611405.25) | I26: [854] | J26: 854 | L26: =IF(ISNUMBER(R26),SQRT((R26-R25)^2+(S26-S25)^2),"") -> 937.5 | N26: =IF(ISNUMBER(O26),O26-1,"") -> 19 | O26: =IF(ISNUMBER(Q26),ROW()-ROW(O$6),"") -> 20 | P26: =IF($AB26=M$3,O26,"") | Q26: =IF(ISNUMBER(R26),Q25+1,"") -> 20 | R26: 464384.78 | S26: 7611405.2 | T26: POINT (464384.7813 7611405.25) | U26: [854] | V26: 854 | W26: =IF(ISNUMBER(R26),R26-MIN(R$7:R$42),"") -> 212.5 | X26: =IF(ISNUMBER(R26),S26-MIN(S$7:S$42),"") -> 3475 | Y26: =IF(ISNUMBER(R26),_xlfn.IFS($Y$3=0,_xlfn.CONCAT(ROUND(W26,0),", ",ROUND(X26,0)),$Y$3=1,N26,$Y$3=2,_xlfn.CONCAT(AB26,AC26),$Y$3=3,_xlfn.CONCAT(AG26,AH26),$Y$3=4,BH26,$Y$3=5,BI26,$Y$3=6,BJ26),"") -> 19 | Z26: =IF(ISNUMBER(R26),V25-V26,"") -> 9 | AA26: =IF(Z26<0,MAX(AA$6:AA25)+1,0) -> 0 | AB26: =IF(ISNUMBER(R26),IF(AA26=0,AB25,AA26),"") -> 5 | AC26: =IF(ISNUMBER(R25),IF(AA26<>0,1,AC25+1),"") -> 4 | AE26: =AE25 -> 3 | AF26: -1 | AG26: =IF(ISNUMBER(R26),AB26+AE26,"") -> 8 | AH26: =IF(ISNUMBER(S26),AC26+AF26,"") -> 3 | AJ26: =AJ14 | AK26: =AK14 | AL26: =AL14 | AM26: =AM14 | AN26: =AN14 | AO26: =AO14 | AP26: =AP14 | AQ26: =AQ14 | ... AS26: =AS14 | AU26: =IF(ISNUMBER(#REF!),INDEX($R$7:$S$42,#REF!,AU$17),AU25) -> 7614180.2 | AV26: =IF(ISNUMBER(#REF!),INDEX($R$7:$S$42,#REF!,AV$17),AV25) -> 7614292.8 | AW26: =IF(ISNUMBER(#REF!),INDEX($R$7:$S$42,#REF!,AW$17),AW25) -> 7613492.8 | AX26: =IF(ISNUMBER(#REF!),INDEX($R$7:$S$42,#REF!,AX$17),AX25) -> 7613092.8 | AY26: =IF(ISNUMBER(#REF!),INDEX($R$7:$S$42,#REF!,AY$17),AY25) -> 7609967.8 | AZ26: =IF(ISNUMBER(#REF!),INDEX($R$7:$S$42,#REF!,AZ$17),AZ25) -> 7609892.8 | BA26: =IF(ISNUMBER(#REF!),INDEX($R$7:$S$42,#REF!,BA$17),BA25) -> 7607930.2 | BB26: =IF(ISNUMBER(#REF!),INDEX($R$7:$S$42,#REF!,BB$17),BB25) -> y | ... BD26: =IF(ISNUMBER(#REF!),INDEX($R$7:$S$42,#REF!,BD$17),BD25) -> y | BF26: 19 | BG26: 19 | BH26: 11 | BI26: =BI25-1 -> -22
B27: =IF(ISNUMBER(C27),B26+1,"") -> 21 | C27: 465422.28 | D27: 7612830.2 | F27: 464297.28 | G27: 7610630.2 | H27: POINT (464297.2813 7610630.25) | I27: [847] | J27: 847 | L27: =IF(ISNUMBER(R27),SQRT((R27-R26)^2+(S27-S26)^2),"") -> 779.92387 | N27: =IF(ISNUMBER(O27),O27-1,"") -> 20 | O27: =IF(ISNUMBER(Q27),ROW()-ROW(O$6),"") -> 21 | P27: =IF($AB27=M$3,O27,"") | Q27: =IF(ISNUMBER(R27),Q26+1,"") -> 21 | R27: 464297.28 | S27: 7610630.2 | T27: POINT (464297.2813 7610630.25) | U27: [847] | V27: 847 | W27: =IF(ISNUMBER(R27),R27-MIN(R$7:R$42),"") -> 125 | X27: =IF(ISNUMBER(R27),S27-MIN(S$7:S$42),"") -> 2700 | Y27: =IF(ISNUMBER(R27),_xlfn.IFS($Y$3=0,_xlfn.CONCAT(ROUND(W27,0),", ",ROUND(X27,0)),$Y$3=1,N27,$Y$3=2,_xlfn.CONCAT(AB27,AC27),$Y$3=3,_xlfn.CONCAT(AG27,AH27),$Y$3=4,BH27,$Y$3=5,BI27,$Y$3=6,BJ27),"") -> 20 | Z27: =IF(ISNUMBER(R27),V26-V27,"") -> 7 | AA27: =IF(Z27<0,MAX(AA$6:AA26)+1,0) -> 0 | AB27: =IF(ISNUMBER(R27),IF(AA27=0,AB26,AA27),"") -> 5 | AC27: =IF(ISNUMBER(R26),IF(AA27<>0,1,AC26+1),"") -> 5 | AE27: =AE26 -> 3 | AF27: -1 | AG27: =IF(ISNUMBER(R27),AB27+AE27,"") -> 8 | AH27: =IF(ISNUMBER(S27),AC27+AF27,"") -> 4 | AJ27: =AJ15 | AK27: =AK15 | AL27: =AL15 | AM27: =AM15 | AN27: =AN15 | AO27: =AO15 | AP27: =AP15 | AQ27: =AQ15 | ... AS27: =AS15 | AU27: =IF(ISNUMBER(#REF!),INDEX($R$7:$S$42,#REF!,AU$17),AU26) -> 7614180.2 | AV27: =IF(ISNUMBER(#REF!),INDEX($R$7:$S$42,#REF!,AV$17),AV26) -> 7614292.8 | AW27: =IF(ISNUMBER(#REF!),INDEX($R$7:$S$42,#REF!,AW$17),AW26) -> 7613492.8 | AX27: =IF(ISNUMBER(#REF!),INDEX($R$7:$S$42,#REF!,AX$17),AX26) -> 7613092.8 | AY27: =IF(ISNUMBER(#REF!),INDEX($R$7:$S$42,#REF!,AY$17),AY26) -> 7609967.8 | AZ27: =IF(ISNUMBER(#REF!),INDEX($R$7:$S$42,#REF!,AZ$17),AZ26) -> 7609892.8 | BA27: =IF(ISNUMBER(#REF!),INDEX($R$7:$S$42,#REF!,BA$17),BA26) -> 7607930.2 | BB27: =IF(ISNUMBER(#REF!),INDEX($R$7:$S$42,#REF!,BB$17),BB26) -> y | ... BD27: =IF(ISNUMBER(#REF!),INDEX($R$7:$S$42,#REF!,BD$17),BD26) -> y | BF27: 20 | BG27: 20 | BH27: 11 | BI27: =BI26-1 -> -23
B28: =IF(ISNUMBER(C28),B27+1,"") -> 22 | C28: 464872.28 | D28: 7613880.2 | F28: 464784.78 | G28: 7609967.8 | H28: POINT (464784.7813 7609967.75) | I28: [844] | J28: 844 | L28: =IF(ISNUMBER(R28),SQRT((R28-R27)^2+(S28-S27)^2),"") -> 822.53419 | N28: =IF(ISNUMBER(O28),O28-1,"") -> 21 | O28: =IF(ISNUMBER(Q28),ROW()-ROW(O$6),"") -> 22 | P28: =IF($AB28=M$3,O28,"") | Q28: =IF(ISNUMBER(R28),Q27+1,"") -> 22 | R28: 464784.78 | S28: 7609967.8 | T28: POINT (464784.7813 7609967.75) | U28: [844] | V28: 844 | W28: =IF(ISNUMBER(R28),R28-MIN(R$7:R$42),"") -> 612.5 | X28: =IF(ISNUMBER(R28),S28-MIN(S$7:S$42),"") -> 2037.5 | Y28: =IF(ISNUMBER(R28),_xlfn.IFS($Y$3=0,_xlfn.CONCAT(ROUND(W28,0),", ",ROUND(X28,0)),$Y$3=1,N28,$Y$3=2,_xlfn.CONCAT(AB28,AC28),$Y$3=3,_xlfn.CONCAT(AG28,AH28),$Y$3=4,BH28,$Y$3=5,BI28,$Y$3=6,BJ28),"") -> 21 | Z28: =IF(ISNUMBER(R28),V27-V28,"") -> 3 | AA28: =IF(Z28<0,MAX(AA$6:AA27)+1,0) -> 0 | AB28: =IF(ISNUMBER(R28),IF(AA28=0,AB27,AA28),"") -> 5 | AC28: =IF(ISNUMBER(R27),IF(AA28<>0,1,AC27+1),"") -> 6 | AE28: =AE27 -> 3 | AF28: -1 | AG28: =IF(ISNUMBER(R28),AB28+AE28,"") -> 8 | AH28: =IF(ISNUMBER(S28),AC28+AF28,"") -> 5 | BF28: 21 | BG28: 21 | BH28: 11 | BI28: =BI27-1 -> -24
B29: =IF(ISNUMBER(C29),B28+1,"") -> 23 | C29: 465422.28 | D29: 7612830.2 | F29: 468284.78 | G29: 7609942.8 | H29: POINT (468284.7813 7609942.75) | I29: [928] | J29: 928 | L29: =IF(ISNUMBER(R29),SQRT((R29-R28)^2+(S29-S28)^2),"") -> 3500.0893 | N29: =IF(ISNUMBER(O29),O29-1,"") -> 22 | O29: =IF(ISNUMBER(Q29),ROW()-ROW(O$6),"") -> 23 | P29: =IF($AB29=M$3,O29,"") | Q29: =IF(ISNUMBER(R29),Q28+1,"") -> 23 | R29: 468284.78 | S29: 7609942.8 | T29: POINT (468284.7813 7609942.75) | U29: [928] | V29: 928 | W29: =IF(ISNUMBER(R29),R29-MIN(R$7:R$42),"") -> 4112.5 | X29: =IF(ISNUMBER(R29),S29-MIN(S$7:S$42),"") -> 2012.5 | Y29: =IF(ISNUMBER(R29),_xlfn.IFS($Y$3=0,_xlfn.CONCAT(ROUND(W29,0),", ",ROUND(X29,0)),$Y$3=1,N29,$Y$3=2,_xlfn.CONCAT(AB29,AC29),$Y$3=3,_xlfn.CONCAT(AG29,AH29),$Y$3=4,BH29,$Y$3=5,BI29,$Y$3=6,BJ29),"") -> 22 | Z29: =IF(ISNUMBER(R29),V28-V29,"") -> -84 | AA29: =IF(Z29<0,MAX(AA$6:AA28)+1,0) -> 6 | AB29: =IF(ISNUMBER(R29),IF(AA29=0,AB28,AA29),"") -> 6 | AC29: =IF(ISNUMBER(R28),IF(AA29<>0,1,AC28+1),"") -> 1 | AE29: =AE28 -> 3 | AF29: 0 | AG29: =IF(ISNUMBER(R29),AB29+AE29,"") -> 9 | AH29: =IF(ISNUMBER(S29),AC29+AF29,"") -> 1 | AJ29: =IF(AND(ISNUMBER(AJ7),(ISNUMBER(O$5))),INDEX($Y$7:$Y$41,AJ7,1),"") -> 0 | AK29: =IF(AND(ISNUMBER(AK7),(ISNUMBER(P$5))),INDEX($Y$7:$Y$41,AK7,1),"") -> 5 | AL29: =IF(AND(ISNUMBER(AL7),(ISNUMBER(Q$5))),INDEX($Y$7:$Y$41,AL7,1),"") -> 8 | AM29: =IF(AND(ISNUMBER(AM7),(ISNUMBER(R$5))),INDEX($Y$7:$Y$41,AM7,1),"") -> 12 | AN29: =IF(AND(ISNUMBER(AN7),(ISNUMBER(S$5))),INDEX($Y$7:$Y$41,AN7,1),"") -> 16 | AO29: =IF(AND(ISNUMBER(AO7),(ISNUMBER(T$5))),INDEX($Y$7:$Y$41,AO7,1),"") -> 22 | AP29: =IF(AND(ISNUMBER(AP7),(ISNUMBER(U$5))),INDEX($Y$7:$Y$41,AP7,1),"") -> 27 | AQ29: =IF(AND(ISNUMBER(AQ7),(ISNUMBER(V$5))),INDEX($Y$7:$Y$41,AQ7,1),"") | AR29: =IF(AND(ISNUMBER(AR7),(ISNUMBER(#REF!))),INDEX($Y$7:$Y$41,AR7,1),"") | AS29: =IF(AND(ISNUMBER(AS7),(ISNUMBER(W$5))),INDEX($Y$7:$Y$41,AS7,1),"") | BF29: 22 | BG29: 22 | BH29: 11 | BI29: =BI28-1 -> -25
B30: =IF(ISNUMBER(C30),B29+1,"") -> 24 | C30: 465284.78 | D30: 7611667.8 | F30: 466622.28 | G30: 7609955.2 | H30: POINT (466622.2813 7609955.25) | I30: [895] | J30: 895 | L30: =IF(ISNUMBER(R30),SQRT((R30-R29)^2+(S30-S29)^2),"") -> 1662.547 | N30: =IF(ISNUMBER(O30),O30-1,"") -> 23 | O30: =IF(ISNUMBER(Q30),ROW()-ROW(O$6),"") -> 24 | P30: =IF($AB30=M$3,O30,"") | Q30: =IF(ISNUMBER(R30),Q29+1,"") -> 24 | R30: 466622.28 | S30: 7609955.2 | T30: POINT (466622.2813 7609955.25) | U30: [895] | V30: 895 | W30: =IF(ISNUMBER(R30),R30-MIN(R$7:R$42),"") -> 2450 | X30: =IF(ISNUMBER(R30),S30-MIN(S$7:S$42),"") -> 2025 | Y30: =IF(ISNUMBER(R30),_xlfn.IFS($Y$3=0,_xlfn.CONCAT(ROUND(W30,0),", ",ROUND(X30,0)),$Y$3=1,N30,$Y$3=2,_xlfn.CONCAT(AB30,AC30),$Y$3=3,_xlfn.CONCAT(AG30,AH30),$Y$3=4,BH30,$Y$3=5,BI30,$Y$3=6,BJ30),"") -> 23 | Z30: =IF(ISNUMBER(R30),V29-V30,"") -> 33 | AA30: =IF(Z30<0,MAX(AA$6:AA29)+1,0) -> 0 | AB30: =IF(ISNUMBER(R30),IF(AA30=0,AB29,AA30),"") -> 6 | AC30: =IF(ISNUMBER(R29),IF(AA30<>0,1,AC29+1),"") -> 2 | AE30: =AE29 -> 3 | AF30: 0 | AG30: =IF(ISNUMBER(R30),AB30+AE30,"") -> 9 | AH30: =IF(ISNUMBER(S30),AC30+AF30,"") -> 2 | AJ30: =IF(AND(ISNUMBER(AJ8),(ISNUMBER(O$5))),INDEX($Y$7:$Y$41,AJ8,1),"") -> 1 | AK30: =IF(AND(ISNUMBER(AK8),(ISNUMBER(P$5))),INDEX($Y$7:$Y$41,AK8,1),"") -> 6 | AL30: =IF(AND(ISNUMBER(AL8),(ISNUMBER(Q$5))),INDEX($Y$7:$Y$41,AL8,1),"") -> 9 | AM30: =IF(AND(ISNUMBER(AM8),(ISNUMBER(R$5))),INDEX($Y$7:$Y$41,AM8,1),"") -> 13 | AN30: =IF(AND(ISNUMBER(AN8),(ISNUMBER(S$5))),INDEX($Y$7:$Y$41,AN8,1),"") -> 17 | AO30: =IF(AND(ISNUMBER(AO8),(ISNUMBER(T$5))),INDEX($Y$7:$Y$41,AO8,1),"") -> 23 | AP30: =IF(AND(ISNUMBER(AP8),(ISNUMBER(U$5))),INDEX($Y$7:$Y$41,AP8,1),"") -> 28 | AQ30: =IF(AND(ISNUMBER(AQ8),(ISNUMBER(V$5))),INDEX($Y$7:$Y$41,AQ8,1),"") | AR30: =IF(AND(ISNUMBER(AR8),(ISNUMBER(#REF!))),INDEX($Y$7:$Y$41,AR8,1),"") | AS30: =IF(AND(ISNUMBER(AS8),(ISNUMBER(W$5))),INDEX($Y$7:$Y$41,AS8,1),"") | BF30: 23 | BG30: 23 | BH30: 11 | BI30: =BI29-1 -> -26
B31: =IF(ISNUMBER(C31),B30+1,"") -> 25 | C31: 464384.78 | D31: 7611405.2 | F31: 466097.28 | G31: 7610467.8 | H31: POINT (466097.2813 7610467.75) | I31: [865] | J31: 865 | L31: =IF(ISNUMBER(R31),SQRT((R31-R30)^2+(S31-S30)^2),"") -> 733.67653 | N31: =IF(ISNUMBER(O31),O31-1,"") -> 24 | O31: =IF(ISNUMBER(Q31),ROW()-ROW(O$6),"") -> 25 | P31: =IF($AB31=M$3,O31,"") | Q31: =IF(ISNUMBER(R31),Q30+1,"") -> 25 | R31: 466097.28 | S31: 7610467.8 | T31: POINT (466097.2813 7610467.75) | U31: [865] | V31: 865 | W31: =IF(ISNUMBER(R31),R31-MIN(R$7:R$42),"") -> 1925 | X31: =IF(ISNUMBER(R31),S31-MIN(S$7:S$42),"") -> 2537.5 | Y31: =IF(ISNUMBER(R31),_xlfn.IFS($Y$3=0,_xlfn.CONCAT(ROUND(W31,0),", ",ROUND(X31,0)),$Y$3=1,N31,$Y$3=2,_xlfn.CONCAT(AB31,AC31),$Y$3=3,_xlfn.CONCAT(AG31,AH31),$Y$3=4,BH31,$Y$3=5,BI31,$Y$3=6,BJ31),"") -> 24 | Z31: =IF(ISNUMBER(R31),V30-V31,"") -> 30 | AA31: =IF(Z31<0,MAX(AA$6:AA30)+1,0) -> 0 | AB31: =IF(ISNUMBER(R31),IF(AA31=0,AB30,AA31),"") -> 6 | AC31: =IF(ISNUMBER(R30),IF(AA31<>0,1,AC30+1),"") -> 3 | AE31: =AE30 -> 3 | AF31: 0 | AG31: =IF(ISNUMBER(R31),AB31+AE31,"") -> 9 | AH31: =IF(ISNUMBER(S31),AC31+AF31,"") -> 3 | AJ31: =IF(AND(ISNUMBER(AJ9),(ISNUMBER(O$5))),INDEX($Y$7:$Y$41,AJ9,1),"") -> 2 | AK31: =IF(AND(ISNUMBER(AK9),(ISNUMBER(P$5))),INDEX($Y$7:$Y$41,AK9,1),"") -> 7 | AL31: =IF(AND(ISNUMBER(AL9),(ISNUMBER(Q$5))),INDEX($Y$7:$Y$41,AL9,1),"") -> 10 | AM31: =IF(AND(ISNUMBER(AM9),(ISNUMBER(R$5))),INDEX($Y$7:$Y$41,AM9,1),"") -> 14 | AN31: =IF(AND(ISNUMBER(AN9),(ISNUMBER(S$5))),INDEX($Y$7:$Y$41,AN9,1),"") -> 18 | AO31: =IF(AND(ISNUMBER(AO9),(ISNUMBER(T$5))),INDEX($Y$7:$Y$41,AO9,1),"") -> 24 | AP31: =IF(AND(ISNUMBER(AP9),(ISNUMBER(U$5))),INDEX($Y$7:$Y$41,AP9,1),"") | AQ31: =IF(AND(ISNUMBER(AQ9),(ISNUMBER(V$5))),INDEX($Y$7:$Y$41,AQ9,1),"") | AR31: =IF(AND(ISNUMBER(AR9),(ISNUMBER(#REF!))),INDEX($Y$7:$Y$41,AR9,1),"") | AS31: =IF(AND(ISNUMBER(AS9),(ISNUMBER(W$5))),INDEX($Y$7:$Y$41,AS9,1),"") | BF31: 24 | BG31: 24 | BH31: 11 | BI31: =BI30-1 -> -27
B32: =IF(ISNUMBER(C32),B31+1,"") -> 26 | C32: 464297.28 | D32: 7610630.2 | F32: 465534.78 | G32: 7610505.2 | H32: POINT (465534.7813 7610505.25) | I32: [856] | J32: 856 | L32: =IF(ISNUMBER(R32),SQRT((R32-R31)^2+(S32-S31)^2),"") -> 563.74861 | N32: =IF(ISNUMBER(O32),O32-1,"") -> 25 | O32: =IF(ISNUMBER(Q32),ROW()-ROW(O$6),"") -> 26 | P32: =IF($AB32=M$3,O32,"") | Q32: =IF(ISNUMBER(R32),Q31+1,"") -> 26 | R32: 465534.78 | S32: 7610505.2 | T32: POINT (465534.7813 7610505.25) | U32: [856] | V32: 856 | W32: =IF(ISNUMBER(R32),R32-MIN(R$7:R$42),"") -> 1362.5 | X32: =IF(ISNUMBER(R32),S32-MIN(S$7:S$42),"") -> 2575 | Y32: =IF(ISNUMBER(R32),_xlfn.IFS($Y$3=0,_xlfn.CONCAT(ROUND(W32,0),", ",ROUND(X32,0)),$Y$3=1,N32,$Y$3=2,_xlfn.CONCAT(AB32,AC32),$Y$3=3,_xlfn.CONCAT(AG32,AH32),$Y$3=4,BH32,$Y$3=5,BI32,$Y$3=6,BJ32),"") -> 25 | Z32: =IF(ISNUMBER(R32),V31-V32,"") -> 9 | AA32: =IF(Z32<0,MAX(AA$6:AA31)+1,0) -> 0 | AB32: =IF(ISNUMBER(R32),IF(AA32=0,AB31,AA32),"") -> 6 | AC32: =IF(ISNUMBER(R31),IF(AA32<>0,1,AC31+1),"") -> 4 | AE32: =AE31 -> 3 | AF32: 0 | AG32: =IF(ISNUMBER(R32),AB32+AE32,"") -> 9 | AH32: =IF(ISNUMBER(S32),AC32+AF32,"") -> 4 | AJ32: =IF(AND(ISNUMBER(AJ10),(ISNUMBER(O$5))),INDEX($Y$7:$Y$41,AJ10,1),"") -> 3 | AK32: =IF(AND(ISNUMBER(AK10),(ISNUMBER(P$5))),INDEX($Y$7:$Y$41,AK10,1),"") | AL32: =IF(AND(ISNUMBER(AL10),(ISNUMBER(Q$5))),INDEX($Y$7:$Y$41,AL10,1),"") -> 11 | AM32: =IF(AND(ISNUMBER(AM10),(ISNUMBER(R$5))),INDEX($Y$7:$Y$41,AM10,1),"") -> 15 | AN32: =IF(AND(ISNUMBER(AN10),(ISNUMBER(S$5))),INDEX($Y$7:$Y$41,AN10,1),"") -> 19 | AO32: =IF(AND(ISNUMBER(AO10),(ISNUMBER(T$5))),INDEX($Y$7:$Y$41,AO10,1),"") -> 25 | AP32: =IF(AND(ISNUMBER(AP10),(ISNUMBER(U$5))),INDEX($Y$7:$Y$41,AP10,1),"") | AQ32: =IF(AND(ISNUMBER(AQ10),(ISNUMBER(V$5))),INDEX($Y$7:$Y$41,AQ10,1),"") | AR32: =IF(AND(ISNUMBER(AR10),(ISNUMBER(#REF!))),INDEX($Y$7:$Y$41,AR10,1),"") | AS32: =IF(AND(ISNUMBER(AS10),(ISNUMBER(W$5))),INDEX($Y$7:$Y$41,AS10,1),"") | BF32: 25 | BG32: 25 | BH32: 11 | BI32: =BI31-1 -> -28
B33: =IF(ISNUMBER(C33),B32+1,"") -> 27 | C33: 468284.78 | D33: 7609942.8 | F33: 464909.78 | G33: 7609892.8 | H33: POINT (464909.7813 7609892.75) | I33: [844] | J33: 844 | L33: =IF(ISNUMBER(R33),SQRT((R33-R32)^2+(S33-S32)^2),"") -> 875.08928 | N33: =IF(ISNUMBER(O33),O33-1,"") -> 26 | O33: =IF(ISNUMBER(Q33),ROW()-ROW(O$6),"") -> 27 | P33: =IF($AB33=M$3,O33,"") | Q33: =IF(ISNUMBER(R33),Q32+1,"") -> 27 | R33: 464909.78 | S33: 7609892.8 | T33: POINT (464909.7813 7609892.75) | U33: [844] | V33: 844 | W33: =IF(ISNUMBER(R33),R33-MIN(R$7:R$42),"") -> 737.5 | X33: =IF(ISNUMBER(R33),S33-MIN(S$7:S$42),"") -> 1962.5 | Y33: =IF(ISNUMBER(R33),_xlfn.IFS($Y$3=0,_xlfn.CONCAT(ROUND(W33,0),", ",ROUND(X33,0)),$Y$3=1,N33,$Y$3=2,_xlfn.CONCAT(AB33,AC33),$Y$3=3,_xlfn.CONCAT(AG33,AH33),$Y$3=4,BH33,$Y$3=5,BI33,$Y$3=6,BJ33),"") -> 26 | Z33: =IF(ISNUMBER(R33),V32-V33,"") -> 12 | AA33: =IF(Z33<0,MAX(AA$6:AA32)+1,0) -> 0 | AB33: =IF(ISNUMBER(R33),IF(AA33=0,AB32,AA33),"") -> 6 | AC33: =IF(ISNUMBER(R32),IF(AA33<>0,1,AC32+1),"") -> 5 | AE33: =AE32 -> 3 | AF33: 0 | AG33: =IF(ISNUMBER(R33),AB33+AE33,"") -> 9 | AH33: =IF(ISNUMBER(S33),AC33+AF33,"") -> 5 | AJ33: =IF(AND(ISNUMBER(AJ11),(ISNUMBER(O$5))),INDEX($Y$7:$Y$41,AJ11,1),"") -> 4 | AK33: =IF(AND(ISNUMBER(AK11),(ISNUMBER(P$5))),INDEX($Y$7:$Y$41,AK11,1),"") | AL33: =IF(AND(ISNUMBER(AL11),(ISNUMBER(Q$5))),INDEX($Y$7:$Y$41,AL11,1),"") | AM33: =IF(AND(ISNUMBER(AM11),(ISNUMBER(R$5))),INDEX($Y$7:$Y$41,AM11,1),"") | AN33: =IF(AND(ISNUMBER(AN11),(ISNUMBER(S$5))),INDEX($Y$7:$Y$41,AN11,1),"") -> 20 | AO33: =IF(AND(ISNUMBER(AO11),(ISNUMBER(T$5))),INDEX($Y$7:$Y$41,AO11,1),"") -> 26 | AP33: =IF(AND(ISNUMBER(AP11),(ISNUMBER(U$5))),INDEX($Y$7:$Y$41,AP11,1),"") | AQ33: =IF(AND(ISNUMBER(AQ11),(ISNUMBER(V$5))),INDEX($Y$7:$Y$41,AQ11,1),"") | AR33: =IF(AND(ISNUMBER(AR11),(ISNUMBER(#REF!))),INDEX($Y$7:$Y$41,AR11,1),"") | AS33: =IF(AND(ISNUMBER(AS11),(ISNUMBER(W$5))),INDEX($Y$7:$Y$41,AS11,1),"") | BF33: 26 | BG33: 26 | BH33: 11 | BI33: =BI32-1 -> -29
B34: =IF(ISNUMBER(C34),B33+1,"") -> 28 | C34: 466622.28 | D34: 7609955.2 | F34: 464822.28 | G34: 7609305.2 | H34: POINT (464822.2813 7609305.25) | I34: [846] | J34: 846 | L34: =IF(ISNUMBER(R34),SQRT((R34-R33)^2+(S34-S33)^2),"") -> 593.98022 | N34: =IF(ISNUMBER(O34),O34-1,"") -> 27 | O34: =IF(ISNUMBER(Q34),ROW()-ROW(O$6),"") -> 28 | P34: =IF($AB34=M$3,O34,"") -> 28 | Q34: =IF(ISNUMBER(R34),Q33+1,"") -> 28 | R34: 464822.28 | S34: 7609305.2 | T34: POINT (464822.2813 7609305.25) | U34: [846] | V34: 846 | W34: =IF(ISNUMBER(R34),R34-MIN(R$7:R$42),"") -> 650 | X34: =IF(ISNUMBER(R34),S34-MIN(S$7:S$42),"") -> 1375 | Y34: =IF(ISNUMBER(R34),_xlfn.IFS($Y$3=0,_xlfn.CONCAT(ROUND(W34,0),", ",ROUND(X34,0)),$Y$3=1,N34,$Y$3=2,_xlfn.CONCAT(AB34,AC34),$Y$3=3,_xlfn.CONCAT(AG34,AH34),$Y$3=4,BH34,$Y$3=5,BI34,$Y$3=6,BJ34),"") -> 27 | Z34: =IF(ISNUMBER(R34),V33-V34,"") -> -2 | AA34: =IF(Z34<0,MAX(AA$6:AA33)+1,0) -> 7 | AB34: =IF(ISNUMBER(R34),IF(AA34=0,AB33,AA34),"") -> 7 | AC34: =IF(ISNUMBER(R33),IF(AA34<>0,1,AC33+1),"") -> 1 | AE34: =AE33 -> 3 | AF34: 0 | AG34: =IF(ISNUMBER(R34),AB34+AE34,"") -> 10 | AH34: =IF(ISNUMBER(S34),AC34+AF34,"") -> 1 | AJ34: =IF(AND(ISNUMBER(AJ12),(ISNUMBER(O$5))),INDEX($Y$7:$Y$41,AJ12,1),"") | AK34: =IF(AND(ISNUMBER(AK12),(ISNUMBER(P$5))),INDEX($Y$7:$Y$41,AK12,1),"") | AL34: =IF(AND(ISNUMBER(AL12),(ISNUMBER(Q$5))),INDEX($Y$7:$Y$41,AL12,1),"") | AM34: =IF(AND(ISNUMBER(AM12),(ISNUMBER(R$5))),INDEX($Y$7:$Y$41,AM12,1),"") | AN34: =IF(AND(ISNUMBER(AN12),(ISNUMBER(S$5))),INDEX($Y$7:$Y$41,AN12,1),"") -> 21 | AO34: =IF(AND(ISNUMBER(AO12),(ISNUMBER(T$5))),INDEX($Y$7:$Y$41,AO12,1),"") | AP34: =IF(AND(ISNUMBER(AP12),(ISNUMBER(U$5))),INDEX($Y$7:$Y$41,AP12,1),"") | AQ34: =IF(AND(ISNUMBER(AQ12),(ISNUMBER(V$5))),INDEX($Y$7:$Y$41,AQ12,1),"") | AR34: =IF(AND(ISNUMBER(AR12),(ISNUMBER(#REF!))),INDEX($Y$7:$Y$41,AR12,1),"") | AS34: =IF(AND(ISNUMBER(AS12),(ISNUMBER(W$5))),INDEX($Y$7:$Y$41,AS12,1),"") | BF34: 27 | BG34: 27 | BH34: 11 | BI34: =BI33-1 -> -30 | BJ34: D
B35: =IF(ISNUMBER(C35),B34+1,"") -> 29 | C35: 466097.28 | D35: 7610467.8 | F35: 464172.28 | G35: 7607930.2 | H35: POINT (464172.2813 7607930.25) | I35: [842] | J35: 842 | L35: =IF(ISNUMBER(R35),SQRT((R35-R34)^2+(S35-S34)^2),"") -> 1520.8961 | N35: =IF(ISNUMBER(O35),O35-1,"") -> 28 | O35: =IF(ISNUMBER(Q35),ROW()-ROW(O$6),"") -> 29 | P35: =IF($AB35=M$3,O35,"") -> 29 | Q35: =IF(ISNUMBER(R35),Q34+1,"") -> 29 | R35: 464172.28 | S35: 7607930.2 | T35: POINT (464172.2813 7607930.25) | U35: [842] | V35: 842 | W35: =IF(ISNUMBER(R35),R35-MIN(R$7:R$42),"") -> 0 | X35: =IF(ISNUMBER(R35),S35-MIN(S$7:S$42),"") -> 0 | Y35: =IF(ISNUMBER(R35),_xlfn.IFS($Y$3=0,_xlfn.CONCAT(ROUND(W35,0),", ",ROUND(X35,0)),$Y$3=1,N35,$Y$3=2,_xlfn.CONCAT(AB35,AC35),$Y$3=3,_xlfn.CONCAT(AG35,AH35),$Y$3=4,BH35,$Y$3=5,BI35,$Y$3=6,BJ35),"") -> 28 | Z35: =IF(ISNUMBER(R35),V34-V35,"") -> 4 | AA35: =IF(Z35<0,MAX(AA$6:AA34)+1,0) -> 0 | AB35: =IF(ISNUMBER(R35),IF(AA35=0,AB34,AA35),"") -> 7 | AC35: =IF(ISNUMBER(R34),IF(AA35<>0,1,AC34+1),"") -> 2 | AE35: =AE34 -> 3 | AF35: 0 | AG35: =IF(ISNUMBER(R35),AB35+AE35,"") -> 10 | AH35: =IF(ISNUMBER(S35),AC35+AF35,"") -> 2 | AJ35: =IF(AND(ISNUMBER(AJ13),(ISNUMBER(O$5))),INDEX($Y$7:$Y$41,AJ13,1),"") | AK35: =IF(AND(ISNUMBER(AK13),(ISNUMBER(P$5))),INDEX($Y$7:$Y$41,AK13,1),"") | AL35: =IF(AND(ISNUMBER(AL13),(ISNUMBER(Q$5))),INDEX($Y$7:$Y$41,AL13,1),"") | AM35: =IF(AND(ISNUMBER(AM13),(ISNUMBER(R$5))),INDEX($Y$7:$Y$41,AM13,1),"") | AN35: =IF(AND(ISNUMBER(AN13),(ISNUMBER(S$5))),INDEX($Y$7:$Y$41,AN13,1),"") | AO35: =IF(AND(ISNUMBER(AO13),(ISNUMBER(T$5))),INDEX($Y$7:$Y$41,AO13,1),"") | AP35: =IF(AND(ISNUMBER(AP13),(ISNUMBER(U$5))),INDEX($Y$7:$Y$41,AP13,1),"") | AQ35: =IF(AND(ISNUMBER(AQ13),(ISNUMBER(V$5))),INDEX($Y$7:$Y$41,AQ13,1),"") | AR35: =IF(AND(ISNUMBER(AR13),(ISNUMBER(#REF!))),INDEX($Y$7:$Y$41,AR13,1),"") | AS35: =IF(AND(ISNUMBER(AS13),(ISNUMBER(W$5))),INDEX($Y$7:$Y$41,AS13,1),"") | BF35: 28 | BG35: 28 | BH35: 11 | BI35: =BI34-1 -> -31
