Workbook
Name a: #REF!
Name ai: #REF!
Name aq: #REF!
Name AV: #REF!
Name baa: #REF!
Name Coord: #REF!
Name CS: #REF!
Name CZ: #REF!
Name DG: #REF!
Name earlier: #REF!
Name EG: #REF!
Name EI: #REF!
Name HLinst: #REF!
Name HP: #REF!
Name I: #REF!
Name JA: #REF!
Name Mean_A: #REF!
Name mean_X: #REF!
Name mean_X.: #REF!
Name mean_Y: #REF!
Name mean_Y.: #REF!
Name mu: #REF!
Name mu_A: #REF!
Name mu_B: #REF!
Name P1_A: #REF!
Name P2_A: #REF!
Name P3_A: #REF!
Name P4_A: #REF!
Name P5_A: #REF!
Name Rot: #REF!
Name SD_A: #REF!
Name SD_X: #REF!
Name SD_Y: #REF!
Name sigma: #REF!
Name sigma_AB: #REF!
Name sigma2_A: #REF!
Name sigma2_B: #REF!
Name Tab.43: #REF!
Name Tab.44: #REF!
Name Target_P: #REF!
Name Total_Mass: #REF!
Name Variance_A: #REF!
Name X: #REF!
Name x_A: #REF!
Name x_B: #REF!
Name Xo: #REF!
Name Yo.1: #REF!
Name Yo.2: #REF!
Name yt: #REF!

Sheet ____
C2: 0 | D2: 1 | E2: 2 | F2: 3 | G2: 4 | H2: 5 | I2: 6 | J2: 7 | K2: 8 | L2: 9 | M2: 10 | N2: 11 | O2: 12 | P2: 13 | Q2: 14 | R2: 15 | S2: 16 | T2: 17 | U2: 18 | V2: 19 | W2: 20 | X2: 21 | Y2: 22 | Z2: 23 | AA2: 24 | AB2: 25 | AC2: 26 | AD2: 27 | AE2: 28 | AF2: 29 | AG2: 30 | AH2: 31 | AI2: 32 | AJ2: 33 | AK2: 34 | AL2: 35 | AM2: 36 | AN2: 37 | AO2: 38 | AP2: 39 | AV2: 0 | AW2: 1 | AX2: 2 | AY2: 3 | AZ2: 4 | BA2: 5 | BB2: 6 | BC2: 7 | BD2: 8 | BE2: 9 | BF2: 10 | BG2: 11 | BH2: 12 | BI2: 13 | BJ2: 14 | BK2: 15 | BL2: 16 | BM2: 17 | BN2: 18 | BO2: 19 | BP2: 20 | BQ2: 21 | BR2: 22 | BS2: 23 | BT2: 24 | BU2: 25 | BV2: 26 | BW2: 27 | BX2: 28 | BY2: 29 | BZ2: 30 | CA2: 31 | CB2: 32 | CC2: 33 | CD2: 34 | CE2: 35 | CF2: 36 | CG2: 37 | CH2: 38 | CI2: 39
B3: 0 | C3: 1e-10 | D3: 1e-10 | E3: 1e-10 | F3: 1e-10 | G3: 1e-10 | H3: 1e-10 | I3: 1e-10 | J3: 1e-10 | K3: 1e-10 | L3: 1e-10 | M3: 1e-10 | N3: 1e-10 | O3: 1e-10 | P3: 1e-10 | Q3: 1e-10 | R3: 1e-10 | S3: 1e-10 | T3: 1e-10 | U3: 1e-10 | V3: 1e-10 | W3: 1e-10 | X3: 1e-10 | Y3: 1e-10 | Z3: 1e-10 | AA3: 1e-10 | AB3: 1e-10 | AC3: 1e-10 | AD3: 1e-10 | AE3: 1e-10 | AF3: 1e-10 | AG3: 1e-10 | AH3: 1e-10 | AI3: 1e-10 | AJ3: 1e-10 | AK3: 1e-10 | AL3: 1e-10 | AM3: 1e-10 | AN3: 1e-10 | AO3: 1e-05 | AP3: 1e-05 | AR3: MAX | AS3: =MAX($C$3:$AP$22) -> 10 | AU3: 0 | AV3: 1e-07 | AW3: 1e-07 | AX3: 1e-07 | AY3: 1e-07 | AZ3: 1e-07 | BA3: 1e-07 | BB3: 1e-07 | BC3: 1e-07 | BD3: 1e-07 | BE3: 1e-07 | BF3: 1e-10 | BG3: 1e-10 | BH3: 1e-10 | BI3: 1e-10 | BJ3: 1e-10 | BK3: 1e-10 | BL3: 1e-07 | BM3: 1e-07 | BN3: 1e-07 | BO3: 1e-07 | BP3: 1e-10 | BQ3: 1e-10 | BR3: 1e-10 | BS3: 1e-10 | BT3: 1e-10 | BU3: 1e-10 | BV3: 1e-10 | BW3: 1e-10 | BX3: 1e-10 | BY3: 1e-10 | BZ3: 1e-10 | CA3: 1e-10 | CB3: 1e-10 | CC3: 1e-10 | CD3: 1e-10 | CE3: 1e-10 | CF3: 1e-10 | CG3: 1e-10 | CH3: 1e-10 | CI3: 1e-10
B4: 1 | C4: 1 | D4: 1e-05 | E4: 1e-05 | F4: 1e-05 | G4: 1e-05 | H4: 1e-05 | I4: 1e-05 | J4: 1e-05 | K4: 1e-05 | L4: 1e-05 | M4: 1e-05 | N4: 1e-05 | O4: 1e-05 | P4: 1e-05 | Q4: 1e-05 | R4: 1e-10 | S4: 1e-10 | T4: 1e-10 | U4: 1e-10 | V4: 1e-10 | W4: 1e-10 | X4: 1e-10 | Y4: 1e-10 | Z4: 1e-05 | AA4: 1e-05 | AB4: 1e-05 | AC4: 1e-05 | AD4: 1e-05 | AE4: 1e-05 | AF4: 1e-05 | AG4: 1e-05 | AH4: 1e-05 | AI4: 1e-05 | AJ4: 1e-05 | AK4: 1e-05 | AL4: 1e-05 | AM4: 1e-05 | AN4: 1e-05 | AO4: 1e-05 | AP4: 1 | AR4: MIN | AS4: =MIN($C$3:$AP$22) -> 1e-10 | AU4: 1 | AV4: 1e-10 | AW4: 1e-10 | AX4: 1e-10 | AY4: 1e-10 | AZ4: 1e-10 | BA4: 1e-10 | BB4: 1e-10 | BC4: 1e-10 | BD4: 1e-10 | BE4: 1e-10 | BF4: 1e-10 | BG4: 1e-10 | BH4: 1e-10 | BI4: 1e-10 | BJ4: 1e-10 | BK4: 1e-10 | BL4: 1e-10 | BM4: 1e-10 | BN4: 1e-10 | BO4: 1e-10 | BP4: 1e-10 | BQ4: 1e-10 | BR4: 1e-10 | BS4: 1e-10 | BT4: 1e-10 | BU4: 1e-10 | BV4: 1e-10 | BW4: 1e-10 | BX4: 1e-10 | BY4: 1e-10 | BZ4: 1e-10 | CA4: 1e-10 | CB4: 1e-10 | CC4: 1e-10 | CD4: 1e-10 | CE4: 1e-10 | CF4: 1e-10 | CG4: 1e-10 | CH4: 1e-10 | CI4: 1e-10
B5: 2 | C5: 1e-10 | D5: 1e-10 | E5: 1e-10 | F5: 1e-10 | G5: 1e-10 | H5: 1e-10 | I5: 1e-10 | J5: 1e-10 | K5: 1e-10 | L5: 1e-10 | M5: 1e-10 | N5: 1e-10 | O5: 1e-10 | P5: 1e-10 | Q5: 1e-10 | R5: 1e-10 | S5: 1e-10 | T5: 1e-10 | U5: 1e-10 | V5: 1e-10 | W5: 1e-10 | X5: 1e-10 | Y5: 1e-10 | Z5: 1e-10 | AA5: 1e-10 | AB5: 1e-10 | AC5: 1e-10 | AD5: 1e-10 | AE5: 1e-10 | AF5: 1e-10 | AG5: 1e-10 | AH5: 1e-10 | AI5: 1e-10 | AJ5: 1e-10 | AK5: 1e-10 | AL5: 1e-10 | AM5: 1e-10 | AN5: 1e-10 | AO5: 1e-10 | AP5: 1e-10 | AR5: AVE | AS5: =AVERAGE($C$3:$AP$22) -> 1.5162525 | AU5: 2 | AV5: 1e-10 | AW5: 1e-10 | AX5: 1e-10 | AY5: 1e-10 | AZ5: 1e-10 | BA5: 1e-10 | BB5: 1e-10 | BC5: 1e-10 | BD5: 1e-10 | BE5: 1e-10 | BF5: 1e-10 | BG5: 1e-10 | BH5: 1e-10 | BI5: 1e-10 | BJ5: 1e-10 | BK5: 1e-10 | BL5: 1e-10 | BM5: 1e-10 | BN5: 1e-10 | BO5: 1e-10 | BP5: 1e-10 | BQ5: 1e-10 | BR5: 1e-10 | BS5: 1e-10 | BT5: 1e-10 | BU5: 1e-10 | BV5: 1e-10 | BW5: 1e-10 | BX5: 1e-10 | BY5: 1e-10 | BZ5: 1e-10 | CA5: 1e-10 | CB5: 1e-10 | CC5: 1e-10 | CD5: 1e-10 | CE5: 1e-10 | CF5: 1e-10 | CG5: 1e-10 | CH5: 1e-10 | CI5: 1e-10
B6: 3 | C6: 1e-05 | D6: 1e-05 | E6: 1e-05 | F6: 1e-05 | G6: 1e-05 | H6: 1e-05 | I6: 1e-05 | J6: 1e-05 | K6: 1e-05 | L6: 1e-05 | M6: 1e-05 | N6: 1 | O6: 2 | P6: 2 | Q6: 2 | R6: 10 | S6: 10 | T6: 10 | U6: 10 | V6: 10 | W6: 10 | X6: 10 | Y6: 10 | Z6: 10 | AA6: 10 | AB6: 10 | AC6: 2 | AD6: 10 | AE6: 2 | AF6: 2 | AG6: 1 | AH6: 1 | AI6: 1 | AJ6: 1e-05 | AK6: 1e-05 | AL6: 1e-05 | AM6: 1e-05 | AN6: 1e-05 | AO6: 1 | AP6: 1e-05 | AR6: MED | AS6: =MEDIAN($C$3:$AP$22) -> 1e-05 | AU6: 3 | AV6: 1e-10 | AW6: 1e-10 | AX6: 1e-10 | AY6: 1e-10 | AZ6: 1e-10 | BA6: 1e-10 | BB6: 1e-10 | BC6: 1e-10 | BD6: 1e-10 | BE6: 1e-10 | BF6: 1e-10 | BG6: 1e-10 | BH6: 1e-10 | BI6: 1e-10 | BJ6: 1e-10 | BK6: 1e-10 | BL6: 1e-10 | BM6: 1e-10 | BN6: 1e-10 | BO6: 1e-10 | BP6: 1e-10 | BQ6: 1e-10 | BR6: 1e-10 | BS6: 1e-10 | BT6: 1e-10 | BU6: 1e-10 | BV6: 1e-10 | BW6: 1e-10 | BX6: 1e-10 | BY6: 1e-10 | BZ6: 1e-10 | CA6: 1e-10 | CB6: 1e-10 | CC6: 1e-10 | CD6: 1e-10 | CE6: 1e-10 | CF6: 1e-10 | CG6: 1e-10 | CH6: 1e-10 | CI6: 1e-10
B7: 4 | C7: 1e-10 | D7: 1e-05 | E7: 1e-05 | F7: 1e-05 | G7: 1e-05 | H7: 1e-10 | I7: 1e-10 | J7: 1e-05 | K7: 1e-05 | L7: 1e-05 | M7: 1e-05 | N7: 1 | O7: 1 | P7: 1 | Q7: 1e-05 | R7: 1e-05 | S7: 1e-05 | T7: 1 | U7: 1 | V7: 1 | W7: 1e-05 | X7: 1e-05 | Y7: 1e-05 | Z7: 1e-05 | AA7: 1e-05 | AB7: 1 | AC7: 1 | AD7: 1 | AE7: 2 | AF7: 1 | AG7: 2 | AH7: 2 | AI7: 2 | AJ7: 2 | AK7: 2 | AL7: 2 | AM7: 2 | AN7: 2 | AO7: 2 | AP7: 1 | AR7: ST | AS7: =_xlfn.STDEV.S($C$3:$AP$22) -> 2.9876221 | AU7: 4 | AV7: 1e-05 | AW7: 1e-05 | AX7: 1e-07 | AY7: 1e-07 | AZ7: 1e-07 | BA7: 1e-07 | BB7: 1e-07 | BC7: 1e-07 | BD7: 1e-07 | BE7: 1e-07 | BF7: 1e-07 | BG7: 1e-07 | BH7: 1e-07 | BI7: 1e-07 | BJ7: 1e-10 | BK7: 1e-10 | BL7: 1e-10 | BM7: 1e-07 | BN7: 1e-07 | BO7: 1e-07 | BP7: 1e-07 | BQ7: 1e-05 | BR7: 1e-05 | BS7: 1e-05 | BT7: 1e-05 | BU7: 1e-07 | BV7: 1e-07 | BW7: 1e-05 | BX7: 1e-07 | BY7: 1e-07 | BZ7: 1e-07 | CA7: 1e-07 | CB7: 1e-07 | CC7: 1e-07 | CD7: 1e-07 | CE7: 1e-07 | CF7: 1e-10 | CG7: 1e-10 | CH7: 1e-10 | CI7: 1e-10
B8: 5 | C8: 1e-05 | D8: 1e-05 | E8: 1e-05 | F8: 1 | G8: 2 | H8: 1 | I8: 1 | J8: 1 | K8: 1 | L8: 1 | M8: 1 | N8: 1 | O8: 1 | P8: 1 | Q8: 1 | R8: 1e-05 | S8: 1e-05 | T8: 1e-05 | U8: 1e-05 | V8: 1e-05 | W8: 1e-05 | X8: 1e-05 | Y8: 1 | Z8: 1 | AA8: 1 | AB8: 1e-05 | AC8: 1e-05 | AD8: 1e-05 | AE8: 1 | AF8: 1e-05 | AG8: 1e-05 | AH8: 1e-05 | AI8: 1 | AJ8: 1 | AK8: 2 | AL8: 2 | AM8: 2 | AN8: 1 | AO8: 1 | AP8: 1 | AU8: 5 | AV8: 1e-07 | AW8: 1e-05 | AX8: 1e-05 | AY8: 1e-05 | AZ8: 0.01 | BA8: 0.01 | BB8: 1e-05 | BC8: 0.01 | BD8: 10 | BE8: 0.01 | BF8: 0.01 | BG8: 0.01 | BH8: 0.01 | BI8: 10 | BJ8: 0.01 | BK8: 0.01 | BL8: 0.01 | BM8: 0.01 | BN8: 0.01 | BO8: 10 | BP8: 10 | BQ8: 0.01 | BR8: 0.01 | BS8: 0.01 | BT8: 0.01 | BU8: 1e-05 | BV8: 1e-05 | BW8: 1e-05 | BX8: 0.01 | BY8: 0.01 | BZ8: 0.01 | CA8: 10 | CB8: 10 | CC8: 10 | CD8: 10 | CE8: 0.01 | CF8: 0.01 | CG8: 0.01 | CH8: 0.01 | CI8: 10
B9: 6 | C9: 1e-10 | D9: 1e-10 | E9: 1e-10 | F9: 1e-10 | G9: 1e-10 | H9: 1e-10 | I9: 1e-10 | J9: 1e-10 | K9: 1e-10 | L9: 1e-10 | M9: 1e-10 | N9: 1e-10 | O9: 1e-10 | P9: 1e-10 | Q9: 1e-10 | R9: 1e-10 | S9: 1e-10 | T9: 1e-10 | U9: 1e-10 | V9: 1e-10 | W9: 1e-10 | X9: 1e-10 | Y9: 1e-10 | Z9: 1e-10 | AA9: 1e-10 | AB9: 1e-10 | AC9: 1e-10 | AD9: 1e-10 | AE9: 1e-10 | AF9: 1e-10 | AG9: 1e-10 | AH9: 1e-10 | AI9: 1e-05 | AJ9: 1e-05 | AK9: 1e-05 | AL9: 1e-05 | AM9: 1 | AN9: 1 | AO9: 1 | AP9: 2 | AU9: 6 | AV9: 1e-10 | AW9: 1e-07 | AX9: 1e-07 | AY9: 1e-10 | AZ9: 1e-10 | BA9: 1e-07 | BB9: 1e-07 | BC9: 1e-07 | BD9: 1e-07 | BE9: 1e-07 | BF9: 1e-07 | BG9: 1e-07 | BH9: 1e-07 | BI9: 1e-05 | BJ9: 1e-07 | BK9: 1e-07 | BL9: 1e-07 | BM9: 1e-07 | BN9: 1e-07 | BO9: 1e-07 | BP9: 1e-05 | BQ9: 1e-05 | BR9: 1e-05 | BS9: 0.01 | BT9: 1e-05 | BU9: 0.01 | BV9: 1e-05 | BW9: 1e-07 | BX9: 1e-07 | BY9: 1e-07 | BZ9: 1e-07 | CA9: 1e-07 | CB9: 1e-07 | CC9: 1e-05 | CD9: 1e-07 | CE9: 1e-07 | CF9: 1e-07 | CG9: 1e-05 | CH9: 1e-05 | CI9: 1e-07
B10: 7 | C10: 1e-05 | D10: 1e-05 | E10: 1e-05 | F10: 1e-05 | G10: 1e-05 | H10: 1e-05 | I10: 1e-05 | J10: 1e-05 | K10: 1e-05 | L10: 1e-05 | M10: 1e-05 | N10: 1e-10 | O10: 1e-10 | P10: 1e-10 | Q10: 1e-10 | R10: 1e-10 | S10: 1e-05 | T10: 1e-10 | U10: 1e-10 | V10: 1e-10 | W10: 1e-10 | X10: 1e-10 | Y10: 1e-10 | Z10: 1e-10 | AA10: 1e-10 | AB10: 1e-10 | AC10: 1e-10 | AD10: 1e-10 | AE10: 1e-10 | AF10: 1e-10 | AG10: 1e-10 | AH10: 1e-10 | AI10: 1e-10 | AJ10: 1e-10 | AK10: 1e-10 | AL10: 1e-10 | AM10: 1e-10 | AN10: 1e-10 | AO10: 1e-10 | AP10: 1e-10 | AS10: =MAX($AV$3:$CI$22) -> 10 | AU10: 7 | AV10: 1e-10 | AW10: 1e-10 | AX10: 1e-10 | AY10: 1e-10 | AZ10: 1e-10 | BA10: 1e-10 | BB10: 1e-10 | BC10: 1e-10 | BD10: 1e-10 | BE10: 1e-10 | BF10: 1e-10 | BG10: 1e-10 | BH10: 1e-10 | BI10: 1e-10 | BJ10: 1e-10 | BK10: 1e-10 | BL10: 1e-10 | BM10: 1e-10 | BN10: 1e-10 | BO10: 1e-10 | BP10: 1e-10 | BQ10: 1e-10 | BR10: 1e-07 | BS10: 1e-10 | BT10: 1e-07 | BU10: 1e-07 | BV10: 1e-10 | BW10: 1e-07 | BX10: 1e-10 | BY10: 1e-10 | BZ10: 1e-07 | CA10: 1e-10 | CB10: 1e-10 | CC10: 1e-07 | CD10: 1e-07 | CE10: 1e-07 | CF10: 1e-05 | CG10: 1e-05 | CH10: 1e-07 | CI10: 1e-07
B11: 8 | C11: 1 | D11: 1 | E11: 1 | F11: 1 | G11: 1e-05 | H11: 1e-05 | I11: 1 | J11: 1 | K11: 1 | L11: 2 | M11: 2 | N11: 2 | O11: 2 | P11: 2 | Q11: 1 | R11: 1 | S11: 1 | T11: 1 | U11: 1e-05 | V11: 1e-05 | W11: 1e-05 | X11: 1e-10 | Y11: 1e-10 | Z11: 1e-10 | AA11: 1e-10 | AB11: 1e-10 | AC11: 1e-10 | AD11: 1e-10 | AE11: 1e-10 | AF11: 1e-10 | AG11: 1e-10 | AH11: 1e-10 | AI11: 1e-10 | AJ11: 1e-10 | AK11: 1e-10 | AL11: 1e-10 | AM11: 1e-10 | AN11: 1e-10 | AO11: 1e-10 | AP11: 1e-10 | AS11: =MIN($AV$3:$CI$22) -> 1e-10 | AU11: 8 | AV11: 1e-05 | AW11: 1e-05 | AX11: 1e-05 | AY11: 0.01 | AZ11: 0.01 | BA11: 1e-05 | BB11: 1e-05 | BC11: 1e-05 | BD11: 1e-05 | BE11: 1e-07 | BF11: 1e-05 | BG11: 1e-05 | BH11: 0.01 | BI11: 0.01 | BJ11: 0.01 | BK11: 0.01 | BL11: 0.01 | BM11: 0.01 | BN11: 0.01 | BO11: 0.01 | BP11: 1e-05 | BQ11: 1e-05 | BR11: 0.01 | BS11: 0.01 | BT11: 10 | BU11: 10 | BV11: 10 | BW11: 10 | BX11: 10 | BY11: 10 | BZ11: 10 | CA11: 0.01 | CB11: 0.01 | CC11: 0.01 | CD11: 0.01 | CE11: 0.01 | CF11: 0.01 | CG11: 0.01 | CH11: 0.01 | CI11: 0.01
B12: 9 | C12: 1 | D12: 1 | E12: 1 | F12: 2 | G12: 1 | H12: 1 | I12: 1 | J12: 1 | K12: 1e-05 | L12: 1e-05 | M12: 1e-05 | N12: 1e-05 | O12: 1e-05 | P12: 1 | Q12: 1 | R12: 1 | S12: 1 | T12: 1 | U12: 1 | V12: 1 | W12: 1 | X12: 1 | Y12: 1 | Z12: 2 | AA12: 1 | AB12: 1 | AC12: 1 | AD12: 1e-05 | AE12: 1e-05 | AF12: 1e-05 | AG12: 1e-05 | AH12: 1e-05 | AI12: 1e-05 | AJ12: 1e-05 | AK12: 1e-05 | AL12: 1e-05 | AM12: 1e-05 | AN12: 1e-05 | AO12: 1 | AP12: 1e-05 | AS12: =AVERAGE($AV$3:$CI$22) -> 0.86403926 | AU12: 9 | AV12: 0.01 | AW12: 0.01 | AX12: 0.01 | AY12: 10 | AZ12: 0.01 | BA12: 0.01 | BB12: 0.01 | BC12: 10 | BD12: 10 | BE12: 10 | BF12: 0.01 | BG12: 10 | BH12: 10 | BI12: 10 | BJ12: 10 | BK12: 10 | BL12: 10 | BM12: 10 | BN12: 10 | BO12: 10 | BP12: 10 | BQ12: 0.01 | BR12: 0.01 | BS12: 10 | BT12: 10 | BU12: 10 | BV12: 10 | BW12: 0.01 | BX12: 0.01 | BY12: 0.01 | BZ12: 0.01 | CA12: 0.01 | CB12: 0.01 | CC12: 0.01 | CD12: 0.01 | CE12: 10 | CF12: 0.01 | CG12: 0.01 | CH12: 0.01 | CI12: 0.01
B13: 10 | C13: 2 | D13: 2 | E13: 10 | F13: 10 | G13: 10 | H13: 10 | I13: 10 | J13: 10 | K13: 10 | L13: 10 | M13: 10 | N13: 10 | O13: 10 | P13: 10 | Q13: 10 | R13: 10 | S13: 2 | T13: 2 | U13: 2 | V13: 2 | W13: 2 | X13: 2 | Y13: 1 | Z13: 1 | AA13: 1 | AB13: 1e-05 | AC13: 1e-05 | AD13: 1e-05 | AE13: 1e-05 | AF13: 1e-05 | AG13: 1e-05 | AH13: 1e-05 | AI13: 1e-05 | AJ13: 1e-05 | AK13: 1 | AL13: 2 | AM13: 2 | AN13: 2 | AO13: 10 | AP13: 2 | AS13: =MEDIAN($AV$3:$CI$22) -> 1e-07 | AU13: 10 | AV13: 0.01 | AW13: 0.01 | AX13: 1e-05 | AY13: 1e-05 | AZ13: 1e-05 | BA13: 0.01 | BB13: 1e-05 | BC13: 1e-05 | BD13: 0.01 | BE13: 0.01 | BF13: 0.01 | BG13: 1e-05 | BH13: 1e-05 | BI13: 1e-05 | BJ13: 1e-07 | BK13: 1e-07 | BL13: 1e-07 | BM13: 1e-07 | BN13: 1e-07 | BO13: 1e-07 | BP13: 1e-07 | BQ13: 1e-07 | BR13: 1e-07 | BS13: 1e-07 | BT13: 1e-07 | BU13: 1e-10 | BV13: 1e-10 | BW13: 1e-07 | BX13: 1e-07 | BY13: 1e-07 | BZ13: 1e-07 | CA13: 1e-07 | CB13: 1e-07 | CC13: 1e-07 | CD13: 1e-07 | CE13: 1e-07 | CF13: 1e-05 | CG13: 1e-05 | CH13: 1e-05 | CI13: 1e-05
B14: 11 | C14: 10 | D14: 10 | E14: 10 | F14: 10 | G14: 10 | H14: 10 | I14: 10 | J14: 10 | K14: 10 | L14: 10 | M14: 10 | N14: 10 | O14: 10 | P14: 10 | Q14: 10 | R14: 10 | S14: 10 | T14: 10 | U14: 10 | V14: 10 | W14: 10 | X14: 10 | Y14: 10 | Z14: 10 | AA14: 10 | AB14: 10 | AC14: 10 | AD14: 10 | AE14: 10 | AF14: 10 | AG14: 10 | AH14: 10 | AI14: 2 | AJ14: 2 | AK14: 2 | AL14: 2 | AM14: 1 | AN14: 1 | AO14: 1 | AP14: 2 | AS14: =_xlfn.STDEV.S($AV$3:$CI$22) -> 2.8086139 | AU14: 11 | AV14: 0.01 | AW14: 10 | AX14: 10 | AY14: 10 | AZ14: 10 | BA14: 10 | BB14: 0.01 | BC14: 0.01 | BD14: 0.01 | BE14: 0.01 | BF14: 10 | BG14: 0.01 | BH14: 10 | BI14: 10 | BJ14: 10 | BK14: 0.01 | BL14: 10 | BM14: 10 | BN14: 10 | BO14: 10 | BP14: 10 | BQ14: 0.01 | BR14: 0.01 | BS14: 0.01 | BT14: 0.01 | BU14: 0.01 | BV14: 0.01 | BW14: 1e-05 | BX14: 0.01 | BY14: 0.01 | BZ14: 0.01 | CA14: 0.01 | CB14: 1e-05 | CC14: 1e-05 | CD14: 1e-05 | CE14: 1e-05 | CF14: 1e-05 | CG14: 1e-05 | CH14: 1e-05 | CI14: 0.01
B15: 12 | C15: 2 | D15: 2 | E15: 2 | F15: 2 | G15: 2 | H15: 1 | I15: 2 | J15: 2 | K15: 2 | L15: 1 | M15: 2 | N15: 1 | O15: 1 | P15: 1 | Q15: 1 | R15: 1e-05 | S15: 1e-05 | T15: 1e-05 | U15: 1e-05 | V15: 1e-05 | W15: 1 | X15: 1 | Y15: 1 | Z15: 1e-05 | AA15: 1 | AB15: 1 | AC15: 1 | AD15: 1 | AE15: 1 | AF15: 1 | AG15: 1 | AH15: 1 | AI15: 1 | AJ15: 1 | AK15: 1 | AL15: 1 | AM15: 1 | AN15: 2 | AO15: 2 | AP15: 2 | AU15: 12 | AV15: 1e-07 | AW15: 1e-10 | AX15: 1e-07 | AY15: 1e-07 | AZ15: 1e-07 | BA15: 1e-07 | BB15: 1e-05 | BC15: 1e-05 | BD15: 1e-05 | BE15: 1e-05 | BF15: 1e-05 | BG15: 1e-05 | BH15: 1e-07 | BI15: 1e-07 | BJ15: 1e-07 | BK15: 1e-07 | BL15: 1e-07 | BM15: 1e-07 | BN15: 1e-07 | BO15: 1e-07 | BP15: 1e-07 | BQ15: 1e-07 | BR15: 1e-07 | BS15: 1e-07 | BT15: 1e-07 | BU15: 1e-05 | BV15: 1e-05 | BW15: 1e-07 | BX15: 1e-07 | BY15: 1e-05 | BZ15: 1e-05 | CA15: 1e-05 | CB15: 1e-05 | CC15: 1e-05 | CD15: 1e-05 | CE15: 1e-05 | CF15: 1e-05 | CG15: 0.01 | CH15: 0.01 | CI15: 1e-05
B16: 13 | C16: 10 | D16: 10 | E16: 10 | F16: 10 | G16: 10 | H16: 10 | I16: 10 | J16: 10 | K16: 10 | L16: 10 | M16: 10 | N16: 10 | O16: 10 | P16: 10 | Q16: 10 | R16: 10 | S16: 2 | T16: 2 | U16: 2 | V16: 1 | W16: 1 | X16: 1 | Y16: 1 | Z16: 1 | AA16: 1 | AB16: 2 | AC16: 2 | AD16: 2 | AE16: 2 | AF16: 2 | AG16: 2 | AH16: 2 | AI16: 2 | AJ16: 2 | AK16: 1 | AL16: 1 | AM16: 1e-05 | AN16: 1e-05 | AO16: 1e-10 | AP16: 1e-10 | AU16: 13 | AV16: 1e-07 | AW16: 1e-05 | AX16: 1e-07 | AY16: 1e-05 | AZ16: 1e-05 | BA16: 1e-07 | BB16: 1e-05 | BC16: 1e-05 | BD16: 1e-05 | BE16: 1e-05 | BF16: 1e-05 | BG16: 1e-05 | BH16: 1e-05 | BI16: 1e-05 | BJ16: 0.01 | BK16: 0.01 | BL16: 0.01 | BM16: 0.01 | BN16: 0.01 | BO16: 0.01 | BP16: 1e-05 | BQ16: 1e-05 | BR16: 1e-05 | BS16: 1e-05 | BT16: 0.01 | BU16: 1e-05 | BV16: 1e-05 | BW16: 1e-05 | BX16: 1e-07 | BY16: 1e-07 | BZ16: 1e-05 | CA16: 1e-07 | CB16: 1e-07 | CC16: 1e-07 | CD16: 1e-07 | CE16: 1e-07 | CF16: 1e-05 | CG16: 1e-05 | CH16: 1e-05 | CI16: 1e-05
B17: 14 | C17: 1e-05 | D17: 1 | E17: 1 | F17: 2 | G17: 2 | H17: 1 | I17: 1 | J17: 1 | K17: 1 | L17: 1e-05 | M17: 1e-05 | N17: 1e-05 | O17: 1e-10 | P17: 1e-10 | Q17: 1e-10 | R17: 1e-10 | S17: 1e-10 | T17: 1e-10 | U17: 1e-10 | V17: 1e-10 | W17: 1e-10 | X17: 1e-10 | Y17: 1e-10 | Z17: 1e-10 | AA17: 1e-10 | AB17: 1e-10 | AC17: 1e-05 | AD17: 1e-05 | AE17: 1e-10 | AF17: 1e-10 | AG17: 1e-10 | AH17: 1e-10 | AI17: 1e-10 | AJ17: 1e-05 | AK17: 1e-10 | AL17: 1e-10 | AM17: 1e-10 | AN17: 1e-10 | AO17: 1e-10 | AP17: 1e-10 | AU17: 14 | AV17: 1e-07 | AW17: 1e-07 | AX17: 1e-10 | AY17: 1e-07 | AZ17: 1e-07 | BA17: 1e-10 | BB17: 1e-10 | BC17: 1e-10 | BD17: 1e-10 | BE17: 1e-10 | BF17: 1e-10 | BG17: 1e-10 | BH17: 1e-10 | BI17: 1e-07 | BJ17: 1e-07 | BK17: 1e-07 | BL17: 1e-07 | BM17: 1e-10 | BN17: 1e-07 | BO17: 1e-07 | BP17: 1e-07 | BQ17: 1e-07 | BR17: 1e-07 | BS17: 1e-07 | BT17: 1e-05 | BU17: 1e-05 | BV17: 1e-05 | BW17: 1e-05 | BX17: 1e-05 | BY17: 1e-05 | BZ17: 1e-05 | CA17: 0.01 | CB17: 1e-05 | CC17: 1e-07 | CD17: 1e-07 | CE17: 1e-07 | CF17: 1e-07 | CG17: 1e-10 | CH17: 1e-10 | CI17: 1e-10
B18: 15 | C18: 1e-10 | D18: 1e-10 | E18: 1e-10 | F18: 1e-10 | G18: 1e-10 | H18: 1e-10 | I18: 1e-10 | J18: 1e-10 | K18: 1e-10 | L18: 1e-10 | M18: 1e-10 | N18: 1e-10 | O18: 1e-10 | P18: 1e-05 | Q18: 1e-05 | R18: 1e-05 | S18: 1e-05 | T18: 1e-05 | U18: 1e-05 | V18: 1e-05 | W18: 1e-05 | X18: 1e-10 | Y18: 1e-05 | Z18: 1e-05 | AA18: 1e-05 | AB18: 1e-05 | AC18: 1e-05 | AD18: 1e-05 | AE18: 1e-05 | AF18: 1e-10 | AG18: 1e-05 | AH18: 1e-05 | AI18: 1e-05 | AJ18: 1e-05 | AK18: 1e-05 | AL18: 1e-05 | AM18: 1e-05 | AN18: 1e-05 | AO18: 1e-05 | AP18: 1e-05 | AU18: 15 | AV18: 1e-10 | AW18: 1e-10 | AX18: 1e-10 | AY18: 1e-10 | AZ18: 1e-10 | BA18: 1e-10 | BB18: 1e-10 | BC18: 1e-10 | BD18: 1e-10 | BE18: 1e-10 | BF18: 1e-10 | BG18: 1e-10 | BH18: 1e-10 | BI18: 1e-10 | BJ18: 1e-10 | BK18: 1e-10 | BL18: 1e-10 | BM18: 1e-10 | BN18: 1e-10 | BO18: 1e-10 | BP18: 1e-10 | BQ18: 1e-10 | BR18: 1e-10 | BS18: 1e-10 | BT18: 1e-10 | BU18: 1e-10 | BV18: 1e-10 | BW18: 1e-10 | BX18: 1e-10 | BY18: 1e-10 | BZ18: 1e-10 | CA18: 1e-10 | CB18: 1e-07 | CC18: 1e-10 | CD18: 1e-10 | CE18: 1e-10 | CF18: 1e-10 | CG18: 1e-10 | CH18: 1e-10 | CI18: 1e-10
B19: 16 | C19: 10 | D19: 10 | E19: 10 | F19: 10 | G19: 10 | H19: 10 | I19: 10 | J19: 2 | K19: 2 | L19: 2 | M19: 2 | N19: 1 | O19: 1 | P19: 1 | Q19: 1 | R19: 1 | S19: 1 | T19: 1 | U19: 1 | V19: 1 | W19: 1e-05 | X19: 1e-05 | Y19: 1e-10 | Z19: 1e-10 | AA19: 1e-10 | AB19: 1e-10 | AC19: 1e-10 | AD19: 1e-10 | AE19: 1e-10 | AF19: 1e-10 | AG19: 1e-10 | AH19: 1e-10 | AI19: 1e-10 | AJ19: 1e-10 | AK19: 1e-10 | AL19: 1e-10 | AM19: 1e-10 | AN19: 1e-10 | AO19: 1e-10 | AP19: 1e-10 | AU19: 16 | AV19: 1e-07 | AW19: 1e-07 | AX19: 1e-07 | AY19: 1e-07 | AZ19: 1e-05 | BA19: 1e-05 | BB19: 1e-05 | BC19: 1e-05 | BD19: 1e-05 | BE19: 1e-05 | BF19: 1e-05 | BG19: 1e-07 | BH19: 1e-07 | BI19: 1e-10 | BJ19: 1e-10 | BK19: 1e-10 | BL19: 1e-10 | BM19: 1e-10 | BN19: 1e-10 | BO19: 1e-10 | BP19: 1e-07 | BQ19: 1e-07 | BR19: 1e-10 | BS19: 1e-10 | BT19: 1e-10 | BU19: 1e-10 | BV19: 1e-10 | BW19: 1e-10 | BX19: 1e-10 | BY19: 1e-10 | BZ19: 1e-10 | CA19: 1e-10 | CB19: 1e-10 | CC19: 1e-07 | CD19: 1e-07 | CE19: 1e-07 | CF19: 1e-05 | CG19: 1e-05 | CH19: 1e-07 | CI19: 1e-07
B20: 17 | C20: 1 | D20: 1 | E20: 2 | F20: 1 | G20: 1 | H20: 1 | I20: 1 | J20: 1 | K20: 1 | L20: 1 | M20: 2 | N20: 1 | O20: 1 | P20: 1 | Q20: 1 | R20: 1 | S20: 1 | T20: 1 | U20: 1e-05 | V20: 1e-05 | W20: 1 | X20: 1 | Y20: 1 | Z20: 1 | AA20: 2 | AB20: 2 | AC20: 2 | AD20: 2 | AE20: 2 | AF20: 2 | AG20: 2 | AH20: 2 | AI20: 2 | AJ20: 1 | AK20: 2 | AL20: 2 | AM20: 1 | AN20: 2 | AO20: 10 | AP20: 10 | AU20: 17 | AV20: 0.01 | AW20: 0.01 | AX20: 1e-05 | AY20: 1e-07 | AZ20: 1e-07 | BA20: 1e-07 | BB20: 1e-07 | BC20: 1e-07 | BD20: 1e-07 | BE20: 1e-07 | BF20: 1e-07 | BG20: 1e-07 | BH20: 1e-10 | BI20: 1e-10 | BJ20: 1e-10 | BK20: 1e-10 | BL20: 1e-07 | BM20: 1e-07 | BN20: 1e-10 | BO20: 1e-10 | BP20: 1e-10 | BQ20: 1e-10 | BR20: 1e-10 | BS20: 1e-10 | BT20: 1e-10 | BU20: 1e-10 | BV20: 1e-10 | BW20: 1e-10 | BX20: 1e-10 | BY20: 1e-10 | BZ20: 1e-10 | CA20: 1e-10 | CB20: 1e-10 | CC20: 1e-10 | CD20: 1e-10 | CE20: 1e-10 | CF20: 1e-10 | CG20: 1e-07 | CH20: 1e-07 | CI20: 1e-10
B21: 18 | C21: 1e-05 | D21: 1e-05 | E21: 1e-05 | F21: 1e-05 | G21: 1e-05 | H21: 1e-05 | I21: 1e-05 | J21: 1e-05 | K21: 1 | L21: 1 | M21: 1 | N21: 1 | O21: 1 | P21: 1 | Q21: 1 | R21: 1 | S21: 1 | T21: 2 | U21: 2 | V21: 1 | W21: 2 | X21: 2 | Y21: 2 | Z21: 2 | AA21: 2 | AB21: 2 | AC21: 1 | AD21: 1 | AE21: 1 | AF21: 1 | AG21: 1 | AH21: 1 | AI21: 1 | AJ21: 1 | AK21: 1 | AL21: 1 | AM21: 1 | AN21: 2 | AO21: 2 | AP21: 1 | AU21: 18 | AV21: 0.01 | AW21: 0.01 | AX21: 0.01 | AY21: 0.01 | AZ21: 1e-05 | BA21: 1e-05 | BB21: 1e-05 | BC21: 1e-05 | BD21: 1e-05 | BE21: 1e-05 | BF21: 1e-07 | BG21: 1e-05 | BH21: 1e-07 | BI21: 1e-07 | BJ21: 1e-07 | BK21: 1e-07 | BL21: 1e-07 | BM21: 1e-07 | BN21: 1e-10 | BO21: 1e-10 | BP21: 1e-10 | BQ21: 1e-10 | BR21: 1e-07 | BS21: 1e-07 | BT21: 1e-07 | BU21: 1e-07 | BV21: 1e-05 | BW21: 1e-05 | BX21: 1e-05 | BY21: 1e-05 | BZ21: 0.01 | CA21: 0.01 | CB21: 1e-05 | CC21: 1e-05 | CD21: 0.01 | CE21: 0.01 | CF21: 0.01 | CG21: 0.01 | CH21: 0.01 | CI21: 1e-05
B22: 19 | C22: 1e-05 | D22: 1e-05 | E22: 1e-05 | F22: 1 | G22: 1 | H22: 1 | I22: 1 | J22: 1 | K22: 1 | L22: 1e-05 | M22: 1e-05 | N22: 1e-05 | O22: 1e-05 | P22: 1e-05 | Q22: 1e-05 | R22: 1e-05 | S22: 1e-05 | T22: 1e-05 | U22: 1e-05 | V22: 1e-05 | W22: 1e-10 | X22: 1e-05 | Y22: 1e-05 | Z22: 1e-05 | AA22: 1e-05 | AB22: 1e-10 | AC22: 1e-10 | AD22: 1e-10 | AE22: 1e-10 | AF22: 1e-10 | AG22: 1e-10 | AH22: 1e-10 | AI22: 1e-10 | AJ22: 1e-05 | AK22: 1e-10 | AL22: 1e-10 | AM22: 1e-10 | AN22: 1e-10 | AO22: 1e-10 | AP22: 1e-10 | AU22: 19 | AV22: 10 | AW22: 10 | AX22: 0.01 | AY22: 0.01 | AZ22: 10 | BA22: 0.01 | BB22: 10 | BC22: 10 | BD22: 10 | BE22: 0.01 | BF22: 10 | BG22: 10 | BH22: 10 | BI22: 10 | BJ22: 10 | BK22: 10 | BL22: 10 | BM22: 10 | BN22: 10 | BO22: 10 | BP22: 10 | BQ22: 10 | BR22: 10 | BS22: 10 | BT22: 0.01 | BU22: 1e-05 | BV22: 1e-05 | BW22: 0.01 | BX22: 0.01 | BY22: 1e-05 | BZ22: 0.01 | CA22: 1e-05 | CB22: 1e-05 | CC22: 1e-05 | CD22: 1e-05 | CE22: 1e-05 | CF22: 1e-05 | CG22: 1e-05 | CH22: 1e-05 | CI22: 0.01
C25: 0 | D25: 1 | E25: 2 | F25: 3 | G25: 4 | H25: 5 | I25: 6 | J25: 7 | K25: 8 | L25: 9 | M25: 10 | N25: 11 | O25: 12 | P25: 13 | Q25: 14 | R25: 15 | S25: 16 | T25: 17 | U25: 18 | V25: 19 | W25: 20 | X25: 21 | Y25: 22 | Z25: 23 | AA25: 24 | AB25: 25 | AC25: 26 | AD25: 27 | AE25: 28 | AF25: 29 | AG25: 30 | AH25: 31 | AI25: 32 | AJ25: 33 | AK25: 34 | AL25: 35 | AM25: 36 | AN25: 37 | AO25: 38 | AP25: 39 | AV25: 0 | AW25: 1 | AX25: 2 | AY25: 3 | AZ25: 4 | BA25: 5 | BB25: 6 | BC25: 7 | BD25: 8 | BE25: 9 | BF25: 10 | BG25: 11 | BH25: 12 | BI25: 13 | BJ25: 14 | BK25: 15 | BL25: 16 | BM25: 17 | BN25: 18 | BO25: 19 | BP25: 20 | BQ25: 21 | BR25: 22 | BS25: 23 | BT25: 24 | BU25: 25 | BV25: 26 | BW25: 27 | BX25: 28 | BY25: 29 | BZ25: 30 | CA25: 31 | CB25: 32 | CC25: 33 | CD25: 34 | CE25: 35 | CF25: 36 | CG25: 37 | CH25: 38 | CI25: 39
B26: 0 | C26: 4.971e-13 | D26: 4.9688e-13 | E26: 4.9674e-13 | F26: 4.9652e-13 | G26: 4.9657e-13 | H26: 4.9648e-13 | I26: 4.9634e-13 | J26: 4.9607e-13 | K26: 4.9605e-13 | L26: 4.9583e-13 | M26: 4.9582e-13 | N26: 4.9571e-13 | O26: 4.956e-13 | P26: 4.9551e-13 | Q26: 4.9543e-13 | R26: 4.9536e-13 | S26: 4.953e-13 | T26: 4.9526e-13 | U26: 4.9524e-13 | V26: 4.9524e-13 | W26: 4.9525e-13 | X26: 4.9529e-13 | Y26: 4.9535e-13 | Z26: 4.9543e-13 | AA26: 4.9553e-13 | AB26: 4.9565e-13 | AC26: 4.958e-13 | AD26: 4.9597e-13 | AE26: 4.9616e-13 | AF26: 4.9637e-13 | AG26: 4.965e-13 | AH26: 4.9672e-13 | AI26: 4.9706e-13 | AJ26: 4.9731e-13 | AK26: 4.9768e-13 | AL26: 4.9787e-13 | AM26: 4.9838e-13 | AN26: 4.9891e-13 | AO26: 4.9932e-13 | AP26: 4.9964e-13 | AR26: MAX | AS26: =MAX($C$26:$AP$45) -> 5.17e-13 | AU26: 0 | AV26: 4.971e-13 | AW26: 4.9688e-13 | AX26: 4.9674e-13 | AY26: 4.9652e-13 | AZ26: 4.9657e-13 | BA26: 4.9648e-13 | BB26: 4.9634e-13 | BC26: 4.9607e-13 | BD26: 4.9605e-13 | BE26: 4.9583e-13 | BF26: 4.9582e-13 | BG26: 4.9571e-13 | BH26: 4.956e-13 | BI26: 4.9551e-13 | BJ26: 4.9543e-13 | BK26: 4.9536e-13 | BL26: 4.953e-13 | BM26: 4.9526e-13 | BN26: 4.9524e-13 | BO26: 4.9524e-13 | BP26: 4.9525e-13 | BQ26: 4.9529e-13 | BR26: 4.9535e-13 | BS26: 4.9543e-13 | BT26: 4.9553e-13 | BU26: 4.9565e-13 | BV26: 4.958e-13 | BW26: 4.9597e-13 | BX26: 4.9616e-13 | BY26: 4.9637e-13 | BZ26: 4.965e-13 | CA26: 4.9672e-13 | CB26: 4.9706e-13 | CC26: 4.9731e-13 | CD26: 4.9768e-13 | CE26: 4.9787e-13 | CF26: 4.9838e-13 | CG26: 4.9891e-13 | CH26: 4.9932e-13 | CI26: 4.9964e-13
B27: 1 | C27: 5.0123e-13 | D27: 5.011e-13 | E27: 5.0096e-13 | F27: 5.0085e-13 | G27: 5.0064e-13 | H27: 5.0039e-13 | I27: 5.0021e-13 | J27: 4.9994e-13 | K27: 4.9974e-13 | L27: 4.9969e-13 | M27: 4.9961e-13 | N27: 4.9953e-13 | O27: 4.9946e-13 | P27: 4.9942e-13 | Q27: 4.9941e-13 | R27: 4.9942e-13 | S27: 4.9945e-13 | T27: 4.9952e-13 | U27: 4.9961e-13 | V27: 4.9972e-13 | W27: 4.9986e-13 | X27: 5.0002e-13 | Y27: 5.0021e-13 | Z27: 5.0042e-13 | AA27: 5.0065e-13 | AB27: 5.009e-13 | AC27: 5.0116e-13 | AD27: 5.0144e-13 | AE27: 5.0173e-13 | AF27: 5.0204e-13 | AG27: 5.0239e-13 | AH27: 5.027e-13 | AI27: 5.0296e-13 | AJ27: 5.0323e-13 | AK27: 5.0353e-13 | AL27: 5.0389e-13 | AM27: 5.0425e-13 | AN27: 5.0449e-13 | AO27: 5.0476e-13 | AP27: 5.0511e-13 | AR27: MIN | AS27: =MIN($C$26:$AP$45) -> 4.7805e-13 | AU27: 1 | AV27: 5.0123e-13 | AW27: 5.011e-13 | AX27: 5.0096e-13 | AY27: 5.0085e-13 | AZ27: 5.0064e-13 | BA27: 5.0039e-13 | BB27: 5.0021e-13 | BC27: 4.9994e-13 | BD27: 4.9974e-13 | BE27: 4.9969e-13 | BF27: 4.9961e-13 | BG27: 4.9953e-13 | BH27: 4.9946e-13 | BI27: 4.9942e-13 | BJ27: 4.9941e-13 | BK27: 4.9942e-13 | BL27: 4.9945e-13 | BM27: 4.9952e-13 | BN27: 4.9961e-13 | BO27: 4.9972e-13 | BP27: 4.9986e-13 | BQ27: 5.0002e-13 | BR27: 5.0021e-13 | BS27: 5.0042e-13 | BT27: 5.0065e-13 | BU27: 5.009e-13 | BV27: 5.0116e-13 | BW27: 5.0144e-13 | BX27: 5.0173e-13 | BY27: 5.0204e-13 | BZ27: 5.0239e-13 | CA27: 5.027e-13 | CB27: 5.0296e-13 | CC27: 5.0323e-13 | CD27: 5.0353e-13 | CE27: 5.0389e-13 | CF27: 5.0425e-13 | CG27: 5.0449e-13 | CH27: 5.0476e-13 | CI27: 5.0511e-13
B28: 2 | C28: 4.9018e-13 | D28: 4.9067e-13 | E28: 4.9104e-13 | F28: 4.9126e-13 | G28: 4.9168e-13 | H28: 4.9228e-13 | I28: 4.9252e-13 | J28: 4.9283e-13 | K28: 4.9316e-13 | L28: 4.9389e-13 | M28: 4.9415e-13 | N28: 4.9459e-13 | O28: 4.9504e-13 | P28: 4.955e-13 | Q28: 4.9596e-13 | R28: 4.9643e-13 | S28: 4.969e-13 | T28: 4.9736e-13 | U28: 4.9782e-13 | V28: 4.9828e-13 | W28: 4.9873e-13 | X28: 4.9917e-13 | Y28: 4.996e-13 | Z28: 5.0001e-13 | AA28: 5.0041e-13 | AB28: 5.0079e-13 | AC28: 5.0116e-13 | AD28: 5.015e-13 | AE28: 5.0181e-13 | AF28: 5.021e-13 | AG28: 5.0236e-13 | AH28: 5.0273e-13 | AI28: 5.0272e-13 | AJ28: 5.0295e-13 | AK28: 5.0297e-13 | AL28: 5.0308e-13 | AM28: 5.0307e-13 | AN28: 5.0304e-13 | AO28: 5.0302e-13 | AP28: 5.0301e-13 | AR28: AVE | AS28: =AVERAGE($C$26:$AP$45) -> 4.9111156e-13 | AU28: 2 | AV28: 4.9018e-13 | AW28: 4.9067e-13 | AX28: 4.9104e-13 | AY28: 4.9126e-13 | AZ28: 4.9168e-13 | BA28: 4.9228e-13 | BB28: 4.9252e-13 | BC28: 4.9283e-13 | BD28: 4.9316e-13 | BE28: 4.9389e-13 | BF28: 4.9415e-13 | BG28: 4.9459e-13 | BH28: 4.9504e-13 | BI28: 4.955e-13 | BJ28: 4.9596e-13 | BK28: 4.9643e-13 | BL28: 4.969e-13 | BM28: 4.9736e-13 | BN28: 4.9782e-13 | BO28: 4.9828e-13 | BP28: 4.9873e-13 | BQ28: 4.9917e-13 | BR28: 4.996e-13 | BS28: 5.0001e-13 | BT28: 5.0041e-13 | BU28: 5.0079e-13 | BV28: 5.0116e-13 | BW28: 5.015e-13 | BX28: 5.0181e-13 | BY28: 5.021e-13 | BZ28: 5.0236e-13 | CA28: 5.0273e-13 | CB28: 5.0272e-13 | CC28: 5.0295e-13 | CD28: 5.0297e-13 | CE28: 5.0308e-13 | CF28: 5.0307e-13 | CG28: 5.0304e-13 | CH28: 5.0302e-13 | CI28: 5.0301e-13
B29: 3 | C29: 4.82e-13 | D29: 4.8231e-13 | E29: 4.8268e-13 | F29: 4.83e-13 | G29: 4.8332e-13 | H29: 4.8381e-13 | I29: 4.841e-13 | J29: 4.8442e-13 | K29: 4.8488e-13 | L29: 4.8528e-13 | M29: 4.8574e-13 | N29: 4.8614e-13 | O29: 4.8655e-13 | P29: 4.8695e-13 | Q29: 4.8736e-13 | R29: 4.8776e-13 | S29: 4.8815e-13 | T29: 4.8854e-13 | U29: 4.8893e-13 | V29: 4.8931e-13 | W29: 4.8967e-13 | X29: 4.9003e-13 | Y29: 4.9037e-13 | Z29: 4.907e-13 | AA29: 4.9102e-13 | AB29: 4.9131e-13 | AC29: 4.9159e-13 | AD29: 4.9186e-13 | AE29: 4.921e-13 | AF29: 4.9232e-13 | AG29: 4.9251e-13 | AH29: 4.926e-13 | AI29: 4.9298e-13 | AJ29: 4.931e-13 | AK29: 4.9316e-13 | AL29: 4.9323e-13 | AM29: 4.931e-13 | AN29: 4.9313e-13 | AO29: 4.9298e-13 | AP29: 4.93e-13 | AR29: MED | AS29: =MEDIAN($C$26:$AP$45) -> 4.8793e-13 | AU29: 3 | AV29: 4.82e-13 | AW29: 4.8231e-13 | AX29: 4.8268e-13 | AY29: 4.83e-13 | AZ29: 4.8332e-13 | BA29: 4.8381e-13 | BB29: 4.841e-13 | BC29: 4.8442e-13 | BD29: 4.8488e-13 | BE29: 4.8528e-13 | BF29: 4.8574e-13 | BG29: 4.8614e-13 | BH29: 4.8655e-13 | BI29: 4.8695e-13 | BJ29: 4.8736e-13 | BK29: 4.8776e-13 | BL29: 4.8815e-13 | BM29: 4.8854e-13 | BN29: 4.8893e-13 | BO29: 4.8931e-13 | BP29: 4.8967e-13 | BQ29: 4.9003e-13 | BR29: 4.9037e-13 | BS29: 4.907e-13 | BT29: 4.9102e-13 | BU29: 4.9131e-13 | BV29: 4.9159e-13 | BW29: 4.9186e-13 | BX29: 4.921e-13 | BY29: 4.9232e-13 | BZ29: 4.9251e-13 | CA29: 4.926e-13 | CB29: 4.9298e-13 | CC29: 4.931e-13 | CD29: 4.9316e-13 | CE29: 4.9323e-13 | CF29: 4.931e-13 | CG29: 4.9313e-13 | CH29: 4.9298e-13 | CI29: 4.93e-13
B30: 4 | C30: 4.8908e-13 | D30: 4.8861e-13 | E30: 4.8814e-13 | F30: 4.8772e-13 | G30: 4.8729e-13 | H30: 4.8687e-13 | I30: 4.8642e-13 | J30: 4.8613e-13 | K30: 4.8573e-13 | L30: 4.8559e-13 | M30: 4.8505e-13 | N30: 4.8476e-13 | O30: 4.8451e-13 | P30: 4.8428e-13 | Q30: 4.8409e-13 | R30: 4.8393e-13 | S30: 4.838e-13 | T30: 4.837e-13 | U30: 4.8363e-13 | V30: 4.836e-13 | W30: 4.8359e-13 | X30: 4.8361e-13 | Y30: 4.8366e-13 | Z30: 4.8374e-13 | AA30: 4.8385e-13 | AB30: 4.8398e-13 | AC30: 4.8414e-13 | AD30: 4.8432e-13 | AE30: 4.8452e-13 | AF30: 4.8475e-13 | AG30: 4.8495e-13 | AH30: 4.8544e-13 | AI30: 4.8563e-13 | AJ30: 4.8588e-13 | AK30: 4.861e-13 | AL30: 4.8654e-13 | AM30: 4.8678e-13 | AN30: 4.8722e-13 | AO30: 4.8759e-13 | AP30: 4.8804e-13 | AR30: ST | AS30: =_xlfn.STDEV.S($C$26:$AP$45) -> 9.7020923e-15 | AU30: 4 | AV30: 4.8908e-13 | AW30: 4.8861e-13 | AX30: 4.8814e-13 | AY30: 4.8772e-13 | AZ30: 4.8729e-13 | BA30: 4.8687e-13 | BB30: 4.8642e-13 | BC30: 4.8613e-13 | BD30: 4.8573e-13 | BE30: 4.8559e-13 | BF30: 4.8505e-13 | BG30: 4.8476e-13 | BH30: 4.8451e-13 | BI30: 4.8428e-13 | BJ30: 4.8409e-13 | BK30: 4.8393e-13 | BL30: 4.838e-13 | BM30: 4.837e-13 | BN30: 4.8363e-13 | BO30: 4.836e-13 | BP30: 4.8359e-13 | BQ30: 4.8361e-13 | BR30: 4.8366e-13 | BS30: 4.8374e-13 | BT30: 4.8385e-13 | BU30: 4.8398e-13 | BV30: 4.8414e-13 | BW30: 4.8432e-13 | BX30: 4.8452e-13 | BY30: 4.8475e-13 | BZ30: 4.8495e-13 | CA30: 4.8544e-13 | CB30: 4.8563e-13 | CC30: 4.8588e-13 | CD30: 4.861e-13 | CE30: 4.8654e-13 | CF30: 4.8678e-13 | CG30: 4.8722e-13 | CH30: 4.8759e-13 | CI30: 4.8804e-13
B31: 5 | C31: 4.9123e-13 | D31: 4.9034e-13 | E31: 4.8955e-13 | F31: 4.8866e-13 | G31: 4.8781e-13 | H31: 4.8712e-13 | I31: 4.8664e-13 | J31: 4.859e-13 | K31: 4.8516e-13 | L31: 4.8455e-13 | M31: 4.8401e-13 | N31: 4.8348e-13 | O31: 4.83e-13 | P31: 4.8256e-13 | Q31: 4.8216e-13 | R31: 4.8181e-13 | S31: 4.8149e-13 | T31: 4.8122e-13 | U31: 4.8099e-13 | V31: 4.808e-13 | W31: 4.8065e-13 | X31: 4.8054e-13 | Y31: 4.8047e-13 | Z31: 4.8044e-13 | AA31: 4.8044e-13 | AB31: 4.8048e-13 | AC31: 4.8056e-13 | AD31: 4.8067e-13 | AE31: 4.8081e-13 | AF31: 4.8099e-13 | AG31: 4.8121e-13 | AH31: 4.8158e-13 | AI31: 4.8184e-13 | AJ31: 4.8227e-13 | AK31: 4.8244e-13 | AL31: 4.829e-13 | AM31: 4.8306e-13 | AN31: 4.8347e-13 | AO31: 4.8404e-13 | AP31: 4.845e-13 | AU31: 5 | AV31: 4.9123e-13 | AW31: 4.9034e-13 | AX31: 4.8955e-13 | AY31: 4.8866e-13 | AZ31: 4.8781e-13 | BA31: 4.8712e-13 | BB31: 4.8664e-13 | BC31: 4.859e-13 | BD31: 4.8516e-13 | BE31: 4.8455e-13 | BF31: 4.8401e-13 | BG31: 4.8348e-13 | BH31: 4.83e-13 | BI31: 4.8256e-13 | BJ31: 4.8216e-13 | BK31: 4.8181e-13 | BL31: 4.8149e-13 | BM31: 4.8122e-13 | BN31: 4.8099e-13 | BO31: 4.808e-13 | BP31: 4.8065e-13 | BQ31: 4.8054e-13 | BR31: 4.8047e-13 | BS31: 4.8044e-13 | BT31: 4.8044e-13 | BU31: 4.8048e-13 | BV31: 4.8056e-13 | BW31: 4.8067e-13 | BX31: 4.8081e-13 | BY31: 4.8099e-13 | BZ31: 4.8121e-13 | CA31: 4.8158e-13 | CB31: 4.8184e-13 | CC31: 4.8227e-13 | CD31: 4.8244e-13 | CE31: 4.829e-13 | CF31: 4.8306e-13 | CG31: 4.8347e-13 | CH31: 4.8404e-13 | CI31: 4.845e-13
B32: 6 | C32: 4.9055e-13 | D32: 4.8998e-13 | E32: 4.8934e-13 | F32: 4.8857e-13 | G32: 4.8771e-13 | H32: 4.8699e-13 | I32: 4.864e-13 | J32: 4.8591e-13 | K32: 4.8528e-13 | L32: 4.8475e-13 | M32: 4.8411e-13 | N32: 4.8358e-13 | O32: 4.8308e-13 | P32: 4.8262e-13 | Q32: 4.8218e-13 | R32: 4.8178e-13 | S32: 4.8141e-13 | T32: 4.8108e-13 | U32: 4.8078e-13 | V32: 4.8051e-13 | W32: 4.8028e-13 | X32: 4.8009e-13 | Y32: 4.7994e-13 | Z32: 4.7982e-13 | AA32: 4.7974e-13 | AB32: 4.7969e-13 | AC32: 4.7969e-13 | AD32: 4.7972e-13 | AE32: 4.7978e-13 | AF32: 4.7988e-13 | AG32: 4.8002e-13 | AH32: 4.803e-13 | AI32: 4.8041e-13 | AJ32: 4.8055e-13 | AK32: 4.8091e-13 | AL32: 4.8121e-13 | AM32: 4.816e-13 | AN32: 4.8187e-13 | AO32: 4.823e-13 | AP32: 4.8249e-13 | AU32: 6 | AV32: 4.9055e-13 | AW32: 4.8998e-13 | AX32: 4.8934e-13 | AY32: 4.8857e-13 | AZ32: 4.8771e-13 | BA32: 4.8699e-13 | BB32: 4.864e-13 | BC32: 4.8591e-13 | BD32: 4.8528e-13 | BE32: 4.8475e-13 | BF32: 4.8411e-13 | BG32: 4.8358e-13 | BH32: 4.8308e-13 | BI32: 4.8262e-13 | BJ32: 4.8218e-13 | BK32: 4.8178e-13 | BL32: 4.8141e-13 | BM32: 4.8108e-13 | BN32: 4.8078e-13 | BO32: 4.8051e-13 | BP32: 4.8028e-13 | BQ32: 4.8009e-13 | BR32: 4.7994e-13 | BS32: 4.7982e-13 | BT32: 4.7974e-13 | BU32: 4.7969e-13 | BV32: 4.7969e-13 | BW32: 4.7972e-13 | BX32: 4.7978e-13 | BY32: 4.7988e-13 | BZ32: 4.8002e-13 | CA32: 4.803e-13 | CB32: 4.8041e-13 | CC32: 4.8055e-13 | CD32: 4.8091e-13 | CE32: 4.8121e-13 | CF32: 4.816e-13 | CG32: 4.8187e-13 | CH32: 4.823e-13 | CI32: 4.8249e-13
B33: 7 | C33: 4.9354e-13 | D33: 4.9305e-13 | E33: 4.9275e-13 | F33: 4.9224e-13 | G33: 4.9186e-13 | H33: 4.9114e-13 | I33: 4.9054e-13 | J33: 4.8999e-13 | K33: 4.8921e-13 | L33: 4.8881e-13 | M33: 4.8826e-13 | N33: 4.8767e-13 | O33: 4.8708e-13 | P33: 4.865e-13 | Q33: 4.8593e-13 | R33: 4.8538e-13 | S33: 4.8484e-13 | T33: 4.8433e-13 | U33: 4.8383e-13 | V33: 4.8336e-13 | W33: 4.8292e-13 | X33: 4.8251e-13 | Y33: 4.8213e-13 | Z33: 4.8178e-13 | AA33: 4.8147e-13 | AB33: 4.812e-13 | AC33: 4.8097e-13 | AD33: 4.8078e-13 | AE33: 4.8063e-13 | AF33: 4.8053e-13 | AG33: 4.8057e-13 | AH33: 4.806e-13 | AI33: 4.8041e-13 | AJ33: 4.8061e-13 | AK33: 4.8065e-13 | AL33: 4.8098e-13 | AM33: 4.8127e-13 | AN33: 4.815e-13 | AO33: 4.8199e-13 | AP33: 4.8225e-13 | AS33: =MAX($AV$26:$CI$45) -> 5.17e-13 | AU33: 7 | AV33: 4.9354e-13 | AW33: 4.9305e-13 | AX33: 4.9275e-13 | AY33: 4.9224e-13 | AZ33: 4.9186e-13 | BA33: 4.9114e-13 | BB33: 4.9054e-13 | BC33: 4.8999e-13 | BD33: 4.8921e-13 | BE33: 4.8881e-13 | BF33: 4.8826e-13 | BG33: 4.8767e-13 | BH33: 4.8708e-13 | BI33: 4.865e-13 | BJ33: 4.8593e-13 | BK33: 4.8538e-13 | BL33: 4.8484e-13 | BM33: 4.8433e-13 | BN33: 4.8383e-13 | BO33: 4.8336e-13 | BP33: 4.8292e-13 | BQ33: 4.8251e-13 | BR33: 4.8213e-13 | BS33: 4.8178e-13 | BT33: 4.8147e-13 | BU33: 4.812e-13 | BV33: 4.8097e-13 | BW33: 4.8078e-13 | BX33: 4.8063e-13 | BY33: 4.8053e-13 | BZ33: 4.8057e-13 | CA33: 4.806e-13 | CB33: 4.8041e-13 | CC33: 4.8061e-13 | CD33: 4.8065e-13 | CE33: 4.8098e-13 | CF33: 4.8127e-13 | CG33: 4.815e-13 | CH33: 4.8199e-13 | CI33: 4.8225e-13
B34: 8 | C34: 4.8359e-13 | D34: 4.8346e-13 | E34: 4.8338e-13 | F34: 4.8344e-13 | G34: 4.8307e-13 | H34: 4.8319e-13 | I34: 4.8296e-13 | J34: 4.8261e-13 | K34: 4.8245e-13 | L34: 4.8207e-13 | M34: 4.8199e-13 | N34: 4.8175e-13 | O34: 4.8151e-13 | P34: 4.8126e-13 | Q34: 4.81e-13 | R34: 4.8075e-13 | S34: 4.8049e-13 | T34: 4.8024e-13 | U34: 4.8e-13 | V34: 4.7976e-13 | W34: 4.7954e-13 | X34: 4.7933e-13 | Y34: 4.7915e-13 | Z34: 4.7898e-13 | AA34: 4.7884e-13 | AB34: 4.7873e-13 | AC34: 4.7865e-13 | AD34: 4.786e-13 | AE34: 4.7859e-13 | AF34: 4.7861e-13 | AG34: 4.7851e-13 | AH34: 4.788e-13 | AI34: 4.7893e-13 | AJ34: 4.7891e-13 | AK34: 4.7947e-13 | AL34: 4.7983e-13 | AM34: 4.8024e-13 | AN34: 4.8051e-13 | AO34: 4.8086e-13 | AP34: 4.8151e-13 | AS34: =MIN($AV$26:$CI$45) -> 4.7805e-13 | AU34: 8 | AV34: 4.8359e-13 | AW34: 4.8346e-13 | AX34: 4.8338e-13 | AY34: 4.8344e-13 | AZ34: 4.8307e-13 | BA34: 4.8319e-13 | BB34: 4.8296e-13 | BC34: 4.8261e-13 | BD34: 4.8245e-13 | BE34: 4.8207e-13 | BF34: 4.8199e-13 | BG34: 4.8175e-13 | BH34: 4.8151e-13 | BI34: 4.8126e-13 | BJ34: 4.81e-13 | BK34: 4.8075e-13 | BL34: 4.8049e-13 | BM34: 4.8024e-13 | BN34: 4.8e-13 | BO34: 4.7976e-13 | BP34: 4.7954e-13 | BQ34: 4.7933e-13 | BR34: 4.7915e-13 | BS34: 4.7898e-13 | BT34: 4.7884e-13 | BU34: 4.7873e-13 | BV34: 4.7865e-13 | BW34: 4.786e-13 | BX34: 4.7859e-13 | BY34: 4.7861e-13 | BZ34: 4.7851e-13 | CA34: 4.788e-13 | CB34: 4.7893e-13 | CC34: 4.7891e-13 | CD34: 4.7947e-13 | CE34: 4.7983e-13 | CF34: 4.8024e-13 | CG34: 4.8051e-13 | CH34: 4.8086e-13 | CI34: 4.8151e-13
B35: 9 | C35: 4.8377e-13 | D35: 4.844e-13 | E35: 4.8455e-13 | F35: 4.849e-13 | G35: 4.8524e-13 | H35: 4.8555e-13 | I35: 4.8587e-13 | J35: 4.8606e-13 | K35: 4.8618e-13 | L35: 4.8654e-13 | M35: 4.8673e-13 | N35: 4.869e-13 | O35: 4.8705e-13 | P35: 4.8718e-13 | Q35: 4.8728e-13 | R35: 4.8737e-13 | S35: 4.8743e-13 | T35: 4.8747e-13 | U35: 4.875e-13 | V35: 4.8751e-13 | W35: 4.8751e-13 | X35: 4.8749e-13 | Y35: 4.8746e-13 | Z35: 4.8742e-13 | AA35: 4.8737e-13 | AB35: 4.8732e-13 | AC35: 4.8727e-13 | AD35: 4.8721e-13 | AE35: 4.8716e-13 | AF35: 4.8711e-13 | AG35: 4.8706e-13 | AH35: 4.8711e-13 | AI35: 4.8714e-13 | AJ35: 4.8719e-13 | AK35: 4.8709e-13 | AL35: 4.8702e-13 | AM35: 4.8715e-13 | AN35: 4.8723e-13 | AO35: 4.8717e-13 | AP35: 4.8718e-13 | AS35: =AVERAGE($AV$26:$CI$45) -> 4.9111156e-13 | AU35: 9 | AV35: 4.8377e-13 | AW35: 4.844e-13 | AX35: 4.8455e-13 | AY35: 4.849e-13 | AZ35: 4.8524e-13 | BA35: 4.8555e-13 | BB35: 4.8587e-13 | BC35: 4.8606e-13 | BD35: 4.8618e-13 | BE35: 4.8654e-13 | BF35: 4.8673e-13 | BG35: 4.869e-13 | BH35: 4.8705e-13 | BI35: 4.8718e-13 | BJ35: 4.8728e-13 | BK35: 4.8737e-13 | BL35: 4.8743e-13 | BM35: 4.8747e-13 | BN35: 4.875e-13 | BO35: 4.8751e-13 | BP35: 4.8751e-13 | BQ35: 4.8749e-13 | BR35: 4.8746e-13 | BS35: 4.8742e-13 | BT35: 4.8737e-13 | BU35: 4.8732e-13 | BV35: 4.8727e-13 | BW35: 4.8721e-13 | BX35: 4.8716e-13 | BY35: 4.8711e-13 | BZ35: 4.8706e-13 | CA35: 4.8711e-13 | CB35: 4.8714e-13 | CC35: 4.8719e-13 | CD35: 4.8709e-13 | CE35: 4.8702e-13 | CF35: 4.8715e-13 | CG35: 4.8723e-13 | CH35: 4.8717e-13 | CI35: 4.8718e-13
B36: 10 | C36: 4.9447e-13 | D36: 4.9526e-13 | E36: 4.9576e-13 | F36: 4.9646e-13 | G36: 4.9723e-13 | H36: 4.9795e-13 | I36: 4.9852e-13 | J36: 4.9923e-13 | K36: 4.9993e-13 | L36: 5.0038e-13 | M36: 5.0097e-13 | N36: 5.0152e-13 | O36: 5.0203e-13 | P36: 5.0252e-13 | Q36: 5.0299e-13 | R36: 5.0342e-13 | S36: 5.0383e-13 | T36: 5.0422e-13 | U36: 5.0458e-13 | V36: 5.0491e-13 | W36: 5.0522e-13 | X36: 5.0551e-13 | Y36: 5.0577e-13 | Z36: 5.0601e-13 | AA36: 5.0623e-13 | AB36: 5.0642e-13 | AC36: 5.066e-13 | AD36: 5.0676e-13 | AE36: 5.069e-13 | AF36: 5.0702e-13 | AG36: 5.0693e-13 | AH36: 5.0713e-13 | AI36: 5.0708e-13 | AJ36: 5.0725e-13 | AK36: 5.0726e-13 | AL36: 5.073e-13 | AM36: 5.0763e-13 | AN36: 5.0757e-13 | AO36: 5.0761e-13 | AP36: 5.0773e-13 | AS36: =MEDIAN($AV$26:$CI$45) -> 4.8793e-13 | AU36: 10 | AV36: 4.9447e-13 | AW36: 4.9526e-13 | AX36: 4.9576e-13 | AY36: 4.9646e-13 | AZ36: 4.9723e-13 | BA36: 4.9795e-13 | BB36: 4.9852e-13 | BC36: 4.9923e-13 | BD36: 4.9993e-13 | BE36: 5.0038e-13 | BF36: 5.0097e-13 | BG36: 5.0152e-13 | BH36: 5.0203e-13 | BI36: 5.0252e-13 | BJ36: 5.0299e-13 | BK36: 5.0342e-13 | BL36: 5.0383e-13 | BM36: 5.0422e-13 | BN36: 5.0458e-13 | BO36: 5.0491e-13 | BP36: 5.0522e-13 | BQ36: 5.0551e-13 | BR36: 5.0577e-13 | BS36: 5.0601e-13 | BT36: 5.0623e-13 | BU36: 5.0642e-13 | BV36: 5.066e-13 | BW36: 5.0676e-13 | BX36: 5.069e-13 | BY36: 5.0702e-13 | BZ36: 5.0693e-13 | CA36: 5.0713e-13 | CB36: 5.0708e-13 | CC36: 5.0725e-13 | CD36: 5.0726e-13 | CE36: 5.073e-13 | CF36: 5.0763e-13 | CG36: 5.0757e-13 | CH36: 5.0761e-13 | CI36: 5.0773e-13
B37: 11 | C37: 5.0176e-13 | D37: 5.0234e-13 | E37: 5.0312e-13 | F37: 5.0405e-13 | G37: 5.0444e-13 | H37: 5.0515e-13 | I37: 5.0597e-13 | J37: 5.0663e-13 | K37: 5.0712e-13 | L37: 5.0778e-13 | M37: 5.0845e-13 | N37: 5.0904e-13 | O37: 5.096e-13 | P37: 5.1014e-13 | Q37: 5.1067e-13 | R37: 5.1117e-13 | S37: 5.1165e-13 | T37: 5.1211e-13 | U37: 5.1255e-13 | V37: 5.1298e-13 | W37: 5.1338e-13 | X37: 5.1376e-13 | Y37: 5.1412e-13 | Z37: 5.1446e-13 | AA37: 5.1478e-13 | AB37: 5.1508e-13 | AC37: 5.1536e-13 | AD37: 5.1561e-13 | AE37: 5.1584e-13 | AF37: 5.1605e-13 | AG37: 5.1625e-13 | AH37: 5.1648e-13 | AI37: 5.1655e-13 | AJ37: 5.1657e-13 | AK37: 5.167e-13 | AL37: 5.1683e-13 | AM37: 5.1696e-13 | AN37: 5.17e-13 | AO37: 5.1677e-13 | AP37: 5.1679e-13 | AS37: =_xlfn.STDEV.S($AV$26:$CI$45) -> 9.7020923e-15 | AU37: 11 | AV37: 5.0176e-13 | AW37: 5.0234e-13 | AX37: 5.0312e-13 | AY37: 5.0405e-13 | AZ37: 5.0444e-13 | BA37: 5.0515e-13 | BB37: 5.0597e-13 | BC37: 5.0663e-13 | BD37: 5.0712e-13 | BE37: 5.0778e-13 | BF37: 5.0845e-13 | BG37: 5.0904e-13 | BH37: 5.096e-13 | BI37: 5.1014e-13 | BJ37: 5.1067e-13 | BK37: 5.1117e-13 | BL37: 5.1165e-13 | BM37: 5.1211e-13 | BN37: 5.1255e-13 | BO37: 5.1298e-13 | BP37: 5.1338e-13 | BQ37: 5.1376e-13 | BR37: 5.1412e-13 | BS37: 5.1446e-13 | BT37: 5.1478e-13 | BU37: 5.1508e-13 | BV37: 5.1536e-13 | BW37: 5.1561e-13 | BX37: 5.1584e-13 | BY37: 5.1605e-13 | BZ37: 5.1625e-13 | CA37: 5.1648e-13 | CB37: 5.1655e-13 | CC37: 5.1657e-13 | CD37: 5.167e-13 | CE37: 5.1683e-13 | CF37: 5.1696e-13 | CG37: 5.17e-13 | CH37: 5.1677e-13 | CI37: 5.1679e-13
B38: 12 | C38: 5.0078e-13 | D38: 5.0148e-13 | E38: 5.0212e-13 | F38: 5.0248e-13 | G38: 5.0315e-13 | H38: 5.0375e-13 | I38: 5.0427e-13 | J38: 5.0478e-13 | K38: 5.0532e-13 | L38: 5.0609e-13 | M38: 5.0649e-13 | N38: 5.0698e-13 | O38: 5.0743e-13 | P38: 5.0786e-13 | Q38: 5.0826e-13 | R38: 5.0864e-13 | S38: 5.0898e-13 | T38: 5.0929e-13 | U38: 5.0958e-13 | V38: 5.0983e-13 | W38: 5.1005e-13 | X38: 5.1024e-13 | Y38: 5.104e-13 | Z38: 5.1052e-13 | AA38: 5.1061e-13 | AB38: 5.1066e-13 | AC38: 5.1068e-13 | AD38: 5.1067e-13 | AE38: 5.1062e-13 | AF38: 5.1054e-13 | AG38: 5.1049e-13 | AH38: 5.1033e-13 | AI38: 5.0992e-13 | AJ38: 5.0982e-13 | AK38: 5.0955e-13 | AL38: 5.093e-13 | AM38: 5.0906e-13 | AN38: 5.0867e-13 | AO38: 5.0821e-13 | AP38: 5.0776e-13 | AU38: 12 | AV38: 5.0078e-13 | AW38: 5.0148e-13 | AX38: 5.0212e-13 | AY38: 5.0248e-13 | AZ38: 5.0315e-13 | BA38: 5.0375e-13 | BB38: 5.0427e-13 | BC38: 5.0478e-13 | BD38: 5.0532e-13 | BE38: 5.0609e-13 | BF38: 5.0649e-13 | BG38: 5.0698e-13 | BH38: 5.0743e-13 | BI38: 5.0786e-13 | BJ38: 5.0826e-13 | BK38: 5.0864e-13 | BL38: 5.0898e-13 | BM38: 5.0929e-13 | BN38: 5.0958e-13 | BO38: 5.0983e-13 | BP38: 5.1005e-13 | BQ38: 5.1024e-13 | BR38: 5.104e-13 | BS38: 5.1052e-13 | BT38: 5.1061e-13 | BU38: 5.1066e-13 | BV38: 5.1068e-13 | BW38: 5.1067e-13 | BX38: 5.1062e-13 | BY38: 5.1054e-13 | BZ38: 5.1049e-13 | CA38: 5.1033e-13 | CB38: 5.0992e-13 | CC38: 5.0982e-13 | CD38: 5.0955e-13 | CE38: 5.093e-13 | CF38: 5.0906e-13 | CG38: 5.0867e-13 | CH38: 5.0821e-13 | CI38: 5.0776e-13
B39: 13 | C39: 4.9939e-13 | D39: 4.9956e-13 | E39: 4.9976e-13 | F39: 4.9972e-13 | G39: 4.9986e-13 | H39: 5.0021e-13 | I39: 4.9997e-13 | J39: 5.0014e-13 | K39: 5.0023e-13 | L39: 5.0016e-13 | M39: 5.0017e-13 | N39: 5.0015e-13 | O39: 5.0011e-13 | P39: 5.0005e-13 | Q39: 4.9997e-13 | R39: 4.9987e-13 | S39: 4.9975e-13 | T39: 4.9962e-13 | U39: 4.9948e-13 | V39: 4.9932e-13 | W39: 4.9914e-13 | X39: 4.9896e-13 | Y39: 4.9876e-13 | Z39: 4.9855e-13 | AA39: 4.9833e-13 | AB39: 4.9811e-13 | AC39: 4.9787e-13 | AD39: 4.9763e-13 | AE39: 4.9738e-13 | AF39: 4.9713e-13 | AG39: 4.9693e-13 | AH39: 4.9662e-13 | AI39: 4.9657e-13 | AJ39: 4.9633e-13 | AK39: 4.9586e-13 | AL39: 4.9561e-13 | AM39: 4.9515e-13 | AN39: 4.948e-13 | AO39: 4.9457e-13 | AP39: 4.9436e-13 | AU39: 13 | AV39: 4.9939e-13 | AW39: 4.9956e-13 | AX39: 4.9976e-13 | AY39: 4.9972e-13 | AZ39: 4.9986e-13 | BA39: 5.0021e-13 | BB39: 4.9997e-13 | BC39: 5.0014e-13 | BD39: 5.0023e-13 | BE39: 5.0016e-13 | BF39: 5.0017e-13 | BG39: 5.0015e-13 | BH39: 5.0011e-13 | BI39: 5.0005e-13 | BJ39: 4.9997e-13 | BK39: 4.9987e-13 | BL39: 4.9975e-13 | BM39: 4.9962e-13 | BN39: 4.9948e-13 | BO39: 4.9932e-13 | BP39: 4.9914e-13 | BQ39: 4.9896e-13 | BR39: 4.9876e-13 | BS39: 4.9855e-13 | BT39: 4.9833e-13 | BU39: 4.9811e-13 | BV39: 4.9787e-13 | BW39: 4.9763e-13 | BX39: 4.9738e-13 | BY39: 4.9713e-13 | BZ39: 4.9693e-13 | CA39: 4.9662e-13 | CB39: 4.9657e-13 | CC39: 4.9633e-13 | CD39: 4.9586e-13 | CE39: 4.9561e-13 | CF39: 4.9515e-13 | CG39: 4.948e-13 | CH39: 4.9457e-13 | CI39: 4.9436e-13
B40: 14 | C40: 4.9791e-13 | D40: 4.9756e-13 | E40: 4.9711e-13 | F40: 4.9668e-13 | G40: 4.9598e-13 | H40: 4.9542e-13 | I40: 4.9479e-13 | J40: 4.9422e-13 | K40: 4.936e-13 | L40: 4.9326e-13 | M40: 4.9244e-13 | N40: 4.9181e-13 | O40: 4.9117e-13 | P40: 4.9054e-13 | Q40: 4.8992e-13 | R40: 4.893e-13 | S40: 4.887e-13 | T40: 4.8811e-13 | U40: 4.8754e-13 | V40: 4.87e-13 | W40: 4.8647e-13 | X40: 4.8596e-13 | Y40: 4.8549e-13 | Z40: 4.8504e-13 | AA40: 4.8462e-13 | AB40: 4.8424e-13 | AC40: 4.8389e-13 | AD40: 4.8357e-13 | AE40: 4.8328e-13 | AF40: 4.8303e-13 | AG40: 4.8268e-13 | AH40: 4.8251e-13 | AI40: 4.8237e-13 | AJ40: 4.8234e-13 | AK40: 4.8218e-13 | AL40: 4.8212e-13 | AM40: 4.8218e-13 | AN40: 4.8235e-13 | AO40: 4.8231e-13 | AP40: 4.8217e-13 | AU40: 14 | AV40: 4.9791e-13 | AW40: 4.9756e-13 | AX40: 4.9711e-13 | AY40: 4.9668e-13 | AZ40: 4.9598e-13 | BA40: 4.9542e-13 | BB40: 4.9479e-13 | BC40: 4.9422e-13 | BD40: 4.936e-13 | BE40: 4.9326e-13 | BF40: 4.9244e-13 | BG40: 4.9181e-13 | BH40: 4.9117e-13 | BI40: 4.9054e-13 | BJ40: 4.8992e-13 | BK40: 4.893e-13 | BL40: 4.887e-13 | BM40: 4.8811e-13 | BN40: 4.8754e-13 | BO40: 4.87e-13 | BP40: 4.8647e-13 | BQ40: 4.8596e-13 | BR40: 4.8549e-13 | BS40: 4.8504e-13 | BT40: 4.8462e-13 | BU40: 4.8424e-13 | BV40: 4.8389e-13 | BW40: 4.8357e-13 | BX40: 4.8328e-13 | BY40: 4.8303e-13 | BZ40: 4.8268e-13 | CA40: 4.8251e-13 | CB40: 4.8237e-13 | CC40: 4.8234e-13 | CD40: 4.8218e-13 | CE40: 4.8212e-13 | CF40: 4.8218e-13 | CG40: 4.8235e-13 | CH40: 4.8231e-13 | CI40: 4.8217e-13
B41: 15 | C41: 4.9303e-13 | D41: 4.9261e-13 | E41: 4.9207e-13 | F41: 4.914e-13 | G41: 4.9095e-13 | H41: 4.9044e-13 | I41: 4.9013e-13 | J41: 4.8941e-13 | K41: 4.888e-13 | L41: 4.8842e-13 | M41: 4.8782e-13 | N41: 4.8731e-13 | O41: 4.8681e-13 | P41: 4.8633e-13 | Q41: 4.8587e-13 | R41: 4.8543e-13 | S41: 4.85e-13 | T41: 4.846e-13 | U41: 4.8423e-13 | V41: 4.8388e-13 | W41: 4.8356e-13 | X41: 4.8327e-13 | Y41: 4.83e-13 | Z41: 4.8277e-13 | AA41: 4.8257e-13 | AB41: 4.8241e-13 | AC41: 4.8227e-13 | AD41: 4.8217e-13 | AE41: 4.8211e-13 | AF41: 4.8208e-13 | AG41: 4.8211e-13 | AH41: 4.8213e-13 | AI41: 4.8225e-13 | AJ41: 4.8235e-13 | AK41: 4.8243e-13 | AL41: 4.8262e-13 | AM41: 4.8275e-13 | AN41: 4.8299e-13 | AO41: 4.8324e-13 | AP41: 4.8352e-13 | AU41: 15 | AV41: 4.9303e-13 | AW41: 4.9261e-13 | AX41: 4.9207e-13 | AY41: 4.914e-13 | AZ41: 4.9095e-13 | BA41: 4.9044e-13 | BB41: 4.9013e-13 | BC41: 4.8941e-13 | BD41: 4.888e-13 | BE41: 4.8842e-13 | BF41: 4.8782e-13 | BG41: 4.8731e-13 | BH41: 4.8681e-13 | BI41: 4.8633e-13 | BJ41: 4.8587e-13 | BK41: 4.8543e-13 | BL41: 4.85e-13 | BM41: 4.846e-13 | BN41: 4.8423e-13 | BO41: 4.8388e-13 | BP41: 4.8356e-13 | BQ41: 4.8327e-13 | BR41: 4.83e-13 | BS41: 4.8277e-13 | BT41: 4.8257e-13 | BU41: 4.8241e-13 | BV41: 4.8227e-13 | BW41: 4.8217e-13 | BX41: 4.8211e-13 | BY41: 4.8208e-13 | BZ41: 4.8211e-13 | CA41: 4.8213e-13 | CB41: 4.8225e-13 | CC41: 4.8235e-13 | CD41: 4.8243e-13 | CE41: 4.8262e-13 | CF41: 4.8275e-13 | CG41: 4.8299e-13 | CH41: 4.8324e-13 | CI41: 4.8352e-13
B42: 16 | C42: 4.892e-13 | D42: 4.8922e-13 | E42: 4.8899e-13 | F42: 4.8898e-13 | G42: 4.8896e-13 | H42: 4.8898e-13 | I42: 4.8898e-13 | J42: 4.8917e-13 | K42: 4.8917e-13 | L42: 4.8918e-13 | M42: 4.8931e-13 | N42: 4.8941e-13 | O42: 4.8953e-13 | P42: 4.8966e-13 | Q42: 4.898e-13 | R42: 4.8995e-13 | S42: 4.9012e-13 | T42: 4.9029e-13 | U42: 4.9046e-13 | V42: 4.9064e-13 | W42: 4.9083e-13 | X42: 4.9102e-13 | Y42: 4.9121e-13 | Z42: 4.914e-13 | AA42: 4.916e-13 | AB42: 4.9179e-13 | AC42: 4.9198e-13 | AD42: 4.9218e-13 | AE42: 4.9237e-13 | AF42: 4.9256e-13 | AG42: 4.9277e-13 | AH42: 4.9307e-13 | AI42: 4.9334e-13 | AJ42: 4.9334e-13 | AK42: 4.9355e-13 | AL42: 4.9358e-13 | AM42: 4.9374e-13 | AN42: 4.9392e-13 | AO42: 4.9408e-13 | AP42: 4.9414e-13 | AU42: 16 | AV42: 4.892e-13 | AW42: 4.8922e-13 | AX42: 4.8899e-13 | AY42: 4.8898e-13 | AZ42: 4.8896e-13 | BA42: 4.8898e-13 | BB42: 4.8898e-13 | BC42: 4.8917e-13 | BD42: 4.8917e-13 | BE42: 4.8918e-13 | BF42: 4.8931e-13 | BG42: 4.8941e-13 | BH42: 4.8953e-13 | BI42: 4.8966e-13 | BJ42: 4.898e-13 | BK42: 4.8995e-13 | BL42: 4.9012e-13 | BM42: 4.9029e-13 | BN42: 4.9046e-13 | BO42: 4.9064e-13 | BP42: 4.9083e-13 | BQ42: 4.9102e-13 | BR42: 4.9121e-13 | BS42: 4.914e-13 | BT42: 4.916e-13 | BU42: 4.9179e-13 | BV42: 4.9198e-13 | BW42: 4.9218e-13 | BX42: 4.9237e-13 | BY42: 4.9256e-13 | BZ42: 4.9277e-13 | CA42: 4.9307e-13 | CB42: 4.9334e-13 | CC42: 4.9334e-13 | CD42: 4.9355e-13 | CE42: 4.9358e-13 | CF42: 4.9374e-13 | CG42: 4.9392e-13 | CH42: 4.9408e-13 | CI42: 4.9414e-13
B43: 17 | C43: 4.8165e-13 | D43: 4.8138e-13 | E43: 4.8113e-13 | F43: 4.8098e-13 | G43: 4.8086e-13 | H43: 4.8063e-13 | I43: 4.8059e-13 | J43: 4.8064e-13 | K43: 4.8051e-13 | L43: 4.8053e-13 | M43: 4.8064e-13 | N43: 4.8073e-13 | O43: 4.8085e-13 | P43: 4.8099e-13 | Q43: 4.8117e-13 | R43: 4.8138e-13 | S43: 4.8161e-13 | T43: 4.8186e-13 | U43: 4.8214e-13 | V43: 4.8243e-13 | W43: 4.8275e-13 | X43: 4.8307e-13 | Y43: 4.8341e-13 | Z43: 4.8376e-13 | AA43: 4.8412e-13 | AB43: 4.8448e-13 | AC43: 4.8485e-13 | AD43: 4.8522e-13 | AE43: 4.8559e-13 | AF43: 4.8597e-13 | AG43: 4.8628e-13 | AH43: 4.8681e-13 | AI43: 4.8716e-13 | AJ43: 4.8759e-13 | AK43: 4.8778e-13 | AL43: 4.8824e-13 | AM43: 4.8848e-13 | AN43: 4.8889e-13 | AO43: 4.8936e-13 | AP43: 4.8967e-13 | AU43: 17 | AV43: 4.8165e-13 | AW43: 4.8138e-13 | AX43: 4.8113e-13 | AY43: 4.8098e-13 | AZ43: 4.8086e-13 | BA43: 4.8063e-13 | BB43: 4.8059e-13 | BC43: 4.8064e-13 | BD43: 4.8051e-13 | BE43: 4.8053e-13 | BF43: 4.8064e-13 | BG43: 4.8073e-13 | BH43: 4.8085e-13 | BI43: 4.8099e-13 | BJ43: 4.8117e-13 | BK43: 4.8138e-13 | BL43: 4.8161e-13 | BM43: 4.8186e-13 | BN43: 4.8214e-13 | BO43: 4.8243e-13 | BP43: 4.8275e-13 | BQ43: 4.8307e-13 | BR43: 4.8341e-13 | BS43: 4.8376e-13 | BT43: 4.8412e-13 | BU43: 4.8448e-13 | BV43: 4.8485e-13 | BW43: 4.8522e-13 | BX43: 4.8559e-13 | BY43: 4.8597e-13 | BZ43: 4.8628e-13 | CA43: 4.8681e-13 | CB43: 4.8716e-13 | CC43: 4.8759e-13 | CD43: 4.8778e-13 | CE43: 4.8824e-13 | CF43: 4.8848e-13 | CG43: 4.8889e-13 | CH43: 4.8936e-13 | CI43: 4.8967e-13
...

Sheet Z_08
B1: HET | C1: =C2/B2 -> 1
B2: =AVERAGE(B6:B2046) -> 0.074812968 | C2: =AVERAGE(C6:C2046) -> 0.074812968 | E2: =MAX(B$6:B$2046) -> 40 | F2: =MAX(C$6:C$2046) -> 40 | AZ2: =COLUMN()-COLUMN(AY2) -> 1 | BT2: =COLUMN()-COLUMN(AZ1) -> 20 | AFU2: =COLUMN()-COLUMN(AFT2) -> 1 | AGO2: =COLUMN()-COLUMN(AFU1) -> 20 | AGQ2: =COLUMN()-COLUMN(AGP2) -> 1 | AHK2: =COLUMN()-COLUMN(AGQ1) -> 20 | AHM2: =COLUMN()-COLUMN(AHL2) -> 1 | AIG2: =COLUMN()-COLUMN(AHM1) -> 20
B3: =COUNT(B6:B4887) -> 802 | C3: =COUNT(C6:C4887) -> 802 | E3: =MIN(B$6:B$2046) -> 4.7805e-13 | F3: =MIN(C$6:C$2046) -> 2.252e-13 | AZ3: =AZ4 -> 0 | CN3: =CN4 -> 1 | EB3: =EB4 -> 2 | FP3: =FP4 -> 3
A4: -1 | B4: =INDEX(B$6:B$807,B$3+$A4,1) -> 20 | C4: =INDEX(C$6:C$807,C$3+$A4,1) -> 20 | E4: =AVERAGE(B$6:B$2046) -> 0.074812968 | F4: =AVERAGE(C$6:C$2046) -> 0.074812968 | AZ4: 0 | BA4: 0 | BB4: 0 | BC4: 0 | BD4: 0 | BE4: 0 | BF4: 0 | BG4: 0 | BH4: 0 | BI4: 0 | BJ4: 0 | BK4: 0 | BL4: 0 | BM4: 0 | BN4: 0 | BO4: 0 | BP4: 0 | BQ4: 0 | BR4: 0 | BS4: 0 | BT4: 0 | BU4: 0 | BV4: 0 | BW4: 0 | BX4: 0 | BY4: 0 | BZ4: 0 | CA4: 0 | CB4: 0 | CC4: 0 | CD4: 0 | CE4: 0 | CF4: 0 | CG4: 0 | CH4: 0 | CI4: 0 | CJ4: 0 | CK4: 0 | CL4: 0 | CM4: 0 | CN4: =AZ4+1 -> 1 | CO4: =BA4+1 -> 1 | CP4: =BB4+1 -> 1 | CQ4: =BC4+1 -> 1 | CR4: =BD4+1 -> 1 | CS4: =BE4+1 -> 1 | CT4: =BF4+1 -> 1 | CU4: =BG4+1 -> 1 | ... AFS4: =AEE4+1 -> 19 | AIJ4: 0 | AIK4: 1 | AIL4: 2 | AIM4: 50 | AIR4: =MAX(AIR7:AKF7) -> 40
A5: 0 | B5: =INDEX(B$6:B$807,B$3+$A5,1) -> 40 | C5: =INDEX(C$6:C$807,C$3+$A5,1) -> 40 | E5: =MEDIAN(B$6:B$2046) -> 4.88075e-13 | F5: =MEDIAN(C$6:C$2046) -> 6.94525e-13 | I5: a | AW5: b | AZ5: 0 | BA5: 1 | BB5: 2 | BC5: 3 | BD5: 4 | BE5: 5 | BF5: 6 | BG5: 7 | BH5: 8 | BI5: 9 | BJ5: 10 | BK5: 11 | BL5: 12 | BM5: 13 | BN5: 14 | BO5: 15 | BP5: 16 | BQ5: 17 | BR5: 18 | BS5: 19 | BT5: 20 | BU5: 21 | BV5: 22 | BW5: 23 | BX5: 24 | BY5: 25 | BZ5: 26 | CA5: 27 | CB5: 28 | CC5: 29 | CD5: 30 | CE5: 31 | CF5: 32 | CG5: 33 | CH5: 34 | CI5: 35 | CJ5: 36 | CK5: 37 | CL5: 38 | CM5: 39 | CN5: =AZ5 -> 0 | CO5: =BA5 -> 1 | CP5: =BB5 -> 2 | CQ5: =BC5 -> 3 | CR5: =BD5 -> 4 | CS5: =BE5 -> 5 | CT5: =BF5 -> 6 | CU5: =BG5 -> 7 | ... AFS5: =AEE5 -> 39 | AFU5: =AFV5+AGO5 -> 19 | AFV5: =AFW5+AGO5 -> 58 | AFW5: =AFX5+AGO5 -> 97 | AFX5: =AFY5+AGO5 -> 136 | AFY5: =AFZ5+AGO5 -> 175 | AFZ5: =AGA5+AGO5 -> 214 | AGA5: =AGB5+AGO5 -> 253 | AGB5: =AGC5+AGO5 -> 292 | AGC5: =AGD5+AGO5 -> 331 | AGD5: =AGE5+AGO5 -> 370 | AGE5: =AGF5+AGO5 -> 409 | AGF5: =AGG5+AGO5 -> 448 | AGG5: =AGH5+AGO5 -> 487 | AGH5: =AGI5+AGO5 -> 526 | AGI5: =AGJ5+AGO5 -> 565 | AGJ5: =AGK5+AGO5 -> 604 | AGK5: =AGL5+AGO5 -> 643 | AGL5: =AGM5+AGO5 -> 682 | AGM5: =AGN5+AGO5 -> 721 | AGN5: =$AFS7+AGO5 -> 760 | AGO5: -39 | AGQ5: =AGR5+AHK5 -> 399 | AGR5: =AGS5+AHK5 -> 419 | AGS5: =AGT5+AHK5 -> 439 | AGT5: =AGU5+AHK5 -> 459 | AGU5: =AGV5+AHK5 -> 479 | AGV5: =AGW5+AHK5 -> 499 | AGW5: =AGX5+AHK5 -> 519 | AGX5: =AGY5+AHK5 -> 539 | AGY5: =AGZ5+AHK5 -> 559 | AGZ5: =AHA5+AHK5 -> 579 | AHA5: =AHB5+AHK5 -> 599 | AHB5: =AHC5+AHK5 -> 619 | AHC5: =AHD5+AHK5 -> 639 | AHD5: =AHE5+AHK5 -> 659 | AHE5: =AHF5+AHK5 -> 679 | AHF5: =AHG5+AHK5 -> 699 | AHG5: =AHH5+AHK5 -> 719 | AHH5: =AHI5+AHK5 -> 739 | AHI5: =AHJ5+AHK5 -> 759 | AHJ5: =$AFS7+AHK5 -> 779 | AHK5: -20 | AHM5: =AHN5+AIG5 -> 799 | AHN5: =AHO5+AIG5 -> 799 | AHO5: =AHP5+AIG5 -> 799 | AHP5: =AHQ5+AIG5 -> 799 | AHQ5: =AHR5+AIG5 -> 799 | AHR5: =AHS5+AIG5 -> 799 | AHS5: =AHT5+AIG5 -> 799 | AHT5: =AHU5+AIG5 -> 799 | AHU5: =AHV5+AIG5 -> 799 | AHV5: =AHW5+AIG5 -> 799 | AHW5: =AHX5+AIG5 -> 799 | AHX5: =AHY5+AIG5 -> 799 | AHY5: =AHZ5+AIG5 -> 799 | AHZ5: =AIA5+AIG5 -> 799 | AIA5: =AIB5+AIG5 -> 799 | AIB5: =AIC5+AIG5 -> 799 | AIC5: =AID5+AIG5 -> 799 | AID5: =AIE5+AIG5 -> 799 | AIE5: =AIF5+AIG5 -> 799 | AIF5: =$AFS7+AIG5 -> 799 | AIG5: 0 | AIJ5: ↓ | AIL5: ↓ | AIR5: =MAX(AIR8:AIR27) -> 20
B6: 4.971e-13 | C6: 5.8603e-13 | AY6: C_all[0].csv | AII6: anis_perm_field
